[{"e": "depthUpdate", "E": 1604221202123, "s": "ETHBTC", "U": 1737811487, "u": 1737811534, "b": [["0.02818300", "0.00000000"], ["0.02818200", "6.00000000"], ["0.02818100", "32.69300000"], ["0.02818000", "0.32000000"], ["0.02817600", "34.64700000"], ["0.02817300", "9.30700000"], ["0.02817100", "17.93000000"], ["0.02816800", "19.50200000"], ["0.02816700", "18.88500000"], ["0.02816500", "0.00000000"], ["0.02816400", "1.60000000"], ["0.02816000", "60.55900000"], ["0.02815600", "11.54400000"], ["0.02815300", "5.09800000"], ["0.02813600", "0.00800000"], ["0.02805400", "0.10400000"], ["0.02805100", "0.42100000"], ["0.02789900", "0.09000000"], ["0.02789600", "1.15600000"], ["0.02780400", "1.63000000"], ["0.02764600", "0.00400000"], ["0.02764200", "0.02900000"], ["0.02719100", "0.06300000"], ["0.02681200", "13.69400000"]], "a": [["0.02818300", "118.49700000"], ["0.02818400", "24.00400000"], ["0.02818800", "0.00000000"], ["0.02819400", "9.14500000"], ["0.02819500", "6.05400000"], ["0.02819600", "15.96500000"], ["0.02819700", "15.04000000"], ["0.02819900", "68.51800000"], ["0.02820100", "4.03700000"], ["0.02820400", "12.11100000"], ["0.02998000", "6.18600000"]]}, {"e": "depthUpdate", "E": 1604221203123, "s": "ETHBTC", "U": 1737811535, "u": 1737811578, "b": [["0.02818200", "0.00000000"], ["0.02818100", "1.66600000"], ["0.02818000", "0.17000000"], ["0.02817900", "0.21400000"], ["0.02817800", "1.00000000"], ["0.02817600", "32.93600000"], ["0.02817500", "22.39200000"], ["0.02817300", "7.09700000"], ["0.02816300", "7.32800000"], ["0.02815400", "5.38500000"], ["0.02815200", "0.00400000"], ["0.02811000", "74.42700000"], ["0.02790900", "0.26600000"], ["0.02790800", "1.08500000"], ["0.02790600", "0.06700000"], ["0.02790000", "5.03200000"], ["0.02789600", "0.94800000"], ["0.02789100", "0.31200000"], ["0.02769000", "0.00000000"]], "a": [["0.02818200", "107.47700000"], ["0.02818300", "24.00000000"], ["0.02818700", "1.00000000"], ["0.02818800", "4.00000000"], ["0.02818900", "6.71100000"], ["0.02819400", "24.06000000"], ["0.02819500", "6.05400000"], ["0.02819700", "0.12500000"], ["0.02819900", "63.13300000"], ["0.02820300", "45.75700000"]]}, {"e": "depthUpdate", "E": 1604221204123, "s": "ETHBTC", "U": 1737811579, "u": 1737811609, "b": [["0.02818100", "7.66600000"], ["0.02817500", "20.68100000"], ["0.02817400", "4.05700000"], ["0.02816800", "7.09800000"], ["0.02816200", "16.06600000"], ["0.02815500", "16.44200000"], ["0.02811200", "0.05000000"], ["0.02788200", "0.06400000"], ["0.02781000", "3.10400000"], ["0.02761600", "0.00400000"], ["0.02741900", "0.00000000"]], "a": [["0.02818200", "111.47700000"], ["0.02818500", "12.99800000"], ["0.02818600", "0.00000000"], ["0.02818800", "0.00000000"], ["0.02823500", "0.00000000"]]}, {"e": "depthUpdate", "E": 1604221205123, "s": "ETHBTC", "U": 1737811610, "u": 1737811624, "b": [["0.02818100", "1.66600000"], ["0.02815600", "16.92800000"], ["0.02815400", "0.00000000"], ["0.02815200", "0.00000000"], ["0.02805100", "0.00800000"], ["0.02804000", "0.41300000"], ["0.02376100", "0.05800000"]], "a": [["0.02818500", "13.02900000"]]}, {"e": "depthUpdate", "E": 1604221206123, "s": "ETHBTC", "U": 1737811625, "u": 1737811664, "b": [["0.02818100", "1.66600000"], ["0.02815500", "4.33100000"], ["0.02809300", "33.24800000"]], "a": [["0.02818500", "13.05500000"], ["0.02818600", "4.00000000"], ["0.02819200", "2.66800000"], ["0.02819300", "14.91500000"], ["0.02819400", "9.14500000"], ["0.02819500", "7.43700000"], ["0.02819800", "9.48600000"], ["0.02826900", "0.00400000"], ["0.02998000", "5.05900000"]]}, {"e": "depthUpdate", "E": 1604221207123, "s": "ETHBTC", "U": 1737811665, "u": 1737811713, "b": [["0.02818100", "1.66600000"], ["0.02817400", "15.05700000"], ["0.02817300", "0.00000000"], ["0.02816200", "36.25200000"], ["0.02816000", "40.37300000"], ["0.02815800", "1.34600000"], ["0.02815700", "24.13000000"], ["0.02815600", "29.03900000"], ["0.02815300", "19.90200000"], ["0.02815000", "0.00000000"], ["0.02813800", "2.01000000"], ["0.02812200", "0.00000000"], ["0.02809300", "32.04700000"], ["0.02789300", "6.16400000"], ["0.01760200", "0.05000000"]], "a": [["0.02818500", "13.10000000"], ["0.02819200", "17.58300000"], ["0.02819300", "0.00000000"], ["0.02998000", "6.18600000"]]}, {"e": "depthUpdate", "E": 1604221208123, "s": "ETHBTC", "U": 1737811714, "u": 1737811744, "b": [["0.02818100", "1.66600000"], ["0.02816500", "7.09800000"], ["0.02804000", "0.00000000"], ["0.02803500", "0.74100000"], ["0.02681200", "1.69900000"], ["0.01494200", "0.04500000"]], "a": [["0.02818200", "107.47700000"], ["0.02818500", "12.89300000"], ["0.02818700", "5.00000000"], ["0.02818800", "0.20400000"], ["0.02819200", "2.66800000"], ["0.02819300", "14.91500000"]]}, {"e": "depthUpdate", "E": 1604221209123, "s": "ETHBTC", "U": 1737811745, "u": 1737811762, "b": [["0.02818100", "1.66600000"], ["0.02816500", "0.00000000"], ["0.02816400", "8.69700000"], ["0.02813700", "0.00000000"], ["0.02811100", "64.28900000"], ["0.02681100", "12.20500000"]], "a": [["0.02818700", "5.25100000"], ["0.02818800", "0.00000000"], ["0.02819200", "17.58300000"], ["0.02819300", "0.00000000"], ["0.02855300", "4.52100000"]]}, {"e": "depthUpdate", "E": 1604221210123, "s": "ETHBTC", "U": 1737811763, "u": 1737811780, "b": [["0.02817400", "13.34600000"], ["0.02817300", "1.71100000"], ["0.02816400", "1.60000000"], ["0.02816200", "43.35000000"], ["0.02815800", "1.34600000"], ["0.02809300", "33.24800000"], ["0.02803500", "0.32800000"], ["0.02803300", "0.41300000"]], "a": [["0.02818200", "111.50200000"], ["0.02818700", "1.25100000"], ["0.02819200", "17.58300000"], ["0.02819300", "0.00000000"], ["0.02819500", "27.62300000"], ["0.02819900", "42.94700000"]]}, {"e": "depthUpdate", "E": 1604221211125, "s": "ETHBTC", "U": 1737811781, "u": 1737811879, "b": [["0.02818100", "7.66600000"], ["0.02818000", "0.00000000"], ["0.02817900", "0.00000000"], ["0.02817700", "0.00000000"], ["0.02817600", "24.93600000"], ["0.02817500", "19.84900000"], ["0.02817400", "11.00000000"], ["0.02817300", "0.00000000"], ["0.02817200", "0.00000000"], ["0.02817100", "0.00000000"], ["0.02817000", "12.77800000"], ["0.02816700", "12.89300000"], ["0.02816600", "2.34600000"], ["0.02816500", "15.02700000"], ["0.02816300", "10.92800000"], ["0.02816200", "13.37500000"], ["0.02816100", "12.89200000"], ["0.02816000", "0.00000000"], ["0.02815900", "2.69100000"], ["0.02815700", "32.13000000"], ["0.02815600", "11.54400000"], ["0.02815500", "9.71300000"], ["0.02815300", "5.09800000"], ["0.02815000", "12.11100000"], ["0.02814800", "40.37400000"], ["0.02812100", "0.01000000"], ["0.02810800", "0.84300000"], ["0.02809300", "32.04700000"], ["0.02809200", "0.90000000"], ["0.02795100", "3.71000000"]], "a": [["0.02818200", "110.16500000"], ["0.02818300", "24.24600000"], ["0.02818400", "24.00400000"], ["0.02818500", "20.99100000"], ["0.02818700", "47.53000000"], ["0.02818800", "4.00000000"], ["0.02818900", "6.71100000"], ["0.02819100", "0.00000000"], ["0.02819200", "0.00000000"], ["0.02819300", "0.00000000"], ["0.02819400", "6.45300000"], ["0.02819500", "27.33000000"], ["0.02819600", "8.86900000"], ["0.02819700", "15.04000000"], ["0.02820000", "45.96400000"], ["0.02820300", "5.38400000"], ["0.02820600", "7.38500000"], ["0.02820700", "0.58500000"], ["0.02827500", "0.02800000"], ["0.02998000", "5.05900000"], ["0.03093600", "0.01700000"]]}, {"e": "depthUpdate", "E": 1604221212124, "s": "ETHBTC", "U": 1737811880, "u": 1737811963, "b": [["0.02818100", "0.00000000"], ["0.02817900", "0.00000000"], ["0.02817800", "0.00000000"], ["0.02817700", "5.41700000"], ["0.02817600", "19.98300000"], ["0.02817400", "12.00000000"], ["0.02817300", "0.00000000"], ["0.02817100", "0.00000000"], ["0.02816900", "3.66600000"], ["0.02816800", "0.00000000"], ["0.02816500", "7.93000000"], ["0.02816300", "10.92800000"], ["0.02816000", "10.26500000"], ["0.02815900", "5.03500000"], ["0.02815700", "9.65000000"], ["0.02815600", "13.49600000"], ["0.02815500", "12.40400000"], ["0.02815100", "4.03600000"], ["0.02815000", "12.10800000"], ["0.02814500", "14.80000000"], ["0.02813100", "0.00000000"], ["0.02812000", "0.30000000"], ["0.02809200", "0.00000000"]], "a": [["0.02818000", "88.76400000"], ["0.02818200", "30.68800000"], ["0.02818400", "0.00400000"], ["0.02818900", "1.71100000"], ["0.02819200", "0.00000000"], ["0.02819300", "0.00000000"], ["0.02819400", "21.36800000"], ["0.02819500", "30.02100000"], ["0.02819600", "1.77200000"], ["0.02819700", "0.12500000"], ["0.02998000", "6.18600000"]]}, {"e": "depthUpdate", "E": 1604221213124, "s": "ETHBTC", "U": 1737811964, "u": 1737812021, "b": [["0.02817800", "0.00000000"], ["0.02817700", "0.00000000"], ["0.02817600", "14.93600000"], ["0.02817500", "24.26700000"], ["0.02817400", "11.00000000"], ["0.02817100", "11.00000000"], ["0.02817000", "5.16000000"], ["0.02816900", "3.55000000"], ["0.02816800", "0.00000000"], ["0.02815900", "12.13500000"], ["0.02815600", "7.50700000"], ["0.02815400", "0.00400000"], ["0.02814100", "0.00000000"], ["0.02812400", "70.64900000"], ["0.02809000", "1.13600000"], ["0.02803300", "0.00000000"], ["0.02803100", "0.43100000"], ["0.02764200", "0.01000000"], ["0.01760200", "0.01200000"]], "a": [["0.02817800", "111.50000000"], ["0.02817900", "24.11900000"], ["0.02818000", "0.00000000"], ["0.02818100", "0.00000000"], ["0.02818300", "0.24600000"], ["0.02818600", "18.91500000"], ["0.02818700", "47.53000000"], ["0.02818800", "7.09900000"], ["0.02819000", "17.89200000"], ["0.02819200", "12.79600000"], ["0.02819400", "6.45300000"], ["0.02819500", "29.75100000"], ["0.02819600", "0.00000000"], ["0.02820500", "7.09500000"], ["0.03125600", "0.14700000"]]}, {"e": "depthUpdate", "E": 1604221214124, "s": "ETHBTC", "U": 1737812022, "u": 1737812046, "b": [["0.02817600", "16.87100000"], ["0.02817500", "20.84900000"], ["0.02817400", "11.18100000"], ["0.02817300", "0.00000000"], ["0.02816800", "1.71000000"], ["0.02816400", "8.69900000"], ["0.02815900", "5.03500000"], ["0.02815500", "7.02200000"], ["0.02815100", "9.41700000"], ["0.02811000", "0.16600000"], ["0.02809000", "1.03600000"], ["0.02753300", "0.01700000"], ["0.02702400", "0.00800000"], ["0.02681200", "1.65300000"], ["0.02681100", "12.25100000"], ["0.01494200", "0.00000000"]], "a": [["0.02819300", "1.67400000"], ["0.02820000", "68.74800000"], ["0.02867900", "0.05300000"]]}, {"e": "depthUpdate", "E": 1604221215124, "s": "ETHBTC", "U": 1737812047, "u": 1737812082, "b": [["0.02817400", "0.26300000"], ["0.02817000", "0.00000000"], ["0.02816400", "1.60000000"], ["0.02815500", "4.33100000"], ["0.02815400", "0.00000000"], ["0.02815200", "2.69100000"], ["0.02813800", "0.00000000"], ["0.02812500", "64.31200000"], ["0.02812300", "2.03600000"], ["0.02811100", "0.00900000"], ["0.02809000", "1.33700000"], ["0.02807800", "25.44800000"], ["0.02788900", "0.04700000"], ["0.02764400", "0.07600000"]], "a": [["0.02818100", "5.00000000"], ["0.02818400", "0.29200000"], ["0.02818600", "19.18500000"], ["0.02819000", "12.89200000"], ["0.02819100", "21.52600000"], ["0.02819400", "0.00000000"], ["0.02819500", "9.56500000"], ["0.02820500", "0.00000000"], ["0.02820800", "0.00000000"], ["0.02864400", "0.23200000"]]}, {"e": "depthUpdate", "E": 1604221216124, "s": "ETHBTC", "U": 1737812083, "u": 1737812109, "b": [["0.02817400", "0.00000000"], ["0.02817300", "0.00000000"], ["0.02817200", "0.28100000"], ["0.02817100", "11.00000000"], ["0.02816800", "0.00000000"], ["0.02816700", "0.00000000"], ["0.02816300", "38.87100000"], ["0.02815900", "12.13500000"], ["0.02815800", "0.00000000"], ["0.02815700", "8.00000000"], ["0.02815400", "1.34500000"], ["0.02815200", "15.57800000"], ["0.02814700", "36.50000000"], ["0.02814500", "20.18200000"], ["0.02809000", "1.03600000"], ["0.02741900", "6.93200000"]], "a": [["0.02818800", "13.54900000"], ["0.02827200", "0.87400000"], ["0.02869100", "0.00000000"], ["0.02998000", "6.18600000"]]}, {"e": "depthUpdate", "E": 1604221217124, "s": "ETHBTC", "U": 1737812110, "u": 1737812151, "b": [["0.02817700", "1.00000000"], ["0.02817600", "11.94600000"], ["0.02817500", "20.08400000"], ["0.02817400", "0.00000000"], ["0.02817200", "0.00000000"], ["0.02817100", "11.00000000"], ["0.02816400", "14.00400000"], ["0.02816200", "0.97100000"], ["0.02815900", "5.03500000"], ["0.02815200", "17.22100000"], ["0.02814800", "40.37400000"], ["0.02809000", "1.33700000"]], "a": [["0.02817800", "107.50000000"], ["0.02817900", "24.00000000"], ["0.02818000", "0.19100000"], ["0.02818100", "0.00000000"], ["0.02818200", "26.68800000"], ["0.02818400", "0.29200000"], ["0.02818900", "5.71100000"], ["0.02819400", "9.00000000"], ["0.02819600", "12.10600000"], ["0.02820400", "0.00000000"], ["0.02854900", "4.32100000"], ["0.02855300", "0.00000000"], ["0.02855400", "50.04000000"], ["0.02857500", "8.24500000"], ["0.03099100", "17.19000000"]]}, {"e": "depthUpdate", "E": 1604221218124, "s": "ETHBTC", "U": 1737812152, "u": 1737812168, "b": [["0.02817700", "1.00000000"], ["0.02817500", "19.84900000"], ["0.02817300", "0.24600000"], ["0.02817200", "2.34600000"], ["0.02816900", "14.55000000"], ["0.02816700", "1.71000000"], ["0.02816600", "0.00000000"], ["0.02816400", "15.61500000"], ["0.02816000", "16.25400000"], ["0.02815800", "7.10000000"], ["0.02815200", "15.57800000"], ["0.02809000", "0.46200000"]], "a": [["0.02819300", "7.05600000"], ["0.02819400", "4.00000000"], ["0.02820300", "0.00000000"]]}, {"e": "depthUpdate", "E": 1604221219124, "s": "ETHBTC", "U": 1737812169, "u": 1737812200, "b": [["0.02817700", "1.00400000"], ["0.02817500", "19.84900000"], ["0.02817400", "0.18500000"], ["0.02817300", "0.00000000"], ["0.02816300", "43.90600000"], ["0.02816200", "8.06900000"], ["0.02815900", "0.00000000"], ["0.02815800", "0.00000000"], ["0.02813700", "2.01000000"], ["0.02812300", "0.02600000"], ["0.02809000", "0.13600000"], ["0.02808900", "1.00000000"], ["0.02795800", "0.00000000"], ["0.02791600", "0.91200000"]], "a": [["0.02818600", "24.18500000"], ["0.02818900", "1.71100000"], ["0.02819100", "1.34500000"], ["0.02819400", "8.00000000"], ["0.02819500", "29.74300000"], ["0.02837400", "16.06100000"], ["0.02838000", "0.07900000"]]}, {"e": "depthUpdate", "E": 1604221220124, "s": "ETHBTC", "U": 1737812201, "u": 1737812219, "b": [["0.02817600", "12.09100000"], ["0.02817500", "20.10400000"], ["0.02817400", "0.00000000"], ["0.02814600", "0.00000000"], ["0.02808900", "1.20100000"], ["0.02796300", "0.24100000"], ["0.02793200", "0.33000000"]], "a": [["0.02818300", "0.00000000"], ["0.02818400", "0.29200000"], ["0.02818900", "5.71100000"], ["0.02819400", "4.00000000"], ["0.02819500", "24.36000000"], ["0.02819600", "0.00000000"], ["0.02819800", "21.59200000"], ["0.02819900", "48.32800000"], ["0.02998000", "5.05900000"]]}, {"e": "depthUpdate", "E": 1604221221124, "s": "ETHBTC", "U": 1737812220, "u": 1737812242, "b": [["0.02817700", "100.00400000"], ["0.02817600", "5.96900000"], ["0.02815200", "15.57800000"], ["0.02815000", "12.10800000"], ["0.02809000", "1.33700000"], ["0.02808900", "0.00000000"]], "a": [["0.02817800", "107.40000000"], ["0.02819500", "25.70500000"], ["0.02819800", "20.24600000"], ["0.02827200", "0.00000000"], ["0.02998000", "6.18600000"]]}, {"e": "depthUpdate", "E": 1604221222124, "s": "ETHBTC", "U": 1737812243, "u": 1737812273, "b": [["0.02817700", "104.21200000"], ["0.02817600", "12.07000000"], ["0.02817200", "0.00000000"], ["0.02816700", "4.05600000"], ["0.02791600", "1.44800000"], ["0.02790300", "0.38500000"], ["0.02706500", "14.85600000"]], "a": [["0.02817800", "107.40000000"], ["0.02818000", "0.00000000"], ["0.02818100", "0.19300000"], ["0.02818400", "4.00400000"], ["0.02818900", "5.99900000"], ["0.02819400", "0.00000000"], ["0.02819800", "8.14000000"], ["0.02820600", "19.49100000"]]}, {"e": "depthUpdate", "E": 1604221223124, "s": "ETHBTC", "U": 1737812274, "u": 1737812293, "b": [["0.02817700", "1.00400000"], ["0.02817600", "11.92500000"], ["0.02815200", "35.75400000"], ["0.02814800", "0.00000000"], ["0.02814300", "40.35300000"], ["0.02813800", "0.00400000"], ["0.02809000", "0.13600000"], ["0.02622800", "0.00000000"]], "a": [["0.02818000", "0.22200000"], ["0.02818100", "4.00000000"], ["0.02818900", "1.99900000"], ["0.02820000", "83.54600000"], ["0.02820500", "7.09500000"], ["0.02822000", "0.00000000"]]}, {"e": "depthUpdate", "E": 1604221224124, "s": "ETHBTC", "U": 1737812294, "u": 1737812320, "b": [["0.02817600", "11.92500000"], ["0.02817200", "0.00000000"], ["0.02816700", "1.71000000"], ["0.02816500", "10.27600000"], ["0.02816300", "21.12200000"], ["0.02816200", "0.97100000"], ["0.02815700", "8.00000000"], ["0.02789600", "0.95200000"], ["0.02705900", "0.00400000"]], "a": [["0.02817900", "24.26300000"], ["0.02818000", "0.13200000"], ["0.02818100", "4.00000000"], ["0.02818200", "26.68800000"], ["0.02819200", "12.79600000"], ["0.02819500", "25.70300000"], ["0.02820000", "68.74800000"], ["0.02820400", "14.79800000"], ["0.02820500", "0.00000000"], ["0.02854900", "0.12800000"]]}, {"e": "depthUpdate", "E": 1604221225124, "s": "ETHBTC", "U": 1737812321, "u": 1737812328, "b": [["0.02816600", "0.00000000"], ["0.02814800", "0.00000000"], ["0.02813800", "0.00000000"], ["0.02622200", "5.70400000"]], "a": [["0.02827200", "1.16500000"], ["0.02998000", "5.05900000"]]}, {"e": "depthUpdate", "E": 1604221226124, "s": "ETHBTC", "U": 1737812329, "u": 1737812343, "b": [["0.02817700", "0.99500000"], ["0.02817600", "12.07600000"], ["0.02817000", "1.71000000"], ["0.02816900", "27.43600000"], ["0.02816700", "0.00000000"], ["0.02816600", "7.09800000"], ["0.02815600", "30.29100000"], ["0.02815200", "22.86700000"], ["0.02812400", "70.74900000"]], "a": [["0.02817900", "24.00000000"], ["0.02818100", "0.00000000"], ["0.02818900", "5.99900000"], ["0.02854900", "4.35900000"], ["0.02998000", "6.18600000"]]}, {"e": "depthUpdate", "E": 1604221227124, "s": "ETHBTC", "U": 1737812344, "u": 1737812362, "b": [["0.02817700", "132.99900000"], ["0.02817600", "12.01500000"], ["0.02817200", "2.34600000"], ["0.02816500", "7.93000000"], ["0.02812400", "70.64900000"]], "a": [["0.02818400", "0.00400000"], ["0.02818900", "5.99900000"], ["0.02819200", "15.48600000"], ["0.02819300", "11.05600000"], ["0.02819500", "23.01200000"], ["0.03958700", "0.24300000"]]}, {"e": "depthUpdate", "E": 1604221228124, "s": "ETHBTC", "U": 1737812363, "u": 1737812428, "b": [["0.02817900", "2.34600000"], ["0.02817800", "7.11400000"], ["0.02817700", "132.00400000"], ["0.02817600", "5.97500000"], ["0.02817500", "19.84900000"], ["0.02817300", "11.00000000"], ["0.02817200", "3.60000000"], ["0.02816500", "7.09800000"], ["0.02816400", "3.21100000"], ["0.02816300", "12.48700000"], ["0.02816100", "12.89200000"], ["0.02815600", "7.50700000"], ["0.02815500", "24.50800000"], ["0.02815200", "2.69100000"], ["0.02815100", "21.52400000"], ["0.02815000", "0.00000000"], ["0.02814700", "76.85300000"], ["0.02814300", "0.00000000"], ["0.02812600", "12.40400000"], ["0.02803100", "0.01800000"], ["0.02681200", "0.00000000"]], "a": [["0.02817800", "0.00000000"], ["0.02817900", "0.00000000"], ["0.02818000", "0.00000000"], ["0.02818100", "0.00000000"], ["0.02818200", "24.32200000"], ["0.02818300", "0.26300000"], ["0.02818500", "30.99100000"], ["0.02818600", "9.27000000"], ["0.02818900", "8.66200000"], ["0.02819100", "16.26000000"], ["0.02820900", "7.09400000"], ["0.02827200", "0.87400000"], ["0.02854900", "0.12800000"]]}, {"e": "depthUpdate", "E": 1604221229124, "s": "ETHBTC", "U": 1737812429, "u": 1737812461, "b": [["0.02817900", "0.00000000"], ["0.02817800", "6.04000000"], ["0.02817700", "132.16200000"], ["0.02817200", "5.94600000"], ["0.02816700", "0.83200000"], ["0.02816500", "12.13100000"], ["0.02803600", "0.41300000"], ["0.02681100", "13.90400000"]], "a": [["0.02818100", "0.28900000"], ["0.02818200", "24.02500000"], ["0.02818400", "4.00400000"], ["0.02819300", "7.05600000"], ["0.02819600", "4.03600000"], ["0.02820100", "0.00000000"]]}, {"e": "depthUpdate", "E": 1604221230124, "s": "ETHBTC", "U": 1737812462, "u": 1737812511, "b": [["0.02818000", "6.04000000"], ["0.02817900", "24.00000000"], ["0.02817800", "0.83200000"], ["0.02817700", "132.12600000"], ["0.02817600", "5.82400000"], ["0.02817500", "19.84900000"], ["0.02817200", "2.34600000"], ["0.02817100", "14.60000000"], ["0.02816700", "0.00000000"], ["0.02816600", "0.00000000"], ["0.02816200", "0.97100000"], ["0.02815500", "27.19800000"], ["0.02815400", "24.12900000"], ["0.02815200", "0.00000000"]], "a": [["0.02818000", "0.00000000"], ["0.02818100", "0.00000000"], ["0.02818300", "0.39600000"], ["0.02818400", "0.00400000"], ["0.02818600", "13.27000000"], ["0.02818900", "4.66200000"], ["0.02819300", "11.05600000"], ["0.02820900", "7.09400000"], ["0.02998000", "6.18600000"]]}, {"e": "depthUpdate", "E": 1604221231124, "s": "ETHBTC", "U": 1737812512, "u": 1737812553, "b": [["0.02818000", "0.00000000"], ["0.02817900", "0.00000000"], ["0.02817800", "0.00000000"], ["0.02817700", "132.00400000"], ["0.02817600", "6.11100000"], ["0.02817500", "19.84900000"], ["0.02816700", "7.09800000"], ["0.02816600", "0.83200000"], ["0.02814900", "5.39200000"], ["0.02814500", "14.80000000"], ["0.02814400", "0.00000000"], ["0.02651900", "0.85900000"]], "a": [["0.02817900", "23.99600000"], ["0.02818000", "10.17400000"], ["0.02818100", "107.50000000"], ["0.02818300", "0.26300000"], ["0.02818500", "19.99100000"], ["0.02818600", "24.18500000"], ["0.02819100", "1.34500000"], ["0.02819300", "13.74700000"], ["0.02819800", "5.44800000"], ["0.02820900", "0.00000000"], ["0.02837400", "0.06100000"], ["0.02837700", "16.09000000"], ["0.03499000", "1.11500000"]]}, {"e": "depthUpdate", "E": 1604221232124, "s": "ETHBTC", "U": 1737812554, "u": 1737812572, "b": [["0.02817600", "6.02000000"], ["0.02817500", "19.84900000"]], "a": [["0.02818000", "10.17400000"], ["0.02819200", "35.66400000"], ["0.02819500", "2.83600000"], ["0.02819700", "40.48100000"], ["0.02820000", "28.37400000"], ["0.03957000", "1.12000000"]]}, {"e": "depthUpdate", "E": 1604221233124, "s": "ETHBTC", "U": 1737812573, "u": 1737812601, "b": [["0.02817700", "132.00400000"], ["0.02817200", "13.34600000"], ["0.02815700", "28.17700000"], ["0.02815500", "7.02100000"], ["0.02815000", "0.00400000"], ["0.02814900", "45.74600000"], ["0.02814700", "36.50000000"], ["0.02803600", "0.00000000"], ["0.02803100", "0.43100000"], ["0.02790700", "0.00400000"]], "a": [["0.02818000", "10.03800000"], ["0.02818100", "107.75200000"], ["0.02819600", "4.10100000"], ["0.02819800", "5.38300000"]]}, {"e": "depthUpdate", "E": 1604221234125, "s": "ETHBTC", "U": 1737812602, "u": 1737812664, "b": [["0.02817900", "135.00000000"], ["0.02817800", "6.61500000"], ["0.02817700", "24.22500000"], ["0.02817600", "5.92400000"], ["0.02817500", "19.84900000"], ["0.02817300", "0.00000000"], ["0.02817200", "0.00000000"], ["0.02817100", "3.60000000"], ["0.02816900", "16.43600000"], ["0.02816500", "7.09800000"], ["0.02816000", "9.15500000"], ["0.02815900", "39.04000000"]], "a": [["0.02817900", "0.00000000"], ["0.02818000", "6.03900000"], ["0.02818100", "24.17500000"], ["0.02818300", "0.00000000"], ["0.02818500", "12.89300000"], ["0.02818600", "13.27000000"], ["0.02818700", "0.00000000"], ["0.02819200", "15.48600000"], ["0.02819500", "17.75100000"], ["0.02819600", "24.27900000"], ["0.02998000", "5.05900000"]]}, {"e": "depthUpdate", "E": 1604221235125, "s": "ETHBTC", "U": 1737812665, "u": 1737812752, "b": [["0.02818100", "139.27000000"], ["0.02818000", "24.00000000"], ["0.02817900", "24.20500000"], ["0.02817800", "0.00000000"], ["0.02817700", "0.00400000"], ["0.02817600", "6.75600000"], ["0.02817200", "2.34600000"], ["0.02816700", "0.00000000"], ["0.02816600", "0.00000000"], ["0.02815000", "0.00000000"], ["0.02803100", "0.01800000"]], "a": [["0.02818000", "0.00000000"], ["0.02818100", "0.00000000"], ["0.02818200", "0.02500000"], ["0.02818400", "6.23000000"], ["0.02818600", "9.27000000"], ["0.02818700", "1.71100000"], ["0.02818800", "6.45000000"], ["0.02818900", "7.38600000"], ["0.02819100", "5.34500000"], ["0.02819200", "30.40100000"], ["0.02819300", "13.72100000"], ["0.02819400", "7.09700000"], ["0.02819500", "2.83600000"], ["0.02819700", "0.12500000"], ["0.02819800", "5.38300000"], ["0.02820000", "31.06500000"], ["0.02820400", "55.15300000"], ["0.02998000", "6.18600000"]]}, {"e": "depthUpdate", "E": 1604221236125, "s": "ETHBTC", "U": 1737812753, "u": 1737812820, "b": [["0.02818100", "0.00000000"], ["0.02818000", "0.00000000"], ["0.02817900", "0.20500000"], ["0.02817600", "5.82400000"], ["0.02817200", "0.00000000"], ["0.02817100", "0.00000000"], ["0.02816700", "2.34600000"], ["0.02816600", "7.93000000"], ["0.02816500", "14.19700000"], ["0.02816200", "4.57100000"], ["0.02816100", "17.92800000"], ["0.02814700", "35.07600000"], ["0.02805400", "0.51700000"]], "a": [["0.02818000", "128.52200000"], ["0.02818100", "4.31400000"], ["0.02818200", "24.02500000"], ["0.02818400", "0.24300000"], ["0.02818500", "14.60400000"], ["0.02818600", "0.27000000"], ["0.02818700", "0.00000000"], ["0.02819100", "5.34500000"], ["0.02819200", "15.48600000"], ["0.02819300", "7.05600000"], ["0.02819500", "2.83600000"], ["0.02820900", "7.09400000"], ["0.03501100", "0.11500000"]]}, {"e": "depthUpdate", "E": 1604221237124, "s": "ETHBTC", "U": 1737812821, "u": 1737812858, "b": [["0.02817900", "0.00000000"], ["0.02817600", "10.09400000"], ["0.02817300", "0.23800000"], ["0.02816600", "0.83200000"], ["0.02816500", "7.09800000"], ["0.02816400", "15.61500000"], ["0.02815500", "14.12000000"], ["0.02815400", "1.34500000"], ["0.02815200", "0.00400000"], ["0.02812600", "0.00000000"], ["0.02810600", "0.00000000"], ["0.02809500", "0.00000000"], ["0.02809000", "0.78900000"]], "a": [["0.02817800", "123.52200000"], ["0.02817900", "0.00000000"], ["0.02818000", "33.27900000"], ["0.02818200", "24.02500000"], ["0.02818400", "0.00400000"], ["0.02819100", "1.34500000"], ["0.02819300", "19.16600000"], ["0.02820600", "7.38500000"]]}, {"e": "depthUpdate", "E": 1604221238125, "s": "ETHBTC", "U": 1737812859, "u": 1737812875, "b": [["0.02817100", "11.00000000"], ["0.02815500", "7.02100000"], ["0.02815100", "61.88700000"], ["0.02814900", "5.39200000"], ["0.02809000", "0.46200000"], ["0.02805400", "0.10400000"], ["0.02803100", "0.43100000"], ["0.02719000", "0.04000000"]], "a": [["0.02817800", "117.50000000"], ["0.02817900", "0.01700000"], ["0.02818400", "2.66900000"], ["0.02820900", "0.00000000"]]}, {"e": "depthUpdate", "E": 1604221239124, "s": "ETHBTC", "U": 1737812876, "u": 1737812895, "b": [["0.02817000", "0.00000000"], ["0.02816800", "1.71100000"], ["0.02816200", "11.67000000"], ["0.02815000", "0.00000000"], ["0.02813500", "0.00000000"], ["0.02813000", "150.00000000"], ["0.02809000", "1.33700000"]], "a": [["0.02817800", "119.52200000"], ["0.02817900", "0.00000000"], ["0.02818400", "6.66900000"], ["0.02818800", "21.36500000"], ["0.02819200", "35.66800000"], ["0.02819600", "4.10100000"], ["0.02854900", "4.53900000"], ["0.02998000", "5.05900000"]]}, {"e": "depthUpdate", "E": 1604221240124, "s": "ETHBTC", "U": 1737812896, "u": 1737812914, "b": [["0.02817300", "0.00000000"], ["0.02817100", "11.29800000"], ["0.02815000", "0.00000000"], ["0.02809000", "0.13600000"]], "a": [["0.02817900", "0.00000000"], ["0.02818400", "6.66900000"], ["0.02819700", "40.48800000"], ["0.02820400", "14.79800000"], ["0.02855300", "4.39000000"], ["0.02998000", "6.18600000"]]}, {"e": "depthUpdate", "E": 1604221241125, "s": "ETHBTC", "U": 1737812915, "u": 1737812935, "b": [["0.02817300", "0.18100000"], ["0.02817200", "2.34600000"], ["0.02817100", "11.00000000"], ["0.02817000", "0.00000000"], ["0.02816900", "3.55000000"], ["0.02816700", "0.00000000"], ["0.02815700", "28.17700000"], ["0.02815600", "20.39800000"], ["0.02808900", "2.10100000"], ["0.02681100", "13.90400000"]], "a": [["0.02817800", "118.58200000"], ["0.02819600", "9.48400000"], ["0.02819900", "42.94700000"]]}, {"e": "depthUpdate", "E": 1604221242125, "s": "ETHBTC", "U": 1737812936, "u": 1737812972, "b": [["0.02817700", "0.00000000"], ["0.02817600", "5.82400000"], ["0.02817200", "0.00000000"], ["0.02816700", "2.34600000"], ["0.02815000", "7.10200000"], ["0.02808900", "0.90000000"], ["0.02790600", "0.07500000"]], "a": [["0.02817700", "117.51800000"], ["0.02817800", "23.06000000"], ["0.02817900", "0.11300000"], ["0.02818000", "45.89100000"], ["0.02818200", "0.02500000"], ["0.02818400", "2.66900000"], ["0.02818800", "9.14100000"], ["0.02819000", "0.00000000"], ["0.02819100", "16.26000000"], ["0.02819200", "32.97800000"], ["0.02819300", "7.05600000"], ["0.02819700", "0.12500000"], ["0.02819800", "17.49300000"], ["0.02820200", "40.36300000"], ["0.02820500", "0.00000000"]]}, {"e": "depthUpdate", "E": 1604221243125, "s": "ETHBTC", "U": 1737812973, "u": 1737812990, "b": [["0.02817600", "116.82800000"], ["0.02817500", "24.12000000"], ["0.02817000", "1.71100000"], ["0.02816800", "0.00000000"], ["0.02814600", "0.00400000"]], "a": [["0.02817700", "113.51800000"], ["0.02818000", "36.89100000"], ["0.02818300", "4.00000000"], ["0.02818900", "16.38600000"], ["0.02837600", "16.00800000"], ["0.02837700", "0.09000000"]]}, {"e": "depthUpdate", "E": 1604221244125, "s": "ETHBTC", "U": 1737812991, "u": 1737813023, "b": [["0.02817600", "145.09900000"], ["0.02817500", "19.84900000"], ["0.02817400", "0.23700000"], ["0.02817300", "0.00000000"], ["0.02817200", "2.34600000"], ["0.02816700", "0.00000000"], ["0.02816600", "7.93000000"], ["0.02815000", "0.00000000"], ["0.02808900", "0.00000000"]], "a": [["0.02817700", "107.50000000"], ["0.02817800", "29.04000000"], ["0.02818100", "0.31400000"], ["0.02819000", "4.00000000"], ["0.02998000", "6.18600000"]]}, {"e": "depthUpdate", "E": 1604221245124, "s": "ETHBTC", "U": 1737813024, "u": 1737813047, "b": [["0.02817600", "121.09900000"], ["0.02817400", "0.12800000"], ["0.02817200", "0.00000000"], ["0.02816700", "2.34600000"], ["0.02816400", "3.21100000"], ["0.02815000", "0.00000000"], ["0.02814600", "0.00000000"], ["0.02813100", "12.40400000"], ["0.02782900", "0.13300000"], ["0.02681100", "1.90800000"]], "a": [["0.02817700", "107.56000000"], ["0.02817800", "23.06000000"]]}, {"e": "depthUpdate", "E": 1604221246125, "s": "ETHBTC", "U": 1737813048, "u": 1737813100, "b": [["0.02817700", "115.77100000"], ["0.02817600", "29.82800000"], ["0.02817500", "19.94900000"], ["0.02817400", "0.29300000"], ["0.02817200", "0.00000000"], ["0.02817100", "0.00000000"], ["0.02815900", "39.04000000"], ["0.02814900", "6.73800000"], ["0.02814700", "33.73000000"], ["0.02808800", "2.84300000"], ["0.02805300", "0.62400000"], ["0.02792000", "0.00500000"], ["0.02681100", "13.90400000"]], "a": [["0.02817700", "0.00000000"], ["0.02817800", "23.06000000"], ["0.02817900", "0.06000000"], ["0.02818000", "37.13900000"], ["0.02818300", "0.00000000"], ["0.02818800", "24.05600000"], ["0.02818900", "36.57100000"], ["0.02819100", "5.34500000"], ["0.02819200", "12.79600000"]]}, {"e": "depthUpdate", "E": 1604221247125, "s": "ETHBTC", "U": 1737813101, "u": 1737813163, "b": [["0.02817900", "0.00000000"], ["0.02817800", "115.77100000"], ["0.02817700", "24.00000000"], ["0.02817400", "0.28100000"], ["0.02817100", "2.06900000"], ["0.02816700", "5.03600000"], ["0.02816100", "12.89200000"], ["0.02805300", "0.48100000"], ["0.02792200", "0.70800000"], ["0.02783000", "9.29300000"]], "a": [["0.02817800", "0.00000000"], ["0.02817900", "0.00000000"], ["0.02818000", "132.37100000"], ["0.02818100", "0.51500000"], ["0.02818200", "0.02500000"], ["0.02818300", "1.71100000"], ["0.02818500", "12.89300000"], ["0.02818800", "9.14100000"], ["0.02818900", "16.38600000"], ["0.02819000", "4.00000000"], ["0.02819100", "5.34500000"], ["0.02819200", "27.71100000"], ["0.02819300", "27.24000000"], ["0.02819800", "57.86500000"], ["0.02820200", "0.00000000"]]}, {"e": "depthUpdate", "E": 1604221248125, "s": "ETHBTC", "U": 1737813164, "u": 1737813210, "b": [["0.02817800", "115.13300000"], ["0.02817700", "24.09900000"], ["0.02817600", "30.00900000"], ["0.02817500", "19.84900000"], ["0.02817400", "0.00000000"], ["0.02817300", "11.00000000"], ["0.02817200", "0.00000000"], ["0.02817000", "1.71100000"], ["0.02803600", "0.41300000"], ["0.02803100", "0.01800000"]], "a": [["0.02817900", "24.00000000"], ["0.02818000", "42.76400000"], ["0.02818100", "0.16500000"], ["0.02818300", "5.71100000"], ["0.02819100", "1.34500000"], ["0.02819200", "12.79600000"], ["0.02998000", "5.05900000"]]}, {"e": "depthUpdate", "E": 1604221249125, "s": "ETHBTC", "U": 1737813211, "u": 1737813285, "b": [["0.02817900", "113.56900000"], ["0.02817800", "24.00400000"], ["0.02817700", "24.35900000"], ["0.02817600", "29.82400000"], ["0.02817300", "0.00000000"], ["0.02817100", "3.60000000"], ["0.02816800", "0.00000000"], ["0.02816200", "8.07000000"], ["0.02816000", "3.16600000"], ["0.02815800", "20.18600000"], ["0.02815700", "8.00000000"], ["0.02815600", "23.08900000"], ["0.02815500", "4.33100000"], ["0.02815200", "56.52300000"], ["0.02815100", "5.38100000"], ["0.02815000", "5.38300000"], ["0.02814900", "1.35600000"], ["0.02808800", "1.64200000"], ["0.02805300", "0.05000000"]], "a": [["0.02817900", "0.00000000"], ["0.02818000", "42.54600000"], ["0.02818100", "0.00000000"], ["0.02818200", "0.21400000"], ["0.02818300", "1.71100000"], ["0.02818400", "0.00400000"], ["0.02819000", "8.00000000"], ["0.02819100", "4.01100000"], ["0.02819800", "17.49300000"], ["0.02820200", "40.37300000"], ["0.02998000", "6.18600000"]]}, {"e": "depthUpdate", "E": 1604221250125, "s": "ETHBTC", "U": 1737813286, "u": 1737813304, "b": [["0.02817900", "111.50000000"], ["0.02817800", "0.00400000"], ["0.02817700", "24.09900000"], ["0.02816900", "5.61900000"], ["0.02816200", "14.06200000"]], "a": [["0.02818000", "132.04600000"], ["0.02819200", "33.09400000"], ["0.02819800", "12.11000000"], ["0.02820900", "7.09500000"]]}, {"e": "depthUpdate", "E": 1604221251125, "s": "ETHBTC", "U": 1737813305, "u": 1737813358, "b": [["0.02817900", "0.00000000"], ["0.02817700", "24.09900000"], ["0.02817600", "30.07200000"], ["0.02817500", "19.84900000"], ["0.02817200", "1.71100000"], ["0.02817100", "0.00000000"], ["0.02817000", "0.00000000"], ["0.02816900", "3.55000000"], ["0.02816600", "0.83200000"], ["0.02816500", "9.16700000"], ["0.02816200", "17.66200000"]], "a": [["0.02817900", "30.85700000"], ["0.02818000", "36.72500000"], ["0.02818100", "0.10900000"], ["0.02818200", "0.02500000"], ["0.02818400", "4.00400000"], ["0.02818700", "2.66600000"], ["0.02819000", "4.00000000"], ["0.02819100", "1.34500000"], ["0.02819200", "18.17900000"], ["0.02819800", "2.01000000"], ["0.02820300", "12.11200000"], ["0.02820900", "0.00000000"], ["0.02821000", "5.20500000"], ["0.02827200", "0.00000000"]]}, {"e": "depthUpdate", "E": 1604221252125, "s": "ETHBTC", "U": 1737813359, "u": 1737813417, "b": [["0.02817900", "139.13300000"], ["0.02817800", "24.83600000"], ["0.02817700", "24.20900000"], ["0.02817600", "5.82400000"], ["0.02817000", "5.66900000"], ["0.02816900", "3.55000000"], ["0.02816800", "12.89100000"], ["0.02816700", "0.00000000"], ["0.02816600", "0.00000000"], ["0.02816500", "7.09800000"], ["0.02816400", "15.61500000"], ["0.02816200", "14.06200000"], ["0.02815600", "10.19800000"], ["0.02813100", "0.00000000"], ["0.02803600", "0.00000000"]], "a": [["0.02817900", "0.00000000"], ["0.02818000", "12.72500000"], ["0.02818100", "0.00000000"], ["0.02818200", "0.02500000"], ["0.02818300", "0.00000000"], ["0.02818400", "0.21600000"], ["0.02818800", "6.45000000"], ["0.02819000", "8.00000000"], ["0.02819100", "16.26000000"], ["0.02819200", "20.87000000"], ["0.02827200", "0.87400000"], ["0.02854900", "4.80400000"]]}, {"e": "depthUpdate", "E": 1604221253125, "s": "ETHBTC", "U": 1737813418, "u": 1737813485, "b": [["0.02817900", "139.13300000"], ["0.02817800", "24.00400000"], ["0.02817700", "24.35500000"], ["0.02817400", "11.00000000"], ["0.02817100", "5.03600000"], ["0.02816900", "4.38200000"], ["0.02816400", "3.21100000"], ["0.02816300", "12.48700000"], ["0.02816000", "3.16600000"], ["0.02815400", "8.44600000"], ["0.02814900", "1.36000000"], ["0.02813100", "12.40400000"], ["0.02805400", "0.51700000"]], "a": [["0.02818000", "24.00000000"], ["0.02818100", "29.76600000"], ["0.02818200", "0.30900000"], ["0.02818300", "0.00000000"], ["0.02818400", "4.00400000"], ["0.02818500", "12.89300000"], ["0.02818900", "16.09800000"], ["0.02819000", "4.29100000"], ["0.02819200", "33.76000000"], ["0.02819600", "4.10100000"], ["0.02819900", "48.33000000"], ["0.02854900", "0.12800000"], ["0.02998000", "6.18600000"]]}, {"e": "depthUpdate", "E": 1604221254125, "s": "ETHBTC", "U": 1737813486, "u": 1737813518, "b": [["0.02817900", "115.13300000"], ["0.02817700", "24.16600000"], ["0.02815900", "44.18000000"], ["0.02815400", "1.34500000"], ["0.02815300", "45.47100000"], ["0.02815200", "16.15200000"], ["0.02813100", "13.77300000"]], "a": [["0.02818000", "114.41200000"], ["0.02818100", "24.31500000"], ["0.02818200", "0.29600000"], ["0.02818300", "0.00000000"], ["0.02818400", "5.71500000"], ["0.02819900", "88.70300000"], ["0.02820200", "0.00000000"], ["0.02827200", "0.00000000"], ["0.02961200", "0.00000000"]]}, {"e": "depthUpdate", "E": 1604221255125, "s": "ETHBTC", "U": 1737813519, "u": 1737813547, "b": [["0.02817700", "24.17800000"], ["0.02817000", "5.66900000"], ["0.02815400", "8.44700000"], ["0.02814900", "1.35600000"], ["0.02805400", "0.10400000"], ["0.02805300", "0.05000000"], ["0.02803600", "0.41300000"], ["0.02793600", "1.67300000"]], "a": [["0.02818000", "24.00000000"], ["0.02818100", "30.08100000"], ["0.02818400", "4.00400000"], ["0.02818500", "14.60400000"], ["0.02819300", "28.58600000"], ["0.02819500", "1.49100000"], ["0.02837600", "0.00800000"], ["0.03333400", "0.02700000"]]}, {"e": "depthUpdate", "E": 1604221256125, "s": "ETHBTC", "U": 1737813548, "u": 1737813580, "b": [["0.02817900", "115.13700000"], ["0.02817800", "24.00000000"], ["0.02817700", "24.14800000"], ["0.02816900", "11.47900000"], ["0.02815900", "59.22500000"], ["0.02815800", "0.00000000"], ["0.02815400", "1.34500000"], ["0.02681100", "13.90400000"], ["0.02642400", "1.14200000"]], "a": [["0.02818000", "105.91200000"], ["0.02818100", "24.31500000"], ["0.02819900", "48.33000000"], ["0.02820300", "40.37100000"], ["0.02820700", "12.69600000"], ["0.02837800", "16.01400000"], ["0.03333400", "0.02400000"]]}, {"e": "depthUpdate", "E": 1604221257125, "s": "ETHBTC", "U": 1737813581, "u": 1737813589, "b": [["0.02817700", "0.00000000"], ["0.02817000", "5.66900000"]], "a": [["0.02998000", "5.05900000"]]}, {"e": "depthUpdate", "E": 1604221258125, "s": "ETHBTC", "U": 1737813590, "u": 1737813638, "b": [["0.02817900", "0.00400000"], ["0.02817800", "0.00000000"], ["0.02817700", "0.00000000"], ["0.02817500", "20.07000000"], ["0.02817200", "0.00000000"], ["0.02817100", "0.00000000"], ["0.02817000", "7.38000000"], ["0.02816900", "4.38200000"], ["0.02816400", "3.21100000"], ["0.02815900", "39.04000000"], ["0.02815800", "5.03500000"], ["0.02815600", "30.38300000"], ["0.02815300", "5.09800000"], ["0.02814900", "41.71900000"]], "a": [["0.02818000", "120.91200000"], ["0.02818100", "24.31700000"], ["0.02818200", "0.27300000"], ["0.02818400", "4.00400000"], ["0.02818900", "7.09800000"], ["0.02819300", "8.40200000"], ["0.02819600", "24.28700000"], ["0.02825400", "0.00000000"], ["0.02854400", "0.17600000"], ["0.02998000", "6.18600000"]]}, {"e": "depthUpdate", "E": 1604221259126, "s": "ETHBTC", "U": 1737813639, "u": 1737813654, "b": [["0.02817500", "19.84900000"], ["0.02817300", "0.00000000"], ["0.02817200", "0.20400000"], ["0.02817000", "5.66900000"], ["0.02816900", "6.09300000"], ["0.02816400", "15.61500000"], ["0.02815800", "12.13500000"], ["0.02813100", "1.36900000"], ["0.02808900", "0.00000000"]], "a": [["0.02818400", "4.00000000"], ["0.02819300", "12.43900000"], ["0.02819600", "20.25100000"], ["0.02823100", "4.58200000"], ["0.02854900", "4.60500000"]]}, {"e": "depthUpdate", "E": 1604221260126, "s": "ETHBTC", "U": 1737813655, "u": 1737813674, "b": [["0.02817200", "0.00000000"], ["0.02817100", "0.22400000"], ["0.02814800", "0.10000000"], ["0.02808900", "0.00000000"], ["0.02792500", "0.14900000"]], "a": [["0.02818500", "12.89300000"], ["0.03333400", "0.02700000"]]}, {"e": "depthUpdate", "E": 1604221261126, "s": "ETHBTC", "U": 1737813675, "u": 1737813699, "b": [["0.02817800", "1.00000000"], ["0.02817100", "0.26500000"], ["0.02814800", "0.00000000"], ["0.02808900", "1.20100000"], ["0.02792300", "1.05100000"]], "a": [["0.02818000", "120.46500000"], ["0.02818800", "7.45000000"], ["0.02819000", "9.67400000"], ["0.02819300", "7.05700000"], ["0.02819800", "42.37400000"], ["0.02820300", "0.00000000"], ["0.03333400", "0.03000000"]]}, {"e": "depthUpdate", "E": 1604221262126, "s": "ETHBTC", "U": 1737813700, "u": 1737813723, "b": [["0.02817100", "0.19800000"], ["0.02816900", "4.38200000"], ["0.02816600", "1.71100000"], ["0.02814900", "1.35600000"], ["0.02814300", "40.36600000"], ["0.02808900", "0.90000000"], ["0.02803600", "0.00000000"], ["0.02773900", "0.49100000"], ["0.02773200", "0.30000000"]], "a": [["0.02818000", "120.46900000"], ["0.02971100", "0.04100000"], ["0.02998000", "5.05900000"]]}, {"e": "depthUpdate", "E": 1604221263126, "s": "ETHBTC", "U": 1737813724, "u": 1737813804, "b": [["0.02817900", "0.00000000"], ["0.02817800", "116.96900000"], ["0.02817700", "0.09700000"], ["0.02817600", "8.03300000"], ["0.02817500", "19.84900000"], ["0.02817300", "0.00000000"], ["0.02817200", "11.00000000"], ["0.02817100", "0.00000000"], ["0.02817000", "3.60000000"], ["0.02816900", "3.55000000"], ["0.02816700", "0.00000000"], ["0.02816600", "7.09800000"], ["0.02816400", "14.00400000"], ["0.02815800", "0.00000000"], ["0.02815700", "9.63000000"], ["0.02815600", "10.19800000"], ["0.02815200", "4.04100000"], ["0.02815100", "25.55700000"], ["0.02814800", "12.10700000"], ["0.02814700", "33.73400000"], ["0.02814400", "0.00000000"], ["0.02809400", "2.40500000"], ["0.02808900", "0.90000000"], ["0.02808800", "0.02100000"], ["0.02807800", "23.04400000"], ["0.02804000", "0.41300000"], ["0.01409000", "0.00000000"]], "a": [["0.02817900", "24.00000000"], ["0.02818000", "23.55700000"], ["0.02818100", "24.00000000"], ["0.02818200", "0.02500000"], ["0.02818400", "0.00000000"], ["0.02818800", "7.62300000"], ["0.02818900", "22.01300000"], ["0.02819000", "8.29100000"], ["0.02819100", "10.34500000"], ["0.02819600", "25.63300000"], ["0.02819800", "2.01000000"], ["0.02820300", "40.36000000"], ["0.02998000", "6.18600000"]]}, {"e": "depthUpdate", "E": 1604221264126, "s": "ETHBTC", "U": 1737813805, "u": 1737813836, "b": [["0.02817800", "1.00000000"], ["0.02817700", "0.00000000"], ["0.02817300", "0.00000000"], ["0.02816900", "4.38200000"], ["0.02816400", "1.60000000"], ["0.02816300", "17.52200000"], ["0.02815100", "25.55700000"], ["0.02815000", "0.00000000"], ["0.02813500", "0.00000000"], ["0.02812600", "12.40400000"], ["0.02808900", "0.00000000"], ["0.02808200", "1.67100000"]], "a": [["0.02818000", "23.87400000"], ["0.02818400", "1.71000000"], ["0.02818600", "0.51400000"], ["0.02818700", "2.66600000"], ["0.02818800", "7.45000000"], ["0.02818900", "7.09800000"], ["0.02819000", "23.20600000"], ["0.02819100", "10.34500000"], ["0.02819300", "27.23500000"], ["0.02819600", "5.44700000"], ["0.02827200", "0.87400000"]]}, {"e": "depthUpdate", "E": 1604221265126, "s": "ETHBTC", "U": 1737813837, "u": 1737813868, "b": [["0.02817600", "5.82400000"], ["0.02817400", "11.14400000"], ["0.02817300", "0.00000000"], ["0.02817000", "5.66900000"], ["0.02816700", "1.71100000"], ["0.02816600", "0.00000000"], ["0.02816400", "14.00400000"], ["0.02815100", "30.93900000"], ["0.02814700", "33.73000000"], ["0.02812600", "0.00000000"]], "a": [["0.02817900", "117.50000000"], ["0.02818300", "0.12400000"], ["0.02818600", "0.27000000"], ["0.02818900", "7.09800000"], ["0.02819000", "19.20600000"], ["0.02819200", "36.45100000"], ["0.02820000", "28.37400000"]]}, {"e": "depthUpdate", "E": 1604221266126, "s": "ETHBTC", "U": 1737813869, "u": 1737813902, "b": [["0.02817400", "11.11400000"], ["0.02816500", "7.09800000"], ["0.02815700", "8.00000000"], ["0.02815300", "5.09800000"], ["0.02814500", "0.00000000"], ["0.02814200", "14.79900000"]], "a": [["0.02817900", "119.16000000"], ["0.02818100", "24.22200000"], ["0.02818300", "0.00000000"], ["0.02818400", "5.71000000"], ["0.02818900", "7.09800000"], ["0.02819000", "19.20600000"]]}, {"e": "depthUpdate", "E": 1604221267126, "s": "ETHBTC", "U": 1737813903, "u": 1737813958, "b": [["0.02817800", "0.00000000"], ["0.02817700", "1.00000000"], ["0.02817600", "9.45900000"], ["0.02817400", "11.10900000"], ["0.02817000", "2.06900000"], ["0.02816400", "21.10300000"], ["0.02816000", "6.76600000"], ["0.02815900", "0.00000000"], ["0.02815800", "1.63700000"], ["0.02815100", "30.93900000"], ["0.02804000", "0.00000000"], ["0.02803600", "0.41300000"], ["0.02783400", "0.08900000"], ["0.02783100", "0.00000000"]], "a": [["0.02817900", "126.38800000"], ["0.02818000", "24.04100000"], ["0.02818100", "24.04000000"], ["0.02818600", "16.18500000"], ["0.02818700", "34.89600000"], ["0.02818800", "9.14000000"], ["0.02818900", "7.09800000"], ["0.02819000", "4.29100000"], ["0.02819200", "20.87000000"], ["0.02998000", "5.05900000"]]}, {"e": "depthUpdate", "E": 1604221268126, "s": "ETHBTC", "U": 1737813959, "u": 1737813989, "b": [["0.02817600", "5.82400000"], ["0.02817500", "23.48400000"], ["0.02817400", "11.22200000"], ["0.02817200", "11.00000000"], ["0.02817000", "13.06900000"], ["0.02814900", "24.12400000"]], "a": [["0.02817800", "113.16000000"], ["0.02817900", "36.88800000"], ["0.02818100", "0.04000000"], ["0.02818300", "4.00000000"], ["0.02818400", "1.71000000"], ["0.02818900", "12.48000000"], ["0.02819600", "45.80300000"], ["0.02819900", "42.94700000"], ["0.02820300", "0.00000000"], ["0.02837700", "16.09000000"], ["0.02837800", "0.01400000"], ["0.02998000", "6.18600000"]]}, {"e": "depthUpdate", "E": 1604221269126, "s": "ETHBTC", "U": 1737813990, "u": 1737814008, "b": [["0.02817700", "112.50000000"], ["0.02817600", "9.45900000"], ["0.02817500", "20.04300000"], ["0.02817400", "11.00000000"], ["0.02816400", "21.10200000"], ["0.02814400", "40.35400000"], ["0.02814300", "0.00000000"], ["0.02681100", "13.90400000"]], "a": []}, {"e": "depthUpdate", "E": 1604221270126, "s": "ETHBTC", "U": 1737814009, "u": 1737814013, "b": [["0.02813000", "150.00000000"]], "a": [["0.02817800", "113.18500000"], ["0.02818900", "7.09800000"], ["0.02819500", "6.87200000"]]}, {"e": "depthUpdate", "E": 1604221271126, "s": "ETHBTC", "U": 1737814014, "u": 1737814029, "b": [["0.02817700", "1.00000000"], ["0.02817600", "5.82400000"], ["0.02817500", "23.67800000"], ["0.02816700", "0.00000000"], ["0.02816400", "8.69800000"], ["0.02813100", "0.00000000"], ["0.02812600", "12.40400000"]], "a": [["0.02817800", "121.84700000"], ["0.02818100", "4.04000000"], ["0.02818200", "5.02500000"], ["0.02818700", "32.23000000"], ["0.02819100", "1.34500000"], ["0.02819500", "18.97900000"], ["0.02820700", "0.58500000"]]}, {"e": "depthUpdate", "E": 1604221272126, "s": "ETHBTC", "U": 1737814030, "u": 1737814042, "b": [["0.02816400", "1.60000000"], ["0.02815800", "14.04100000"], ["0.02815200", "11.14000000"], ["0.02812600", "0.00000000"], ["0.02732400", "0.19500000"], ["0.02732300", "0.00000000"]], "a": [["0.02817800", "119.84700000"], ["0.02818300", "0.00000000"], ["0.02818500", "19.99200000"], ["0.02819400", "0.00000000"], ["0.02998000", "6.18600000"]]}, {"e": "depthUpdate", "E": 1604221273126, "s": "ETHBTC", "U": 1737814043, "u": 1737814085, "b": [["0.02817700", "0.00000000"], ["0.02817600", "6.82400000"], ["0.02817500", "19.84900000"], ["0.02817400", "11.00000000"], ["0.02817300", "0.00000000"], ["0.02816800", "0.00000000"], ["0.02816600", "1.71000000"], ["0.02816500", "0.00000000"], ["0.02815900", "7.09900000"], ["0.02815600", "23.08400000"], ["0.02815400", "8.44600000"], ["0.02815200", "4.04100000"], ["0.02814900", "1.35600000"], ["0.02814600", "0.00400000"], ["0.02803600", "0.00000000"]], "a": [["0.02817700", "114.51300000"], ["0.02817800", "32.39800000"], ["0.02817900", "37.13200000"], ["0.02818000", "0.32100000"], ["0.02818400", "1.00000000"], ["0.02818600", "0.27000000"], ["0.02819000", "19.20600000"], ["0.02819100", "21.52300000"], ["0.02819300", "7.05700000"]]}, {"e": "depthUpdate", "E": 1604221274126, "s": "ETHBTC", "U": 1737814086, "u": 1737814128, "b": [["0.02817600", "0.00000000"], ["0.02817500", "20.84900000"], ["0.02817200", "11.14100000"], ["0.02817000", "13.06900000"], ["0.02816600", "0.00000000"], ["0.02816500", "1.71100000"], ["0.02805300", "0.48100000"], ["0.02803300", "0.41300000"]], "a": [["0.02817600", "113.16000000"], ["0.02817700", "24.00000000"], ["0.02817800", "32.51700000"], ["0.02817900", "12.88800000"], ["0.02818400", "15.91500000"], ["0.02818500", "21.67400000"], ["0.02818600", "0.27000000"], ["0.02819000", "4.29100000"], ["0.02819300", "5.38300000"], ["0.02819500", "6.87200000"], ["0.02820000", "40.48100000"]]}, {"e": "depthUpdate", "E": 1604221275126, "s": "ETHBTC", "U": 1737814129, "u": 1737814170, "b": [["0.02817400", "0.00000000"], ["0.02817000", "11.00000000"], ["0.02816500", "3.78000000"], ["0.02815400", "1.34500000"], ["0.02814700", "56.49800000"], ["0.02814600", "0.00000000"], ["0.02814500", "40.35400000"], ["0.02814400", "0.00000000"], ["0.02814100", "7.10500000"], ["0.02814000", "0.00000000"], ["0.02805300", "0.05000000"], ["0.02762000", "1.24000000"], ["0.02761000", "10.97500000"]], "a": [["0.02817800", "28.59300000"], ["0.02818200", "6.02500000"], ["0.02818300", "4.00000000"], ["0.02818400", "14.91500000"], ["0.02819000", "4.00000000"]]}, {"e": "depthUpdate", "E": 1604221276127, "s": "ETHBTC", "U": 1737814171, "u": 1737814214, "b": [["0.02817400", "0.09900000"], ["0.02817300", "0.13200000"], ["0.02817200", "11.00000000"], ["0.02815400", "8.44700000"], ["0.02815200", "29.59800000"], ["0.02815100", "5.38200000"], ["0.02814900", "0.01000000"], ["0.02814100", "0.00000000"], ["0.02812400", "79.31300000"], ["0.02803300", "0.00000000"], ["0.02803100", "0.43100000"]], "a": [["0.02817600", "29.66000000"], ["0.02817800", "25.73600000"], ["0.02817900", "13.08600000"], ["0.02818100", "8.04000000"], ["0.02818300", "4.00000000"], ["0.02818400", "14.91500000"], ["0.02819000", "0.00000000"], ["0.02819100", "1.34500000"], ["0.02819400", "20.17600000"], ["0.02998000", "5.05900000"]]}, {"e": "depthUpdate", "E": 1604221277127, "s": "ETHBTC", "U": 1737814215, "u": 1737814247, "b": [["0.02817500", "135.98400000"], ["0.02817300", "2.20100000"], ["0.02816500", "8.81000000"], ["0.02815700", "10.69000000"], ["0.02815600", "20.39300000"], ["0.02815400", "1.34500000"], ["0.02815100", "6.72700000"], ["0.02814600", "0.00000000"]], "a": [["0.02817800", "24.02500000"], ["0.02817900", "13.01800000"], ["0.02818000", "0.32100000"], ["0.02818100", "0.04000000"], ["0.02818200", "1.02500000"], ["0.02818300", "0.00000000"], ["0.02818400", "2.66100000"], ["0.02818600", "15.18500000"], ["0.02818900", "11.09800000"], ["0.02819000", "8.00000000"], ["0.02819100", "6.34500000"], ["0.02819600", "5.44700000"], ["0.02820000", "80.83200000"], ["0.02857500", "0.05600000"], ["0.02998000", "6.18600000"]]}, {"e": "depthUpdate", "E": 1604221278127, "s": "ETHBTC", "U": 1737814248, "u": 1737814269, "b": [["0.02817500", "20.84900000"], ["0.02817300", "0.13200000"], ["0.02816700", "1.71000000"], ["0.02816600", "2.06900000"], ["0.02816500", "0.00000000"], ["0.02816200", "21.16200000"], ["0.02808800", "1.22200000"]], "a": [["0.02817600", "113.16000000"], ["0.02818000", "5.32100000"], ["0.02818100", "4.04000000"], ["0.02818300", "4.00000000"], ["0.02818500", "21.96100000"], ["0.02818800", "6.45000000"], ["0.02818900", "7.09800000"], ["0.02819000", "4.00000000"], ["0.02819100", "1.34500000"], ["0.02819200", "23.56000000"], ["0.02819900", "55.05300000"], ["0.02820000", "68.72500000"], ["0.02857500", "16.46500000"]]}, {"e": "depthUpdate", "E": 1604221279127, "s": "ETHBTC", "U": 1737814270, "u": 1737814283, "b": [["0.02816700", "1.71000000"], ["0.02816200", "14.06200000"], ["0.02815600", "27.49200000"], ["0.02815400", "5.38000000"], ["0.02815200", "25.56100000"], ["0.02814900", "12.11500000"], ["0.02814800", "0.00000000"], ["0.02814700", "33.73000000"], ["0.02808900", "1.20100000"]], "a": [["0.02817600", "29.66000000"], ["0.02817900", "12.88800000"], ["0.02818000", "5.58700000"], ["0.02827200", "0.00000000"]]}, {"e": "depthUpdate", "E": 1604221280127, "s": "ETHBTC", "U": 1737814284, "u": 1737814298, "b": [["0.02811100", "0.00900000"], ["0.02809000", "0.46200000"], ["0.02808900", "0.00000000"], ["0.02808800", "0.02100000"]], "a": [["0.02817600", "113.16000000"], ["0.02817700", "28.00000000"], ["0.02818300", "0.00000000"], ["0.02820000", "28.37400000"], ["0.02820400", "55.14400000"], ["0.02827200", "0.87400000"], ["0.02837400", "16.06100000"], ["0.02837700", "0.09000000"]]}, {"e": "depthUpdate", "E": 1604221281127, "s": "ETHBTC", "U": 1737814299, "u": 1737814318, "b": [["0.02815800", "14.04100000"], ["0.02815600", "20.39300000"], ["0.02815400", "1.34500000"], ["0.02815300", "25.27100000"], ["0.02815200", "5.38500000"], ["0.02815000", "4.03500000"], ["0.02814900", "34.88300000"], ["0.02814600", "40.35000000"], ["0.02814500", "0.00000000"], ["0.02813500", "0.00000000"], ["0.02810600", "0.00000000"], ["0.02809000", "0.13600000"]], "a": [["0.02817700", "24.00000000"], ["0.02817900", "13.06300000"], ["0.02818000", "5.32100000"], ["0.02818200", "5.02500000"], ["0.02998000", "5.05900000"]]}, {"e": "depthUpdate", "E": 1604221282127, "s": "ETHBTC", "U": 1737814319, "u": 1737814320, "b": [["0.02816000", "13.86500000"]], "a": [["0.02998000", "6.18600000"]]}, {"e": "depthUpdate", "E": 1604221283127, "s": "ETHBTC", "U": 1737814321, "u": 1737814326, "b": [["0.02817500", "19.84900000"], ["0.02817400", "1.09900000"], ["0.02816900", "15.38200000"], ["0.02814500", "0.00400000"], ["0.02761300", "0.01200000"]], "a": [["0.02817600", "113.15600000"]]}, {"e": "depthUpdate", "E": 1604221284127, "s": "ETHBTC", "U": 1737814327, "u": 1737814336, "b": [["0.02817100", "0.00000000"], ["0.02816700", "0.00000000"], ["0.02816600", "2.06900000"], ["0.02816500", "1.71000000"], ["0.02761200", "0.10500000"], ["0.02681100", "12.25100000"]], "a": []}, {"e": "depthUpdate", "E": 1604221285127, "s": "ETHBTC", "U": 1737814337, "u": 1737814360, "b": [["0.02817400", "1.00000000"], ["0.02816700", "1.71000000"], ["0.02816500", "0.00000000"], ["0.02814500", "0.00000000"], ["0.02811100", "0.00900000"], ["0.02803300", "0.41300000"], ["0.02803100", "0.01800000"], ["0.02681100", "13.90400000"]], "a": [["0.02817600", "29.65600000"], ["0.02817800", "24.02500000"], ["0.02817900", "12.88800000"], ["0.02819000", "10.72500000"], ["0.02819100", "6.72600000"], ["0.02819300", "4.03700000"], ["0.02819500", "1.49100000"], ["0.02819600", "0.06500000"], ["0.02819900", "95.40000000"], ["0.02820400", "14.79800000"], ["0.02998000", "5.05900000"]]}, {"e": "depthUpdate", "E": 1604221286127, "s": "ETHBTC", "U": 1737814361, "u": 1737814423, "b": [["0.02817600", "106.13900000"], ["0.02817500", "43.84900000"], ["0.02817400", "0.17500000"], ["0.02817300", "0.00000000"], ["0.02817200", "0.00000000"], ["0.02817000", "2.06900000"], ["0.02816900", "4.38200000"], ["0.02816700", "8.80800000"], ["0.02816600", "0.00000000"], ["0.02815900", "0.00000000"], ["0.02815400", "21.51700000"], ["0.02815300", "5.09800000"], ["0.02815200", "10.76600000"], ["0.02815100", "1.34500000"], ["0.02814900", "12.11500000"], ["0.02814700", "74.07600000"], ["0.02814600", "0.00000000"], ["0.02812900", "0.10000000"]], "a": [["0.02817600", "0.00000000"], ["0.02817800", "24.02500000"], ["0.02817900", "13.01100000"], ["0.02818000", "0.32100000"], ["0.02818100", "0.04000000"], ["0.02818200", "1.02500000"], ["0.02818300", "1.71000000"], ["0.02818800", "10.45000000"], ["0.02819000", "15.72500000"], ["0.02819100", "10.72600000"], ["0.02998000", "6.18600000"]]}, {"e": "depthUpdate", "E": 1604221287127, "s": "ETHBTC", "U": 1737814424, "u": 1737814467, "b": [["0.02817600", "0.00000000"], ["0.02817500", "20.84900000"], ["0.02817400", "0.24100000"], ["0.02817000", "0.00000000"], ["0.02816800", "1.71000000"], ["0.02816700", "7.09800000"], ["0.02816500", "2.06900000"], ["0.02812900", "0.00000000"], ["0.02811500", "0.00000000"], ["0.02803300", "0.00000000"]], "a": [["0.02817600", "4.00000000"], ["0.02817700", "107.50000000"], ["0.02817800", "24.17300000"], ["0.02817900", "12.88800000"], ["0.02818100", "13.04000000"], ["0.02818600", "15.18500000"], ["0.02818800", "6.45000000"], ["0.02819000", "6.72500000"], ["0.02819100", "6.72600000"]]}, {"e": "depthUpdate", "E": 1604221288127, "s": "ETHBTC", "U": 1737814468, "u": 1737814500, "b": [["0.02817400", "0.00000000"], ["0.02817300", "0.16500000"], ["0.02816900", "15.38200000"], ["0.02815500", "0.00000000"], ["0.02814800", "4.33200000"], ["0.02811100", "0.00900000"], ["0.02803100", "0.43100000"]], "a": [["0.02817600", "117.12600000"], ["0.02817700", "24.00000000"], ["0.02817800", "24.16600000"], ["0.02818600", "15.18500000"], ["0.02819000", "26.89800000"], ["0.02819400", "0.00000000"], ["0.02820000", "5.59000000"], ["0.02820400", "19.13000000"], ["0.02821400", "9.96000000"]]}, {"e": "depthUpdate", "E": 1604221289128, "s": "ETHBTC", "U": 1737814501, "u": 1737814520, "b": [["0.02817500", "19.84900000"], ["0.02817400", "1.00000000"], ["0.02817300", "0.00000000"], ["0.02816800", "0.00000000"], ["0.02816600", "1.83600000"]], "a": [["0.02817800", "24.29500000"], ["0.02821100", "66.34000000"], ["0.02822900", "0.00000000"]]}, {"e": "depthUpdate", "E": 1604221290127, "s": "ETHBTC", "U": 1737814521, "u": 1737814558, "b": [["0.02817400", "0.00000000"], ["0.02817200", "1.00000000"], ["0.02816800", "0.27300000"], ["0.02816700", "0.00000000"], ["0.02816600", "0.00000000"], ["0.02816500", "3.77900000"], ["0.02816400", "1.60000000"], ["0.02816100", "19.99100000"], ["0.02815400", "1.34500000"], ["0.02815100", "21.51900000"], ["0.02781000", "4.60100000"]], "a": [["0.02817600", "113.12600000"], ["0.02817800", "24.26800000"], ["0.02818000", "1.32100000"], ["0.02818200", "0.02500000"], ["0.02819000", "30.93300000"], ["0.02819300", "0.00000000"], ["0.02819900", "118.16800000"], ["0.02998000", "5.05900000"]]}, {"e": "depthUpdate", "E": 1604221291128, "s": "ETHBTC", "U": 1737814559, "u": 1737814576, "b": [["0.02817300", "0.25400000"], ["0.02816800", "0.00000000"], ["0.02814900", "52.46100000"], ["0.02814700", "33.73000000"], ["0.02811900", "0.00000000"]], "a": [["0.02817800", "24.19100000"], ["0.02818300", "5.71000000"], ["0.02998000", "6.18600000"]]}, {"e": "depthUpdate", "E": 1604221292128, "s": "ETHBTC", "U": 1737814577, "u": 1737814598, "b": [["0.02816800", "11.00000000"], ["0.02815800", "16.73100000"], ["0.02815700", "8.00000000"], ["0.02814900", "75.22900000"], ["0.02808200", "0.04900000"], ["0.02807600", "1.63000000"]], "a": [["0.02817800", "24.17000000"], ["0.02822400", "44.07100000"], ["0.02823700", "0.00000000"], ["0.13713300", "0.00600000"], ["0.13715300", "0.00000000"]]}, {"e": "depthUpdate", "E": 1604221293128, "s": "ETHBTC", "U": 1737814599, "u": 1737814612, "b": [["0.02815200", "10.77000000"], ["0.02803100", "0.01800000"]], "a": [["0.02817600", "117.12600000"], ["0.02817800", "24.13100000"], ["0.02818300", "1.71000000"], ["0.02818700", "34.92000000"], ["0.02819200", "32.97400000"], ["0.02819900", "106.06200000"]]}, {"e": "depthUpdate", "E": 1604221294128, "s": "ETHBTC", "U": 1737814613, "u": 1737814628, "b": [["0.02816000", "6.76600000"], ["0.02815000", "11.13500000"], ["0.02802700", "0.42900000"]], "a": [["0.02817600", "113.12600000"], ["0.02817800", "24.19100000"], ["0.02818200", "4.02500000"], ["0.02819900", "42.94700000"], ["0.02998000", "5.05900000"]]}, {"e": "depthUpdate", "E": 1604221295128, "s": "ETHBTC", "U": 1737814629, "u": 1737814662, "b": [["0.02817500", "14.06800000"], ["0.02817000", "2.06900000"], ["0.02816500", "1.71000000"], ["0.02815900", "7.10000000"], ["0.02815200", "30.93900000"], ["0.02815100", "1.34500000"], ["0.02815000", "16.13900000"], ["0.02814900", "63.12400000"]], "a": [["0.02817600", "110.12600000"], ["0.02817700", "24.31500000"], ["0.02817800", "24.30900000"], ["0.02818000", "1.00400000"], ["0.02818600", "17.87500000"], ["0.02819200", "30.28300000"], ["0.02819600", "0.06500000"], ["0.02820000", "45.93600000"], ["0.02827200", "0.00000000"], ["0.02998000", "6.18600000"]]}, {"e": "depthUpdate", "E": 1604221296128, "s": "ETHBTC", "U": 1737814663, "u": 1737814680, "b": [["0.02808900", "2.10100000"], ["0.02803000", "21.78800000"], ["0.02802700", "0.01600000"], ["0.02681100", "13.90400000"]], "a": [["0.02817800", "24.13200000"], ["0.02818600", "15.18500000"], ["0.02818900", "9.78800000"]]}, {"e": "depthUpdate", "E": 1604221297128, "s": "ETHBTC", "U": 1737814681, "u": 1737814705, "b": [["0.02812900", "0.00000000"], ["0.02808900", "1.20100000"]], "a": [["0.02817800", "24.02500000"], ["0.02819800", "24.77800000"]]}, {"e": "depthUpdate", "E": 1604221298128, "s": "ETHBTC", "U": 1737814706, "u": 1737814724, "b": [["0.02816700", "1.71000000"], ["0.02816600", "12.88400000"], ["0.02816500", "0.00000000"], ["0.02816100", "27.09100000"], ["0.02815900", "0.00000000"], ["0.02815600", "7.50700000"], ["0.02815100", "41.69200000"], ["0.02814900", "22.77800000"]], "a": [["0.02817800", "24.31700000"], ["0.02818000", "5.00400000"], ["0.02818200", "0.02500000"]]}, {"e": "depthUpdate", "E": 1604221299128, "s": "ETHBTC", "U": 1737814725, "u": 1737814738, "b": [["0.02764000", "1.00000000"]], "a": [["0.02817800", "24.26200000"], ["0.02819200", "18.17900000"], ["0.02819600", "12.16900000"], ["0.02998000", "5.05900000"]]}, {"e": "depthUpdate", "E": 1604221300128, "s": "ETHBTC", "U": 1737814739, "u": 1737814759, "b": [["0.02816700", "0.00000000"], ["0.02815500", "20.17300000"], ["0.02815200", "10.76600000"], ["0.01408800", "0.20000000"]], "a": [["0.02817800", "24.14200000"], ["0.02998000", "6.18600000"]]}, {"e": "depthUpdate", "E": 1604221301128, "s": "ETHBTC", "U": 1737814760, "u": 1737814780, "b": [["0.02816700", "1.71000000"], ["0.02809000", "1.33700000"], ["0.02808900", "0.00000000"], ["0.02764000", "1.03600000"], ["0.01408800", "0.00000000"]], "a": [["0.02817800", "24.13600000"]]}, {"e": "depthUpdate", "E": 1604221302128, "s": "ETHBTC", "U": 1737814781, "u": 1737814793, "b": [["0.02810700", "0.05400000"], ["0.02809000", "1.03600000"]], "a": [["0.02817800", "24.02500000"]]}, {"e": "depthUpdate", "E": 1604221303128, "s": "ETHBTC", "U": 1737814794, "u": 1737814807, "b": [["0.02816700", "0.00000000"], ["0.02816500", "1.71000000"], ["0.02815200", "51.11100000"], ["0.02815100", "1.34500000"]], "a": [["0.02817800", "24.27700000"], ["0.02819000", "26.89800000"]]}, {"e": "depthUpdate", "E": 1604221304128, "s": "ETHBTC", "U": 1737814808, "u": 1737814831, "b": [["0.02814600", "0.00400000"], ["0.02809000", "1.03600000"], ["0.01832800", "0.00000000"]], "a": [["0.02817800", "24.23400000"], ["0.02819300", "4.03500000"], ["0.02998000", "5.05900000"], ["0.03637400", "0.00300000"]]}, {"e": "depthUpdate", "E": 1604221305128, "s": "ETHBTC", "U": 1737814832, "u": 1737814862, "b": [["0.02816700", "1.71000000"], ["0.02816500", "0.00000000"], ["0.02815700", "28.17300000"], ["0.02815500", "0.00000000"], ["0.02814600", "0.00000000"], ["0.02812400", "79.31300000"], ["0.02809000", "0.13600000"], ["0.02808900", "1.20100000"], ["0.02794800", "13.80100000"], ["0.02794100", "1.86500000"]], "a": [["0.02817800", "24.27000000"], ["0.02827200", "1.16500000"], ["0.02998000", "6.18600000"]]}, {"e": "depthUpdate", "E": 1604221306128, "s": "ETHBTC", "U": 1737814863, "u": 1737814876, "b": [["0.02815600", "8.85200000"], ["0.02815400", "0.00000000"], ["0.02812300", "0.02600000"]], "a": [["0.02817800", "24.30400000"]]}, {"e": "depthUpdate", "E": 1604221307128, "s": "ETHBTC", "U": 1737814877, "u": 1737814894, "b": [["0.02817000", "14.95200000"], ["0.02816800", "12.71000000"], ["0.02816700", "0.00000000"], ["0.02816100", "14.19900000"], ["0.02815200", "52.45600000"], ["0.02815100", "0.00000000"]], "a": [["0.02817800", "24.26400000"]]}, {"e": "depthUpdate", "E": 1604221308128, "s": "ETHBTC", "U": 1737814895, "u": 1737814910, "b": [["0.02817500", "95.06800000"], ["0.02817200", "0.00000000"], ["0.02814900", "0.01000000"], ["0.02808900", "0.00000000"], ["0.02788800", "0.00000000"]], "a": [["0.02817600", "109.87300000"], ["0.02817800", "24.20000000"]]}, {"e": "depthUpdate", "E": 1604221309128, "s": "ETHBTC", "U": 1737814911, "u": 1737814939, "b": [["0.02817500", "14.06800000"], ["0.02816800", "11.00000000"], ["0.02816700", "1.71000000"], ["0.02815800", "4.32700000"], ["0.02813100", "12.40400000"], ["0.02811200", "0.05000000"], ["0.02803000", "21.37500000"]], "a": [["0.02817600", "109.83400000"], ["0.02817800", "24.17400000"], ["0.02818700", "32.23000000"], ["0.02819000", "29.58800000"], ["0.02998000", "6.18600000"]]}, {"e": "depthUpdate", "E": 1604221310128, "s": "ETHBTC", "U": 1737814940, "u": 1737814966, "b": [["0.02817500", "153.20200000"], ["0.02816800", "33.76800000"], ["0.02816700", "1.71000000"], ["0.02816100", "7.10000000"], ["0.02815800", "16.73100000"], ["0.02813100", "0.00000000"], ["0.02802700", "0.42900000"], ["0.02788700", "1.42400000"], ["0.02780100", "1.06600000"], ["0.02255000", "0.06700000"]], "a": [["0.02817600", "80.20800000"], ["0.02817800", "25.22900000"], ["0.02818000", "1.00400000"], ["0.02818500", "25.96100000"], ["0.02819200", "26.17900000"], ["0.02819600", "52.52000000"], ["0.02820000", "5.59000000"], ["0.02821300", "46.54900000"]]}, {"e": "depthUpdate", "E": 1604221311128, "s": "ETHBTC", "U": 1737814967, "u": 1737815009, "b": [["0.02817500", "41.70200000"], ["0.02816900", "17.09200000"], ["0.02816700", "0.00000000"], ["0.02815800", "4.32700000"], ["0.02815100", "4.03500000"], ["0.02815000", "12.10400000"], ["0.02814600", "0.00000000"], ["0.02812600", "12.40400000"], ["0.02681100", "13.90400000"]], "a": [["0.02817600", "104.20800000"], ["0.02817700", "1.45700000"], ["0.02817800", "24.20400000"], ["0.02818400", "2.66100000"], ["0.02818600", "15.18500000"], ["0.02818700", "32.23000000"], ["0.02821100", "0.00000000"], ["0.02822300", "66.34000000"]]}, {"e": "depthUpdate", "E": 1604221312129, "s": "ETHBTC", "U": 1737815010, "u": 1737815033, "b": [["0.02817500", "14.06300000"], ["0.02815800", "16.73100000"], ["0.02812600", "0.00000000"], ["0.02803000", "21.78800000"], ["0.02802700", "0.01600000"]], "a": [["0.02817600", "109.73400000"], ["0.02817700", "4.31500000"], ["0.02817800", "24.22100000"], ["0.02818500", "21.96100000"]]}, {"e": "depthUpdate", "E": 1604221313128, "s": "ETHBTC", "U": 1737815034, "u": 1737815044, "b": [["0.02814800", "4.33200000"]], "a": [["0.02817800", "24.02500000"]]}, {"e": "depthUpdate", "E": 1604221314129, "s": "ETHBTC", "U": 1737815045, "u": 1737815062, "b": [["0.02814500", "0.00400000"], ["0.02805700", "4.30000000"], ["0.02803000", "21.37500000"]], "a": [["0.02817800", "24.15800000"], ["0.02819300", "16.14000000"], ["0.02819600", "40.41600000"], ["0.02819700", "14.92100000"], ["0.02820400", "4.33200000"], ["0.02998000", "6.18600000"]]}, {"e": "depthUpdate", "E": 1604221315129, "s": "ETHBTC", "U": 1737815063, "u": 1737815077, "b": [["0.02815000", "12.10400000"], ["0.02814500", "0.00000000"], ["0.02802700", "0.42900000"]], "a": [["0.02817600", "115.73400000"], ["0.02817800", "24.22600000"]]}, {"e": "depthUpdate", "E": 1604221316129, "s": "ETHBTC", "U": 1737815078, "u": 1737815132, "b": [["0.02817500", "14.06300000"], ["0.02817000", "12.88300000"], ["0.02816500", "2.06900000"], ["0.02816100", "7.09800000"], ["0.02815800", "36.90600000"], ["0.02815700", "8.00000000"], ["0.02815300", "45.44800000"], ["0.02815200", "12.11100000"], ["0.02815100", "16.14000000"], ["0.02815000", "0.00000000"]], "a": [["0.02817600", "109.73400000"], ["0.02817700", "0.31500000"], ["0.02817800", "24.26300000"], ["0.02818200", "4.02500000"], ["0.02818400", "2.66100000"], ["0.02818600", "15.18500000"], ["0.02819600", "0.06500000"], ["0.02820200", "40.35200000"], ["0.02837300", "17.36300000"], ["0.02837400", "0.06100000"]]}, {"e": "depthUpdate", "E": 1604221317129, "s": "ETHBTC", "U": 1737815133, "u": 1737815157, "b": [["0.02816900", "26.25900000"], ["0.02816500", "0.00000000"], ["0.02816100", "0.00000000"], ["0.02814600", "0.00000000"], ["0.02804800", "0.49400000"]], "a": [["0.02817800", "24.14000000"], ["0.02819300", "16.13900000"]]}, {"e": "depthUpdate", "E": 1604221318129, "s": "ETHBTC", "U": 1737815158, "u": 1737815183, "b": [["0.02816900", "24.54900000"], ["0.02816800", "11.00000000"], ["0.02816700", "1.71000000"], ["0.02815900", "0.00000000"], ["0.02815800", "34.21600000"], ["0.02815600", "11.54200000"]], "a": [["0.02817600", "109.73400000"], ["0.02817800", "24.15100000"], ["0.02818100", "17.04000000"], ["0.02818200", "0.02500000"], ["0.02819300", "4.03500000"], ["0.02819800", "36.88200000"], ["0.02998000", "5.05900000"]]}, {"e": "depthUpdate", "E": 1604221319129, "s": "ETHBTC", "U": 1737815184, "u": 1737815196, "b": [["0.02804800", "0.00000000"]], "a": [["0.02817600", "109.73400000"], ["0.02817800", "24.02500000"], ["0.02998000", "6.18600000"]]}, {"e": "depthUpdate", "E": 1604221320129, "s": "ETHBTC", "U": 1737815197, "u": 1737815214, "b": [["0.02816800", "12.71000000"], ["0.02816700", "0.00000000"], ["0.02815800", "56.97600000"], ["0.02812400", "79.31300000"]], "a": [["0.02817600", "119.73400000"], ["0.02817800", "24.50600000"], ["0.02818100", "13.04000000"]]}, {"e": "depthUpdate", "E": 1604221321129, "s": "ETHBTC", "U": 1737815215, "u": 1737815228, "b": [["0.02817300", "0.00000000"], ["0.02817200", "0.23400000"], ["0.02817100", "1.00000000"], ["0.02815800", "34.21600000"]], "a": [["0.02817800", "24.02500000"]]}, {"e": "depthUpdate", "E": 1604221322129, "s": "ETHBTC", "U": 1737815229, "u": 1737815250, "b": [["0.02816900", "17.45100000"], ["0.02816800", "11.00000000"], ["0.02816700", "1.71000000"]], "a": [["0.02817600", "119.73400000"], ["0.02817800", "24.28200000"], ["0.02819200", "66.53100000"], ["0.02820200", "0.00000000"]]}, {"e": "depthUpdate", "E": 1604221323129, "s": "ETHBTC", "U": 1737815251, "u": 1737815285, "b": [["0.02816900", "14.55000000"], ["0.02816400", "2.06900000"], ["0.02816000", "7.59800000"], ["0.02815800", "14.04100000"], ["0.02815400", "21.77600000"], ["0.02811200", "0.05000000"], ["0.02809700", "90.65300000"], ["0.02681100", "13.90300000"]], "a": [["0.02817800", "24.15000000"], ["0.02819600", "0.00000000"], ["0.02822900", "0.06500000"], ["0.02998000", "5.05900000"]]}, {"e": "depthUpdate", "E": 1604221324130, "s": "ETHBTC", "U": 1737815286, "u": 1737815335, "b": [["0.02817400", "0.09600000"], ["0.02817000", "12.88300000"], ["0.02816500", "0.00000000"], ["0.02816400", "0.00000000"], ["0.02816300", "17.52200000"], ["0.02816000", "6.76600000"], ["0.02815900", "2.06900000"], ["0.02815700", "8.83200000"], ["0.02815400", "21.77600000"], ["0.02815300", "5.09800000"], ["0.02814900", "22.76500000"], ["0.02813500", "0.00400000"], ["0.02812000", "0.30000000"]], "a": [["0.02817600", "115.73400000"], ["0.02817700", "0.00000000"], ["0.02817800", "24.25800000"], ["0.02818000", "1.00000000"], ["0.02818100", "20.13900000"], ["0.02818200", "4.02500000"], ["0.02818900", "5.38000000"], ["0.02819000", "24.20800000"], ["0.02819200", "20.79600000"], ["0.02819300", "6.72500000"], ["0.02819400", "5.38100000"], ["0.02998000", "6.18600000"]]}, {"e": "depthUpdate", "E": 1604221325130, "s": "ETHBTC", "U": 1737815336, "u": 1737815413, "b": [["0.02817500", "10.91200000"], ["0.02817400", "0.00000000"], ["0.02817300", "0.00000000"], ["0.02817200", "0.00000000"], ["0.02817100", "0.00000000"], ["0.02817000", "0.00000000"], ["0.02816900", "14.71600000"], ["0.02816700", "0.00000000"], ["0.02816300", "7.32800000"], ["0.02816200", "6.96300000"], ["0.02816000", "3.16600000"], ["0.02815900", "22.05800000"], ["0.02815600", "14.60700000"], ["0.02815500", "5.16100000"], ["0.02815400", "1.60000000"], ["0.02815300", "7.78900000"], ["0.02815200", "5.38600000"], ["0.02815100", "1.34600000"], ["0.02815000", "7.63700000"], ["0.02814900", "21.53600000"], ["0.02814400", "40.36200000"], ["0.02814200", "12.10900000"], ["0.02814000", "5.38100000"], ["0.02813500", "14.80200000"]], "a": [["0.02817600", "119.73400000"], ["0.02817700", "0.31800000"], ["0.02817800", "24.20800000"], ["0.02818000", "0.00000000"], ["0.02818200", "0.02500000"], ["0.02818700", "53.90600000"], ["0.02819000", "2.69100000"], ["0.02819100", "5.38100000"], ["0.02819400", "45.72800000"], ["0.02819500", "0.00000000"], ["0.03439100", "0.42100000"]]}, {"e": "depthUpdate", "E": 1604221326130, "s": "ETHBTC", "U": 1737815414, "u": 1737815485, "b": [["0.02817500", "0.00000000"], ["0.02816900", "14.55000000"], ["0.02816800", "12.10900000"], ["0.02816300", "0.12900000"], ["0.02816200", "0.97100000"], ["0.02816000", "0.00000000"], ["0.02815900", "12.88900000"], ["0.02815400", "8.70700000"], ["0.02815200", "3.17300000"], ["0.02815000", "3.60000000"], ["0.02814600", "11.13800000"], ["0.02814500", "5.38200000"], ["0.02814300", "7.22500000"], ["0.02810000", "1.03700000"], ["0.02781000", "3.10400000"], ["0.02537000", "0.11200000"]], "a": [["0.02817000", "109.52600000"], ["0.02817100", "24.00000000"], ["0.02817200", "13.00000000"], ["0.02817300", "0.28900000"], ["0.02817400", "24.00000000"], ["0.02817500", "3.67500000"], ["0.02817600", "4.00000000"], ["0.02817700", "0.31800000"], ["0.02817800", "0.02500000"], ["0.02818100", "7.13900000"], ["0.02818400", "14.91500000"], ["0.02818500", "29.34900000"], ["0.02818600", "0.27000000"], ["0.02818700", "56.59700000"], ["0.02819600", "0.00000000"], ["0.02819800", "14.11400000"], ["0.02821200", "0.00000000"], ["0.02823000", "150.13400000"], ["0.02826000", "0.00000000"], ["0.02827200", "0.00000000"], ["0.03129200", "0.02100000"]]}, {"e": "depthUpdate", "E": 1604221327129, "s": "ETHBTC", "U": 1737815486, "u": 1737815517, "b": [["0.02816900", "3.55000000"], ["0.02816100", "1.71100000"], ["0.02816000", "0.00000000"], ["0.02815800", "1.63700000"], ["0.02815600", "21.70800000"], ["0.02815500", "7.23000000"], ["0.02815400", "6.63800000"], ["0.02815000", "21.99400000"], ["0.02814600", "4.03700000"], ["0.02812000", "0.00000000"], ["0.02809300", "39.27100000"], ["0.02802700", "0.01600000"], ["0.02254000", "0.91100000"]], "a": [["0.02817000", "119.53000000"], ["0.02817200", "4.00000000"], ["0.02817400", "26.95200000"], ["0.02817600", "0.00000000"], ["0.02818100", "16.13900000"], ["0.02818800", "7.79500000"], ["0.02819000", "1.34600000"], ["0.02827200", "0.87400000"]]}, {"e": "depthUpdate", "E": 1604221328129, "s": "ETHBTC", "U": 1737815518, "u": 1737815537, "b": [["0.02816700", "0.26600000"], ["0.02816300", "11.02400000"], ["0.02816100", "3.78000000"], ["0.02815500", "5.16100000"], ["0.02810800", "1.44400000"], ["0.02808400", "0.93000000"], ["0.02802900", "35.94300000"], ["0.02789600", "0.94800000"], ["0.02705900", "0.00000000"]], "a": [["0.02817000", "128.53000000"], ["0.02817500", "1.00000000"], ["0.02818100", "7.13900000"], ["0.02819300", "29.49300000"], ["0.02819600", "7.09700000"], ["0.02998000", "5.05900000"]]}, {"e": "depthUpdate", "E": 1604221329130, "s": "ETHBTC", "U": 1737815538, "u": 1737815578, "b": [["0.02816900", "97.55000000"], ["0.02816700", "0.16200000"], ["0.02816000", "3.60000000"], ["0.02815600", "14.60700000"], ["0.02815000", "18.39400000"], ["0.02814400", "0.00000000"], ["0.02814300", "14.32900000"], ["0.02814100", "40.37200000"], ["0.02808400", "0.03000000"], ["0.02755600", "0.01100000"], ["0.02622200", "5.70000000"]], "a": [["0.02817000", "109.53000000"], ["0.02817200", "0.00000000"], ["0.02818000", "9.00000000"], ["0.02818100", "11.13900000"], ["0.02818200", "4.02500000"], ["0.02819100", "5.44600000"], ["0.02819600", "0.00000000"], ["0.02822900", "0.00000000"], ["0.02998000", "6.18600000"]]}, {"e": "depthUpdate", "E": 1604221330130, "s": "ETHBTC", "U": 1737815579, "u": 1737815623, "b": [["0.02816900", "3.55000000"], ["0.02816700", "0.10500000"], ["0.02816100", "0.00000000"], ["0.02816000", "1.71100000"], ["0.02815500", "7.23000000"], ["0.02815300", "14.89000000"], ["0.02815100", "4.94600000"], ["0.02814900", "21.53600000"], ["0.02814300", "7.22500000"], ["0.02808400", "0.93000000"], ["0.02803100", "0.43100000"], ["0.02802900", "35.53000000"], ["0.02789400", "0.00400000"], ["0.02705700", "0.00400000"]], "a": [["0.02817000", "128.55500000"], ["0.02817300", "4.28900000"], ["0.02818000", "0.00000000"], ["0.02818100", "7.13900000"], ["0.02818200", "14.94000000"], ["0.02818300", "21.89700000"], ["0.02818400", "0.00000000"], ["0.02818700", "76.78900000"], ["0.02818900", "10.76200000"], ["0.02819100", "0.06500000"], ["0.02819400", "5.38100000"], ["0.02819600", "7.09800000"]]}, {"e": "depthUpdate", "E": 1604221331130, "s": "ETHBTC", "U": 1737815624, "u": 1737815650, "b": [["0.02816700", "0.28200000"], ["0.02622000", "0.00400000"]], "a": [["0.02817000", "118.55500000"], ["0.02817700", "0.58800000"], ["0.02817800", "4.02500000"], ["0.02818600", "0.06500000"], ["0.02819100", "0.00000000"], ["0.02819600", "0.00000000"]]}, {"e": "depthUpdate", "E": 1604221332130, "s": "ETHBTC", "U": 1737815651, "u": 1737815696, "b": [["0.02816800", "1.00000000"], ["0.02816700", "0.14900000"], ["0.02816600", "0.00000000"], ["0.02816400", "2.06900000"], ["0.02816000", "0.00000000"], ["0.02815500", "5.16100000"], ["0.02815300", "12.19900000"], ["0.02815200", "16.06400000"], ["0.02815100", "3.60000000"], ["0.02814900", "0.01000000"], ["0.02814800", "2.69100000"], ["0.02814700", "35.07600000"], ["0.02814500", "6.72800000"], ["0.02814400", "20.18400000"], ["0.02813800", "4.33300000"], ["0.02813700", "0.00000000"], ["0.02812500", "0.03900000"], ["0.02811700", "2.02100000"], ["0.02809800", "64.34600000"]], "a": [["0.02817000", "124.55500000"], ["0.02817200", "0.28200000"], ["0.02817300", "4.00000000"], ["0.02817600", "11.10200000"], ["0.02817800", "0.02500000"], ["0.02818500", "22.25000000"], ["0.02819600", "0.00000000"]]}, {"e": "depthUpdate", "E": 1604221333130, "s": "ETHBTC", "U": 1737815697, "u": 1737815721, "b": [["0.02816700", "0.14900000"], ["0.02816200", "11.97100000"], ["0.02815900", "14.60000000"], ["0.02814500", "5.38200000"], ["0.02814200", "0.00000000"], ["0.02814100", "41.71700000"], ["0.02813900", "16.61000000"], ["0.02803100", "0.01800000"], ["0.02784200", "8.34700000"]], "a": [["0.02817000", "128.55500000"], ["0.02817600", "7.10200000"], ["0.02818600", "12.17500000"], ["0.02818700", "36.41700000"], ["0.02819100", "40.36600000"], ["0.02819800", "2.01000000"], ["0.02998000", "5.05900000"]]}, {"e": "depthUpdate", "E": 1604221334130, "s": "ETHBTC", "U": 1737815722, "u": 1737815749, "b": [["0.02816700", "0.13700000"], ["0.02815300", "5.09800000"], ["0.02814200", "40.36900000"], ["0.02814100", "1.34500000"], ["0.02814000", "5.38500000"], ["0.02802900", "35.94300000"]], "a": [["0.02817000", "124.55500000"], ["0.02817600", "11.10200000"], ["0.02818500", "26.28700000"], ["0.02818600", "12.17600000"], ["0.02819300", "2.69000000"], ["0.02821000", "0.00000000"], ["0.02998000", "6.18600000"]]}, {"e": "depthUpdate", "E": 1604221335130, "s": "ETHBTC", "U": 1737815750, "u": 1737815770, "b": [["0.02816700", "0.00000000"], ["0.02816000", "3.60000000"], ["0.02815400", "13.73900000"], ["0.02815100", "0.00000000"], ["0.02814600", "0.00000000"], ["0.02814100", "5.38200000"], ["0.02814000", "5.38100000"]], "a": [["0.02818300", "26.99400000"], ["0.02818600", "0.06500000"], ["0.02819300", "14.80100000"], ["0.02854400", "0.01600000"]]}, {"e": "depthUpdate", "E": 1604221336130, "s": "ETHBTC", "U": 1737815771, "u": 1737815789, "b": [["0.02816700", "0.27700000"], ["0.02763400", "0.10600000"]], "a": [["0.02817000", "124.55500000"], ["0.02817600", "11.10200000"], ["0.02819100", "63.13700000"], ["0.02853400", "6.37600000"], ["0.02855300", "0.00000000"]]}, {"e": "depthUpdate", "E": 1604221337130, "s": "ETHBTC", "U": 1737815790, "u": 1737815831, "b": [["0.02816900", "0.00000000"], ["0.02816800", "0.00000000"], ["0.02816700", "1.00000000"], ["0.02816600", "0.13700000"], ["0.02816500", "0.15400000"], ["0.02814600", "20.18500000"], ["0.02814400", "0.00000000"], ["0.02813900", "16.61000000"], ["0.02808400", "1.23100000"], ["0.02681100", "13.90300000"], ["0.02535200", "0.15900000"]], "a": [["0.02816800", "115.52600000"], ["0.02816900", "24.00000000"], ["0.02817000", "33.02900000"], ["0.02817100", "0.28200000"], ["0.02817200", "0.00000000"], ["0.02817300", "5.00000000"], ["0.02817400", "2.95200000"], ["0.02817500", "0.00000000"], ["0.02818000", "14.91500000"], ["0.02818200", "0.02500000"], ["0.02818500", "24.60500000"]]}, {"e": "depthUpdate", "E": 1604221338130, "s": "ETHBTC", "U": 1737815832, "u": 1737815871, "b": [["0.02816700", "106.14100000"], ["0.02816100", "11.00000000"], ["0.02815900", "12.88900000"], ["0.02815800", "1.71100000"], ["0.02815400", "15.38200000"], ["0.02803000", "0.32700000"], ["0.02801200", "23.55600000"], ["0.02781400", "0.00000000"]], "a": [["0.02816800", "109.52600000"], ["0.02817000", "29.02900000"], ["0.02817100", "0.23600000"], ["0.02817600", "12.78600000"], ["0.02817800", "0.02500000"], ["0.02817900", "23.34000000"], ["0.02818000", "0.00000000"], ["0.02818200", "14.94000000"], ["0.02818600", "0.06500000"], ["0.02818800", "1.34500000"], ["0.02819000", "41.71600000"], ["0.02819100", "22.77100000"], ["0.02998000", "6.18600000"], ["0.03129500", "0.11900000"], ["0.03439700", "0.54800000"]]}, {"e": "depthUpdate", "E": 1604221339130, "s": "ETHBTC", "U": 1737815872, "u": 1737815891, "b": [["0.02816700", "102.50000000"], ["0.02816400", "0.00000000"], ["0.02816000", "0.00000000"], ["0.02815800", "3.78000000"], ["0.02815100", "3.60000000"], ["0.02815000", "5.99000000"], ["0.02811000", "12.57000000"], ["0.02808400", "0.03000000"], ["0.02738500", "0.00000000"]], "a": [["0.02816900", "28.00000000"], ["0.02817100", "0.00000000"], ["0.02817600", "8.78600000"], ["0.02818800", "6.72800000"], ["0.02819400", "0.00000000"]]}, {"e": "depthUpdate", "E": 1604221340130, "s": "ETHBTC", "U": 1737815892, "u": 1737815909, "b": [["0.02814000", "5.38100000"], ["0.02793600", "1.13700000"], ["0.02733200", "0.10600000"], ["0.02731600", "1.90000000"]], "a": [["0.02817100", "0.20700000"], ["0.02836600", "16.02900000"], ["0.02837300", "1.36300000"]]}, {"e": "depthUpdate", "E": 1604221341130, "s": "ETHBTC", "U": 1737815910, "u": 1737815937, "b": [["0.02816700", "106.14100000"], ["0.02815300", "5.09800000"], ["0.02814900", "0.01000000"], ["0.02814100", "10.76400000"], ["0.02814000", "0.00000000"], ["0.02810200", "0.18300000"], ["0.02790500", "0.55400000"]], "a": [["0.02816900", "24.00000000"], ["0.02817100", "0.12900000"], ["0.02817500", "4.00000000"], ["0.02818200", "17.63100000"], ["0.02818700", "33.72600000"]]}, {"e": "depthUpdate", "E": 1604221342130, "s": "ETHBTC", "U": 1737815938, "u": 1737815956, "b": [["0.02814700", "55.26100000"], ["0.02814600", "0.00000000"], ["0.02809800", "94.34600000"]], "a": [["0.02817100", "0.26300000"], ["0.02822200", "30.00000000"], ["0.02998000", "5.05900000"]]}, {"e": "depthUpdate", "E": 1604221343130, "s": "ETHBTC", "U": 1737815957, "u": 1737815983, "b": [], "a": [["0.02816800", "24.00000000"], ["0.02816900", "25.14400000"], ["0.02817100", "0.21900000"], ["0.02817200", "1.71100000"], ["0.02817400", "13.95200000"], ["0.02818300", "25.28400000"], ["0.02818700", "74.09500000"], ["0.02819000", "1.34600000"], ["0.02998000", "6.18600000"]]}, {"e": "depthUpdate", "E": 1604221344131, "s": "ETHBTC", "U": 1737815984, "u": 1737816006, "b": [["0.02816700", "1.00000000"], ["0.02816400", "0.00000000"], ["0.02815800", "3.78000000"], ["0.02815000", "5.99400000"], ["0.02802900", "35.53000000"], ["0.02758500", "91.00000000"]], "a": [["0.02816800", "119.52600000"], ["0.02816900", "24.00000000"], ["0.02817100", "0.00000000"], ["0.02817200", "8.81200000"], ["0.02817400", "2.95200000"], ["0.02817900", "19.34000000"], ["0.02818100", "0.04000000"]]}, {"e": "depthUpdate", "E": 1604221345130, "s": "ETHBTC", "U": 1737816007, "u": 1737816035, "b": [["0.02816700", "0.00000000"], ["0.02816600", "0.13700000"], ["0.02816500", "0.11100000"], ["0.02816200", "12.97100000"], ["0.02815300", "0.00000000"], ["0.02815200", "16.06400000"], ["0.02815000", "5.99000000"], ["0.02814800", "15.09500000"], ["0.02814700", "55.26100000"], ["0.02813700", "5.15500000"], ["0.02811000", "0.16600000"], ["0.02808100", "0.95900000"], ["0.02803100", "0.43100000"], ["0.02780100", "2.56400000"]], "a": [["0.02816800", "123.52600000"], ["0.02817100", "0.00000000"], ["0.02817500", "0.00000000"], ["0.02818300", "20.18700000"], ["0.02818600", "5.44700000"], ["0.02818900", "5.38000000"]]}, {"e": "depthUpdate", "E": 1604221346130, "s": "ETHBTC", "U": 1737816036, "u": 1737816096, "b": [["0.02816500", "0.00000000"], ["0.02816400", "0.14800000"], ["0.02814100", "15.91100000"], ["0.02813700", "27.92600000"], ["0.02808100", "0.05900000"], ["0.02803800", "0.00000000"], ["0.02780100", "1.49800000"], ["0.02764600", "0.01000000"]], "a": [["0.02816700", "76.10800000"], ["0.02816800", "28.00000000"], ["0.02817000", "5.02900000"], ["0.02817100", "1.00000000"], ["0.02817300", "8.00000000"], ["0.02818100", "0.04000000"], ["0.02818200", "2.71600000"]]}, {"e": "depthUpdate", "E": 1604221347130, "s": "ETHBTC", "U": 1737816097, "u": 1737816155, "b": [["0.02816600", "0.00000000"], ["0.02816500", "140.42500000"], ["0.02816400", "1.13800000"], ["0.02816300", "11.02400000"], ["0.02816200", "11.97100000"], ["0.02810900", "19.00000000"], ["0.02809300", "39.27100000"], ["0.02803800", "0.49400000"], ["0.02796100", "0.09500000"], ["0.02793600", "1.14100000"], ["0.02784200", "8.30700000"]], "a": [["0.02816600", "0.00000000"], ["0.02816700", "100.10800000"], ["0.02816800", "24.00000000"], ["0.02816900", "0.00000000"], ["0.02817000", "0.32200000"], ["0.02817200", "1.71100000"], ["0.02817700", "7.68900000"], ["0.02817800", "4.02500000"], ["0.02818100", "5.04000000"], ["0.02818300", "25.41100000"], ["0.02818400", "0.00000000"], ["0.02853400", "6.40200000"], ["0.02998000", "6.18600000"]]}, {"e": "depthUpdate", "E": 1604221348130, "s": "ETHBTC", "U": 1737816156, "u": 1737816202, "b": [["0.02816400", "3.19400000"], ["0.02815800", "1.71100000"], ["0.02815400", "8.28100000"], ["0.02814600", "7.10100000"], ["0.02814100", "28.02200000"], ["0.02813900", "4.50000000"], ["0.02812200", "0.00000000"], ["0.02792200", "0.53600000"], ["0.02775400", "0.00900000"], ["0.02758800", "0.22800000"]], "a": [["0.02816700", "105.63400000"], ["0.02817000", "0.02900000"], ["0.02817300", "20.89100000"], ["0.02818200", "17.63100000"], ["0.02818300", "20.18700000"], ["0.02818400", "0.00000000"], ["0.02818500", "11.71200000"], ["0.02841200", "0.84000000"], ["0.02853400", "6.48600000"]]}, {"e": "depthUpdate", "E": 1604221349131, "s": "ETHBTC", "U": 1737816203, "u": 1737816243, "b": [["0.02816500", "140.28500000"], ["0.02816400", "1.39900000"], ["0.02816300", "11.02400000"], ["0.02815900", "14.95800000"], ["0.02815500", "12.26200000"], ["0.02814700", "35.07600000"], ["0.02814600", "0.00000000"], ["0.02814300", "27.41100000"], ["0.02814200", "0.00000000"], ["0.02813800", "44.70600000"], ["0.02794100", "2.03700000"]], "a": [["0.02816700", "81.63400000"], ["0.02816800", "24.28700000"], ["0.02817000", "0.02900000"], ["0.02817100", "6.00000000"], ["0.02818100", "0.04000000"], ["0.02818200", "2.71600000"], ["0.02818300", "20.18700000"], ["0.02818500", "26.62700000"], ["0.02818700", "74.09900000"], ["0.02858200", "0.16500000"], ["0.02875400", "0.00000000"]]}, {"e": "depthUpdate", "E": 1604221350131, "s": "ETHBTC", "U": 1737816244, "u": 1737816319, "b": [["0.02816600", "7.68600000"], ["0.02816500", "135.70400000"], ["0.02816400", "1.14000000"], ["0.02816300", "14.62400000"], ["0.02815900", "12.88900000"], ["0.02815700", "8.00000000"], ["0.02815400", "3.24300000"], ["0.02815100", "0.00000000"], ["0.02814900", "2.70100000"], ["0.02814800", "12.40400000"], ["0.02813700", "5.15500000"], ["0.02813200", "0.00700000"], ["0.02803800", "0.00000000"], ["0.02803100", "0.01800000"], ["0.02801200", "2.49400000"], ["0.02801000", "21.06300000"], ["0.02777300", "0.19100000"], ["0.02760600", "0.34500000"], ["0.02714100", "0.05400000"], ["0.02681100", "13.85700000"]], "a": [["0.02816700", "0.00000000"], ["0.02816800", "0.00000000"], ["0.02816900", "29.67400000"], ["0.02817000", "0.02900000"], ["0.02817100", "5.00000000"], ["0.02817200", "1.71100000"], ["0.02817400", "1.00000000"], ["0.02818100", "0.04000000"], ["0.02818200", "17.63100000"], ["0.02818500", "11.71200000"], ["0.02818700", "33.72600000"], ["0.02819100", "75.25000000"], ["0.02819300", "2.69000000"], ["0.02839600", "0.15600000"], ["0.02856600", "0.26600000"]]}, {"e": "depthUpdate", "E": 1604221351131, "s": "ETHBTC", "U": 1737816320, "u": 1737816406, "b": [["0.02816900", "137.67700000"], ["0.02816800", "1.60000000"], ["0.02816700", "24.15900000"], ["0.02816600", "4.61200000"], ["0.02816500", "24.00000000"], ["0.02816400", "0.14000000"], ["0.02816300", "3.62400000"], ["0.02816200", "0.97100000"], ["0.02816100", "0.00000000"], ["0.02816000", "0.00000000"], ["0.02815800", "0.00000000"], ["0.02815700", "8.00000000"], ["0.02815600", "7.50700000"], ["0.02815500", "5.16100000"], ["0.02815400", "1.64300000"], ["0.02815200", "3.17300000"], ["0.02815000", "0.00000000"], ["0.02805100", "0.42100000"], ["0.02681100", "13.90300000"], ["0.01760200", "0.05100000"], ["0.01495100", "0.04500000"]], "a": [["0.02816900", "0.00000000"], ["0.02817000", "0.02900000"], ["0.02817100", "0.00000000"], ["0.02817200", "0.00000000"], ["0.02817300", "0.00000000"], ["0.02817400", "0.12200000"], ["0.02817500", "0.00000000"], ["0.02817600", "0.00000000"], ["0.02817700", "0.27000000"], ["0.02817800", "18.94000000"], ["0.02817900", "20.34000000"], ["0.02818100", "4.04000000"], ["0.02818200", "0.02500000"], ["0.02818300", "0.00000000"], ["0.02818400", "6.69100000"], ["0.02818500", "24.56200000"], ["0.02818600", "32.72600000"], ["0.02818700", "32.23000000"], ["0.02819100", "0.00000000"], ["0.02819600", "1.49500000"], ["0.02820000", "45.95000000"], ["0.02873800", "0.31200000"], ["0.02998000", "5.05900000"]]}, {"e": "depthUpdate", "E": 1604221352132, "s": "ETHBTC", "U": 1737816407, "u": 1737816528, "b": [["0.02817500", "0.00000000"], ["0.02817400", "28.73200000"], ["0.02817300", "1.00000000"], ["0.02817200", "0.83200000"], ["0.02817100", "7.09700000"], ["0.02817000", "2.17600000"], ["0.02816900", "136.67700000"], ["0.02816700", "24.00000000"], ["0.02816600", "1.71100000"], ["0.02816500", "0.00000000"], ["0.02816400", "7.23800000"], ["0.02816300", "6.78900000"], ["0.02816200", "8.61800000"], ["0.02816000", "5.98600000"], ["0.02815900", "53.63900000"], ["0.02815500", "0.00000000"], ["0.02815400", "0.00000000"], ["0.02815200", "5.11900000"], ["0.02815100", "4.33100000"], ["0.02813800", "40.37300000"], ["0.02786100", "1.27700000"], ["0.02784200", "8.31100000"], ["0.02780100", "0.00000000"], ["0.02728200", "0.00400000"]], "a": [["0.02817000", "0.00000000"], ["0.02817400", "0.00000000"], ["0.02817600", "0.00000000"], ["0.02817700", "0.00000000"], ["0.02817800", "0.02500000"], ["0.02817900", "0.26100000"], ["0.02818000", "0.00000000"], ["0.02818200", "2.73500000"], ["0.02818300", "0.06500000"], ["0.02818400", "6.69100000"], ["0.02818500", "16.88700000"], ["0.02818600", "7.09900000"], ["0.02818700", "4.27000000"], ["0.02818800", "4.03500000"], ["0.02818900", "9.41600000"], ["0.02819000", "1.34600000"], ["0.02819200", "28.83900000"], ["0.02819500", "0.00000000"], ["0.02819600", "1.49500000"], ["0.02819700", "0.12500000"], ["0.02819800", "22.18600000"], ["0.02820100", "17.48800000"], ["0.02820600", "22.18300000"], ["0.02822500", "193.66500000"], ["0.02823000", "0.13400000"], ["0.02836600", "0.02900000"], ["0.02837200", "17.00000000"], ["0.02853400", "1.84400000"], ["0.02854900", "0.12800000"], ["0.02998000", "6.18600000"]]}, {"e": "depthUpdate", "E": 1604221353132, "s": "ETHBTC", "U": 1737816529, "u": 1737816599, "b": [["0.02817600", "24.00000000"], ["0.02817500", "6.85100000"], ["0.02817400", "23.95000000"], ["0.02817300", "1.21900000"], ["0.02817200", "5.86200000"], ["0.02817100", "21.69700000"], ["0.02817000", "0.10700000"], ["0.02816900", "135.50000000"], ["0.02816700", "5.15700000"], ["0.02816500", "12.88600000"], ["0.02816300", "4.79600000"], ["0.02812200", "0.29500000"], ["0.02810800", "0.84300000"], ["0.02807400", "30.02800000"], ["0.02806000", "0.41300000"], ["0.02805100", "0.00800000"], ["0.01760200", "0.01200000"]], "a": [["0.02817700", "5.49100000"], ["0.02817800", "24.02500000"], ["0.02817900", "0.46800000"], ["0.02818100", "0.04000000"], ["0.02818200", "13.73500000"], ["0.02818300", "0.00000000"], ["0.02818400", "5.00000000"], ["0.02818800", "0.00000000"], ["0.02818900", "4.00000000"], ["0.02819000", "16.26100000"], ["0.02819100", "20.04700000"], ["0.02819200", "20.98800000"], ["0.02819300", "8.07000000"], ["0.02819400", "1.34500000"], ["0.02819600", "10.91300000"], ["0.02819900", "65.71800000"], ["0.02827200", "30.87400000"]]}, {"e": "depthUpdate", "E": 1604221354131, "s": "ETHBTC", "U": 1737816600, "u": 1737816629, "b": [["0.02817600", "0.00000000"], ["0.02817100", "14.60000000"], ["0.02817000", "0.00000000"], ["0.02816500", "19.98500000"], ["0.02815500", "0.00400000"], ["0.02814800", "32.57900000"], ["0.02814400", "40.35000000"], ["0.02814300", "7.22500000"], ["0.02813800", "0.00000000"], ["0.02790100", "0.01500000"], ["0.01495100", "0.00000000"]], "a": [["0.02817800", "24.20100000"], ["0.02817900", "0.26100000"], ["0.02818300", "4.00000000"], ["0.02818900", "1.75400000"], ["0.02819000", "18.95100000"], ["0.02819300", "5.38000000"]]}, {"e": "depthUpdate", "E": 1604221355131, "s": "ETHBTC", "U": 1737816630, "u": 1737816652, "b": [["0.02815500", "0.00000000"], ["0.02814900", "25.46400000"]], "a": [["0.02817800", "24.23000000"], ["0.02818000", "1.71000000"], ["0.02818200", "12.02500000"], ["0.02818800", "6.44800000"]]}, {"e": "depthUpdate", "E": 1604221356131, "s": "ETHBTC", "U": 1737816653, "u": 1737816682, "b": [["0.02814500", "10.76400000"], ["0.02814100", "22.64000000"], ["0.02813100", "64.25800000"], ["0.02809800", "30.04000000"], ["0.02806000", "0.00000000"], ["0.02805400", "0.51700000"]], "a": [["0.02817800", "24.22200000"], ["0.02818100", "0.00000000"], ["0.02818700", "4.55800000"], ["0.02819200", "26.07300000"], ["0.02853400", "2.00400000"], ["0.02998000", "6.18600000"]]}, {"e": "depthUpdate", "E": 1604221357131, "s": "ETHBTC", "U": 1737816683, "u": 1737816744, "b": [["0.02817500", "0.00000000"], ["0.02817400", "140.23200000"], ["0.02817300", "1.00000000"], ["0.02817200", "5.24000000"], ["0.02817100", "11.00000000"], ["0.02816900", "24.00000000"], ["0.02816800", "0.00000000"], ["0.02816600", "3.78000000"], ["0.02816300", "6.39600000"], ["0.02816200", "9.45000000"], ["0.02816000", "9.58600000"], ["0.02815300", "0.00000000"], ["0.02815100", "4.33100000"]], "a": [["0.02817500", "76.00000000"], ["0.02817600", "24.03300000"], ["0.02817700", "0.28000000"], ["0.02817800", "24.02500000"], ["0.02818000", "5.00000000"], ["0.02818200", "0.02500000"], ["0.02818300", "0.00000000"], ["0.02819200", "46.24800000"], ["0.02819300", "5.38000000"], ["0.02819800", "2.01000000"], ["0.02820000", "45.94000000"]]}, {"e": "depthUpdate", "E": 1604221358131, "s": "ETHBTC", "U": 1737816745, "u": 1737816766, "b": [["0.02817400", "135.45000000"], ["0.02816900", "35.00000000"], ["0.02805400", "0.10400000"]], "a": [["0.02817500", "105.49100000"], ["0.02817600", "24.00000000"], ["0.02817700", "0.12600000"]]}, {"e": "depthUpdate", "E": 1604221359131, "s": "ETHBTC", "U": 1737816767, "u": 1737816807, "b": [["0.02817400", "140.23200000"], ["0.02817300", "1.10300000"], ["0.02817200", "5.03000000"], ["0.02817100", "11.83200000"], ["0.02816200", "8.61800000"], ["0.02815100", "24.50500000"], ["0.02814800", "52.75300000"], ["0.02814400", "0.00000000"], ["0.02803100", "0.43100000"]], "a": [["0.02817500", "0.00000000"], ["0.02817600", "24.03300000"], ["0.02817700", "0.25500000"], ["0.02818100", "1.71000000"], ["0.02854900", "4.35100000"]]}, {"e": "depthUpdate", "E": 1604221360131, "s": "ETHBTC", "U": 1737816808, "u": 1737816848, "b": [["0.02817600", "140.28200000"], ["0.02817500", "3.06900000"], ["0.02817400", "23.95000000"], ["0.02817300", "0.10300000"], ["0.02817100", "0.83200000"], ["0.02817000", "3.60000000"], ["0.02816900", "24.00000000"], ["0.02816600", "1.71100000"], ["0.02816000", "5.98600000"], ["0.02795600", "0.00000000"]], "a": [["0.02817600", "0.00000000"], ["0.02817700", "0.04000000"], ["0.02817800", "24.02500000"], ["0.02817900", "0.41300000"], ["0.02818000", "0.00000000"], ["0.02818100", "0.00000000"], ["0.02818300", "2.71000000"], ["0.02818600", "11.09900000"], ["0.02819200", "26.07300000"], ["0.02819900", "85.89100000"], ["0.02998000", "5.05900000"]]}, {"e": "depthUpdate", "E": 1604221361131, "s": "ETHBTC", "U": 1737816849, "u": 1737816869, "b": [["0.02817600", "128.67900000"], ["0.02817300", "0.00000000"], ["0.02817200", "6.76100000"], ["0.02816300", "4.79600000"], ["0.02805900", "0.45300000"], ["0.02803100", "0.01800000"], ["0.02681100", "13.90300000"]], "a": [["0.02817700", "29.53100000"], ["0.02817800", "0.02500000"], ["0.02818300", "1.00000000"], ["0.02818400", "6.71000000"], ["0.02818500", "12.88700000"], ["0.02819400", "5.34500000"], ["0.02820400", "0.00000000"], ["0.02821300", "50.88000000"], ["0.02858500", "5.76000000"], ["0.02998000", "6.18600000"]]}, {"e": "depthUpdate", "E": 1604221362131, "s": "ETHBTC", "U": 1737816870, "u": 1737816939, "b": [["0.02817600", "0.00000000"], ["0.02817500", "117.28200000"], ["0.02817400", "23.95000000"], ["0.02817200", "1.93000000"], ["0.02817100", "0.00000000"], ["0.02817000", "0.00000000"], ["0.02816600", "2.06900000"], ["0.02816500", "12.88600000"], ["0.02816200", "10.21800000"], ["0.02816100", "4.43200000"], ["0.02813000", "150.00000000"], ["0.02803000", "21.37500000"], ["0.02801000", "0.00000000"], ["0.02794100", "2.21600000"]], "a": [["0.02817600", "0.00000000"], ["0.02817700", "105.53100000"], ["0.02817800", "0.22100000"], ["0.02817900", "0.26100000"], ["0.02818200", "4.02500000"], ["0.02818700", "0.55800000"], ["0.02818800", "10.44800000"], ["0.02819000", "18.95100000"], ["0.02819200", "23.41200000"], ["0.02819400", "1.34500000"]]}, {"e": "depthUpdate", "E": 1604221363131, "s": "ETHBTC", "U": 1737816940, "u": 1737816982, "b": [["0.02817600", "140.28200000"], ["0.02817500", "1.00000000"], ["0.02817400", "24.15200000"], ["0.02817300", "2.06900000"], ["0.02817200", "2.54200000"], ["0.02817000", "3.60000000"], ["0.02816600", "7.09800000"], ["0.02816100", "0.00000000"], ["0.02814600", "1.34500000"], ["0.02814400", "12.10500000"], ["0.02814100", "9.18400000"], ["0.02805900", "0.04000000"], ["0.02681100", "13.90300000"]], "a": [["0.02817700", "0.04000000"], ["0.02817800", "0.02500000"], ["0.02817900", "0.45000000"], ["0.02818100", "0.00000000"], ["0.02818200", "0.02500000"], ["0.02818500", "15.54900000"], ["0.02818600", "7.09900000"], ["0.02818700", "4.55800000"], ["0.02819400", "5.34500000"]]}, {"e": "depthUpdate", "E": 1604221364132, "s": "ETHBTC", "U": 1737816983, "u": 1737817002, "b": [["0.02817600", "114.07400000"], ["0.02817400", "23.95000000"], ["0.02817300", "2.06900000"], ["0.02817200", "2.73900000"], ["0.02817100", "5.03200000"], ["0.02816100", "0.00400000"], ["0.02815300", "20.17500000"], ["0.02815100", "4.33100000"], ["0.02815000", "40.35000000"], ["0.02814800", "12.40400000"], ["0.02804000", "0.41300000"]], "a": [["0.02817700", "29.56300000"], ["0.02837200", "1.00000000"], ["0.02837400", "16.06100000"]]}, {"e": "depthUpdate", "E": 1604221365132, "s": "ETHBTC", "U": 1737817003, "u": 1737817024, "b": [["0.02817600", "118.85600000"], ["0.02817500", "1.00000000"], ["0.02817300", "2.24400000"], ["0.02817200", "2.54200000"], ["0.02817100", "6.63200000"], ["0.02816200", "8.61800000"], ["0.02816100", "0.00000000"], ["0.02815100", "7.02100000"], ["0.02814900", "22.77300000"], ["0.02814500", "14.79900000"], ["0.02814100", "5.14700000"], ["0.02813100", "64.25800000"]], "a": [["0.02817700", "0.04000000"], ["0.02819000", "16.26100000"], ["0.02819300", "25.55600000"], ["0.02819400", "8.03500000"], ["0.02819900", "65.71800000"], ["0.02827200", "30.00000000"], ["0.02998000", "5.05900000"]]}, {"e": "depthUpdate", "E": 1604221366132, "s": "ETHBTC", "U": 1737817025, "u": 1737817041, "b": [["0.02817600", "132.26300000"], ["0.02817300", "2.21800000"], ["0.02817200", "2.54200000"], ["0.02814800", "0.00000000"], ["0.02813100", "76.66200000"], ["0.02812300", "0.02600000"], ["0.02805900", "0.45300000"], ["0.02804000", "0.00000000"], ["0.02764200", "0.00500000"], ["0.02763100", "0.06500000"]], "a": [["0.02819300", "5.38000000"], ["0.02820000", "66.11500000"], ["0.02998000", "6.18600000"]]}, {"e": "depthUpdate", "E": 1604221367132, "s": "ETHBTC", "U": 1737817042, "u": 1737817045, "b": [], "a": [["0.02818500", "19.54900000"], ["0.02819300", "10.76100000"], ["0.02819400", "4.03500000"], ["0.02820100", "12.10700000"]]}, {"e": "depthUpdate", "E": 1604221368132, "s": "ETHBTC", "U": 1737817046, "u": 1737817065, "b": [["0.02817400", "24.16700000"], ["0.02817300", "2.06900000"], ["0.02817200", "13.54200000"]], "a": [["0.02817900", "0.18900000"], ["0.02818300", "12.00000000"], ["0.02818400", "5.00000000"], ["0.02818500", "18.59700000"], ["0.02819700", "40.47400000"], ["0.02819800", "14.11600000"], ["0.02820000", "25.76500000"], ["0.02820100", "0.00000000"]]}, {"e": "depthUpdate", "E": 1604221369132, "s": "ETHBTC", "U": 1737817066, "u": 1737817095, "b": [["0.02817400", "24.11000000"], ["0.02816600", "0.00000000"], ["0.02816400", "14.33600000"], ["0.02815500", "20.17700000"], ["0.02815300", "0.00000000"], ["0.02815200", "45.47300000"], ["0.02815000", "0.00000000"], ["0.02813800", "0.00000000"], ["0.02733200", "0.00000000"]], "a": [["0.02818900", "4.41600000"]]}, {"e": "depthUpdate", "E": 1604221370132, "s": "ETHBTC", "U": 1737817096, "u": 1737817122, "b": [["0.02817400", "24.10500000"], ["0.02731900", "0.22200000"]], "a": [["0.02818300", "11.00000000"], ["0.02819700", "0.12500000"], ["0.02820300", "40.35400000"], ["0.02851400", "0.00000000"], ["0.02998000", "6.18600000"]]}, {"e": "depthUpdate", "E": 1604221371132, "s": "ETHBTC", "U": 1737817123, "u": 1737817148, "b": [["0.02817400", "24.24600000"], ["0.02814700", "40.45700000"], ["0.02814500", "9.41700000"], ["0.02810900", "19.00000000"]], "a": [["0.02819500", "20.17700000"], ["0.02820000", "5.59000000"], ["0.02822500", "193.71600000"], ["0.02854100", "1.14400000"]]}, {"e": "depthUpdate", "E": 1604221372132, "s": "ETHBTC", "U": 1737817149, "u": 1737817170, "b": [["0.02817400", "24.18700000"]], "a": [["0.02818200", "0.02500000"], ["0.02818700", "4.55800000"]]}, {"e": "depthUpdate", "E": 1604221373132, "s": "ETHBTC", "U": 1737817171, "u": 1737817191, "b": [["0.02817400", "24.07200000"], ["0.02816600", "7.09900000"], ["0.02816400", "7.23800000"], ["0.02815000", "0.00000000"]], "a": [["0.02817900", "0.25700000"], ["0.02818000", "0.00000000"], ["0.02818500", "16.88700000"], ["0.02818600", "8.80900000"], ["0.02854900", "4.66200000"]]}, {"e": "depthUpdate", "E": 1604221374132, "s": "ETHBTC", "U": 1737817192, "u": 1737817218, "b": [["0.02817400", "24.09000000"], ["0.02815600", "27.68400000"], ["0.02815500", "0.00000000"], ["0.02815400", "40.35400000"], ["0.02815200", "5.11900000"], ["0.02814200", "0.00400000"]], "a": [["0.02817700", "0.04000000"], ["0.02817900", "0.18600000"], ["0.02818000", "0.00000000"], ["0.02818400", "6.71000000"], ["0.02818600", "7.09900000"]]}, {"e": "depthUpdate", "E": 1604221375132, "s": "ETHBTC", "U": 1737817219, "u": 1737817242, "b": [["0.02817400", "24.19300000"], ["0.02816500", "12.88600000"], ["0.02814200", "0.00000000"]], "a": [["0.02819500", "20.17700000"], ["0.02819900", "65.71800000"], ["0.02820300", "40.35400000"], ["0.02822500", "193.71600000"], ["0.02827200", "30.87400000"], ["0.02998000", "6.18600000"]]}, {"e": "depthUpdate", "E": 1604221376132, "s": "ETHBTC", "U": 1737817243, "u": 1737817262, "b": [["0.02817400", "24.08300000"]], "a": [["0.02818200", "4.02500000"], ["0.02818700", "0.55800000"]]}, {"e": "depthUpdate", "E": 1604221377132, "s": "ETHBTC", "U": 1737817263, "u": 1737817281, "b": [["0.02817400", "24.07500000"], ["0.02816600", "0.00000000"], ["0.02816500", "19.98400000"], ["0.02811600", "0.00600000"], ["0.02805300", "0.54600000"]], "a": []}, {"e": "depthUpdate", "E": 1604221378132, "s": "ETHBTC", "U": 1737817282, "u": 1737817294, "b": [["0.02817400", "24.19600000"], ["0.02814700", "52.56300000"], ["0.02814400", "0.00000000"]], "a": [["0.02818400", "17.71000000"]]}, {"e": "depthUpdate", "E": 1604221379133, "s": "ETHBTC", "U": 1737817295, "u": 1737817409, "b": [["0.02817600", "0.00000000"], ["0.02817500", "0.00000000"], ["0.02817400", "0.00000000"], ["0.02817300", "0.00000000"], ["0.02817200", "0.00000000"], ["0.02817100", "0.00000000"], ["0.02817000", "0.00000000"], ["0.02816800", "0.00000000"], ["0.02816700", "0.00000000"], ["0.02816600", "0.14900000"], ["0.02816500", "12.88600000"], ["0.02816400", "0.14000000"], ["0.02816300", "0.85600000"], ["0.02816200", "3.04000000"], ["0.02816100", "5.20000000"], ["0.02815800", "7.10000000"], ["0.02815600", "14.60700000"], ["0.02815500", "4.85800000"], ["0.02815300", "5.03700000"], ["0.02815200", "25.30000000"], ["0.02814900", "0.01000000"], ["0.02805300", "0.42200000"], ["0.02775900", "0.83500000"], ["0.02775400", "0.11300000"]], "a": [["0.02817200", "1.25800000"], ["0.02817300", "84.00000000"], ["0.02817400", "35.00000000"], ["0.02817500", "24.00000000"], ["0.02817600", "28.00000000"], ["0.02817700", "0.30100000"], ["0.02817800", "7.12500000"], ["0.02817900", "12.88800000"], ["0.02818300", "0.00000000"], ["0.02818400", "1.71000000"], ["0.02818500", "18.38300000"], ["0.02818600", "7.46000000"], ["0.02818700", "2.96000000"], ["0.02818800", "6.44800000"], ["0.02818900", "1.75400000"], ["0.02819000", "1.34600000"], ["0.02819100", "25.62400000"], ["0.02819200", "20.72200000"], ["0.02819500", "0.00000000"], ["0.02819600", "4.03600000"], ["0.02819900", "42.94700000"], ["0.02820100", "4.33200000"], ["0.02821300", "46.54900000"], ["0.02822500", "193.66500000"], ["0.02998000", "5.05900000"]]}, {"e": "depthUpdate", "E": 1604221380133, "s": "ETHBTC", "U": 1737817410, "u": 1737817430, "b": [["0.02816600", "0.00000000"], ["0.02816400", "0.00000000"], ["0.02816100", "5.46900000"], ["0.02815900", "58.79900000"], ["0.02815500", "17.26200000"], ["0.02815400", "0.00000000"], ["0.02814700", "40.45700000"], ["0.02814500", "49.78100000"], ["0.02814300", "19.33400000"], ["0.02813100", "64.25800000"], ["0.02805900", "0.04000000"]], "a": [["0.02817100", "4.00000000"], ["0.02818100", "1.69700000"], ["0.02818200", "0.02500000"], ["0.02818300", "7.10000000"], ["0.02818400", "16.62500000"], ["0.02818900", "0.00000000"], ["0.02819100", "65.98800000"], ["0.02820300", "0.00000000"]]}, {"e": "depthUpdate", "E": 1604221381133, "s": "ETHBTC", "U": 1737817431, "u": 1737817459, "b": [["0.02817000", "140.28300000"], ["0.02816800", "0.15300000"], ["0.02816200", "3.19600000"], ["0.02816100", "5.20000000"], ["0.02815300", "0.00000000"], ["0.02802900", "35.94300000"], ["0.02780100", "2.56400000"], ["0.02681100", "13.90300000"]], "a": [["0.02817100", "4.00000000"], ["0.02817200", "0.00000000"], ["0.02817300", "89.78300000"], ["0.02817400", "5.00000000"], ["0.02817900", "13.88800000"], ["0.02818200", "2.68800000"], ["0.02818400", "1.71000000"], ["0.02818600", "22.37500000"], ["0.02819800", "36.88200000"], ["0.02863000", "0.57900000"], ["0.02998000", "6.18600000"]]}, {"e": "depthUpdate", "E": 1604221382133, "s": "ETHBTC", "U": 1737817460, "u": 1737817502, "b": [["0.02817100", "3.78300000"], ["0.02817000", "136.50000000"], ["0.02816700", "0.13200000"], ["0.02816400", "5.03500000"], ["0.02816200", "3.04000000"], ["0.02815500", "4.85800000"], ["0.02813100", "0.00000000"], ["0.02812500", "64.31100000"], ["0.02809800", "42.44400000"]], "a": [["0.02817100", "0.00000000"], ["0.02817200", "90.00000000"], ["0.02817300", "0.00000000"], ["0.02817400", "1.25600000"], ["0.02818000", "4.00000000"], ["0.02818200", "2.97700000"], ["0.02818400", "1.71000000"], ["0.02818600", "7.46000000"], ["0.02818700", "8.34200000"], ["0.02819300", "5.38000000"]]}, {"e": "depthUpdate", "E": 1604221383133, "s": "ETHBTC", "U": 1737817503, "u": 1737817567, "b": [["0.02817200", "4.61500000"], ["0.02817100", "135.50000000"], ["0.02817000", "25.00000000"], ["0.02816900", "24.24600000"], ["0.02816700", "0.00000000"], ["0.02816300", "0.02400000"], ["0.02815500", "4.85800000"], ["0.02815200", "27.99100000"], ["0.02815100", "4.33100000"], ["0.02814500", "72.54900000"], ["0.02810800", "0.84300000"], ["0.02802900", "35.53000000"]], "a": [["0.02817200", "0.00000000"], ["0.02817300", "6.00000000"], ["0.02817400", "0.00000000"], ["0.02817500", "0.22100000"], ["0.02817600", "0.00000000"], ["0.02817800", "0.02500000"], ["0.02818100", "1.69700000"], ["0.02818200", "2.97700000"], ["0.02818300", "19.19900000"], ["0.02818400", "16.62500000"], ["0.02818500", "22.38300000"], ["0.02818800", "7.79300000"], ["0.02818900", "4.03700000"], ["0.02819000", "13.45500000"], ["0.02819400", "2.69000000"], ["0.02819600", "0.00000000"], ["0.02819800", "24.77600000"], ["0.02822100", "0.05100000"], ["0.02822700", "0.99000000"]]}, {"e": "depthUpdate", "E": 1604221384133, "s": "ETHBTC", "U": 1737817568, "u": 1737817636, "b": [["0.02817400", "3.05800000"], ["0.02817300", "24.00000000"], ["0.02817200", "112.50000000"], ["0.02817100", "24.00000000"], ["0.02817000", "0.00000000"], ["0.02816900", "0.15400000"], ["0.02816600", "2.06900000"], ["0.02816200", "1.80300000"], ["0.02815100", "4.33500000"], ["0.02814000", "0.00000000"], ["0.02805900", "0.45300000"], ["0.02789300", "3.30100000"], ["0.01408500", "0.00000000"]], "a": [["0.02817300", "0.00000000"], ["0.02817500", "120.19000000"], ["0.02817600", "0.00000000"], ["0.02817700", "0.46700000"], ["0.02817900", "13.88800000"], ["0.02818200", "2.97700000"], ["0.02818400", "1.71000000"], ["0.02818500", "37.29800000"], ["0.02818600", "27.64000000"], ["0.02819100", "5.44600000"], ["0.02819400", "43.05100000"], ["0.02822100", "0.00000000"], ["0.02822700", "0.95400000"], ["0.02998000", "5.05900000"]]}, {"e": "depthUpdate", "E": 1604221385133, "s": "ETHBTC", "U": 1737817637, "u": 1737817657, "b": [["0.02817400", "0.00000000"], ["0.02817300", "23.36500000"], ["0.02815100", "4.33100000"]], "a": [["0.02817400", "115.13100000"], ["0.02817500", "24.00000000"], ["0.02817600", "0.21400000"], ["0.02817700", "0.30100000"], ["0.02818500", "37.29800000"], ["0.02818800", "6.44800000"], ["0.02819200", "22.06700000"], ["0.02827200", "30.00000000"], ["0.02998000", "6.18600000"]]}, {"e": "depthUpdate", "E": 1604221386133, "s": "ETHBTC", "U": 1737817658, "u": 1737817725, "b": [["0.02817300", "0.00000000"], ["0.02817200", "0.00000000"], ["0.02817100", "104.98500000"], ["0.02816600", "0.00000000"], ["0.02816400", "1.71100000"], ["0.02816100", "3.60000000"], ["0.02816000", "8.05500000"], ["0.02815100", "5.93100000"], ["0.02814700", "45.83900000"], ["0.02814500", "67.16700000"], ["0.02808500", "0.38800000"], ["0.02805900", "0.04000000"], ["0.02805300", "0.05000000"], ["0.02803100", "0.43100000"], ["0.02803000", "0.32700000"], ["0.02801600", "21.62100000"], ["0.02788200", "2.92800000"], ["0.02781000", "3.00000000"]], "a": [["0.02817200", "120.24600000"], ["0.02817300", "32.00000000"], ["0.02817400", "24.19900000"], ["0.02817500", "0.00000000"], ["0.02817600", "0.00000000"], ["0.02818000", "0.00000000"], ["0.02818300", "14.19900000"], ["0.02818400", "16.62500000"], ["0.02818500", "14.38300000"], ["0.02818700", "2.96000000"], ["0.02819200", "27.44900000"]]}, {"e": "depthUpdate", "E": 1604221387133, "s": "ETHBTC", "U": 1737817726, "u": 1737817760, "b": [["0.02817100", "24.98500000"], ["0.02816500", "23.88600000"], ["0.02816100", "8.63600000"], ["0.02814700", "47.18400000"], ["0.02814600", "0.00000000"], ["0.02812300", "0.02600000"], ["0.02808500", "0.06200000"]], "a": [["0.02817200", "115.24600000"], ["0.02817300", "28.00000000"], ["0.02817400", "24.27900000"], ["0.02817800", "4.02500000"], ["0.02818100", "6.69700000"], ["0.02818200", "6.97700000"], ["0.02818400", "16.62500000"], ["0.02818500", "14.38300000"]]}, {"e": "depthUpdate", "E": 1604221388133, "s": "ETHBTC", "U": 1737817761, "u": 1737817794, "b": [["0.02816400", "0.00000000"], ["0.02816300", "1.73500000"], ["0.02816000", "9.65500000"], ["0.02815300", "12.40400000"], ["0.02815100", "4.33100000"], ["0.02809800", "30.04000000"], ["0.02808400", "0.03000000"], ["0.02790600", "0.00800000"], ["0.02779300", "0.15300000"]], "a": [["0.02817200", "115.24600000"], ["0.02817400", "24.15800000"], ["0.02817800", "4.02500000"], ["0.02836800", "16.05000000"], ["0.02837400", "0.06100000"]]}, {"e": "depthUpdate", "E": 1604221389133, "s": "ETHBTC", "U": 1737817795, "u": 1737817828, "b": [["0.02816900", "0.00000000"], ["0.02816800", "0.33400000"], ["0.02816500", "11.00000000"], ["0.02816300", "1.73500000"], ["0.02815200", "40.88100000"], ["0.02812500", "0.03900000"], ["0.02809900", "65.50600000"], ["0.02803100", "0.01800000"], ["0.02802700", "0.42900000"]], "a": [["0.02817200", "119.24600000"], ["0.02817400", "24.14500000"], ["0.02817700", "1.30100000"], ["0.02817800", "0.02500000"], ["0.02817900", "12.88800000"], ["0.02818900", "44.40100000"], ["0.02819400", "2.69000000"], ["0.02822700", "0.93900000"], ["0.02998000", "5.05900000"]]}, {"e": "depthUpdate", "E": 1604221390133, "s": "ETHBTC", "U": 1737817829, "u": 1737817863, "b": [["0.02817100", "0.00000000"], ["0.02817000", "1.00000000"], ["0.02816300", "0.02400000"], ["0.02816000", "11.36600000"], ["0.02815100", "0.00000000"], ["0.02813900", "8.83300000"], ["0.02813000", "0.00000000"], ["0.02812500", "150.03900000"], ["0.02809500", "0.00000000"], ["0.02789400", "0.07100000"]], "a": [["0.02817100", "119.96700000"], ["0.02817200", "33.00000000"], ["0.02817300", "28.29100000"], ["0.02817400", "0.00000000"], ["0.02817800", "0.29500000"], ["0.02818100", "1.69700000"], ["0.02818200", "21.89200000"], ["0.02818400", "1.71000000"], ["0.02818700", "2.69000000"], ["0.02998000", "6.18600000"]]}, {"e": "depthUpdate", "E": 1604221391133, "s": "ETHBTC", "U": 1737817864, "u": 1737817878, "b": [["0.02816200", "0.97100000"], ["0.02816100", "5.03600000"], ["0.02816000", "3.78000000"], ["0.02815800", "0.00000000"], ["0.02815500", "1.69000000"], ["0.02815300", "13.23600000"], ["0.02815200", "38.19000000"], ["0.02814800", "5.20000000"], ["0.02814500", "44.39900000"], ["0.02810000", "8.15200000"], ["0.02681100", "12.25000000"]], "a": [["0.02818200", "4.31400000"]]}, {"e": "depthUpdate", "E": 1604221392133, "s": "ETHBTC", "U": 1737817879, "u": 1737817906, "b": [["0.02816300", "11.02400000"], ["0.02816000", "1.71100000"], ["0.02815900", "53.63900000"], ["0.02815800", "2.43200000"], ["0.02815600", "21.70800000"], ["0.02815500", "3.75900000"], ["0.02815400", "5.16100000"], ["0.02815300", "12.40400000"], ["0.02815100", "5.99100000"], ["0.02815000", "3.17000000"], ["0.02814900", "2.70100000"], ["0.02814800", "0.00000000"], ["0.02812200", "0.00000000"], ["0.02810800", "1.52900000"], ["0.02810000", "1.03700000"], ["0.02681100", "13.90300000"]], "a": [["0.02817100", "123.96700000"], ["0.02817200", "35.66400000"], ["0.02818100", "1.69700000"], ["0.02818200", "14.94000000"], ["0.02819700", "0.12500000"], ["0.02819800", "2.01000000"]]}, {"e": "depthUpdate", "E": 1604221393133, "s": "ETHBTC", "U": 1737817907, "u": 1737817914, "b": [["0.02816000", "3.78000000"], ["0.02815700", "11.60000000"], ["0.02815500", "1.69000000"]], "a": [["0.02818300", "39.52500000"], ["0.02818600", "7.46000000"], ["0.02819700", "0.12500000"]]}, {"e": "depthUpdate", "E": 1604221394133, "s": "ETHBTC", "U": 1737817915, "u": 1737817952, "b": [["0.02817000", "0.00000000"], ["0.02816900", "1.00000000"], ["0.02816800", "0.15300000"], ["0.02816700", "0.24300000"], ["0.02816400", "0.00400000"], ["0.02808100", "1.26000000"]], "a": [["0.02817000", "115.35500000"], ["0.02817100", "28.00000000"], ["0.02817200", "35.77100000"], ["0.02817300", "4.00000000"], ["0.02817400", "12.89100000"], ["0.02817800", "0.58400000"], ["0.02818300", "42.21600000"], ["0.02818500", "1.49600000"], ["0.02818700", "5.38200000"], ["0.02819100", "22.83600000"], ["0.02853400", "6.39800000"], ["0.02998000", "5.05900000"]]}, {"e": "depthUpdate", "E": 1604221395133, "s": "ETHBTC", "U": 1737817953, "u": 1737817981, "b": [["0.02816700", "0.11900000"], ["0.02816400", "0.00000000"], ["0.02816100", "6.74700000"], ["0.02816000", "2.06900000"], ["0.02815600", "14.60700000"], ["0.02815500", "8.79100000"], ["0.02808100", "1.26000000"], ["0.02802900", "35.94300000"], ["0.02802700", "0.01600000"]], "a": [["0.02818600", "10.15100000"], ["0.02819400", "0.00000000"], ["0.02827200", "31.15000000"], ["0.02998000", "6.18600000"]]}, {"e": "depthUpdate", "E": 1604221396134, "s": "ETHBTC", "U": 1737817982, "u": 1737818003, "b": [["0.02816700", "0.21700000"], ["0.02816100", "5.03600000"], ["0.02816000", "0.00000000"], ["0.02815800", "0.83200000"], ["0.02815500", "10.86000000"], ["0.02814900", "4.30100000"], ["0.02814500", "4.03500000"], ["0.02814300", "42.10500000"], ["0.02808100", "0.05900000"]], "a": []}, {"e": "depthUpdate", "E": 1604221397134, "s": "ETHBTC", "U": 1737818004, "u": 1737818026, "b": [["0.02816800", "0.00000000"], ["0.02816700", "0.26500000"], ["0.02816100", "0.00000000"], ["0.02816000", "2.06900000"], ["0.02815500", "8.79100000"], ["0.02815200", "23.04500000"], ["0.02814300", "50.17900000"], ["0.02814000", "40.36500000"], ["0.02813700", "17.26500000"], ["0.02809900", "65.50600000"], ["0.02802900", "35.53000000"], ["0.02681100", "1.90800000"]], "a": [["0.02818700", "55.83200000"]]}, {"e": "depthUpdate", "E": 1604221398134, "s": "ETHBTC", "U": 1737818027, "u": 1737818098, "b": [["0.02816900", "0.00000000"], ["0.02816800", "0.00000000"], ["0.02816700", "0.00000000"], ["0.02816600", "5.96700000"], ["0.02816500", "135.69300000"], ["0.02816400", "1.19900000"], ["0.02816100", "11.00000000"], ["0.02815900", "12.88900000"], ["0.02815200", "17.93000000"], ["0.02808000", "1.30300000"], ["0.02802700", "0.42900000"], ["0.02801600", "0.56200000"], ["0.02801400", "21.06000000"], ["0.02681100", "13.90300000"]], "a": [["0.02816600", "0.00000000"], ["0.02816700", "84.00000000"], ["0.02816800", "24.00000000"], ["0.02816900", "0.00000000"], ["0.02817000", "24.29500000"], ["0.02817100", "4.00000000"], ["0.02817200", "7.66400000"], ["0.02817300", "5.00000000"], ["0.02817400", "19.99200000"], ["0.02817500", "0.00000000"], ["0.02817700", "4.30100000"], ["0.02818200", "14.94000000"], ["0.02818300", "35.11700000"], ["0.02818500", "1.49600000"], ["0.02818800", "0.00000000"], ["0.02819100", "22.77100000"], ["0.02822300", "66.40500000"]]}, {"e": "depthUpdate", "E": 1604221399133, "s": "ETHBTC", "U": 1737818099, "u": 1737818147, "b": [["0.02816600", "142.46700000"], ["0.02816500", "35.19300000"], ["0.02816400", "0.17800000"], ["0.02816300", "0.02400000"], ["0.02816100", "0.00000000"], ["0.02816000", "0.83200000"], ["0.02815800", "0.00000000"], ["0.02815700", "11.60000000"], ["0.02815300", "2.06900000"], ["0.02814900", "4.30100000"], ["0.02814800", "0.00000000"], ["0.02814700", "36.42100000"], ["0.02814300", "32.79000000"], ["0.02813800", "5.38300000"], ["0.02812600", "12.40400000"], ["0.02780100", "0.00000000"]], "a": [["0.02816700", "113.52700000"], ["0.02817000", "0.13100000"], ["0.02817100", "0.00000000"], ["0.02817900", "19.33900000"], ["0.02818000", "4.00000000"], ["0.02818500", "1.56100000"], ["0.02822300", "66.34000000"], ["0.02998000", "5.05900000"]]}, {"e": "depthUpdate", "E": 1604221400133, "s": "ETHBTC", "U": 1737818148, "u": 1737818202, "b": [["0.02816700", "0.00000000"], ["0.02816600", "141.67800000"], ["0.02816500", "36.19300000"], ["0.02816400", "0.00000000"], ["0.02816100", "2.06900000"], ["0.02815800", "1.60000000"], ["0.02815500", "1.69000000"], ["0.02815300", "0.00000000"], ["0.02814900", "2.70100000"], ["0.02811200", "0.05000000"]], "a": [["0.02816700", "0.00000000"], ["0.02816800", "90.85500000"], ["0.02816900", "24.00000000"], ["0.02817000", "0.26000000"], ["0.02817100", "1.71100000"], ["0.02817300", "4.00000000"], ["0.02817800", "0.58400000"], ["0.02818400", "0.00000000"], ["0.02818800", "12.11000000"], ["0.02819000", "1.34600000"], ["0.02836500", "16.00000000"], ["0.02836800", "0.05000000"], ["0.02998000", "6.18600000"]]}, {"e": "depthUpdate", "E": 1604221401134, "s": "ETHBTC", "U": 1737818203, "u": 1737818249, "b": [["0.02816600", "141.46700000"], ["0.02816500", "36.19300000"], ["0.02816400", "0.26500000"], ["0.02814600", "7.10100000"], ["0.02814000", "63.13600000"], ["0.02813500", "14.80200000"], ["0.02812400", "79.31300000"], ["0.02808000", "0.10200000"], ["0.02682700", "563.33800000"]], "a": [["0.02816700", "6.03700000"], ["0.02816800", "108.85500000"], ["0.02817000", "0.13200000"], ["0.02817400", "20.99200000"], ["0.02827200", "30.86300000"]]}, {"e": "depthUpdate", "E": 1604221402134, "s": "ETHBTC", "U": 1737818250, "u": 1737818292, "b": [["0.02816400", "0.00000000"], ["0.02815500", "8.79100000"], ["0.02814600", "0.00000000"], ["0.02814400", "20.18300000"], ["0.02814300", "12.60700000"], ["0.02814100", "45.51200000"], ["0.02814000", "22.77100000"], ["0.02802900", "35.94300000"], ["0.02802700", "0.01600000"]], "a": [["0.02816700", "114.89200000"], ["0.02816800", "24.00000000"], ["0.02816900", "0.00000000"], ["0.02817000", "0.00000000"], ["0.02818100", "3.19700000"], ["0.02818200", "0.02500000"], ["0.02818500", "0.06500000"], ["0.02818600", "15.53300000"], ["0.02819200", "22.06700000"]]}, {"e": "depthUpdate", "E": 1604221403134, "s": "ETHBTC", "U": 1737818293, "u": 1737818332, "b": [["0.02816600", "141.46700000"], ["0.02816500", "36.19300000"], ["0.02816400", "0.21900000"], ["0.02816100", "13.06900000"], ["0.02815500", "1.69000000"], ["0.02814100", "45.51200000"], ["0.02790000", "4.92800000"]], "a": [["0.02816700", "0.03700000"], ["0.02816800", "25.35500000"], ["0.02817000", "0.25500000"], ["0.02817300", "15.00000000"], ["0.02817800", "15.49900000"], ["0.02818100", "3.19700000"]]}, {"e": "depthUpdate", "E": 1604221404134, "s": "ETHBTC", "U": 1737818333, "u": 1737818398, "b": [["0.02816400", "0.00000000"], ["0.02815600", "14.60700000"], ["0.02815200", "12.89400000"], ["0.02814700", "35.07600000"], ["0.02814600", "4.03700000"], ["0.02814500", "0.00000000"], ["0.02814300", "13.95300000"], ["0.02814200", "0.00400000"], ["0.02814000", "0.00000000"], ["0.02802900", "35.53000000"], ["0.02788500", "34.02800000"]], "a": [["0.02816800", "0.00000000"], ["0.02816900", "0.00000000"], ["0.02817000", "0.00000000"], ["0.02817100", "0.00000000"], ["0.02817200", "9.37500000"], ["0.02817400", "13.89100000"], ["0.02817600", "0.05100000"], ["0.02817800", "0.58400000"], ["0.02817900", "6.45100000"], ["0.02818000", "23.98800000"], ["0.02818200", "14.94000000"], ["0.02818900", "4.03700000"], ["0.02819500", "40.36100000"], ["0.02998000", "6.18600000"]]}, {"e": "depthUpdate", "E": 1604221405134, "s": "ETHBTC", "U": 1737818399, "u": 1737818440, "b": [["0.02816600", "143.53600000"], ["0.02816400", "0.12200000"], ["0.02816200", "0.97100000"], ["0.02816100", "11.00000000"], ["0.02814600", "0.00000000"], ["0.02814400", "24.22000000"], ["0.02814200", "0.00000000"], ["0.02814000", "0.00000000"], ["0.02803100", "0.43100000"], ["0.02791600", "1.09100000"]], "a": [["0.02816900", "0.13600000"], ["0.02817000", "0.00000000"], ["0.02817100", "0.00000000"], ["0.02817200", "5.00000000"], ["0.02817400", "12.89100000"], ["0.02817600", "1.76200000"], ["0.02817700", "5.30100000"], ["0.02818100", "1.69700000"], ["0.02818300", "14.93400000"], ["0.02818600", "17.03000000"], ["0.02818700", "76.01300000"], ["0.02818800", "0.00000000"], ["0.02819000", "13.45600000"], ["0.02853400", "1.84400000"]]}, {"e": "depthUpdate", "E": 1604221406134, "s": "ETHBTC", "U": 1737818441, "u": 1737818456, "b": [["0.02816400", "0.00000000"], ["0.02815800", "8.70000000"], ["0.02814200", "22.77100000"], ["0.02791600", "0.55500000"], ["0.02790900", "0.62300000"]], "a": [["0.02817900", "9.11500000"]]}, {"e": "depthUpdate", "E": 1604221407134, "s": "ETHBTC", "U": 1737818457, "u": 1737818480, "b": [["0.02816400", "0.22200000"], ["0.02816100", "16.03600000"], ["0.02814600", "20.18400000"], ["0.02814400", "4.03700000"], ["0.02814200", "63.13900000"], ["0.02814100", "5.14700000"], ["0.02813100", "0.00000000"], ["0.02809800", "30.04000000"], ["0.02805100", "0.42100000"], ["0.02803100", "0.01800000"]], "a": [["0.02827200", "30.86200000"]]}, {"e": "depthUpdate", "E": 1604221408134, "s": "ETHBTC", "U": 1737818481, "u": 1737818495, "b": [["0.02816400", "0.18000000"], ["0.02816300", "11.02400000"], ["0.02815800", "1.60000000"], ["0.02815300", "0.00000000"], ["0.02814800", "7.10100000"], ["0.02790500", "1.09000000"]], "a": [["0.02817300", "16.71100000"], ["0.02817500", "11.00000000"], ["0.02817600", "0.05100000"], ["0.02853400", "6.61800000"], ["0.02998000", "5.05900000"]]}, {"e": "depthUpdate", "E": 1604221409135, "s": "ETHBTC", "U": 1737818496, "u": 1737818578, "b": [["0.02816900", "0.00000000"], ["0.02816800", "0.00000000"], ["0.02816700", "6.91700000"], ["0.02816600", "135.50000000"], ["0.02816500", "35.00000000"], ["0.02816400", "0.00000000"], ["0.02816300", "11.02400000"], ["0.02816000", "2.90100000"], ["0.02815200", "19.99500000"], ["0.02814900", "0.01000000"], ["0.02814800", "0.00000000"], ["0.02814600", "22.87500000"], ["0.02814200", "40.36800000"], ["0.02805100", "0.00800000"]], "a": [["0.02816700", "0.00000000"], ["0.02816800", "113.50000000"], ["0.02816900", "0.22100000"], ["0.02817000", "1.35500000"], ["0.02817100", "24.00000000"], ["0.02817200", "5.00000000"], ["0.02817300", "4.00000000"], ["0.02817400", "13.89100000"], ["0.02817500", "1.00000000"], ["0.02817700", "4.04000000"], ["0.02818200", "0.02500000"], ["0.02818500", "40.43900000"], ["0.02819500", "0.00000000"], ["0.02998000", "6.18600000"]]}, {"e": "depthUpdate", "E": 1604221410134, "s": "ETHBTC", "U": 1737818579, "u": 1737818636, "b": [["0.02816800", "138.53900000"], ["0.02816700", "25.00000000"], ["0.02816600", "24.00000000"], ["0.02816500", "0.00000000"], ["0.02816400", "0.22500000"], ["0.02816300", "0.02400000"], ["0.02816100", "5.03600000"], ["0.02815200", "12.89400000"], ["0.02814400", "11.14100000"], ["0.02803000", "0.74000000"], ["0.02801400", "0.00000000"], ["0.02801000", "21.06300000"]], "a": [["0.02816800", "0.00000000"], ["0.02816900", "24.22100000"], ["0.02817000", "14.43900000"], ["0.02817400", "12.89100000"], ["0.02817700", "0.04000000"], ["0.02817800", "4.58400000"], ["0.02818000", "11.10000000"], ["0.02818200", "14.94000000"], ["0.02818400", "20.18800000"], ["0.02818700", "55.83200000"], ["0.02823300", "2.92600000"]]}, {"e": "depthUpdate", "E": 1604221411134, "s": "ETHBTC", "U": 1737818637, "u": 1737818685, "b": [["0.02816800", "0.00000000"], ["0.02816700", "6.91700000"], ["0.02816500", "0.17000000"], ["0.02816400", "0.00000000"], ["0.02816000", "0.00000000"], ["0.02815800", "0.00000000"], ["0.02815700", "8.00000000"], ["0.02815500", "3.75900000"], ["0.02815100", "6.82300000"], ["0.02814800", "5.20000000"], ["0.02814400", "4.03700000"], ["0.02814200", "47.47300000"], ["0.02814000", "22.77100000"]], "a": [["0.02816800", "93.50000000"], ["0.02816900", "24.22100000"], ["0.02817000", "13.04500000"], ["0.02817100", "24.00000000"], ["0.02817800", "0.58400000"], ["0.02818100", "4.38900000"], ["0.02818300", "12.24300000"]]}, {"e": "depthUpdate", "E": 1604221412134, "s": "ETHBTC", "U": 1737818686, "u": 1737818775, "b": [["0.02816700", "0.00000000"], ["0.02816600", "0.00000000"], ["0.02816500", "4.03900000"], ["0.02816400", "135.60400000"], ["0.02816300", "0.21700000"], ["0.02816200", "0.97100000"], ["0.02816100", "0.00000000"], ["0.02815600", "7.10000000"], ["0.02815500", "2.06900000"], ["0.02815300", "12.40400000"], ["0.02815100", "8.47000000"], ["0.02815000", "10.44900000"], ["0.02814200", "0.00000000"], ["0.02813900", "8.83300000"], ["0.02813800", "57.87200000"], ["0.02813700", "5.15500000"], ["0.02812600", "7.10500000"], ["0.02808100", "0.05900000"], ["0.02803000", "0.32700000"], ["0.02802700", "0.42900000"]], "a": [["0.02816500", "0.00000000"], ["0.02816600", "0.00000000"], ["0.02816700", "1.35500000"], ["0.02816800", "107.74100000"], ["0.02817000", "12.89300000"], ["0.02817100", "2.66500000"], ["0.02817200", "12.10200000"], ["0.02817300", "4.00000000"], ["0.02817400", "13.89100000"], ["0.02817500", "0.00000000"], ["0.02817600", "4.05100000"], ["0.02817700", "4.04000000"], ["0.02817900", "14.10400000"], ["0.02818000", "0.00000000"], ["0.02818200", "14.94000000"], ["0.02818400", "20.18800000"], ["0.02819100", "0.00000000"], ["0.02820600", "14.80800000"]]}, {"e": "depthUpdate", "E": 1604221413134, "s": "ETHBTC", "U": 1737818776, "u": 1737818802, "b": [["0.02816400", "135.50000000"], ["0.02816000", "11.00000000"], ["0.02815600", "12.13800000"], ["0.02814100", "5.14700000"], ["0.02812600", "0.00000000"], ["0.02681100", "13.90300000"]], "a": [["0.02816800", "111.74100000"], ["0.02817600", "0.05100000"], ["0.02818200", "20.32300000"], ["0.02818500", "44.47700000"], ["0.02818900", "0.00000000"], ["0.02819300", "0.00000000"], ["0.02998000", "5.05900000"]]}, {"e": "depthUpdate", "E": 1604221414134, "s": "ETHBTC", "U": 1737818803, "u": 1737818834, "b": [["0.02816500", "3.03900000"], ["0.02816400", "136.67200000"], ["0.02816100", "0.00000000"], ["0.02815600", "14.20700000"], ["0.02815500", "0.00000000"], ["0.02814500", "0.00400000"], ["0.02814100", "5.14700000"], ["0.02814000", "28.15400000"], ["0.02813800", "52.48900000"]], "a": [["0.02816700", "0.43100000"], ["0.02816800", "107.74100000"], ["0.02817300", "8.00000000"], ["0.02819000", "36.22700000"], ["0.02998000", "6.18600000"]]}, {"e": "depthUpdate", "E": 1604221415134, "s": "ETHBTC", "U": 1737818835, "u": 1737818873, "b": [["0.02816500", "114.53900000"], ["0.02816400", "25.00000000"], ["0.02816300", "0.38300000"], ["0.02816000", "0.00000000"], ["0.02814500", "0.00000000"], ["0.02814000", "28.15400000"], ["0.02813500", "0.00000000"], ["0.02811800", "0.00000000"], ["0.02802900", "35.94300000"], ["0.02802700", "0.01600000"]], "a": [["0.02816600", "24.00000000"], ["0.02816700", "0.00000000"], ["0.02817200", "13.10200000"], ["0.02817400", "12.89100000"], ["0.02817800", "1.93000000"], ["0.02818000", "20.18800000"], ["0.02818200", "5.40800000"], ["0.02818300", "13.58900000"], ["0.02818400", "0.00000000"], ["0.02819000", "34.88100000"], ["0.02819200", "20.72200000"]]}, {"e": "depthUpdate", "E": 1604221416134, "s": "ETHBTC", "U": 1737818874, "u": 1737818891, "b": [["0.02816300", "0.43200000"], ["0.02815300", "0.00000000"], ["0.02814000", "35.25900000"], ["0.02813600", "14.81300000"], ["0.02811000", "12.57000000"], ["0.02307100", "0.00000000"]], "a": [["0.02817800", "16.84500000"]]}, {"e": "depthUpdate", "E": 1604221417135, "s": "ETHBTC", "U": 1737818892, "u": 1737818940, "b": [["0.02816500", "135.50000000"], ["0.02816300", "0.21700000"], ["0.02816200", "1.80300000"], ["0.02815800", "3.60000000"], ["0.02815700", "9.60000000"], ["0.02815100", "12.73100000"], ["0.02814800", "20.18800000"], ["0.02814600", "2.69100000"], ["0.02814000", "68.53400000"], ["0.02813900", "8.83300000"], ["0.02813800", "12.11200000"], ["0.02808900", "0.00000000"], ["0.02802900", "35.53000000"]], "a": [["0.02816600", "0.00000000"], ["0.02816700", "0.43100000"], ["0.02816800", "24.00000000"], ["0.02816900", "24.00000000"], ["0.02817100", "0.00000000"], ["0.02817200", "7.71100000"], ["0.02817300", "4.00000000"], ["0.02817700", "4.04000000"], ["0.02817800", "1.93000000"], ["0.02817900", "18.10400000"], ["0.02818500", "4.10300000"], ["0.02818700", "5.38200000"], ["0.03508000", "0.02000000"]]}, {"e": "depthUpdate", "E": 1604221418136, "s": "ETHBTC", "U": 1737818941, "u": 1737819051, "b": [["0.02816800", "29.70400000"], ["0.02816700", "0.00000000"], ["0.02816600", "135.64400000"], ["0.02816500", "24.00000000"], ["0.02816400", "0.00000000"], ["0.02816300", "1.04900000"], ["0.02816200", "11.97100000"], ["0.02815900", "48.31900000"], ["0.02815600", "7.10000000"], ["0.02815500", "2.06900000"], ["0.02815300", "0.00000000"], ["0.02815100", "1.64700000"], ["0.02813800", "12.11200000"], ["0.02813300", "2.01000000"], ["0.02811700", "0.01100000"], ["0.02802700", "0.42900000"], ["0.02681100", "13.90300000"]], "a": [["0.02816700", "0.00000000"], ["0.02816800", "0.00000000"], ["0.02816900", "89.50000000"], ["0.02817000", "0.00000000"], ["0.02817100", "0.16800000"], ["0.02817200", "1.71100000"], ["0.02817300", "0.00000000"], ["0.02817500", "0.00000000"], ["0.02817700", "0.04000000"], ["0.02817800", "0.58400000"], ["0.02817900", "14.10400000"], ["0.02818000", "7.10000000"], ["0.02818100", "24.68800000"], ["0.02818200", "5.02500000"], ["0.02818300", "7.10000000"], ["0.02818400", "14.24000000"], ["0.02818500", "4.10300000"], ["0.02818600", "11.64800000"], ["0.02818700", "29.57500000"], ["0.02818900", "9.34600000"], ["0.02819000", "17.49400000"], ["0.02819100", "40.38200000"], ["0.02998000", "6.18600000"], ["0.03508000", "0.01500000"]]}, {"e": "depthUpdate", "E": 1604221419135, "s": "ETHBTC", "U": 1737819052, "u": 1737819100, "b": [["0.02816800", "143.27300000"], ["0.02816600", "24.13500000"], ["0.02816400", "0.00000000"], ["0.02816200", "0.97100000"], ["0.02815700", "16.70100000"], ["0.02815600", "13.09300000"], ["0.02815500", "0.00000000"], ["0.02780100", "0.00000000"]], "a": [["0.02816900", "6.00000000"], ["0.02817100", "0.25600000"], ["0.02817200", "0.00000000"], ["0.02817300", "1.71200000"], ["0.02817800", "4.58400000"], ["0.02817900", "18.10400000"], ["0.02818000", "7.10000000"], ["0.02818100", "9.68300000"], ["0.02818300", "22.01500000"], ["0.02818600", "11.64800000"], ["0.02818900", "1.34600000"], ["0.02853400", "1.84400000"], ["0.03508700", "0.08000000"], ["0.03561400", "0.05400000"]]}, {"e": "depthUpdate", "E": 1604221420135, "s": "ETHBTC", "U": 1737819101, "u": 1737819127, "b": [["0.02816800", "141.20400000"], ["0.02816300", "3.11800000"], ["0.02806000", "0.41300000"], ["0.02802700", "0.01600000"], ["0.02786500", "1.98900000"], ["0.02711000", "0.82000000"]], "a": [["0.02817100", "0.28700000"], ["0.02817200", "0.00000000"], ["0.02817700", "8.04000000"], ["0.02817900", "14.10400000"], ["0.02818100", "4.29900000"], ["0.02818600", "17.03300000"], ["0.02818700", "25.57500000"], ["0.02819400", "22.77100000"]]}, {"e": "depthUpdate", "E": 1604221421135, "s": "ETHBTC", "U": 1737819128, "u": 1737819160, "b": [["0.02816900", "4.17700000"], ["0.02816800", "135.74300000"], ["0.02816600", "24.00000000"], ["0.02816500", "0.00000000"], ["0.02815600", "20.32300000"]], "a": [["0.02816900", "0.00000000"], ["0.02817100", "6.00000000"], ["0.02817200", "0.00000000"], ["0.02817300", "0.00000000"], ["0.02817400", "14.60300000"], ["0.02817500", "0.00000000"], ["0.02817700", "8.31900000"], ["0.02817800", "4.58400000"], ["0.02817900", "6.45100000"], ["0.02818100", "1.60700000"], ["0.02818200", "19.94000000"], ["0.02818300", "12.26200000"], ["0.02818500", "0.06500000"], ["0.02819000", "21.53200000"]]}, {"e": "depthUpdate", "E": 1604221422135, "s": "ETHBTC", "U": 1737819161, "u": 1737819224, "b": [["0.02817100", "124.62800000"], ["0.02817000", "24.00000000"], ["0.02816900", "0.00000000"], ["0.02816800", "0.13000000"], ["0.02816700", "0.00000000"], ["0.02816600", "0.00000000"], ["0.02816400", "4.55600000"], ["0.02816300", "1.04900000"], ["0.02815100", "5.97800000"], ["0.02814800", "21.53400000"], ["0.02814700", "33.73000000"], ["0.02814500", "0.00000000"], ["0.02814400", "44.42500000"], ["0.02814000", "28.15400000"], ["0.02813900", "4.50000000"], ["0.02806000", "0.00000000"], ["0.02801400", "21.06000000"], ["0.02801000", "0.00000000"], ["0.02761300", "0.00000000"]], "a": [["0.02817000", "0.00000000"], ["0.02817100", "0.00000000"], ["0.02817200", "6.00000000"], ["0.02817300", "0.00000000"], ["0.02817400", "0.00000000"], ["0.02817500", "1.71200000"], ["0.02817700", "8.30200000"], ["0.02817800", "4.29500000"], ["0.02818200", "5.02500000"], ["0.02818500", "2.75700000"], ["0.02818800", "12.89600000"], ["0.02998000", "5.05900000"]]}, {"e": "depthUpdate", "E": 1604221423136, "s": "ETHBTC", "U": 1737819225, "u": 1737819297, "b": [["0.02817100", "0.00000000"], ["0.02817000", "0.00000000"], ["0.02816900", "0.00000000"], ["0.02816800", "135.50000000"], ["0.02816700", "0.00000000"], ["0.02816600", "0.10100000"], ["0.02816400", "0.00000000"], ["0.02816300", "11.21700000"], ["0.02816000", "1.71200000"], ["0.02815800", "5.66900000"], ["0.02815700", "9.60000000"], ["0.02815400", "5.99300000"], ["0.02815100", "1.64700000"], ["0.02814900", "0.01000000"], ["0.02814800", "1.34600000"], ["0.02814500", "20.19200000"], ["0.02814400", "8.36900000"], ["0.02813900", "44.88400000"], ["0.02805600", "0.41700000"], ["0.02760200", "0.55600000"]], "a": [["0.02816900", "10.00000000"], ["0.02817000", "83.98300000"], ["0.02817100", "24.00000000"], ["0.02817200", "0.00000000"], ["0.02817600", "0.26400000"], ["0.02817700", "4.33200000"], ["0.02817900", "6.45100000"], ["0.02818300", "7.10000000"], ["0.02818400", "34.43100000"], ["0.02818600", "26.45700000"], ["0.02818700", "0.00000000"], ["0.02819000", "12.11400000"], ["0.02819100", "0.00000000"], ["0.02819200", "26.10600000"], ["0.02819500", "40.38300000"], ["0.02998000", "6.18600000"], ["0.03556200", "0.24900000"]]}, {"e": "depthUpdate", "E": 1604221424135, "s": "ETHBTC", "U": 1737819298, "u": 1737819335, "b": [["0.02816600", "0.00000000"], ["0.02816100", "0.28900000"], ["0.02815800", "12.77000000"], ["0.02815100", "1.64700000"], ["0.02813500", "0.00400000"], ["0.02796300", "0.16200000"]], "a": [["0.02816900", "89.98300000"], ["0.02817000", "0.00000000"], ["0.02817100", "24.16500000"], ["0.02817400", "4.00000000"], ["0.02817600", "0.05100000"], ["0.02818200", "19.94000000"], ["0.02818300", "7.10000000"], ["0.02836500", "0.00000000"], ["0.02836800", "16.05000000"]]}, {"e": "depthUpdate", "E": 1604221425135, "s": "ETHBTC", "U": 1737819336, "u": 1737819359, "b": [["0.02816800", "24.00000000"], ["0.02815100", "6.80800000"], ["0.02814700", "36.42200000"], ["0.02814600", "0.00000000"], ["0.02813200", "0.00700000"], ["0.02805600", "0.00400000"], ["0.02803000", "0.74000000"]], "a": [["0.02816900", "113.98300000"], ["0.02817100", "24.12700000"], ["0.02817300", "5.00000000"], ["0.02817900", "11.61300000"], ["0.02818200", "0.02500000"], ["0.02818300", "22.01500000"]]}, {"e": "depthUpdate", "E": 1604221426135, "s": "ETHBTC", "U": 1737819360, "u": 1737819388, "b": [["0.02816800", "135.50000000"], ["0.02816600", "0.20300000"], ["0.02816100", "0.00000000"], ["0.02815700", "12.08700000"], ["0.02815100", "1.64700000"], ["0.02814800", "13.75000000"], ["0.02813500", "0.00000000"], ["0.02813100", "0.00000000"], ["0.02811000", "0.16600000"], ["0.01408300", "0.20000000"]], "a": [["0.02816900", "89.98300000"], ["0.02817100", "24.18300000"], ["0.02818200", "14.94000000"], ["0.02818300", "7.10000000"], ["0.02818600", "14.34200000"]]}, {"e": "depthUpdate", "E": 1604221427135, "s": "ETHBTC", "U": 1737819389, "u": 1737819426, "b": [["0.02817000", "2.06900000"], ["0.02816900", "0.83200000"], ["0.02816800", "135.63500000"], ["0.02816600", "0.00000000"], ["0.02815900", "55.41800000"], ["0.02815800", "3.60000000"], ["0.02815400", "5.16100000"], ["0.02815300", "0.00000000"], ["0.02815100", "6.76300000"], ["0.02814800", "1.34600000"], ["0.02814000", "40.26900000"], ["0.02813800", "0.00000000"], ["0.02812600", "12.40400000"], ["0.02803000", "0.32700000"], ["0.01408300", "0.00000000"]], "a": [["0.02816900", "0.00000000"], ["0.02817100", "0.00000000"], ["0.02817200", "6.00000000"], ["0.02817300", "6.82300000"], ["0.02817500", "0.00000000"], ["0.02818200", "0.02500000"], ["0.02819300", "12.11600000"], ["0.02998000", "6.18600000"]]}, {"e": "depthUpdate", "E": 1604221428135, "s": "ETHBTC", "U": 1737819427, "u": 1737819461, "b": [["0.02817000", "0.00000000"], ["0.02816900", "116.14800000"], ["0.02816800", "24.00000000"], ["0.02816700", "0.28000000"], ["0.02816400", "2.06900000"], ["0.02816300", "0.21700000"], ["0.02815800", "4.43200000"], ["0.02814700", "56.61300000"], ["0.02814500", "0.00000000"], ["0.02814000", "80.65200000"], ["0.02813900", "4.50000000"], ["0.02805400", "0.51700000"]], "a": [["0.02817000", "89.50000000"], ["0.02817100", "0.00000000"], ["0.02817200", "0.20100000"], ["0.02817300", "6.71200000"], ["0.02818400", "33.08500000"], ["0.02818800", "14.24200000"]]}, {"e": "depthUpdate", "E": 1604221429135, "s": "ETHBTC", "U": 1737819462, "u": 1737819476, "b": [["0.02816700", "0.29700000"], ["0.02814100", "10.53100000"], ["0.02814000", "75.26900000"], ["0.02812200", "0.00000000"]], "a": [["0.02818300", "22.01500000"]]}, {"e": "depthUpdate", "E": 1604221430135, "s": "ETHBTC", "U": 1737819477, "u": 1737819488, "b": [["0.02816700", "0.00000000"], ["0.02805400", "0.10400000"], ["0.02803300", "0.41300000"], ["0.02792200", "0.00000000"], ["0.02789400", "0.06700000"]], "a": [["0.02817000", "83.50000000"]]}, {"e": "depthUpdate", "E": 1604221431135, "s": "ETHBTC", "U": 1737819489, "u": 1737819513, "b": [["0.02816900", "24.00000000"], ["0.02816800", "28.18400000"], ["0.02816700", "0.00000000"], ["0.02816500", "0.12200000"], ["0.02816000", "1.71200000"], ["0.02815100", "1.64700000"], ["0.02810100", "0.13900000"], ["0.02791000", "0.79500000"], ["0.02705700", "0.00000000"]], "a": [["0.02817000", "113.98300000"], ["0.02818200", "14.94000000"], ["0.02818300", "7.10000000"], ["0.02819300", "52.50000000"], ["0.02819500", "0.00000000"], ["0.02998000", "5.05900000"]]}, {"e": "depthUpdate", "E": 1604221432135, "s": "ETHBTC", "U": 1737819514, "u": 1737819532, "b": [["0.02816900", "138.64700000"], ["0.02816800", "24.00000000"], ["0.02816600", "0.22100000"], ["0.02816500", "0.00000000"], ["0.02815300", "12.40400000"], ["0.02815100", "6.79800000"], ["0.02812600", "0.00000000"], ["0.02622000", "0.00000000"]], "a": [["0.02817000", "80.71700000"], ["0.02817300", "1.71200000"], ["0.02817400", "0.00000000"], ["0.02817900", "15.61300000"], ["0.02818200", "0.02500000"], ["0.02818300", "22.01500000"], ["0.02998000", "6.18600000"]]}, {"e": "depthUpdate", "E": 1604221433135, "s": "ETHBTC", "U": 1737819533, "u": 1737819570, "b": [["0.02816700", "0.27300000"], ["0.02816600", "0.00000000"], ["0.02816400", "13.06900000"], ["0.02815900", "48.31900000"], ["0.02815300", "0.00000000"], ["0.02814900", "7.11100000"], ["0.02814800", "21.53600000"], ["0.02814700", "36.42200000"], ["0.02814100", "50.91200000"], ["0.02814000", "34.88600000"], ["0.02812600", "12.40400000"], ["0.02809500", "0.00000000"], ["0.02805100", "0.42100000"], ["0.02803300", "0.00000000"], ["0.02788800", "0.00400000"], ["0.02705100", "0.00800000"], ["0.02621400", "0.01800000"]], "a": [["0.02818200", "5.02500000"], ["0.02818300", "7.10000000"], ["0.02818400", "12.89400000"], ["0.02818900", "21.53700000"]]}, {"e": "depthUpdate", "E": 1604221434135, "s": "ETHBTC", "U": 1737819571, "u": 1737819635, "b": [["0.02817200", "0.21900000"], ["0.02817100", "4.43200000"], ["0.02817000", "0.00000000"], ["0.02816900", "133.00000000"], ["0.02816700", "0.00000000"], ["0.02816600", "12.89300000"], ["0.02816300", "7.31500000"], ["0.02816000", "4.87800000"], ["0.02815800", "0.00000000"], ["0.02815700", "9.60000000"], ["0.02815400", "0.00000000"], ["0.02815200", "0.00400000"], ["0.02815000", "7.27900000"], ["0.02814900", "0.01000000"], ["0.02814500", "1.35000000"], ["0.02814300", "12.60700000"], ["0.02814000", "12.11500000"], ["0.02801400", "0.00000000"], ["0.02681100", "13.90300000"]], "a": [["0.02817000", "0.00000000"], ["0.02817200", "0.00000000"], ["0.02817300", "0.00000000"], ["0.02817400", "0.00000000"], ["0.02817500", "0.11000000"], ["0.02817600", "0.05100000"], ["0.02817700", "1.75100000"], ["0.02817900", "10.45100000"], ["0.02818100", "1.60700000"], ["0.02818200", "5.02500000"], ["0.02818300", "7.39100000"], ["0.02818500", "2.75700000"], ["0.02818600", "18.34200000"], ["0.02818900", "1.34600000"], ["0.02819200", "46.29500000"], ["0.02819300", "12.11600000"], ["0.02819800", "42.38500000"], ["0.02822000", "150.00000000"], ["0.02822500", "43.66500000"], ["0.03199000", "1.62800000"]]}, {"e": "depthUpdate", "E": 1604221435135, "s": "ETHBTC", "U": 1737819636, "u": 1737819690, "b": [["0.02817200", "129.68400000"], ["0.02817100", "2.06900000"], ["0.02817000", "0.00000000"], ["0.02816900", "24.00000000"], ["0.02816800", "0.00000000"], ["0.02816600", "13.05200000"], ["0.02816400", "0.00000000"], ["0.02816300", "7.31600000"], ["0.02816200", "5.40300000"], ["0.02816100", "5.16100000"], ["0.02815800", "3.21600000"], ["0.02815700", "8.00000000"], ["0.02815200", "0.00400000"], ["0.02815100", "5.15100000"], ["0.02814600", "4.03800000"], ["0.02814500", "1.34600000"], ["0.02814400", "4.33200000"], ["0.02812200", "0.00000000"], ["0.02801300", "21.07700000"]], "a": [["0.02817300", "6.00000000"], ["0.02817400", "0.00000000"], ["0.02817800", "0.29500000"], ["0.02818200", "5.02500000"], ["0.02818300", "7.39100000"], ["0.02818500", "17.67200000"], ["0.02818700", "4.00000000"], ["0.02818900", "1.34600000"]]}, {"e": "depthUpdate", "E": 1604221436135, "s": "ETHBTC", "U": 1737819691, "u": 1737819717, "b": [["0.02816800", "0.00000000"], ["0.02816600", "13.12800000"], ["0.02814600", "26.81400000"], ["0.02805400", "0.51700000"], ["0.02805100", "0.00800000"], ["0.02794600", "0.09500000"]], "a": [["0.02817500", "0.17800000"], ["0.02817600", "0.05100000"], ["0.02817700", "1.75100000"], ["0.02817800", "0.02500000"], ["0.02818300", "0.29100000"], ["0.02818600", "22.27600000"], ["0.02818900", "8.44400000"], ["0.02819100", "1.49400000"], ["0.02819200", "40.91100000"], ["0.02819800", "7.39400000"], ["0.02820200", "40.37600000"], ["0.02998000", "6.18600000"]]}, {"e": "depthUpdate", "E": 1604221437136, "s": "ETHBTC", "U": 1737819718, "u": 1737819807, "b": [["0.02817200", "0.00000000"], ["0.02817100", "0.00000000"], ["0.02817000", "0.00000000"], ["0.02816900", "0.00000000"], ["0.02816600", "36.89300000"], ["0.02816400", "0.00000000"], ["0.02816300", "0.21700000"], ["0.02816200", "0.97100000"], ["0.02816000", "1.71200000"], ["0.02815600", "13.09300000"], ["0.02815400", "0.00000000"], ["0.02815300", "7.72500000"], ["0.02815200", "4.43600000"], ["0.02811800", "0.21100000"], ["0.02810800", "0.84300000"], ["0.02606800", "0.23800000"]], "a": [["0.02816700", "6.00000000"], ["0.02816800", "0.00000000"], ["0.02816900", "8.48100000"], ["0.02817000", "81.00000000"], ["0.02817100", "29.00000000"], ["0.02817200", "0.00000000"], ["0.02817300", "0.00000000"], ["0.02817500", "0.21700000"], ["0.02817600", "4.05100000"], ["0.02817800", "0.20200000"], ["0.02817900", "14.28800000"], ["0.02818200", "0.02500000"], ["0.02818300", "15.20600000"], ["0.02818400", "12.89400000"], ["0.02818500", "2.75700000"], ["0.02818600", "12.84500000"], ["0.02818700", "0.00000000"], ["0.02818900", "1.34600000"], ["0.02819100", "0.00000000"]]}, {"e": "depthUpdate", "E": 1604221438136, "s": "ETHBTC", "U": 1737819808, "u": 1737819854, "b": [["0.02816800", "114.50000000"], ["0.02816700", "24.00000000"], ["0.02816400", "11.00000000"], ["0.02816200", "3.04000000"], ["0.02815700", "15.10100000"], ["0.02815300", "5.65600000"], ["0.02814900", "32.60400000"], ["0.02814800", "1.34600000"], ["0.02814500", "41.72500000"], ["0.02814100", "10.53100000"], ["0.02812600", "0.00000000"], ["0.02605400", "0.12900000"]], "a": [["0.02816700", "0.00000000"], ["0.02816800", "0.00000000"], ["0.02816900", "0.00000000"], ["0.02817000", "110.64800000"], ["0.02817500", "4.00000000"], ["0.02817700", "1.75100000"], ["0.02817800", "4.02500000"], ["0.02818000", "14.20100000"], ["0.02818300", "1.78900000"], ["0.02818500", "17.67200000"]]}, {"e": "depthUpdate", "E": 1604221439136, "s": "ETHBTC", "U": 1737819855, "u": 1737819900, "b": [["0.02816900", "143.18500000"], ["0.02816800", "0.00000000"], ["0.02816400", "0.00000000"], ["0.02816300", "0.35600000"], ["0.02816100", "9.59300000"], ["0.02815300", "3.16900000"], ["0.02815200", "0.00400000"], ["0.02814900", "20.20000000"], ["0.02812600", "12.40400000"], ["0.02805400", "0.10400000"], ["0.02805300", "0.42600000"], ["0.02681100", "13.85700000"]], "a": [["0.02817000", "4.79500000"], ["0.02817100", "24.48100000"], ["0.02817200", "0.24600000"], ["0.02817500", "0.00000000"], ["0.02817600", "0.05100000"], ["0.02818200", "9.02500000"], ["0.02818300", "1.78900000"], ["0.02818500", "6.75700000"], ["0.02818700", "14.91500000"], ["0.02818900", "21.53800000"], ["0.02819200", "20.72200000"]]}, {"e": "depthUpdate", "E": 1604221440136, "s": "ETHBTC", "U": 1737819901, "u": 1737819996, "b": [["0.02817100", "0.00000000"], ["0.02817000", "140.86600000"], ["0.02816900", "23.37100000"], ["0.02816700", "0.00000000"], ["0.02816600", "12.89300000"], ["0.02816300", "0.21700000"], ["0.02816200", "0.97100000"], ["0.02816100", "0.83200000"], ["0.02816000", "1.87700000"], ["0.02815900", "48.31900000"], ["0.02815800", "1.61600000"], ["0.02815700", "15.52000000"], ["0.02815400", "2.06900000"], ["0.02815300", "4.76900000"], ["0.02815200", "3.60400000"], ["0.02814900", "22.89200000"], ["0.02814700", "33.73000000"], ["0.02814400", "11.43200000"], ["0.02803100", "0.43100000"], ["0.02681100", "13.90300000"]], "a": [["0.02817000", "0.00000000"], ["0.02817100", "10.49700000"], ["0.02817200", "81.00000000"], ["0.02817300", "0.26100000"], ["0.02817800", "0.02500000"], ["0.02817900", "6.72100000"], ["0.02818100", "2.60700000"], ["0.02818200", "19.94000000"], ["0.02818300", "1.78900000"], ["0.02818400", "18.05600000"], ["0.02818500", "6.75700000"], ["0.02818700", "0.00000000"], ["0.02819000", "20.11400000"], ["0.02819200", "20.72200000"], ["0.02819700", "0.12500000"], ["0.02998000", "5.05900000"]]}, {"e": "depthUpdate", "E": 1604221441136, "s": "ETHBTC", "U": 1737819997, "u": 1737820039, "b": [["0.02817000", "145.93500000"], ["0.02816800", "0.09600000"], ["0.02816700", "0.29400000"], ["0.02816400", "3.60000000"], ["0.02816300", "4.30400000"], ["0.02816200", "0.97100000"], ["0.02816000", "6.87500000"], ["0.02815400", "0.00000000"], ["0.02815300", "3.16900000"], ["0.02815200", "0.00400000"], ["0.02814400", "4.33200000"], ["0.02794600", "0.01600000"]], "a": [["0.02817100", "4.79500000"], ["0.02817200", "0.00000000"], ["0.02817500", "1.71200000"], ["0.02817700", "4.04000000"], ["0.02817900", "10.72100000"], ["0.02818000", "7.10000000"], ["0.02818100", "1.60700000"], ["0.02818200", "5.02500000"], ["0.02818300", "15.20600000"], ["0.02818400", "18.05600000"], ["0.02818500", "14.85600000"], ["0.02818900", "23.03400000"], ["0.02819000", "12.11400000"], ["0.02819300", "12.11600000"], ["0.02819800", "47.78000000"], ["0.02820200", "0.00000000"], ["0.02998000", "6.18600000"]]}, {"e": "depthUpdate", "E": 1604221442136, "s": "ETHBTC", "U": 1737820040, "u": 1737820069, "b": [["0.02816700", "0.27400000"], ["0.02816200", "8.07000000"], ["0.02814800", "1.34600000"], ["0.02814400", "16.44700000"], ["0.02814000", "0.00000000"], ["0.02794700", "6.07900000"]], "a": [["0.02817300", "0.07200000"], ["0.02817600", "0.26100000"], ["0.02817700", "4.04000000"], ["0.02819500", "14.80800000"], ["0.02820600", "0.01000000"]]}, {"e": "depthUpdate", "E": 1604221443136, "s": "ETHBTC", "U": 1737820070, "u": 1737820097, "b": [["0.02816700", "0.23800000"], ["0.02816600", "23.89300000"], ["0.02816300", "4.11100000"], ["0.02814500", "1.34600000"], ["0.02813300", "2.01000000"], ["0.02811100", "0.00900000"], ["0.02805600", "0.41700000"], ["0.02803100", "0.01800000"]], "a": [["0.02817500", "0.00000000"], ["0.02817700", "16.75200000"]]}, {"e": "depthUpdate", "E": 1604221444136, "s": "ETHBTC", "U": 1737820098, "u": 1737820145, "b": [["0.02817100", "137.00000000"], ["0.02817000", "24.00000000"], ["0.02816900", "0.00000000"], ["0.02816700", "0.00000000"], ["0.02816600", "12.89300000"], ["0.02816500", "2.06900000"], ["0.02815000", "27.47000000"], ["0.02814900", "2.70200000"], ["0.02814700", "74.11100000"], ["0.02814400", "21.83200000"], ["0.02814200", "0.00400000"], ["0.02814100", "5.14700000"], ["0.02773900", "0.13200000"], ["0.02772500", "0.40000000"]], "a": [["0.02817100", "0.00000000"], ["0.02817200", "81.00000000"], ["0.02817300", "0.07200000"], ["0.02817600", "0.05100000"], ["0.02817700", "5.75200000"], ["0.02818100", "2.60700000"], ["0.02818300", "15.20600000"], ["0.02818400", "18.05600000"], ["0.02818500", "13.85600000"]]}, {"e": "depthUpdate", "E": 1604221445136, "s": "ETHBTC", "U": 1737820146, "u": 1737820188, "b": [["0.02816700", "0.20200000"], ["0.02816200", "0.97100000"], ["0.02814200", "0.00000000"], ["0.02812700", "64.26700000"], ["0.02809900", "1.20000000"], ["0.02805600", "0.00400000"], ["0.02792300", "0.51500000"], ["0.02681100", "12.25000000"]], "a": [["0.02817200", "85.79500000"], ["0.02817400", "0.14600000"], ["0.02998000", "5.05900000"]]}, {"e": "depthUpdate", "E": 1604221446136, "s": "ETHBTC", "U": 1737820189, "u": 1737820209, "b": [["0.02817100", "140.00000000"], ["0.02816700", "0.29800000"], ["0.02815800", "1.61600000"], ["0.02805100", "0.42100000"], ["0.02681100", "13.90300000"]], "a": [["0.02817200", "81.00000000"], ["0.02817400", "0.25700000"], ["0.02819300", "52.49700000"], ["0.02819800", "7.39400000"], ["0.02998000", "6.18600000"]]}, {"e": "depthUpdate", "E": 1604221447136, "s": "ETHBTC", "U": 1737820210, "u": 1737820241, "b": [["0.02817200", "3.00000000"], ["0.02817100", "143.86700000"], ["0.02816900", "0.11800000"], ["0.02816700", "0.00000000"], ["0.02816000", "13.97500000"], ["0.02813300", "2.01000000"], ["0.02812300", "0.02600000"], ["0.02791100", "0.53600000"]], "a": [["0.02817200", "0.00000000"], ["0.02817400", "0.15700000"], ["0.02817700", "5.71200000"]]}, {"e": "depthUpdate", "E": 1604221448137, "s": "ETHBTC", "U": 1737820242, "u": 1737820330, "b": [["0.02817200", "0.00000000"], ["0.02817100", "0.00000000"], ["0.02817000", "0.00000000"], ["0.02816900", "0.00000000"], ["0.02816800", "0.09600000"], ["0.02816700", "11.00000000"], ["0.02816600", "13.12600000"], ["0.02816500", "0.00000000"], ["0.02816400", "0.00000000"], ["0.02816300", "0.02400000"], ["0.02816000", "2.06900000"], ["0.02815800", "0.00000000"], ["0.02815400", "5.20000000"], ["0.02815100", "0.00000000"], ["0.02814400", "16.44700000"], ["0.02814100", "10.53200000"], ["0.02808600", "1.88500000"], ["0.02805100", "0.00800000"], ["0.02803600", "0.41300000"]], "a": [["0.02816900", "26.41000000"], ["0.02817000", "0.00000000"], ["0.02817100", "5.00000000"], ["0.02817200", "1.71200000"], ["0.02817300", "24.00000000"], ["0.02817400", "0.00000000"], ["0.02817500", "0.00000000"], ["0.02817600", "4.35900000"], ["0.02817700", "4.00000000"], ["0.02818100", "1.60700000"], ["0.02818200", "0.02500000"], ["0.02818300", "15.20600000"], ["0.02818400", "12.89400000"], ["0.02818500", "7.16400000"], ["0.02818600", "33.03700000"], ["0.02818900", "1.49600000"], ["0.02819000", "24.23000000"], ["0.02819300", "40.38100000"]]}, {"e": "depthUpdate", "E": 1604221449137, "s": "ETHBTC", "U": 1737820331, "u": 1737820390, "b": [["0.02816800", "124.46400000"], ["0.02816700", "0.00000000"], ["0.02816600", "12.89300000"], ["0.02816500", "0.27700000"], ["0.02816400", "0.00000000"], ["0.02816300", "0.02400000"], ["0.02815800", "5.16400000"], ["0.02815500", "0.00000000"], ["0.02815400", "5.20000000"], ["0.02815100", "20.19400000"], ["0.02815000", "7.27900000"], ["0.02814800", "13.75000000"], ["0.02814700", "33.73000000"], ["0.02814600", "4.03800000"], ["0.02814400", "56.83300000"], ["0.02812600", "0.00000000"], ["0.02808600", "0.03100000"]], "a": [["0.02816900", "26.41000000"], ["0.02817100", "0.00000000"], ["0.02817200", "5.00000000"], ["0.02817300", "24.00000000"], ["0.02817500", "0.26800000"], ["0.02817600", "4.12300000"], ["0.02817900", "10.72100000"], ["0.02818100", "2.60700000"], ["0.02818200", "2.71800000"], ["0.02818600", "34.38300000"]]}, {"e": "depthUpdate", "E": 1604221450136, "s": "ETHBTC", "U": 1737820391, "u": 1737820407, "b": [["0.02816800", "127.46400000"], ["0.02815500", "1.67600000"], ["0.02814600", "4.03800000"], ["0.02814400", "63.93700000"], ["0.02810900", "19.00000000"], ["0.02780100", "1.49700000"]], "a": [["0.02816900", "2.41000000"], ["0.02817100", "4.00000000"], ["0.02817800", "0.02500000"], ["0.02817900", "6.72100000"], ["0.02818100", "2.60700000"], ["0.02998000", "6.18600000"]]}, {"e": "depthUpdate", "E": 1604221451136, "s": "ETHBTC", "U": 1737820408, "u": 1737820439, "b": [["0.02816800", "140.96400000"], ["0.02816600", "0.16700000"], ["0.02816500", "0.00000000"], ["0.02815300", "16.06800000"], ["0.02814600", "26.81400000"], ["0.02805100", "0.42100000"], ["0.02803600", "0.00000000"], ["0.02779200", "1.13500000"]], "a": [["0.02816900", "26.41000000"], ["0.02817100", "4.24200000"], ["0.02817500", "0.04000000"], ["0.02818100", "7.77000000"], ["0.02818400", "18.28000000"], ["0.02818600", "38.42200000"], ["0.02818700", "5.38500000"], ["0.02819000", "14.80800000"], ["0.02819300", "0.00000000"], ["0.02819600", "40.38900000"], ["0.02819800", "2.01000000"]]}, {"e": "depthUpdate", "E": 1604221452137, "s": "ETHBTC", "U": 1737820440, "u": 1737820494, "b": [["0.02817000", "143.86800000"], ["0.02816900", "0.00000000"], ["0.02816800", "24.09600000"], ["0.02816600", "0.26300000"], ["0.02816300", "3.62400000"], ["0.02816200", "3.46000000"], ["0.02815400", "1.60000000"], ["0.02814800", "1.34600000"], ["0.02814400", "56.83300000"], ["0.02812600", "12.40400000"]], "a": [["0.02816900", "0.00000000"], ["0.02817100", "4.79500000"], ["0.02817200", "0.79800000"], ["0.02817300", "24.17200000"], ["0.02817600", "8.12300000"], ["0.02817800", "0.02500000"], ["0.02818100", "12.77000000"], ["0.02818300", "15.20600000"], ["0.02818400", "12.89400000"], ["0.02818500", "7.16400000"], ["0.02818800", "19.62800000"], ["0.02819400", "0.00000000"]]}, {"e": "depthUpdate", "E": 1604221453137, "s": "ETHBTC", "U": 1737820495, "u": 1737820530, "b": [["0.02817000", "140.86800000"], ["0.02816600", "0.37100000"], ["0.02816500", "11.00000000"], ["0.02816300", "0.02400000"], ["0.02815600", "13.09300000"], ["0.02815400", "5.20000000"], ["0.02814400", "16.44700000"], ["0.02814000", "40.39300000"], ["0.02805400", "0.51700000"], ["0.02805100", "0.00800000"], ["0.02783400", "0.00000000"], ["0.02782300", "0.13600000"]], "a": [["0.02817100", "4.79500000"], ["0.02817200", "5.79800000"], ["0.02817300", "24.17200000"], ["0.02817700", "15.00000000"], ["0.02818100", "7.77000000"], ["0.02818300", "0.29100000"], ["0.02818500", "9.85700000"], ["0.02818700", "0.00000000"], ["0.02819000", "12.11600000"], ["0.02819300", "5.38500000"], ["0.02827200", "30.41300000"]]}, {"e": "depthUpdate", "E": 1604221454137, "s": "ETHBTC", "U": 1737820531, "u": 1737820607, "b": [["0.02817000", "0.00000000"], ["0.02816900", "0.00000000"], ["0.02816800", "0.09600000"], ["0.02816600", "0.09600000"], ["0.02816500", "11.00000000"], ["0.02816300", "1.02400000"], ["0.02816200", "0.97100000"], ["0.02816100", "0.00000000"], ["0.02816000", "0.00000000"], ["0.02815800", "0.00000000"], ["0.02815700", "7.52000000"], ["0.02815600", "5.99300000"], ["0.02815500", "1.67600000"], ["0.02815300", "21.23400000"], ["0.02815200", "0.83600000"], ["0.02814800", "3.41500000"], ["0.02814600", "4.03800000"], ["0.02814500", "0.00000000"], ["0.02814200", "0.00400000"], ["0.02814100", "11.87800000"], ["0.02813800", "8.00000000"]], "a": [["0.02816900", "77.94600000"], ["0.02817000", "0.00000000"], ["0.02817100", "31.10200000"], ["0.02817200", "5.00000000"], ["0.02817300", "24.00000000"], ["0.02817600", "9.12300000"], ["0.02817700", "16.90200000"], ["0.02817900", "28.42000000"], ["0.02818000", "0.00000000"], ["0.02818100", "1.60700000"], ["0.02818200", "2.71800000"], ["0.02818300", "14.91500000"], ["0.02818400", "12.89400000"], ["0.02818600", "18.23000000"], ["0.02818800", "6.73200000"], ["0.02818900", "0.00000000"], ["0.02819200", "43.49800000"], ["0.02998000", "5.05900000"], ["0.03490600", "0.06900000"]]}, {"e": "depthUpdate", "E": 1604221455137, "s": "ETHBTC", "U": 1737820608, "u": 1737820681, "b": [["0.02816800", "0.00000000"], ["0.02816100", "0.11600000"], ["0.02816000", "0.00000000"], ["0.02815700", "8.35200000"], ["0.02815600", "8.06200000"], ["0.02815400", "17.60400000"], ["0.02815200", "0.00400000"], ["0.02815100", "7.10200000"], ["0.02815000", "7.27900000"], ["0.02814800", "0.00000000"], ["0.02814600", "0.00000000"], ["0.02814400", "4.33200000"], ["0.02814300", "8.57100000"], ["0.02814200", "0.00000000"], ["0.02814100", "11.88000000"], ["0.02814000", "60.59300000"], ["0.02813800", "12.03900000"], ["0.02813700", "22.66200000"], ["0.02813600", "0.00800000"], ["0.02813100", "14.81000000"], ["0.02812600", "0.00000000"]], "a": [["0.02816700", "4.79500000"], ["0.02816800", "4.79900000"], ["0.02816900", "109.00000000"], ["0.02817000", "0.10400000"], ["0.02817100", "31.10200000"], ["0.02817400", "1.00000000"], ["0.02817500", "0.33500000"], ["0.02817600", "11.22400000"], ["0.02817700", "12.90200000"], ["0.02817900", "8.22100000"], ["0.02818100", "16.52200000"], ["0.02818200", "22.91800000"], ["0.02818300", "5.12300000"], ["0.02818500", "2.75800000"], ["0.02819200", "20.72200000"], ["0.02819400", "0.00000000"], ["0.02998000", "6.18600000"]]}, {"e": "depthUpdate", "E": 1604221456137, "s": "ETHBTC", "U": 1737820682, "u": 1737820720, "b": [["0.02814900", "0.01000000"], ["0.02814800", "0.00000000"], ["0.02814400", "7.02600000"], ["0.02812700", "0.00000000"], ["0.02809900", "65.50600000"], ["0.02805400", "0.10400000"], ["0.02805300", "0.05000000"], ["0.02802900", "35.94300000"]], "a": [["0.02816700", "34.39600000"], ["0.02816800", "4.00000000"], ["0.02816900", "28.00000000"], ["0.02817000", "0.28300000"], ["0.02817300", "0.00000000"], ["0.02818100", "16.52200000"], ["0.02818400", "12.89400000"], ["0.02819200", "61.12600000"], ["0.02819600", "0.00000000"]]}, {"e": "depthUpdate", "E": 1604221457137, "s": "ETHBTC", "U": 1737820721, "u": 1737820734, "b": [["0.02815700", "15.45200000"]], "a": [["0.02816900", "28.19100000"], ["0.02817000", "1.71300000"], ["0.02817500", "5.50000000"], ["0.02819000", "34.89500000"]]}, {"e": "depthUpdate", "E": 1604221458137, "s": "ETHBTC", "U": 1737820735, "u": 1737820765, "b": [["0.02816500", "0.00000000"], ["0.02816100", "0.00000000"], ["0.02816000", "0.00000000"], ["0.02815800", "11.28500000"], ["0.02815700", "8.35200000"], ["0.02815500", "0.00000000"], ["0.02815400", "5.20000000"], ["0.02815200", "0.00400000"], ["0.02815100", "9.59300000"], ["0.02814800", "12.40400000"], ["0.02814200", "1.62900000"], ["0.02814100", "11.88000000"], ["0.02814000", "20.20000000"], ["0.02813700", "22.66200000"], ["0.02813300", "40.40800000"], ["0.02812100", "2.02000000"], ["0.02802900", "35.53000000"], ["0.02732400", "0.08900000"], ["0.02731500", "0.16400000"]], "a": [["0.02816700", "115.39600000"], ["0.02821100", "38.35800000"], ["0.02822400", "0.00000000"], ["0.02853400", "6.32500000"]]}, {"e": "depthUpdate", "E": 1604221459137, "s": "ETHBTC", "U": 1737820766, "u": 1737820774, "b": [["0.02815400", "12.30200000"], ["0.02815200", "0.00400000"], ["0.02802700", "0.42900000"], ["0.02801300", "0.01600000"], ["0.02801200", "23.55600000"]], "a": [["0.02998000", "5.05900000"], ["0.03508200", "0.06200000"], ["0.03637400", "0.00000000"]]}, {"e": "depthUpdate", "E": 1604221460137, "s": "ETHBTC", "U": 1737820775, "u": 1737820811, "b": [["0.02816600", "0.00000000"], ["0.02816300", "31.74900000"], ["0.02815900", "12.88900000"], ["0.02815700", "0.83200000"], ["0.02815300", "16.06800000"], ["0.02814500", "5.16600000"], ["0.02814400", "2.69400000"], ["0.02813700", "17.27600000"], ["0.02813500", "4.33300000"], ["0.02813200", "5.39200000"], ["0.02810600", "0.00000000"]], "a": [["0.02816400", "2.41000000"], ["0.02816500", "0.00000000"], ["0.02816600", "0.85000000"], ["0.02816700", "105.14300000"], ["0.02816900", "28.00000000"], ["0.02817000", "5.71300000"], ["0.02817500", "5.20500000"], ["0.02817600", "7.22400000"], ["0.02817800", "14.94000000"], ["0.02817900", "15.65800000"], ["0.02818100", "1.60700000"], ["0.02818700", "45.86000000"], ["0.02836000", "16.68700000"], ["0.02836800", "0.05000000"], ["0.02998000", "6.18600000"], ["0.03637400", "0.00300000"]]}, {"e": "depthUpdate", "E": 1604221461137, "s": "ETHBTC", "U": 1737820812, "u": 1737820854, "b": [["0.02816400", "3.00000000"], ["0.02816300", "116.74900000"], ["0.02815400", "5.20000000"], ["0.02811500", "0.00000000"], ["0.02811000", "0.16600000"], ["0.02802900", "35.94300000"], ["0.02802700", "0.01600000"]], "a": [["0.02816400", "0.00000000"], ["0.02816500", "107.79100000"], ["0.02816600", "0.00000000"], ["0.02816700", "24.00000000"], ["0.02817100", "7.10200000"], ["0.02817200", "6.00000000"], ["0.02817400", "0.29500000"], ["0.02817600", "7.22400000"], ["0.02817700", "12.90200000"], ["0.02817800", "14.94000000"], ["0.02818900", "40.41000000"], ["0.02819200", "20.72200000"]]}, {"e": "depthUpdate", "E": 1604221462137, "s": "ETHBTC", "U": 1737820855, "u": 1737820871, "b": [["0.02815200", "7.10600000"]], "a": [["0.02816700", "24.00000000"], ["0.02838100", "0.71600000"], ["0.02841200", "0.13000000"]]}, {"e": "depthUpdate", "E": 1604221463137, "s": "ETHBTC", "U": 1737820872, "u": 1737820915, "b": [["0.02816400", "0.00000000"], ["0.02816300", "0.88000000"], ["0.02816000", "0.00000000"], ["0.02815900", "23.88900000"], ["0.02815800", "11.00000000"], ["0.02815400", "6.91300000"], ["0.02813600", "40.41700000"], ["0.02813300", "0.00000000"]], "a": [["0.02816400", "86.11400000"], ["0.02816500", "29.44800000"], ["0.02816600", "0.00000000"], ["0.02816700", "24.00000000"], ["0.02816900", "24.00000000"], ["0.02817200", "6.00000000"], ["0.02817400", "4.29500000"], ["0.02817500", "5.20500000"], ["0.02817600", "7.22400000"], ["0.02817700", "12.90200000"], ["0.02817800", "0.02500000"], ["0.02818300", "20.03800000"], ["0.02818500", "14.88100000"], ["0.02819000", "22.77900000"], ["0.02854900", "4.35100000"]]}, {"e": "depthUpdate", "E": 1604221464137, "s": "ETHBTC", "U": 1737820916, "u": 1737821008, "b": [["0.02816400", "119.87000000"], ["0.02816300", "24.00000000"], ["0.02816200", "24.97100000"], ["0.02816100", "0.00000000"], ["0.02816000", "0.00000000"], ["0.02815900", "12.88900000"], ["0.02815800", "0.00000000"], ["0.02815600", "8.35900000"], ["0.02815400", "6.91300000"], ["0.02815300", "16.06800000"], ["0.02815200", "0.00400000"], ["0.02814600", "0.00400000"], ["0.02814200", "0.00000000"], ["0.02814100", "32.08500000"], ["0.02814000", "0.00000000"], ["0.02813400", "23.38100000"], ["0.02761200", "0.00000000"]], "a": [["0.02816300", "0.00000000"], ["0.02816400", "0.00000000"], ["0.02816500", "29.11400000"], ["0.02816600", "1.00300000"], ["0.02816700", "24.12700000"], ["0.02816800", "0.00000000"], ["0.02816900", "0.00000000"], ["0.02817000", "2.71300000"], ["0.02817100", "0.00000000"], ["0.02817200", "0.00000000"], ["0.02817300", "6.77200000"], ["0.02817400", "4.29500000"], ["0.02817500", "5.20500000"], ["0.02817600", "7.22400000"], ["0.02817700", "16.90200000"], ["0.02817800", "2.71900000"], ["0.02818100", "18.91500000"], ["0.02818200", "20.22500000"], ["0.02818300", "5.12300000"], ["0.02821000", "66.34000000"], ["0.02822300", "0.00000000"], ["0.02998000", "6.18600000"]]}, {"e": "depthUpdate", "E": 1604221465137, "s": "ETHBTC", "U": 1737821009, "u": 1737821050, "b": [["0.02816500", "6.87000000"], ["0.02816400", "137.00000000"], ["0.02816300", "26.06900000"], ["0.02815800", "0.10400000"], ["0.02815700", "0.83200000"], ["0.02815600", "5.99300000"], ["0.02815500", "5.16500000"], ["0.02815200", "7.10500000"], ["0.02815100", "11.24000000"], ["0.02814600", "0.00000000"], ["0.02814500", "0.00000000"], ["0.02812400", "10.68500000"], ["0.02809800", "30.14000000"], ["0.02802900", "35.53000000"], ["0.02760100", "0.10500000"]], "a": [["0.02816500", "0.00000000"], ["0.02816600", "5.11400000"], ["0.02816700", "29.44800000"], ["0.02816800", "0.28100000"], ["0.02817000", "1.71300000"], ["0.02817300", "7.77200000"], ["0.02817500", "20.12000000"], ["0.02817600", "14.32500000"], ["0.02818000", "20.20400000"], ["0.02818100", "4.00000000"], ["0.02818200", "0.02500000"]]}, {"e": "depthUpdate", "E": 1604221466138, "s": "ETHBTC", "U": 1737821051, "u": 1737821201, "b": [["0.02817300", "24.00000000"], ["0.02817200", "6.00000000"], ["0.02817100", "25.00000000"], ["0.02817000", "0.10700000"], ["0.02816900", "0.00000000"], ["0.02816800", "0.83200000"], ["0.02816700", "29.20000000"], ["0.02816600", "112.34100000"], ["0.02816500", "0.00000000"], ["0.02816400", "0.00000000"], ["0.02816300", "2.06900000"], ["0.02816200", "0.97100000"], ["0.02816100", "7.27300000"], ["0.02816000", "0.00000000"], ["0.02815900", "44.76900000"], ["0.02815800", "0.00000000"], ["0.02815700", "0.00000000"], ["0.02815400", "1.71300000"], ["0.02815200", "7.10400000"], ["0.02815100", "6.78600000"], ["0.02814800", "4.33200000"], ["0.02813500", "0.00000000"], ["0.02813400", "0.60000000"], ["0.02811100", "62.56600000"], ["0.02811000", "12.57000000"], ["0.02809800", "30.04000000"], ["0.02802700", "0.42900000"], ["0.02681100", "13.90300000"]], "a": [["0.02816600", "0.00000000"], ["0.02816700", "0.00000000"], ["0.02816800", "0.00000000"], ["0.02816900", "0.00000000"], ["0.02817000", "0.00000000"], ["0.02817200", "0.00000000"], ["0.02817300", "0.00000000"], ["0.02817400", "0.00000000"], ["0.02817500", "0.16700000"], ["0.02817600", "1.12400000"], ["0.02817700", "12.90200000"], ["0.02817800", "0.02500000"], ["0.02817900", "6.72100000"], ["0.02818000", "0.00000000"], ["0.02818100", "8.00000000"], ["0.02818200", "12.12500000"], ["0.02818300", "1.66900000"], ["0.02818400", "12.89400000"], ["0.02818500", "2.75800000"], ["0.02818600", "18.19100000"], ["0.02818700", "0.00000000"], ["0.02818800", "21.64700000"], ["0.02818900", "20.20200000"], ["0.02819000", "16.16000000"], ["0.02819300", "5.38500000"], ["0.02819800", "42.41400000"]]}, {"e": "depthUpdate", "E": 1604221467138, "s": "ETHBTC", "U": 1737821202, "u": 1737821294, "b": [["0.02817300", "0.00000000"], ["0.02817200", "0.00000000"], ["0.02817100", "0.00000000"], ["0.02817000", "6.00000000"], ["0.02816900", "1.00000000"], ["0.02816800", "0.00000000"], ["0.02816700", "24.00000000"], ["0.02816500", "0.00000000"], ["0.02816400", "0.12200000"], ["0.02816300", "7.09900000"], ["0.02816100", "9.34200000"], ["0.02815700", "7.93200000"], ["0.02815400", "6.91300000"], ["0.02815200", "0.00400000"], ["0.02815100", "1.64700000"], ["0.02811200", "0.05000000"]], "a": [["0.02817100", "3.00000000"], ["0.02817200", "116.29300000"], ["0.02817300", "24.00000000"], ["0.02817400", "24.25100000"], ["0.02817500", "0.04000000"], ["0.02817600", "0.12400000"], ["0.02817800", "1.02500000"], ["0.02818200", "7.12500000"], ["0.02818300", "23.97700000"], ["0.02818400", "12.89400000"], ["0.02818500", "2.69300000"], ["0.02818600", "14.19100000"], ["0.02818700", "1.56100000"], ["0.02818800", "1.34600000"], ["0.02822000", "150.00000000"], ["0.02853400", "1.84400000"]]}, {"e": "depthUpdate", "E": 1604221468138, "s": "ETHBTC", "U": 1737821295, "u": 1737821325, "b": [["0.02816400", "11.00000000"], ["0.02816300", "7.09900000"], ["0.02816200", "1.24900000"], ["0.02816100", "2.06900000"], ["0.02814600", "0.00000000"], ["0.02814200", "22.78100000"], ["0.02811200", "12.45400000"], ["0.02811000", "0.16600000"], ["0.02745600", "0.54500000"]], "a": [["0.02817100", "113.41800000"], ["0.02817200", "29.00000000"], ["0.02817300", "24.29700000"], ["0.02817400", "0.00000000"], ["0.02817700", "18.06700000"], ["0.02818200", "22.04000000"], ["0.02818300", "9.06200000"], ["0.02818700", "1.49600000"], ["0.02818900", "22.89500000"], ["0.02819000", "21.54400000"], ["0.02819200", "26.10800000"], ["0.02819300", "0.00000000"], ["0.02819400", "0.06500000"], ["0.02998000", "5.05900000"]]}, {"e": "depthUpdate", "E": 1604221469137, "s": "ETHBTC", "U": 1737821326, "u": 1737821342, "b": [["0.02816800", "0.00000000"], ["0.02816700", "24.11100000"], ["0.02816200", "3.04000000"], ["0.02816100", "0.00000000"], ["0.02815800", "2.49000000"], ["0.02814500", "20.20200000"], ["0.02814100", "11.88000000"], ["0.02813800", "52.44300000"], ["0.02813600", "0.00800000"], ["0.02811300", "64.36000000"], ["0.02809900", "1.20000000"]], "a": [["0.02817600", "1.12400000"], ["0.02817800", "0.02500000"], ["0.02818100", "12.00000000"], ["0.02998000", "6.18600000"]]}, {"e": "depthUpdate", "E": 1604221470137, "s": "ETHBTC", "U": 1737821343, "u": 1737821388, "b": [["0.02817000", "0.00000000"], ["0.02816900", "30.00000000"], ["0.02816800", "3.60900000"], ["0.02816700", "24.00000000"], ["0.02816300", "0.00000000"], ["0.02816200", "3.24500000"], ["0.02815800", "9.59000000"], ["0.02814000", "12.12100000"], ["0.02813700", "5.15500000"], ["0.02812500", "0.03900000"], ["0.02812000", "150.00000000"], ["0.02811400", "12.40400000"], ["0.02811200", "0.05000000"], ["0.02803100", "0.43100000"], ["0.02802700", "0.01600000"], ["0.02681100", "13.90300000"]], "a": [["0.02817000", "110.29300000"], ["0.02817100", "24.00000000"], ["0.02817200", "29.14100000"], ["0.02817300", "0.00000000"], ["0.02817500", "4.04000000"], ["0.02818100", "8.00000000"], ["0.02818200", "22.04000000"], ["0.02819500", "14.81000000"]]}, {"e": "depthUpdate", "E": 1604221471138, "s": "ETHBTC", "U": 1737821389, "u": 1737821493, "b": [["0.02816900", "0.00000000"], ["0.02816800", "0.00000000"], ["0.02816700", "0.00000000"], ["0.02816600", "31.00000000"], ["0.02816500", "0.00000000"], ["0.02816400", "24.00000000"], ["0.02816300", "0.00000000"], ["0.02816200", "1.31100000"], ["0.02816000", "0.00000000"], ["0.02815900", "46.48200000"], ["0.02815800", "2.72700000"], ["0.02815600", "8.06200000"], ["0.02815400", "5.20000000"], ["0.02814800", "0.00000000"], ["0.02814400", "0.00000000"], ["0.02814200", "0.00000000"], ["0.02813800", "56.77600000"], ["0.02813500", "0.00000000"], ["0.02811600", "0.00600000"], ["0.02783700", "1.01600000"], ["0.02781800", "1.47200000"], ["0.02681100", "13.90300000"]], "a": [["0.02816500", "0.00000000"], ["0.02816600", "0.00000000"], ["0.02816700", "27.00000000"], ["0.02816800", "5.44900000"], ["0.02816900", "113.10800000"], ["0.02817000", "24.00000000"], ["0.02817100", "0.00000000"], ["0.02817200", "5.00000000"], ["0.02817400", "8.10100000"], ["0.02817600", "0.12400000"], ["0.02817700", "18.06700000"], ["0.02817800", "7.57900000"], ["0.02818000", "0.00000000"], ["0.02818100", "14.91500000"], ["0.02818200", "7.12500000"], ["0.02818300", "1.96300000"], ["0.02819000", "16.16000000"], ["0.02819500", "20.19400000"]]}, {"e": "depthUpdate", "E": 1604221472138, "s": "ETHBTC", "U": 1737821494, "u": 1737821540, "b": [["0.02816600", "142.61000000"], ["0.02816400", "24.24200000"], ["0.02815800", "2.49000000"], ["0.02815700", "15.03300000"], ["0.02815600", "8.06200000"], ["0.02814800", "12.40400000"], ["0.02814600", "2.69400000"], ["0.02811400", "0.00000000"]], "a": [["0.02816700", "4.00000000"], ["0.02816800", "5.44900000"], ["0.02816900", "105.00000000"], ["0.02817200", "0.00000000"], ["0.02817500", "0.04000000"], ["0.02817700", "18.06700000"], ["0.02817800", "7.57900000"], ["0.02817900", "6.72100000"], ["0.02818000", "0.00000000"], ["0.02818100", "9.00000000"], ["0.02818300", "16.87800000"], ["0.02818600", "14.19100000"], ["0.02818900", "22.89700000"], ["0.02819500", "60.60100000"], ["0.02819800", "2.01000000"]]}, {"e": "depthUpdate", "E": 1604221473138, "s": "ETHBTC", "U": 1737821541, "u": 1737821591, "b": [["0.02816700", "32.90100000"], ["0.02816600", "136.61000000"], ["0.02816500", "0.20300000"], ["0.02816400", "24.00000000"], ["0.02816300", "0.00000000"], ["0.02816200", "12.31100000"], ["0.02815800", "9.59000000"], ["0.02815700", "7.10000000"], ["0.02815600", "5.99300000"], ["0.02815400", "3.60000000"], ["0.02814800", "0.00000000"], ["0.02814000", "34.90200000"], ["0.02811400", "12.40400000"], ["0.02803100", "0.01800000"], ["0.02802900", "35.94300000"]], "a": [["0.02816700", "0.00000000"], ["0.02816800", "3.00000000"], ["0.02816900", "4.87100000"], ["0.02817400", "1.00000000"], ["0.02817500", "12.75200000"], ["0.02817600", "4.31100000"], ["0.02817900", "6.72100000"], ["0.02818000", "0.00000000"], ["0.02818100", "20.10000000"], ["0.02818300", "7.15600000"], ["0.02836000", "0.68700000"], ["0.02836300", "16.05000000"], ["0.02998000", "6.18600000"]]}, {"e": "depthUpdate", "E": 1604221474138, "s": "ETHBTC", "U": 1737821592, "u": 1737821687, "b": [["0.02816700", "0.00000000"], ["0.02816600", "98.70400000"], ["0.02816500", "1.34000000"], ["0.02816400", "24.17700000"], ["0.02816200", "11.97100000"], ["0.02816100", "0.00000000"], ["0.02816000", "1.71300000"], ["0.02815900", "44.76900000"], ["0.02815800", "0.00000000"], ["0.02815700", "2.49200000"], ["0.02815600", "13.09400000"], ["0.02815500", "8.06600000"], ["0.02815400", "5.20000000"], ["0.02814600", "22.89800000"], ["0.02814500", "0.00000000"], ["0.02813900", "44.90800000"], ["0.02813800", "16.37200000"], ["0.02813500", "0.00400000"], ["0.02808600", "1.65300000"], ["0.02807600", "0.00800000"]], "a": [["0.02816700", "27.00000000"], ["0.02816800", "29.34800000"], ["0.02816900", "0.25600000"], ["0.02817000", "24.00000000"], ["0.02817100", "0.00000000"], ["0.02817300", "4.00000000"], ["0.02817400", "0.00000000"], ["0.02817500", "0.04000000"], ["0.02817600", "0.12400000"], ["0.02818500", "2.69300000"], ["0.02818800", "1.41100000"], ["0.02819400", "0.00000000"]]}, {"e": "depthUpdate", "E": 1604221475138, "s": "ETHBTC", "U": 1737821688, "u": 1737821728, "b": [["0.02816800", "5.74800000"], ["0.02816700", "136.00000000"], ["0.02816600", "24.00000000"], ["0.02816500", "0.00000000"], ["0.02816400", "0.00000000"], ["0.02816200", "1.16400000"], ["0.02816000", "3.78200000"], ["0.02815500", "5.99700000"], ["0.02814200", "0.00000000"], ["0.02813500", "0.00000000"], ["0.02813200", "0.00700000"], ["0.02802900", "35.53000000"]], "a": [["0.02816700", "0.00000000"], ["0.02816800", "0.00000000"], ["0.02816900", "4.97200000"], ["0.02817000", "24.15200000"], ["0.02817300", "0.00000000"], ["0.02817500", "1.75200000"], ["0.02817900", "10.72100000"], ["0.02818300", "1.96300000"]]}, {"e": "depthUpdate", "E": 1604221476138, "s": "ETHBTC", "U": 1737821729, "u": 1737821785, "b": [["0.02816800", "140.96700000"], ["0.02816700", "24.00000000"], ["0.02816600", "0.00000000"], ["0.02816300", "0.20400000"], ["0.02816200", "0.97100000"], ["0.02815600", "13.09400000"], ["0.02814000", "12.12100000"], ["0.02813600", "5.39300000"], ["0.02805400", "0.51700000"]], "a": [["0.02816900", "3.00000000"], ["0.02817000", "29.34800000"], ["0.02817100", "0.18900000"], ["0.02817400", "1.71300000"], ["0.02817500", "0.04000000"], ["0.02818000", "14.91500000"], ["0.02818300", "1.96300000"]]}, {"e": "depthUpdate", "E": 1604221477138, "s": "ETHBTC", "U": 1737821786, "u": 1737821840, "b": [["0.02816800", "23.61000000"], ["0.02816700", "0.00000000"], ["0.02816300", "0.25500000"], ["0.02816100", "1.71300000"], ["0.02816000", "0.00000000"], ["0.02815600", "20.19500000"], ["0.02815200", "2.07300000"]], "a": [["0.02816900", "36.97200000"], ["0.02817000", "24.00000000"], ["0.02817100", "0.14900000"], ["0.02818000", "0.00000000"], ["0.02818100", "15.10000000"], ["0.02818300", "1.96300000"], ["0.02818500", "37.81200000"], ["0.02818900", "2.69300000"], ["0.02819200", "66.52000000"], ["0.02819500", "20.19400000"], ["0.02827200", "30.00000000"], ["0.02998000", "5.05900000"]]}, {"e": "depthUpdate", "E": 1604221478138, "s": "ETHBTC", "U": 1737821841, "u": 1737821895, "b": [["0.02816800", "0.00000000"], ["0.02816500", "140.96700000"], ["0.02816400", "0.00000000"], ["0.02816300", "0.34000000"], ["0.02816200", "12.13600000"], ["0.02816100", "2.06900000"], ["0.02816000", "1.71300000"], ["0.02815200", "0.00400000"], ["0.02814800", "12.40400000"], ["0.02814700", "56.51100000"], ["0.02811400", "0.00000000"], ["0.02805400", "0.10400000"], ["0.02802700", "0.42900000"], ["0.01760200", "0.05100000"]], "a": [["0.02816600", "3.00000000"], ["0.02816800", "5.52300000"], ["0.02816900", "24.00000000"], ["0.02817000", "0.00000000"], ["0.02817100", "0.00000000"], ["0.02817400", "5.71300000"], ["0.02817500", "11.04000000"], ["0.02817800", "12.57900000"], ["0.02817900", "6.72100000"], ["0.02818300", "1.66900000"], ["0.02818400", "12.89400000"], ["0.02818500", "22.89700000"], ["0.02998000", "6.18600000"]]}, {"e": "depthUpdate", "E": 1604221479138, "s": "ETHBTC", "U": 1737821896, "u": 1737821908, "b": [["0.02815600", "13.09400000"], ["0.02814800", "0.00000000"], ["0.02814200", "40.40900000"], ["0.02813900", "4.50000000"], ["0.02811400", "12.40400000"], ["0.01494600", "0.04500000"]], "a": [["0.02816600", "0.00000000"], ["0.02816800", "5.52300000"], ["0.02817300", "4.00000000"], ["0.02817400", "1.71300000"], ["0.02817600", "15.33500000"]]}, {"e": "depthUpdate", "E": 1604221480138, "s": "ETHBTC", "U": 1737821909, "u": 1737821987, "b": [["0.02816800", "139.63800000"], ["0.02816700", "24.00000000"], ["0.02816600", "0.13300000"], ["0.02816500", "0.00000000"], ["0.02816400", "0.00000000"], ["0.02816300", "0.34000000"], ["0.02816200", "0.97100000"], ["0.02815700", "9.59300000"], ["0.02815200", "0.00400000"], ["0.02814700", "76.71500000"], ["0.02814600", "2.69400000"], ["0.02802700", "0.01600000"], ["0.02761700", "0.00400000"], ["0.02759700", "2.51700000"]], "a": [["0.02816800", "0.00000000"], ["0.02816900", "3.00000000"], ["0.02817000", "0.00000000"], ["0.02817100", "0.12600000"], ["0.02817300", "0.00000000"], ["0.02817400", "0.00000000"], ["0.02817600", "1.83700000"], ["0.02817700", "12.90200000"], ["0.02817900", "10.72100000"], ["0.02818200", "7.12500000"], ["0.02818300", "16.58400000"], ["0.02818400", "12.89400000"], ["0.02818600", "14.19400000"], ["0.02827200", "30.86200000"]]}, {"e": "depthUpdate", "E": 1604221481138, "s": "ETHBTC", "U": 1737821988, "u": 1737822013, "b": [["0.02816800", "142.53900000"], ["0.02816300", "5.54000000"], ["0.02816100", "0.00000000"], ["0.02815500", "5.16500000"], ["0.02815400", "0.00000000"], ["0.02815100", "1.64700000"], ["0.02805400", "0.51700000"]], "a": [["0.02817100", "0.24800000"], ["0.02817600", "0.12400000"], ["0.02817700", "14.61500000"], ["0.02818400", "18.05900000"], ["0.02818500", "0.00000000"], ["0.02818900", "22.89800000"], ["0.02827200", "30.00000000"]]}, {"e": "depthUpdate", "E": 1604221482138, "s": "ETHBTC", "U": 1737822014, "u": 1737822110, "b": [["0.02816900", "0.40800000"], ["0.02816800", "133.40100000"], ["0.02816700", "24.28500000"], ["0.02816600", "0.00000000"], ["0.02815300", "21.17800000"], ["0.02813500", "0.00000000"], ["0.02251500", "0.02300000"], ["0.01760200", "0.01200000"]], "a": [["0.02816900", "0.00000000"], ["0.02817000", "6.00000000"], ["0.02817100", "0.00000000"], ["0.02817200", "0.26500000"], ["0.02817700", "12.90200000"], ["0.02817800", "1.73800000"], ["0.02817900", "6.72100000"], ["0.02818100", "11.10000000"], ["0.02818300", "4.36300000"], ["0.02818700", "10.49600000"], ["0.02819000", "20.16000000"], ["0.02819500", "5.38400000"], ["0.02819800", "16.82000000"], ["0.02827200", "30.41300000"], ["0.02998000", "6.18600000"]]}, {"e": "depthUpdate", "E": 1604221483139, "s": "ETHBTC", "U": 1737822111, "u": 1737822209, "b": [["0.02817200", "0.00000000"], ["0.02817000", "28.53000000"], ["0.02816900", "81.50000000"], ["0.02816800", "27.11300000"], ["0.02816700", "24.00000000"], ["0.02816500", "12.90400000"], ["0.02816400", "7.09800000"], ["0.02816000", "0.00000000"], ["0.02815800", "7.24600000"], ["0.02815700", "0.00000000"], ["0.02815600", "5.99300000"], ["0.02815500", "0.00000000"], ["0.02815300", "5.11000000"], ["0.02815000", "11.61000000"], ["0.02814700", "55.28000000"], ["0.02814100", "10.53400000"], ["0.02814000", "17.50600000"], ["0.02813800", "12.03900000"], ["0.02813600", "0.00800000"], ["0.02805900", "0.45300000"], ["0.02805400", "0.10400000"], ["0.02805200", "0.12000000"], ["0.02801300", "21.07700000"], ["0.02801200", "2.49400000"], ["0.01494600", "0.00000000"]], "a": [["0.02817000", "0.00000000"], ["0.02817100", "6.00000000"], ["0.02817200", "0.00000000"], ["0.02817300", "0.00000000"], ["0.02817400", "0.00000000"], ["0.02817500", "2.56800000"], ["0.02817600", "0.30100000"], ["0.02817700", "0.00000000"], ["0.02817800", "0.02500000"], ["0.02817900", "0.27000000"], ["0.02818000", "12.71300000"], ["0.02818100", "4.00000000"], ["0.02818200", "4.02500000"], ["0.02818300", "1.66900000"], ["0.02818400", "12.89400000"], ["0.02818500", "0.00000000"], ["0.02818600", "7.46000000"], ["0.02818700", "12.09800000"], ["0.02818800", "2.75800000"], ["0.02818900", "2.69300000"], ["0.02819000", "11.09800000"], ["0.02819100", "5.38700000"], ["0.02819200", "21.02300000"], ["0.02819300", "1.49400000"], ["0.02819400", "20.20400000"], ["0.02819500", "1.34600000"], ["0.02819600", "12.12100000"], ["0.02819700", "4.16400000"], ["0.02819800", "7.39500000"], ["0.02820000", "46.00600000"], ["0.02820300", "14.81000000"]]}, {"e": "depthUpdate", "E": 1604221484139, "s": "ETHBTC", "U": 1737822210, "u": 1737822269, "b": [["0.02817200", "0.00000000"], ["0.02817100", "0.00000000"], ["0.02817000", "140.20900000"], ["0.02816900", "3.77400000"], ["0.02816800", "26.90100000"], ["0.02816500", "16.06900000"], ["0.02816400", "0.00000000"], ["0.02816300", "7.10700000"], ["0.02816200", "0.97100000"], ["0.02816000", "7.10000000"], ["0.02815700", "9.69500000"], ["0.02815100", "0.00000000"], ["0.02814800", "40.41500000"], ["0.02814400", "0.00400000"], ["0.02814200", "0.00000000"], ["0.02813800", "4.03900000"], ["0.02813700", "0.00000000"]], "a": [["0.02817100", "0.00000000"], ["0.02817200", "5.31900000"], ["0.02817300", "0.00000000"], ["0.02817400", "0.00000000"], ["0.02817600", "0.05100000"], ["0.02817900", "15.18500000"], ["0.02818000", "12.71300000"], ["0.02818200", "4.02500000"], ["0.02818300", "1.82600000"], ["0.02818500", "6.45900000"], ["0.02818800", "8.14500000"], ["0.02819000", "16.33300000"], ["0.02819100", "0.00000000"], ["0.02819200", "16.98300000"], ["0.02819600", "0.00000000"], ["0.02819700", "9.55100000"], ["0.02820100", "12.12000000"], ["0.02820900", "4.33100000"], ["0.03309000", "0.35000000"]]}, {"e": "depthUpdate", "E": 1604221485139, "s": "ETHBTC", "U": 1737822270, "u": 1737822312, "b": [["0.02817100", "136.34900000"], ["0.02817000", "28.20900000"], ["0.02816700", "0.00000000"], ["0.02816600", "7.09800000"], ["0.02815100", "20.20400000"], ["0.02814700", "47.19600000"], ["0.02814400", "4.03900000"], ["0.02814000", "5.38500000"], ["0.02813800", "0.00000000"]], "a": [["0.02817200", "0.00900000"], ["0.02817500", "0.00000000"], ["0.02817600", "0.24100000"], ["0.02817700", "0.00000000"], ["0.02817800", "5.02500000"], ["0.02817900", "0.27000000"], ["0.02818000", "15.00000000"], ["0.02818200", "4.18800000"], ["0.02818300", "1.66900000"], ["0.02818700", "7.39700000"], ["0.02818900", "14.91500000"], ["0.02819000", "12.33300000"], ["0.02819100", "12.90500000"], ["0.02819300", "4.18800000"], ["0.02819600", "22.78100000"], ["0.02836300", "0.05000000"], ["0.02836800", "16.05000000"], ["0.03728300", "1.29200000"], ["0.03747900", "0.08400000"]]}, {"e": "depthUpdate", "E": 1604221486139, "s": "ETHBTC", "U": 1737822313, "u": 1737822358, "b": [["0.02817300", "24.29000000"], ["0.02817200", "6.00000000"], ["0.02817100", "136.00000000"], ["0.02817000", "28.20900000"], ["0.02816900", "3.60000000"], ["0.02816800", "2.90100000"], ["0.02815700", "9.69500000"], ["0.02806500", "3.11800000"]], "a": [["0.02817200", "0.00000000"], ["0.02817300", "0.00000000"], ["0.02817400", "0.00000000"], ["0.02817500", "0.00000000"], ["0.02817700", "4.18200000"], ["0.02817800", "5.22600000"], ["0.02818200", "0.02500000"], ["0.02818300", "3.38200000"], ["0.02821100", "0.00000000"], ["0.02823300", "0.00000000"], ["0.02998000", "5.05900000"], ["0.03508100", "0.55300000"]]}, {"e": "depthUpdate", "E": 1604221487139, "s": "ETHBTC", "U": 1737822359, "u": 1737822405, "b": [["0.02817500", "147.64400000"], ["0.02817400", "0.00000000"], ["0.02817300", "24.20400000"], ["0.02817200", "0.00000000"], ["0.02817100", "24.00000000"], ["0.02817000", "4.20900000"], ["0.02815100", "22.89700000"], ["0.02815000", "34.39100000"], ["0.02814700", "47.19600000"], ["0.02814600", "0.00000000"], ["0.02794900", "0.01400000"]], "a": [["0.02817400", "0.00000000"], ["0.02817500", "0.00000000"], ["0.02817700", "0.18200000"], ["0.02817800", "5.15200000"], ["0.02817900", "0.00000000"], ["0.02818100", "5.71300000"], ["0.02818200", "4.02500000"], ["0.02818300", "1.66900000"], ["0.02818600", "12.62600000"], ["0.02822500", "82.95600000"], ["0.02998000", "6.18600000"]]}, {"e": "depthUpdate", "E": 1604221488139, "s": "ETHBTC", "U": 1737822406, "u": 1737822435, "b": [["0.02817500", "141.64400000"], ["0.02817000", "15.20900000"], ["0.02816700", "7.09800000"], ["0.02816000", "0.00000000"], ["0.02251500", "0.00000000"]], "a": [["0.02817600", "24.24100000"], ["0.02817800", "5.12600000"], ["0.02818200", "15.02500000"], ["0.02818900", "15.18500000"], ["0.02820300", "0.00000000"], ["0.02820600", "14.82000000"]]}, {"e": "depthUpdate", "E": 1604221489139, "s": "ETHBTC", "U": 1737822436, "u": 1737822467, "b": [["0.02817400", "2.06900000"], ["0.02816800", "0.83200000"], ["0.02816100", "0.00000000"], ["0.02815600", "0.00000000"], ["0.02815100", "63.31300000"], ["0.02814800", "0.00000000"]], "a": [["0.02817700", "0.00000000"], ["0.02817800", "0.29800000"], ["0.02818000", "11.00000000"], ["0.02818100", "4.00000000"], ["0.02818300", "3.38200000"], ["0.02818700", "12.39700000"], ["0.02818900", "19.18500000"], ["0.02821000", "0.00000000"], ["0.02821900", "66.34000000"]]}, {"e": "depthUpdate", "E": 1604221490139, "s": "ETHBTC", "U": 1737822468, "u": 1737822489, "b": [["0.02817500", "141.48200000"], ["0.02817400", "0.00000000"], ["0.02816800", "2.90100000"], ["0.02816400", "6.00000000"], ["0.02815400", "20.20800000"], ["0.02815100", "43.10900000"], ["0.02805900", "0.04000000"], ["0.02805400", "0.51700000"]], "a": [["0.02817800", "0.17400000"], ["0.02818300", "1.66900000"], ["0.02818400", "14.60700000"], ["0.02819400", "0.00000000"], ["0.02819800", "27.60300000"]]}, {"e": "depthUpdate", "E": 1604221491139, "s": "ETHBTC", "U": 1737822490, "u": 1737822523, "b": [["0.02817500", "112.00000000"], ["0.02816700", "0.00000000"], ["0.02816000", "7.09900000"], ["0.02813900", "4.50000000"], ["0.02800000", "112.67800000"], ["0.02797900", "10.50400000"]], "a": [["0.02817600", "29.08000000"], ["0.02817800", "0.02500000"], ["0.02818600", "27.54100000"], ["0.02818700", "12.39700000"], ["0.02818800", "8.14500000"], ["0.02818900", "4.47900000"], ["0.02820000", "5.59000000"], ["0.02820400", "40.41400000"], ["0.02831700", "17.24400000"], ["0.02833800", "0.00000000"], ["0.02998000", "5.05900000"]]}, {"e": "depthUpdate", "E": 1604221492139, "s": "ETHBTC", "U": 1737822524, "u": 1737822552, "b": [["0.02817500", "142.00000000"], ["0.02817200", "11.00000000"], ["0.02816800", "0.83200000"], ["0.02816300", "9.17600000"], ["0.02816100", "5.09400000"], ["0.02816000", "0.00000000"]], "a": [["0.02817600", "0.24100000"], ["0.02818000", "11.14400000"], ["0.02818300", "11.00000000"], ["0.02818500", "6.45900000"], ["0.02818600", "12.62600000"], ["0.02818800", "8.08000000"], ["0.02818900", "19.39400000"], ["0.02819000", "7.09800000"], ["0.02819300", "1.49400000"], ["0.02819500", "1.41100000"], ["0.02819600", "0.00000000"], ["0.02819700", "12.24500000"], ["0.02998000", "6.18600000"]]}, {"e": "depthUpdate", "E": 1604221493139, "s": "ETHBTC", "U": 1737822553, "u": 1737822586, "b": [["0.02817500", "147.48200000"], ["0.02817400", "0.00000000"], ["0.02817100", "31.09700000"], ["0.02817000", "15.20900000"], ["0.02816800", "2.90100000"], ["0.02816300", "1.94000000"], ["0.02813000", "0.00000000"]], "a": [["0.02817600", "0.24100000"], ["0.02818000", "11.00000000"], ["0.02818200", "15.17500000"], ["0.02818500", "6.45900000"], ["0.02818600", "12.62600000"], ["0.02818700", "12.39700000"], ["0.02818800", "2.69300000"], ["0.02818900", "4.47900000"], ["0.02819000", "7.09800000"], ["0.02819100", "27.82000000"], ["0.02819200", "22.36900000"], ["0.02819700", "13.91400000"], ["0.02820400", "0.00000000"], ["0.02820800", "40.41300000"]]}, {"e": "depthUpdate", "E": 1604221494139, "s": "ETHBTC", "U": 1737822587, "u": 1737822647, "b": [["0.02817600", "123.48200000"], ["0.02817500", "0.00000000"], ["0.02817400", "0.26100000"], ["0.02817300", "24.00000000"], ["0.02817200", "0.00000000"], ["0.02817100", "0.00000000"], ["0.02817000", "9.37400000"], ["0.02816900", "0.00000000"], ["0.02816800", "0.83200000"], ["0.02816700", "0.00400000"], ["0.02816500", "23.16800000"], ["0.02816300", "4.00900000"], ["0.02816100", "0.00000000"], ["0.02816000", "3.60000000"], ["0.02805400", "0.10400000"], ["0.02681100", "13.85700000"], ["0.02537000", "0.02300000"]], "a": [["0.02817600", "0.00000000"], ["0.02817700", "17.37800000"], ["0.02818100", "4.25400000"], ["0.02818200", "15.02500000"], ["0.02818700", "12.09800000"], ["0.02818900", "19.39400000"], ["0.02819000", "7.09800000"], ["0.02819100", "12.90500000"], ["0.02819700", "13.88800000"], ["0.02819800", "27.60100000"], ["0.02820000", "28.38700000"], ["0.02820600", "14.82000000"]]}, {"e": "depthUpdate", "E": 1604221495139, "s": "ETHBTC", "U": 1737822648, "u": 1737822703, "b": [["0.02817600", "112.00000000"], ["0.02817400", "0.13200000"], ["0.02816700", "2.06900000"], ["0.02816300", "1.94000000"], ["0.02816000", "8.72900000"], ["0.02815500", "20.20400000"], ["0.02815400", "0.00000000"], ["0.02815200", "40.41200000"], ["0.02815100", "2.69300000"], ["0.02814600", "0.00000000"], ["0.02806000", "0.41300000"], ["0.02803000", "21.37500000"], ["0.02801300", "0.01600000"], ["0.02681100", "13.90300000"]], "a": [["0.02817700", "124.21700000"], ["0.02818000", "0.00000000"], ["0.02818100", "4.28200000"], ["0.02818200", "4.02500000"], ["0.02818300", "0.00000000"], ["0.02819200", "22.66700000"], ["0.02819700", "14.00400000"], ["0.02819800", "7.39500000"], ["0.02820100", "32.32400000"], ["0.02820600", "0.01000000"], ["0.02821000", "14.81000000"], ["0.02998000", "5.05900000"], ["0.03052500", "0.00700000"]]}, {"e": "depthUpdate", "E": 1604221496139, "s": "ETHBTC", "U": 1737822704, "u": 1737822746, "b": [["0.02817600", "117.48200000"], ["0.02817400", "0.23400000"]], "a": [["0.02817700", "104.37800000"], ["0.02818100", "4.22900000"], ["0.02818900", "4.47900000"], ["0.02819000", "7.09800000"], ["0.02819200", "27.81900000"], ["0.02819700", "12.24500000"], ["0.02998000", "6.18600000"]]}, {"e": "depthUpdate", "E": 1604221497139, "s": "ETHBTC", "U": 1737822747, "u": 1737822783, "b": [["0.02817400", "0.24300000"], ["0.02817100", "11.00000000"], ["0.02806000", "0.00000000"], ["0.02805400", "0.51700000"], ["0.02535900", "0.08900000"]], "a": [["0.02818100", "4.27500000"], ["0.02818300", "9.00000000"], ["0.02819100", "27.82000000"], ["0.02836800", "0.05000000"], ["0.02837500", "16.03700000"], ["0.03052000", "6.24600000"]]}, {"e": "depthUpdate", "E": 1604221498139, "s": "ETHBTC", "U": 1737822784, "u": 1737822834, "b": [["0.02817600", "141.48200000"], ["0.02817500", "0.20400000"], ["0.02817400", "2.06900000"], ["0.02816900", "3.60000000"], ["0.02816700", "0.00000000"], ["0.02816000", "0.00000000"], ["0.02814000", "0.00000000"]], "a": [["0.02817700", "0.00000000"], ["0.02817800", "28.86400000"], ["0.02818100", "4.13600000"], ["0.02818200", "1.73700000"], ["0.02818400", "12.89400000"], ["0.02818700", "16.09800000"], ["0.02819000", "8.78800000"], ["0.02819100", "12.90500000"]]}, {"e": "depthUpdate", "E": 1604221499139, "s": "ETHBTC", "U": 1737822835, "u": 1737822866, "b": [["0.02817700", "117.48200000"], ["0.02817600", "24.00000000"], ["0.02817400", "9.16500000"], ["0.02817100", "0.00000000"], ["0.02816500", "16.06900000"], ["0.02816200", "6.17900000"], ["0.02814600", "5.38400000"]], "a": [["0.02817800", "24.02500000"], ["0.02818100", "0.26100000"], ["0.02818200", "1.73700000"], ["0.02819000", "23.70300000"], ["0.02819100", "16.90500000"], ["0.02819800", "7.39500000"], ["0.02820100", "20.20400000"], ["0.02820400", "40.41100000"], ["0.02820800", "0.00000000"]]}, {"e": "depthUpdate", "E": 1604221500139, "s": "ETHBTC", "U": 1737822867, "u": 1737822894, "b": [["0.02817700", "112.00000000"], ["0.02817400", "7.09600000"], ["0.02816900", "5.66900000"], ["0.02815600", "20.20600000"], ["0.02815500", "0.00000000"], ["0.02815300", "45.52100000"], ["0.02815200", "0.00400000"], ["0.02815000", "46.51000000"], ["0.02814700", "35.07600000"], ["0.02812600", "1.36900000"], ["0.02812500", "74.66000000"], ["0.02811200", "0.05000000"], ["0.02811100", "0.00900000"]], "a": [["0.02817800", "28.88300000"], ["0.02818000", "0.27300000"], ["0.02818100", "0.00000000"], ["0.02820200", "12.11900000"], ["0.02998000", "5.05900000"]]}, {"e": "depthUpdate", "E": 1604221501139, "s": "ETHBTC", "U": 1737822895, "u": 1737822908, "b": [["0.02817700", "113.00000000"]], "a": [["0.02817800", "28.87500000"], ["0.02818000", "0.23200000"], ["0.02818200", "1.73700000"], ["0.02818300", "9.00000000"], ["0.02818500", "7.45900000"], ["0.02818700", "12.09800000"], ["0.02818800", "6.69300000"], ["0.02819800", "27.59900000"], ["0.02820100", "0.00000000"], ["0.02998000", "6.18600000"]]}, {"e": "depthUpdate", "E": 1604221502139, "s": "ETHBTC", "U": 1737822909, "u": 1737822918, "b": [["0.02817700", "111.76500000"], ["0.02817400", "0.00000000"], ["0.02815400", "2.69300000"], ["0.02815100", "0.00000000"], ["0.02764600", "0.00600000"], ["0.02763100", "0.06900000"]], "a": [["0.02818200", "0.02500000"], ["0.02818300", "10.71200000"], ["0.02820400", "0.00000000"], ["0.02820800", "40.40700000"]]}, {"e": "depthUpdate", "E": 1604221503140, "s": "ETHBTC", "U": 1737822919, "u": 1737822990, "b": [["0.02817700", "0.00000000"], ["0.02817600", "0.00000000"], ["0.02817500", "0.00000000"], ["0.02817400", "0.19600000"], ["0.02817300", "0.00000000"], ["0.02817100", "1.00000000"], ["0.02817000", "5.16500000"], ["0.02816900", "12.71300000"], ["0.02816700", "0.00000000"], ["0.02816300", "4.00900000"], ["0.02816200", "0.97100000"], ["0.02816100", "7.10000000"], ["0.02816000", "6.09100000"], ["0.02815300", "5.11000000"], ["0.02815000", "23.72900000"], ["0.02814800", "40.40600000"], ["0.02812400", "10.68500000"], ["0.02689400", "0.01300000"]], "a": [["0.02817600", "83.00000000"], ["0.02817700", "13.85800000"], ["0.02817800", "24.01700000"], ["0.02817900", "0.18700000"], ["0.02818000", "0.26100000"], ["0.02818100", "5.71300000"], ["0.02818200", "5.02500000"], ["0.02818300", "0.00000000"], ["0.02818500", "6.45900000"], ["0.02818600", "7.46000000"], ["0.02818700", "7.09800000"], ["0.02818800", "2.69300000"], ["0.02818900", "0.47900000"], ["0.02819000", "8.78800000"], ["0.02819100", "12.90500000"], ["0.02819400", "5.38300000"], ["0.02819700", "6.85800000"], ["0.02819800", "22.21400000"], ["0.02853400", "2.00400000"], ["0.02854900", "4.58500000"]]}, {"e": "depthUpdate", "E": 1604221504140, "s": "ETHBTC", "U": 1737822991, "u": 1737823055, "b": [["0.02817400", "0.00000000"], ["0.02817300", "0.00000000"], ["0.02817200", "0.00000000"], ["0.02817100", "0.00000000"], ["0.02817000", "1.00000000"], ["0.02816900", "11.11600000"], ["0.02816600", "0.00000000"], ["0.02816500", "12.90400000"], ["0.02816400", "0.00000000"], ["0.02816100", "0.00000000"], ["0.02816000", "21.66100000"], ["0.02815900", "19.98800000"], ["0.02815800", "14.34600000"], ["0.02815600", "0.00000000"], ["0.02815200", "20.20800000"], ["0.02815000", "11.61000000"], ["0.02814700", "35.07600000"], ["0.02814600", "5.38800000"], ["0.02811400", "0.00000000"], ["0.02808800", "1.22200000"], ["0.02808600", "0.03100000"], ["0.02683900", "0.01900000"]], "a": [["0.02817200", "87.85800000"], ["0.02817300", "24.00000000"], ["0.02817400", "4.00000000"], ["0.02817500", "0.00000000"], ["0.02817600", "24.22500000"], ["0.02817700", "9.00000000"], ["0.02817800", "0.01700000"], ["0.02818000", "6.16500000"], ["0.02818200", "0.02500000"], ["0.02818300", "0.00000000"], ["0.02818400", "12.89400000"], ["0.02818600", "22.37500000"], ["0.02818700", "40.47800000"], ["0.02818900", "0.20900000"], ["0.02819200", "27.52100000"], ["0.02819500", "6.79800000"], ["0.02820000", "5.59000000"]]}, {"e": "depthUpdate", "E": 1604221505140, "s": "ETHBTC", "U": 1737823056, "u": 1737823083, "b": [["0.02816300", "7.57400000"], ["0.02815500", "5.99700000"], ["0.02815400", "4.29300000"], ["0.02815200", "0.00400000"], ["0.02814800", "60.60900000"], ["0.02814600", "17.50900000"], ["0.02811300", "0.06100000"], ["0.02809900", "65.50600000"], ["0.02809400", "4.02700000"], ["0.02808800", "0.02100000"], ["0.02805400", "0.10400000"], ["0.01408900", "3.00000000"]], "a": [["0.02817200", "87.77900000"], ["0.02817400", "4.16000000"], ["0.02817600", "24.00000000"], ["0.02817800", "1.01700000"], ["0.02818000", "5.46500000"], ["0.02998000", "5.05900000"]]}, {"e": "depthUpdate", "E": 1604221506140, "s": "ETHBTC", "U": 1737823084, "u": 1737823119, "b": [["0.02817000", "0.00000000"], ["0.02816900", "11.00000000"], ["0.02816800", "1.97800000"], ["0.02816700", "0.00000000"], ["0.02816100", "1.71300000"], ["0.02814600", "17.50500000"], ["0.02808300", "0.00000000"], ["0.02802700", "0.42