[{"e": "depthUpdate", "E": 1604224802322, "s": "ETHBTC", "U": 1737948025, "u": 1737948064, "b": [["0.02820000", "49.23700000"], ["0.02819900", "12.94200000"], ["0.02819800", "0.20900000"], ["0.02819600", "0.00000000"], ["0.02819100", "7.90800000"], ["0.02817600", "40.49100000"], ["0.02817200", "31.88400000"], ["0.02816700", "0.00000000"], ["0.02815400", "0.00000000"], ["0.02815200", "0.00000000"], ["0.02814500", "150.25300000"], ["0.02797900", "0.19100000"]], "a": [["0.02820100", "30.00000000"], ["0.02821100", "0.00000000"], ["0.02821300", "16.64100000"], ["0.02821700", "5.16300000"]]}, {"e": "depthUpdate", "E": 1604224803322, "s": "ETHBTC", "U": 1737948065, "u": 1737948135, "b": [["0.02820200", "25.50000000"], ["0.02820100", "0.00000000"], ["0.02820000", "24.00000000"], ["0.02819900", "13.37600000"], ["0.02819800", "0.00000000"], ["0.02819700", "1.00000000"], ["0.02819500", "5.83200000"], ["0.02818300", "6.71900000"], ["0.02817800", "12.15300000"], ["0.02817700", "24.80600000"], ["0.02817400", "10.80500000"], ["0.02817300", "7.09600000"], ["0.02817200", "9.06400000"], ["0.02807800", "1.67100000"], ["0.02804800", "0.00000000"], ["0.02804400", "21.03800000"], ["0.02700900", "0.04600000"]], "a": [["0.02820100", "0.00000000"], ["0.02820200", "0.00000000"], ["0.02820300", "31.00000000"], ["0.02820400", "0.18200000"], ["0.02821000", "0.20800000"], ["0.02821100", "0.00000000"], ["0.02821200", "3.96000000"], ["0.02821300", "16.64100000"], ["0.02822100", "12.94000000"], ["0.02822500", "0.00500000"], ["0.02822900", "75.46800000"], ["0.02839800", "16.00000000"], ["0.02839900", "0.28000000"]]}, {"e": "depthUpdate", "E": 1604224804322, "s": "ETHBTC", "U": 1737948136, "u": 1737948187, "b": [["0.02820300", "54.41900000"], ["0.02820200", "24.00000000"], ["0.02820100", "0.14800000"], ["0.02819900", "14.09100000"], ["0.02819800", "5.18100000"], ["0.02819700", "0.00000000"], ["0.02819100", "3.90800000"], ["0.02818300", "4.01800000"], ["0.02817400", "5.40200000"], ["0.02817300", "0.00000000"], ["0.02814100", "0.00000000"], ["0.02812900", "0.00000000"], ["0.02741900", "0.00000000"], ["0.02719500", "0.00000000"]], "a": [["0.02820300", "0.00000000"], ["0.02820400", "0.00800000"], ["0.02820500", "0.00000000"], ["0.02820600", "0.25300000"], ["0.02820900", "1.00000000"], ["0.02821100", "1.72800000"], ["0.02821400", "21.44900000"], ["0.02821600", "5.48000000"], ["0.02821900", "5.16200000"], ["0.02822000", "11.95000000"], ["0.02822300", "25.41400000"], ["0.02822700", "13.66600000"], ["0.02822900", "26.86700000"], ["0.02823100", "10.12400000"], ["0.02823200", "12.14200000"], ["0.02823300", "43.61800000"], ["0.02823800", "16.21700000"], ["0.02857800", "4.62800000"], ["0.02998000", "5.05900000"]]}, {"e": "depthUpdate", "E": 1604224805322, "s": "ETHBTC", "U": 1737948188, "u": 1737948218, "b": [["0.02820300", "26.42900000"], ["0.02820200", "25.49000000"], ["0.02819600", "4.00000000"], ["0.02818900", "2.26400000"], ["0.02818700", "13.10500000"], ["0.02818300", "13.89600000"], ["0.02817800", "0.01000000"], ["0.02817500", "22.81500000"], ["0.02816200", "63.92000000"], ["0.02814600", "0.00000000"], ["0.02633800", "0.01000000"]], "a": [["0.02820400", "115.43000000"], ["0.02820500", "1.00000000"], ["0.02820900", "0.00000000"], ["0.02821300", "1.72600000"], ["0.02821500", "4.07600000"], ["0.02821600", "5.48000000"], ["0.02821700", "5.16300000"], ["0.02822600", "13.39700000"], ["0.02823900", "3.12000000"], ["0.02857800", "4.70700000"], ["0.02998000", "6.18600000"]]}, {"e": "depthUpdate", "E": 1604224806322, "s": "ETHBTC", "U": 1737948219, "u": 1737948269, "b": [["0.02820300", "0.00000000"], ["0.02820200", "26.68100000"], ["0.02820100", "0.00000000"], ["0.02820000", "0.00000000"], ["0.02819900", "14.38800000"], ["0.02819700", "0.00000000"], ["0.02819600", "4.00000000"], ["0.02819500", "7.56000000"], ["0.02818700", "6.01400000"], ["0.02817300", "7.09600000"], ["0.02811800", "0.00000000"], ["0.02721300", "0.03600000"], ["0.02654800", "0.01400000"]], "a": [["0.02820300", "33.44300000"], ["0.02820400", "25.00800000"], ["0.02820500", "0.23900000"], ["0.02820600", "0.00000000"], ["0.02821200", "0.00000000"], ["0.02821700", "9.12300000"], ["0.02822300", "5.16700000"], ["0.02822800", "21.59800000"], ["0.02823200", "0.00000000"], ["0.02823600", "63.19100000"], ["0.02823800", "1.37700000"], ["0.02824400", "14.84800000"]]}, {"e": "depthUpdate", "E": 1604224807322, "s": "ETHBTC", "U": 1737948270, "u": 1737948343, "b": [["0.02820200", "47.80500000"], ["0.02820100", "0.14600000"], ["0.02820000", "0.26200000"], ["0.02819900", "12.94200000"], ["0.02819800", "0.00000000"], ["0.02819700", "0.00000000"], ["0.02819600", "4.00000000"], ["0.02819500", "5.83200000"], ["0.02819300", "0.00000000"], ["0.02817300", "0.00400000"], ["0.02816300", "0.00000000"]], "a": [["0.02820300", "7.00000000"], ["0.02820400", "0.00800000"], ["0.02820500", "0.21700000"], ["0.02820600", "0.00000000"], ["0.02821000", "4.16800000"], ["0.02821700", "5.16300000"], ["0.02822600", "17.44500000"], ["0.02822800", "20.24800000"], ["0.02822900", "22.82000000"], ["0.02825800", "35.83800000"]]}, {"e": "depthUpdate", "E": 1604224808322, "s": "ETHBTC", "U": 1737948344, "u": 1737948376, "b": [["0.02820300", "49.50000000"], ["0.02820200", "26.30500000"], ["0.02820100", "0.32300000"], ["0.02820000", "0.00000000"], ["0.02819700", "6.18100000"], ["0.02819600", "0.00000000"], ["0.02819300", "7.09100000"], ["0.02819200", "20.03600000"], ["0.02818600", "7.25600000"], ["0.02818500", "5.17100000"], ["0.02817500", "0.00000000"], ["0.02817300", "0.00000000"]], "a": [["0.02820300", "0.00000000"], ["0.02820400", "0.00800000"], ["0.02820500", "1.00000000"], ["0.02820900", "11.00000000"], ["0.02821000", "4.16800000"], ["0.02821200", "0.28700000"], ["0.02821300", "16.64100000"], ["0.02826700", "0.01300000"]]}, {"e": "depthUpdate", "E": 1604224809323, "s": "ETHBTC", "U": 1737948377, "u": 1737948400, "b": [["0.02820300", "50.65100000"], ["0.02819200", "12.94400000"], ["0.02811300", "0.54200000"], ["0.02751600", "1.41900000"]], "a": [["0.02820400", "6.00800000"], ["0.02821100", "0.00000000"], ["0.02821200", "1.72800000"], ["0.02821400", "21.68300000"], ["0.02821900", "0.00000000"], ["0.02822300", "10.32700000"], ["0.02822600", "18.79600000"], ["0.02823100", "0.25000000"], ["0.02827200", "0.00500000"], ["0.02832300", "0.50000000"], ["0.02998000", "6.18600000"]]}, {"e": "depthUpdate", "E": 1604224810323, "s": "ETHBTC", "U": 1737948401, "u": 1737948481, "b": [["0.02820500", "0.00000000"], ["0.02820400", "49.50000000"], ["0.02820300", "25.49000000"], ["0.02820200", "0.00000000"], ["0.02820100", "0.14600000"], ["0.02819400", "12.59200000"], ["0.02818000", "6.42300000"], ["0.02817900", "28.21200000"], ["0.02817500", "7.09600000"], ["0.02812400", "2.00000000"], ["0.02811300", "0.23800000"], ["0.02807800", "2.08400000"], ["0.02806000", "0.00000000"], ["0.02782600", "2.00700000"], ["0.02680800", "12.28000000"], ["0.02680700", "1.71000000"]], "a": [["0.02820400", "0.00000000"], ["0.02820500", "10.61600000"], ["0.02820600", "24.00000000"], ["0.02820700", "0.00000000"], ["0.02820900", "0.00000000"], ["0.02821000", "0.20800000"], ["0.02821300", "1.72600000"], ["0.02821400", "21.44900000"], ["0.02821500", "8.03600000"], ["0.02821600", "5.48000000"], ["0.02821700", "5.16300000"], ["0.02822000", "11.95000000"], ["0.02823000", "5.15600000"], ["0.02823300", "3.12400000"], ["0.02823500", "40.49300000"], ["0.02832800", "0.01600000"]]}, {"e": "depthUpdate", "E": 1604224811322, "s": "ETHBTC", "U": 1737948482, "u": 1737948569, "b": [["0.02820500", "4.49000000"], ["0.02820400", "46.50000000"], ["0.02820300", "24.00000000"], ["0.02820200", "0.00000000"], ["0.02820000", "7.90800000"], ["0.02819500", "5.83200000"], ["0.02819400", "8.59200000"], ["0.02819300", "14.64200000"], ["0.02819100", "0.00000000"], ["0.02818800", "68.50600000"], ["0.02818100", "2.69800000"], ["0.02817800", "7.10500000"], ["0.02817500", "0.00000000"], ["0.02816000", "0.00000000"], ["0.02811300", "0.20400000"], ["0.02722600", "0.08800000"]], "a": [["0.02820500", "0.00000000"], ["0.02820600", "141.50000000"], ["0.02820700", "0.00000000"], ["0.02820800", "1.29300000"], ["0.02820900", "0.00000000"], ["0.02821900", "0.00000000"], ["0.02822300", "30.57300000"], ["0.02822800", "0.00000000"], ["0.02825800", "35.88900000"]]}, {"e": "depthUpdate", "E": 1604224812323, "s": "ETHBTC", "U": 1737948570, "u": 1737948627, "b": [["0.02820500", "1.49000000"], ["0.02820400", "24.00000000"], ["0.02820300", "0.23800000"], ["0.02820000", "4.00000000"], ["0.02819900", "13.94200000"], ["0.02819700", "11.01300000"], ["0.02819500", "0.00000000"], ["0.02819100", "3.90800000"], ["0.02818200", "0.00800000"], ["0.02817800", "0.01000000"]], "a": [["0.02820600", "127.99800000"], ["0.02820700", "1.00000000"], ["0.02820800", "0.24100000"], ["0.02820900", "0.00000000"], ["0.02821000", "0.00000000"], ["0.02821100", "24.00000000"], ["0.02821200", "1.79600000"], ["0.02821300", "0.00000000"], ["0.02821800", "0.00000000"], ["0.02822100", "12.94000000"], ["0.02822400", "0.00000000"], ["0.02822800", "15.60100000"], ["0.02825800", "35.83800000"], ["0.02827500", "0.04100000"]]}, {"e": "depthUpdate", "E": 1604224813323, "s": "ETHBTC", "U": 1737948628, "u": 1737948676, "b": [["0.02820500", "0.00000000"], ["0.02820400", "35.75800000"], ["0.02820300", "0.00000000"], ["0.02820200", "0.00000000"], ["0.02820000", "0.00000000"], ["0.02819900", "23.94200000"], ["0.02819600", "1.00000000"], ["0.02819500", "4.00000000"], ["0.02817300", "7.09600000"], ["0.02680700", "1.66400000"]], "a": [["0.02820500", "7.79200000"], ["0.02820600", "24.00000000"], ["0.02820700", "0.00000000"], ["0.02820800", "0.00000000"], ["0.02820900", "3.96000000"], ["0.02821000", "0.00000000"], ["0.02821500", "5.78900000"], ["0.02821900", "0.00000000"], ["0.02822000", "11.95000000"], ["0.02998000", "5.05900000"]]}, {"e": "depthUpdate", "E": 1604224814323, "s": "ETHBTC", "U": 1737948677, "u": 1737948748, "b": [["0.02820500", "54.50000000"], ["0.02820400", "29.75800000"], ["0.02820300", "0.20100000"], ["0.02820200", "0.00000000"], ["0.02820000", "8.45400000"], ["0.02819900", "12.94200000"], ["0.02819800", "0.00000000"], ["0.02819600", "0.00000000"], ["0.02819100", "0.00000000"], ["0.02819000", "0.00000000"], ["0.02818800", "62.08300000"], ["0.02818600", "9.95700000"], ["0.02818100", "8.10000000"], ["0.02818000", "6.42300000"], ["0.02817300", "0.00000000"], ["0.02680800", "12.32600000"]], "a": [["0.02820500", "0.00000000"], ["0.02820600", "4.66200000"], ["0.02820700", "0.00000000"], ["0.02820800", "0.00000000"], ["0.02820900", "0.00000000"], ["0.02821000", "0.00000000"], ["0.02821100", "0.26400000"], ["0.02821200", "0.06800000"], ["0.02821300", "1.72800000"], ["0.02821500", "9.74900000"], ["0.02822000", "11.95000000"], ["0.02823000", "7.85700000"], ["0.02823200", "5.40200000"], ["0.02823600", "73.06500000"], ["0.02998000", "6.18600000"]]}, {"e": "depthUpdate", "E": 1604224815323, "s": "ETHBTC", "U": 1737948749, "u": 1737948792, "b": [["0.02820500", "48.50000000"], ["0.02820400", "29.75800000"], ["0.02820000", "4.54600000"], ["0.02819500", "4.00000000"], ["0.02819400", "15.01700000"], ["0.02819000", "3.90800000"], ["0.02818500", "7.86900000"], ["0.02818100", "5.40200000"], ["0.02817700", "30.20800000"], ["0.02817400", "0.00000000"], ["0.02807800", "1.67100000"], ["0.02804800", "21.03500000"], ["0.02804400", "0.00000000"], ["0.02785000", "12.52200000"], ["0.02784900", "16.65100000"]], "a": [["0.02820600", "139.66200000"], ["0.02820700", "1.00000000"], ["0.02820800", "0.12900000"], ["0.02820900", "0.00000000"], ["0.02821000", "0.00000000"], ["0.02821100", "0.00000000"], ["0.02821800", "0.00000000"], ["0.02821900", "15.60100000"], ["0.02822000", "26.86500000"], ["0.02822800", "0.00000000"], ["0.02823200", "45.89500000"], ["0.02823500", "0.00000000"], ["0.02839800", "0.00000000"], ["0.02839900", "16.28000000"]]}, {"e": "depthUpdate", "E": 1604224816323, "s": "ETHBTC", "U": 1737948793, "u": 1737948816, "b": [["0.02820500", "0.90100000"], ["0.02820400", "24.00000000"], ["0.02819100", "0.00000000"], ["0.02816200", "0.00000000"], ["0.02815700", "63.93100000"], ["0.02806000", "0.41300000"]], "a": [["0.02820600", "112.00000000"], ["0.02820800", "0.00000000"], ["0.02820900", "0.22500000"], ["0.02821900", "0.00000000"], ["0.02822000", "11.95000000"], ["0.02823100", "15.85100000"], ["0.02838500", "16.55000000"], ["0.02856000", "0.39600000"], ["0.03097600", "0.00000000"]]}, {"e": "depthUpdate", "E": 1604224817323, "s": "ETHBTC", "U": 1737948817, "u": 1737948859, "b": [["0.02820500", "24.72100000"], ["0.02820000", "4.54600000"], ["0.02819300", "14.64200000"], ["0.02819000", "3.90800000"], ["0.02817500", "0.00400000"], ["0.02741900", "6.93200000"], ["0.02735100", "2.95200000"], ["0.02733100", "0.00800000"]], "a": [["0.02820600", "136.00000000"], ["0.02820800", "0.12200000"], ["0.02820900", "0.00000000"], ["0.02821000", "0.00000000"], ["0.02821200", "0.06800000"], ["0.02885200", "8.18800000"]]}, {"e": "depthUpdate", "E": 1604224818323, "s": "ETHBTC", "U": 1737948860, "u": 1737948885, "b": [["0.02820500", "0.00000000"], ["0.02820400", "0.00000000"], ["0.02820300", "0.00000000"], ["0.02820200", "0.13200000"], ["0.02820000", "3.54600000"], ["0.02819800", "11.00000000"], ["0.02819300", "21.73400000"], ["0.02817500", "0.00000000"]], "a": [["0.02820500", "7.80100000"], ["0.02820600", "136.18900000"], ["0.02820700", "0.00000000"], ["0.02820800", "0.00000000"], ["0.02820900", "0.00000000"], ["0.02821500", "5.78900000"], ["0.02822200", "17.66100000"], ["0.02823500", "7.08800000"], ["0.02861200", "0.38700000"], ["0.02864300", "0.21000000"], ["0.02998000", "5.05900000"]]}, {"e": "depthUpdate", "E": 1604224819323, "s": "ETHBTC", "U": 1737948886, "u": 1737948938, "b": [["0.02820400", "82.91100000"], ["0.02820300", "24.00000000"], ["0.02820200", "0.00000000"], ["0.02820000", "7.45400000"], ["0.02819800", "0.00000000"], ["0.02819700", "11.14100000"], ["0.02819400", "11.60600000"], ["0.02819300", "14.64200000"], ["0.02819000", "0.00000000"], ["0.02802800", "0.05000000"]], "a": [["0.02820400", "0.00000000"], ["0.02820500", "0.03600000"], ["0.02820600", "27.84200000"], ["0.02820700", "0.11600000"], ["0.02821100", "1.72800000"], ["0.02821200", "0.06800000"], ["0.02821300", "0.00000000"], ["0.02821700", "9.12300000"], ["0.02821900", "14.91500000"], ["0.02822000", "11.95000000"], ["0.02822200", "2.74600000"], ["0.02823500", "0.00000000"], ["0.02998000", "6.18600000"]]}, {"e": "depthUpdate", "E": 1604224820323, "s": "ETHBTC", "U": 1737948939, "u": 1737948964, "b": [["0.02820400", "92.67000000"], ["0.02819900", "13.21200000"], ["0.02819700", "11.01300000"], ["0.02819500", "0.00000000"], ["0.02819300", "14.64200000"], ["0.02818600", "22.10000000"], ["0.02818300", "1.75400000"], ["0.02816300", "0.00000000"], ["0.02812900", "0.10000000"]], "a": [["0.02820600", "0.00000000"], ["0.02820700", "0.00000000"], ["0.02820900", "0.27500000"], ["0.02821200", "4.02800000"], ["0.02821300", "14.91500000"], ["0.02821700", "5.16300000"], ["0.02821900", "0.00000000"]]}, {"e": "depthUpdate", "E": 1604224821323, "s": "ETHBTC", "U": 1737948965, "u": 1737948987, "b": [["0.02820400", "89.25900000"], ["0.02819500", "3.41100000"], ["0.02818900", "2.26400000"], ["0.02812900", "0.00000000"]], "a": [["0.02820900", "0.14600000"], ["0.02821900", "15.60100000"], ["0.02822800", "12.14400000"], ["0.02822900", "63.31400000"], ["0.02823100", "0.25000000"], ["0.02823200", "5.40200000"], ["0.02823600", "60.92200000"], ["0.02857800", "4.76800000"]]}, {"e": "depthUpdate", "E": 1604224822323, "s": "ETHBTC", "U": 1737948988, "u": 1737949028, "b": [["0.02820800", "5.70200000"], ["0.02820700", "24.00000000"], ["0.02820600", "5.83200000"], ["0.02820500", "0.00000000"], ["0.02820400", "77.50000000"], ["0.02820100", "3.55700000"], ["0.02820000", "7.58300000"], ["0.02819900", "12.94200000"], ["0.02819800", "6.41300000"], ["0.02819700", "5.18100000"], ["0.02819500", "0.00000000"], ["0.02818800", "55.66600000"], ["0.02817800", "0.01000000"], ["0.02806000", "0.00000000"], ["0.02785500", "1.36400000"], ["0.02784200", "0.00400000"]], "a": [["0.02820500", "0.00000000"], ["0.02820900", "0.00000000"], ["0.02821000", "27.84200000"], ["0.02821100", "0.28900000"], ["0.02821200", "0.06800000"], ["0.02821300", "0.00000000"], ["0.02821400", "23.17600000"], ["0.02821500", "1.71300000"], ["0.02821700", "3.96000000"], ["0.02822300", "10.32700000"], ["0.02822500", "20.25000000"], ["0.02822900", "22.82000000"], ["0.02823300", "43.61500000"], ["0.02823600", "51.04800000"], ["0.02857800", "4.80300000"]]}, {"e": "depthUpdate", "E": 1604224823323, "s": "ETHBTC", "U": 1737949029, "u": 1737949097, "b": [["0.02820900", "0.00000000"], ["0.02820800", "5.70100000"], ["0.02820700", "24.15300000"], ["0.02820600", "0.00000000"], ["0.02820300", "0.00000000"], ["0.02820200", "0.00000000"], ["0.02820000", "3.90800000"], ["0.02819700", "5.83200000"], ["0.02819500", "2.26400000"], ["0.02818900", "0.00000000"], ["0.02818700", "0.00000000"], ["0.02818300", "0.00000000"], ["0.02817900", "5.39700000"], ["0.02816700", "0.00000000"], ["0.02809800", "0.45200000"]], "a": [["0.02821000", "27.84100000"], ["0.02821100", "0.12100000"], ["0.02821200", "0.06800000"], ["0.02821400", "14.67100000"], ["0.02821900", "0.00000000"], ["0.02822300", "18.40000000"], ["0.02822400", "19.60100000"], ["0.02822500", "20.75200000"], ["0.02822800", "0.00000000"], ["0.02822900", "0.00000000"], ["0.02823400", "0.01000000"], ["0.02823600", "63.19100000"], ["0.02857300", "0.00400000"], ["0.02857500", "0.05600000"], ["0.02857800", "0.04300000"], ["0.02998000", "6.18600000"]]}, {"e": "depthUpdate", "E": 1604224824323, "s": "ETHBTC", "U": 1737949098, "u": 1737949108, "b": [["0.02820100", "8.73800000"], ["0.02819500", "9.35400000"], ["0.02818900", "7.71700000"]], "a": [["0.02821000", "27.85600000"], ["0.02821400", "12.94400000"], ["0.02821500", "3.44000000"], ["0.02821900", "14.91500000"], ["0.02822300", "13.24000000"], ["0.02822900", "5.15800000"], ["0.02823500", "9.87400000"]]}, {"e": "depthUpdate", "E": 1604224825323, "s": "ETHBTC", "U": 1737949109, "u": 1737949130, "b": [["0.02820700", "24.00000000"], ["0.02820600", "0.00000000"], ["0.02820500", "0.18700000"], ["0.02819500", "2.26400000"], ["0.02818900", "11.93600000"], ["0.02815000", "150.00000000"], ["0.02814500", "0.25300000"], ["0.02762000", "1.13100000"]], "a": [["0.02821300", "1.72700000"], ["0.02821500", "1.71300000"], ["0.02823300", "66.42200000"]]}, {"e": "depthUpdate", "E": 1604224826323, "s": "ETHBTC", "U": 1737949131, "u": 1737949157, "b": [["0.02820500", "0.10200000"], ["0.02819800", "6.41300000"], ["0.02818100", "9.44900000"], ["0.02817700", "26.16100000"], ["0.02817500", "0.00000000"], ["0.02815000", "150.10000000"], ["0.02809800", "0.04000000"], ["0.02792100", "0.00000000"], ["0.02763400", "0.17800000"], ["0.02708300", "0.00000000"]], "a": []}, {"e": "depthUpdate", "E": 1604224827323, "s": "ETHBTC", "U": 1737949158, "u": 1737949187, "b": [["0.02820500", "0.21300000"], ["0.02818200", "0.00800000"], ["0.02818100", "32.26100000"], ["0.02816500", "0.00400000"], ["0.02815000", "150.00000000"], ["0.02814400", "0.01000000"], ["0.02814200", "30.10000000"], ["0.02807800", "2.08400000"], ["0.02805200", "21.15200000"], ["0.02804800", "0.00000000"], ["0.02787200", "0.01600000"], ["0.02624500", "0.00000000"]], "a": [["0.02821200", "4.02800000"], ["0.02821700", "0.00000000"], ["0.02822600", "18.79600000"], ["0.02823000", "48.34800000"], ["0.02823300", "25.93100000"], ["0.02823700", "3.54500000"], ["0.02839900", "0.28000000"], ["0.02840700", "16.85500000"], ["0.02998000", "5.05900000"]]}, {"e": "depthUpdate", "E": 1604224828323, "s": "ETHBTC", "U": 1737949188, "u": 1737949239, "b": [["0.02820800", "0.00000000"], ["0.02820700", "0.00000000"], ["0.02820600", "30.00000000"], ["0.02820500", "0.00000000"], ["0.02820400", "24.24100000"], ["0.02820300", "0.00000000"], ["0.02819800", "10.41300000"], ["0.02818200", "7.10300000"], ["0.02817900", "6.74700000"], ["0.02817700", "24.81000000"], ["0.02816500", "0.00000000"], ["0.02814200", "30.00000000"], ["0.02792600", "2.01200000"], ["0.02708800", "0.07900000"], ["0.02625000", "27.60100000"], ["0.01410100", "0.20000000"]], "a": [["0.02820700", "0.00000000"], ["0.02820900", "5.93400000"], ["0.02821000", "25.74200000"], ["0.02821100", "0.00000000"], ["0.02821200", "15.02800000"], ["0.02821300", "0.00000000"], ["0.02821500", "9.71300000"], ["0.02822200", "22.99200000"], ["0.02822300", "9.24000000"], ["0.02822400", "15.60100000"], ["0.02822500", "0.50700000"], ["0.02998000", "6.18600000"]]}, {"e": "depthUpdate", "E": 1604224829324, "s": "ETHBTC", "U": 1737949240, "u": 1737949276, "b": [["0.02820400", "24.22100000"], ["0.02820200", "0.00000000"], ["0.02818800", "51.15000000"], ["0.02818600", "26.61100000"], ["0.02818500", "13.27100000"], ["0.02818200", "0.00800000"], ["0.02818100", "4.04700000"], ["0.02811800", "0.00000000"], ["0.01410100", "0.00000000"]], "a": [["0.02820900", "5.80900000"], ["0.02822100", "18.10000000"], ["0.02822500", "0.00500000"], ["0.02822900", "5.40200000"], ["0.02823200", "0.00000000"], ["0.02823300", "3.12400000"]]}, {"e": "depthUpdate", "E": 1604224830324, "s": "ETHBTC", "U": 1737949277, "u": 1737949310, "b": [["0.02820800", "24.00000000"], ["0.02820700", "6.80600000"], ["0.02820600", "24.00000000"], ["0.02820500", "0.27900000"], ["0.02820400", "24.00000000"], ["0.02818800", "53.84800000"], ["0.02818500", "10.57300000"], ["0.02818200", "0.00800000"], ["0.02817800", "5.41200000"], ["0.02817700", "19.40800000"]], "a": [["0.02820900", "5.65700000"], ["0.02821000", "25.74200000"], ["0.02821100", "0.18600000"], ["0.02821200", "11.06800000"], ["0.02821700", "3.96000000"], ["0.02821800", "0.50300000"], ["0.02822900", "0.00000000"], ["0.02823500", "15.27600000"]]}, {"e": "depthUpdate", "E": 1604224831324, "s": "ETHBTC", "U": 1737949311, "u": 1737949397, "b": [["0.02820800", "0.00000000"], ["0.02820700", "0.00000000"], ["0.02820600", "0.00000000"], ["0.02820500", "0.00000000"], ["0.02820400", "0.00000000"], ["0.02820100", "6.00000000"], ["0.02820000", "0.81100000"], ["0.02819800", "0.39800000"], ["0.02819700", "5.83200000"], ["0.02819600", "0.00000000"], ["0.02819500", "0.00000000"], ["0.02819400", "5.18100000"], ["0.02819300", "4.00000000"], ["0.02819200", "16.35500000"], ["0.02819000", "3.90800000"], ["0.02818900", "6.48300000"], ["0.02818800", "2.69800000"], ["0.02818700", "6.41600000"], ["0.02818600", "33.03400000"], ["0.02818500", "5.40200000"], ["0.02818300", "1.70900000"], ["0.02818200", "7.10100000"], ["0.02813800", "7.20700000"], ["0.02707300", "7.21600000"], ["0.02680700", "0.01100000"], ["0.02642300", "0.00900000"]], "a": [["0.02820200", "24.00000000"], ["0.02820300", "4.10500000"], ["0.02820400", "0.00000000"], ["0.02820500", "4.00000000"], ["0.02820600", "24.00000000"], ["0.02820700", "7.84000000"], ["0.02820800", "14.91500000"], ["0.02820900", "128.00000000"], ["0.02821000", "1.74200000"], ["0.02821100", "0.00000000"], ["0.02821200", "0.06800000"], ["0.02821500", "1.71300000"], ["0.02821600", "0.01000000"], ["0.02821700", "5.25000000"], ["0.02821800", "0.00000000"], ["0.02821900", "0.00000000"], ["0.02822000", "11.95000000"], ["0.02822200", "63.54200000"], ["0.02822300", "5.16700000"], ["0.02822800", "22.81200000"]]}, {"e": "depthUpdate", "E": 1604224832324, "s": "ETHBTC", "U": 1737949398, "u": 1737949445, "b": [["0.02820100", "56.31100000"], ["0.02820000", "0.00000000"], ["0.02819900", "0.00000000"], ["0.02819800", "0.12400000"], ["0.02819700", "5.94900000"], ["0.02819100", "7.09200000"], ["0.02818700", "11.59700000"], ["0.02818600", "28.52300000"], ["0.02818400", "12.94100000"], ["0.02818000", "10.93200000"], ["0.02817800", "0.01000000"], ["0.02817200", "14.46600000"], ["0.02815700", "0.00000000"], ["0.02815200", "63.94300000"], ["0.02814900", "0.01000000"], ["0.02680800", "13.97900000"]], "a": [["0.02820200", "91.00000000"], ["0.02820300", "0.00000000"], ["0.02820400", "0.00000000"], ["0.02820600", "24.15200000"], ["0.02820700", "7.84000000"], ["0.02820800", "0.00000000"], ["0.02820900", "24.00000000"], ["0.02821300", "4.00000000"], ["0.02822000", "26.86500000"], ["0.02823200", "7.08900000"], ["0.02998000", "5.05900000"]]}, {"e": "depthUpdate", "E": 1604224833324, "s": "ETHBTC", "U": 1737949446, "u": 1737949529, "b": [["0.02820300", "0.00000000"], ["0.02820200", "6.00000000"], ["0.02820100", "47.52800000"], ["0.02820000", "24.27500000"], ["0.02819900", "0.00000000"], ["0.02819800", "0.12400000"], ["0.02819700", "5.83200000"], ["0.02816100", "14.84000000"], ["0.02815300", "2.01000000"], ["0.02815100", "49.65800000"], ["0.02813100", "0.00000000"]], "a": [["0.02820100", "0.00000000"], ["0.02820200", "0.00000000"], ["0.02820300", "115.43200000"], ["0.02820400", "0.00000000"], ["0.02820500", "4.00000000"], ["0.02820600", "24.00000000"], ["0.02820900", "24.29400000"], ["0.02821300", "11.58900000"], ["0.02821400", "27.85900000"], ["0.02821600", "4.08300000"], ["0.02821800", "0.00000000"], ["0.02821900", "35.85100000"], ["0.02822000", "11.95000000"], ["0.02822200", "43.29600000"], ["0.02822400", "0.00000000"], ["0.02822500", "40.50500000"], ["0.02823000", "7.85700000"], ["0.02823100", "4.57900000"], ["0.02823200", "0.00000000"], ["0.02823600", "58.86300000"], ["0.02998000", "6.18600000"]]}, {"e": "depthUpdate", "E": 1604224834324, "s": "ETHBTC", "U": 1737949530, "u": 1737949541, "b": [["0.02818800", "8.70900000"], ["0.02818500", "10.56100000"], ["0.02817700", "42.22000000"]], "a": [["0.02820300", "91.43200000"], ["0.02820900", "24.16900000"], ["0.02821000", "1.72700000"], ["0.02821300", "11.58900000"], ["0.02821400", "12.94400000"], ["0.02821800", "14.91500000"], ["0.02823000", "9.21600000"]]}, {"e": "depthUpdate", "E": 1604224835324, "s": "ETHBTC", "U": 1737949542, "u": 1737949564, "b": [["0.02820200", "53.50000000"], ["0.02820100", "24.00000000"], ["0.02819100", "7.09200000"], ["0.02818800", "20.85200000"], ["0.02818600", "16.38000000"], ["0.02818200", "0.00800000"]], "a": [["0.02820300", "0.01500000"], ["0.02820500", "5.92100000"], ["0.02820700", "0.00000000"], ["0.02821000", "0.00000000"], ["0.02821100", "1.72700000"], ["0.02821200", "4.02800000"], ["0.02821400", "16.82100000"], ["0.02821500", "6.21600000"], ["0.02822300", "6.51600000"], ["0.02823800", "0.02800000"]]}, {"e": "depthUpdate", "E": 1604224836324, "s": "ETHBTC", "U": 1737949565, "u": 1737949589, "b": [["0.02820000", "0.00000000"], ["0.02819800", "0.22600000"], ["0.02819300", "4.00000000"], ["0.02818200", "0.10800000"], ["0.02707300", "0.00000000"]], "a": [["0.02820300", "112.01500000"], ["0.02820500", "5.92100000"], ["0.02820900", "0.00000000"], ["0.02821900", "15.60100000"], ["0.02822500", "0.00500000"], ["0.02857800", "4.49800000"], ["0.02858400", "4.51200000"], ["0.02998000", "5.05900000"]]}, {"e": "depthUpdate", "E": 1604224837325, "s": "ETHBTC", "U": 1737949590, "u": 1737949635, "b": [["0.02820200", "28.34200000"], ["0.02820000", "0.11300000"], ["0.02819800", "0.12400000"], ["0.02818300", "1.71300000"], ["0.02818200", "0.00800000"], ["0.02800000", "111.18400000"], ["0.02799300", "0.01000000"]], "a": [["0.02820300", "28.45700000"], ["0.02820500", "0.13000000"], ["0.02820900", "11.00000000"], ["0.02822400", "20.25000000"], ["0.02822800", "22.81200000"], ["0.02823200", "40.52800000"], ["0.02833200", "0.00000000"], ["0.02998000", "6.18600000"]]}, {"e": "depthUpdate", "E": 1604224838324, "s": "ETHBTC", "U": 1737949636, "u": 1737949674, "b": [["0.02820200", "52.28200000"], ["0.02819400", "6.79800000"], ["0.02818300", "1.70900000"], ["0.02817300", "0.00000000"], ["0.02816200", "7.09900000"], ["0.02807800", "1.67100000"]], "a": [["0.02820300", "3.97500000"], ["0.02820500", "5.86100000"], ["0.02821200", "0.06800000"], ["0.02822400", "20.25000000"], ["0.02822800", "34.95500000"], ["0.02823600", "46.72000000"], ["0.03637400", "0.00000000"]]}, {"e": "depthUpdate", "E": 1604224839324, "s": "ETHBTC", "U": 1737949675, "u": 1737949727, "b": [["0.02820200", "0.00000000"], ["0.02820100", "29.50000000"], ["0.02820000", "0.00000000"], ["0.02819900", "0.00000000"], ["0.02819800", "0.39300000"], ["0.02819700", "5.83200000"], ["0.02819400", "5.18100000"], ["0.02816700", "0.00000000"], ["0.02816200", "0.00000000"], ["0.02813700", "0.00000000"], ["0.02806000", "0.41300000"], ["0.02805200", "0.12000000"], ["0.02804700", "21.10200000"]], "a": [["0.02820200", "5.80400000"], ["0.02820300", "24.01500000"], ["0.02820400", "4.00000000"], ["0.02820500", "4.00000000"], ["0.02820600", "24.00000000"], ["0.02820700", "0.20300000"], ["0.02820800", "1.72700000"], ["0.02821100", "0.00000000"], ["0.02821300", "11.54900000"], ["0.02821500", "2.21600000"], ["0.02839900", "16.28000000"], ["0.02840700", "0.85500000"], ["0.03637400", "0.00300000"]]}, {"e": "depthUpdate", "E": 1604224840324, "s": "ETHBTC", "U": 1737949728, "u": 1737949764, "b": [["0.02820100", "53.50000000"], ["0.02820000", "0.00000000"], ["0.02819900", "0.00000000"], ["0.02819800", "0.41600000"], ["0.02819700", "0.00000000"], ["0.02818800", "11.84300000"], ["0.02818600", "13.67900000"], ["0.02818500", "5.15900000"], ["0.02818300", "4.40800000"], ["0.02818200", "2.70900000"], ["0.02817600", "58.03800000"], ["0.02815700", "7.10000000"], ["0.02680800", "13.97900000"]], "a": [["0.02820200", "117.80400000"], ["0.02820400", "7.96000000"], ["0.02821300", "7.58900000"]]}, {"e": "depthUpdate", "E": 1604224841324, "s": "ETHBTC", "U": 1737949765, "u": 1737949797, "b": [["0.02819800", "0.12400000"], ["0.02815700", "0.00000000"], ["0.02790600", "0.05800000"], ["0.02789900", "0.09000000"]], "a": [["0.02820200", "5.80400000"], ["0.02820300", "0.01500000"], ["0.02820400", "0.00000000"], ["0.02820500", "0.00000000"], ["0.02821200", "4.02800000"], ["0.02821500", "10.21600000"], ["0.02823500", "5.40200000"], ["0.02824100", "17.75500000"], ["0.02998000", "5.05900000"]]}, {"e": "depthUpdate", "E": 1604224842324, "s": "ETHBTC", "U": 1737949798, "u": 1737949859, "b": [["0.02820200", "52.94000000"], ["0.02820100", "24.00000000"], ["0.02820000", "0.15300000"], ["0.02819900", "0.00000000"], ["0.02819800", "0.12400000"], ["0.02819700", "5.83200000"], ["0.02819600", "4.00000000"], ["0.02819500", "6.79800000"], ["0.02819300", "0.00000000"], ["0.02818800", "6.01100000"], ["0.02818700", "6.41600000"], ["0.02818500", "10.55700000"], ["0.02817900", "1.35000000"], ["0.02816200", "0.00000000"], ["0.02777900", "0.15000000"], ["0.02775900", "0.83500000"]], "a": [["0.02820200", "0.00000000"], ["0.02820300", "137.96900000"], ["0.02820500", "3.96000000"], ["0.02820700", "0.00000000"], ["0.02820800", "11.00000000"], ["0.02820900", "11.00000000"], ["0.02821200", "0.06800000"], ["0.02821300", "22.50400000"], ["0.02821800", "0.00000000"], ["0.02822100", "18.10000000"], ["0.02822400", "0.00000000"], ["0.02822500", "20.26900000"], ["0.02998000", "6.18600000"]]}, {"e": "depthUpdate", "E": 1604224843324, "s": "ETHBTC", "U": 1737949860, "u": 1737949890, "b": [["0.02820000", "0.00000000"], ["0.02818900", "4.21900000"], ["0.02818600", "15.94300000"], ["0.02817300", "7.09600000"], ["0.02806000", "0.00000000"]], "a": [["0.02820400", "0.00000000"], ["0.02820500", "0.00000000"], ["0.02821200", "3.96000000"], ["0.02821300", "22.50400000"], ["0.02822600", "59.32500000"], ["0.02823200", "0.00000000"], ["0.02824500", "0.00000000"]]}, {"e": "depthUpdate", "E": 1604224844324, "s": "ETHBTC", "U": 1737949891, "u": 1737949927, "b": [["0.02820000", "3.54600000"], ["0.02819900", "0.25600000"], ["0.02817900", "2.69900000"], ["0.02817300", "7.09600000"], ["0.02817200", "13.11700000"], ["0.02805600", "0.41700000"], ["0.02789400", "0.00000000"]], "a": [["0.02820300", "0.01500000"], ["0.02820400", "0.28300000"], ["0.02820500", "5.96000000"], ["0.02821300", "22.50400000"], ["0.02822300", "9.21700000"], ["0.02823000", "6.51500000"], ["0.02825000", "150.12400000"]]}, {"e": "depthUpdate", "E": 1604224845325, "s": "ETHBTC", "U": 1737949928, "u": 1737949965, "b": [["0.02820200", "30.00000000"], ["0.02820100", "0.00000000"], ["0.02820000", "3.81000000"], ["0.02819900", "12.94100000"], ["0.02819700", "0.00000000"], ["0.02819300", "0.00000000"], ["0.02818800", "11.84300000"], ["0.02818400", "0.00000000"], ["0.02817300", "0.00000000"]], "a": [["0.02820300", "140.50200000"], ["0.02820400", "0.00000000"], ["0.02820500", "0.23600000"], ["0.02820700", "1.72700000"], ["0.02822900", "5.40300000"], ["0.02823500", "0.00000000"]]}, {"e": "depthUpdate", "E": 1604224846324, "s": "ETHBTC", "U": 1737949966, "u": 1737950049, "b": [["0.02820200", "0.00000000"], ["0.02820100", "6.00000000"], ["0.02820000", "3.54600000"], ["0.02819900", "0.00000000"], ["0.02819800", "0.12400000"], ["0.02819600", "0.00000000"], ["0.02819500", "0.00000000"], ["0.02819200", "12.94400000"], ["0.02819100", "0.00000000"], ["0.02819000", "4.00000000"], ["0.02818800", "31.87600000"], ["0.02818500", "5.39800000"], ["0.02818400", "7.09300000"], ["0.02818200", "6.12000000"], ["0.02818100", "7.95500000"], ["0.02817700", "19.40800000"], ["0.02816300", "0.00000000"], ["0.02812200", "0.00000000"], ["0.02791700", "3.72800000"], ["0.02623800", "1.14300000"]], "a": [["0.02820200", "97.82100000"], ["0.02820300", "24.01500000"], ["0.02820400", "0.14100000"], ["0.02820500", "0.50600000"], ["0.02820700", "0.00000000"], ["0.02820800", "0.00000000"], ["0.02820900", "0.00000000"], ["0.02821200", "4.00000000"], ["0.02821300", "7.58900000"], ["0.02821400", "12.94400000"], ["0.02821500", "1.71300000"], ["0.02821800", "0.00000000"], ["0.02821900", "30.51600000"], ["0.02822100", "5.16000000"], ["0.02998000", "6.18600000"]]}, {"e": "depthUpdate", "E": 1604224847325, "s": "ETHBTC", "U": 1737950050, "u": 1737950093, "b": [["0.02819900", "0.10900000"], ["0.02819500", "15.00000000"], ["0.02819300", "0.00000000"], ["0.02819200", "16.35500000"], ["0.02819000", "3.90800000"], ["0.02818600", "21.12300000"], ["0.02818200", "2.70900000"], ["0.02818100", "4.04700000"], ["0.02817500", "0.00400000"], ["0.02817300", "5.40300000"], ["0.02817200", "7.71500000"], ["0.02815100", "8.65800000"], ["0.02810300", "21.07300000"], ["0.02810200", "0.83600000"], ["0.02706700", "7.73100000"], ["0.02680800", "13.97900000"]], "a": [["0.02820200", "147.53800000"], ["0.02820300", "24.01500000"], ["0.02820400", "0.00000000"], ["0.02820500", "0.50600000"], ["0.02820600", "35.00000000"], ["0.02820800", "12.94200000"], ["0.02821100", "8.20800000"], ["0.02821200", "8.00000000"], ["0.02821800", "14.91500000"], ["0.02821900", "15.60100000"], ["0.02822000", "27.89100000"], ["0.02822500", "0.00500000"]]}, {"e": "depthUpdate", "E": 1604224848325, "s": "ETHBTC", "U": 1737950094, "u": 1737950125, "b": [["0.02819900", "0.00000000"], ["0.02819500", "11.16000000"], ["0.02819200", "12.94400000"], ["0.02819000", "7.90800000"], ["0.02818400", "12.25100000"], ["0.02818300", "7.81900000"], ["0.02817600", "58.03800000"], ["0.02817500", "0.00000000"], ["0.02816000", "0.00000000"], ["0.02810200", "0.18300000"], ["0.02791800", "0.35700000"]], "a": [["0.02820300", "24.29800000"], ["0.02820400", "4.24800000"], ["0.02820500", "0.50600000"], ["0.02821200", "4.00000000"], ["0.02821800", "14.91500000"]]}, {"e": "depthUpdate", "E": 1604224849325, "s": "ETHBTC", "U": 1737950126, "u": 1737950141, "b": [["0.02819500", "11.00000000"], ["0.02819400", "5.30100000"], ["0.02818800", "25.86500000"], ["0.02817900", "2.70000000"], ["0.02817800", "6.02200000"], ["0.02817300", "5.40300000"], ["0.02812900", "0.00000000"]], "a": [["0.02821800", "14.91500000"], ["0.02822200", "83.81900000"], ["0.02822600", "18.79600000"]]}, {"e": "depthUpdate", "E": 1604224850326, "s": "ETHBTC", "U": 1737950142, "u": 1737950177, "b": [["0.02819900", "0.29700000"], ["0.02819600", "0.00000000"], ["0.02819500", "11.00000000"], ["0.02819400", "5.18100000"], ["0.02819300", "3.41100000"], ["0.02818800", "18.77300000"], ["0.02818400", "7.09300000"], ["0.02818300", "4.40800000"], ["0.02817900", "25.51200000"], ["0.02817700", "19.40800000"], ["0.02805600", "0.00400000"], ["0.02805100", "0.42100000"], ["0.02792800", "0.62800000"], ["0.02706700", "14.94900000"]], "a": [["0.02820200", "141.85100000"], ["0.02820300", "24.29800000"], ["0.02820400", "4.00000000"], ["0.02820500", "0.50600000"], ["0.02820600", "35.00000000"], ["0.02820700", "3.96000000"], ["0.02821800", "0.00000000"], ["0.02821900", "30.51600000"], ["0.02822300", "6.51600000"], ["0.02822800", "37.65700000"], ["0.02998000", "5.05900000"]]}, {"e": "depthUpdate", "E": 1604224851325, "s": "ETHBTC", "U": 1737950178, "u": 1737950192, "b": [["0.02819900", "0.00000000"], ["0.02819400", "6.83400000"], ["0.02819300", "3.67200000"], ["0.02818900", "0.00000000"], ["0.02818400", "12.34200000"], ["0.02818200", "6.92900000"], ["0.02817900", "2.70000000"]], "a": [["0.02820400", "4.17100000"], ["0.02821800", "35.17400000"], ["0.02821900", "15.60100000"], ["0.02822000", "7.62800000"], ["0.02998000", "6.18600000"]]}, {"e": "depthUpdate", "E": 1604224852325, "s": "ETHBTC", "U": 1737950193, "u": 1737950217, "b": [["0.02820100", "30.00000000"], ["0.02819600", "4.00000000"], ["0.02819400", "5.18100000"], ["0.02819300", "3.41100000"], ["0.02819200", "12.94400000"], ["0.02819100", "7.09200000"], ["0.02819000", "3.90800000"], ["0.02817100", "0.00000000"]], "a": [["0.02820200", "117.85100000"], ["0.02821200", "18.91500000"], ["0.02821800", "0.00000000"], ["0.02822300", "26.77500000"]]}, {"e": "depthUpdate", "E": 1604224853326, "s": "ETHBTC", "U": 1737950218, "u": 1737950262, "b": [["0.02820100", "3.00000000"], ["0.02820000", "0.00000000"], ["0.02819800", "0.00000000"], ["0.02819700", "0.26600000"], ["0.02819600", "0.00000000"], ["0.02819500", "11.00000000"], ["0.02819400", "5.18100000"], ["0.02819100", "4.00000000"], ["0.02818900", "0.00000000"], ["0.02817900", "25.51200000"], ["0.02817800", "0.01000000"]], "a": [["0.02820200", "144.85100000"], ["0.02820300", "24.29800000"], ["0.02821200", "4.00000000"], ["0.02821800", "17.61400000"], ["0.02822200", "40.59800000"], ["0.02822300", "26.77500000"], ["0.02822600", "59.31700000"], ["0.02822800", "25.51400000"]]}, {"e": "depthUpdate", "E": 1604224854326, "s": "ETHBTC", "U": 1737950263, "u": 1737950402, "b": [["0.02820100", "0.00000000"], ["0.02820000", "0.00000000"], ["0.02819900", "0.00000000"], ["0.02819800", "0.00000000"], ["0.02819700", "0.00000000"], ["0.02819600", "0.00000000"], ["0.02819500", "47.50000000"], ["0.02819400", "1.77400000"], ["0.02819300", "0.26000000"], ["0.02819200", "12.94400000"], ["0.02819100", "0.00000000"], ["0.02819000", "0.00000000"], ["0.02818900", "5.17800000"], ["0.02818700", "8.34000000"], ["0.02818600", "14.70000000"], ["0.02818400", "3.41100000"], ["0.02818300", "2.69900000"], ["0.02818100", "7.95500000"], ["0.02818000", "14.93200000"], ["0.02817900", "1.34900000"], ["0.02817800", "1.74300000"], ["0.02817700", "15.08000000"], ["0.02817400", "1.35100000"], ["0.02817300", "5.40300000"], ["0.02817200", "12.04400000"], ["0.02737100", "0.00000000"]], "a": [["0.02819600", "0.00000000"], ["0.02819700", "0.00000000"], ["0.02819800", "3.96000000"], ["0.02819900", "8.85300000"], ["0.02820000", "27.00000000"], ["0.02820100", "0.00000000"], ["0.02820200", "0.00000000"], ["0.02820300", "0.56400000"], ["0.02820400", "0.00000000"], ["0.02820600", "0.00000000"], ["0.02820700", "1.73700000"], ["0.02820800", "0.00000000"], ["0.02820900", "14.91500000"], ["0.02821000", "37.45000000"], ["0.02821100", "4.32700000"], ["0.02821300", "11.58900000"], ["0.02821500", "0.00000000"], ["0.02821600", "5.17500000"], ["0.02821800", "2.69900000"], ["0.02822100", "0.00000000"], ["0.02822300", "41.06000000"], ["0.02822400", "12.14400000"], ["0.02822600", "17.44500000"], ["0.02822800", "2.70200000"], ["0.02823900", "0.00000000"], ["0.03957900", "0.00000000"]]}, {"e": "depthUpdate", "E": 1604224855325, "s": "ETHBTC", "U": 1737950403, "u": 1737950505, "b": [["0.02820200", "28.43700000"], ["0.02820100", "0.00000000"], ["0.02820000", "0.00000000"], ["0.02819900", "0.00000000"], ["0.02819800", "5.83200000"], ["0.02819700", "23.50000000"], ["0.02819600", "3.51800000"], ["0.02819500", "24.00000000"], ["0.02819400", "0.12800000"], ["0.02819300", "7.90800000"], ["0.02819100", "6.43000000"], ["0.02819000", "7.09200000"], ["0.02818800", "12.94100000"], ["0.02818700", "12.58300000"], ["0.02818600", "7.25600000"], ["0.02818400", "0.00000000"], ["0.02818300", "17.43000000"], ["0.02818100", "4.04700000"], ["0.02818000", "10.93200000"], ["0.02817800", "2.27400000"], ["0.02817600", "40.49100000"], ["0.02817100", "14.80800000"], ["0.02816100", "0.00000000"], ["0.02813200", "0.10000000"], ["0.02786800", "0.00000000"]], "a": [["0.02819800", "0.00000000"], ["0.02819900", "0.00000000"], ["0.02820000", "0.00000000"], ["0.02820200", "0.00000000"], ["0.02820300", "144.86800000"], ["0.02820400", "0.00000000"], ["0.02820500", "0.00000000"], ["0.02820700", "0.00000000"], ["0.02820900", "0.00000000"], ["0.02821000", "0.00000000"], ["0.02821100", "0.00000000"], ["0.02821200", "24.63200000"], ["0.02821300", "15.66100000"], ["0.02821600", "0.01000000"], ["0.02821700", "4.32900000"], ["0.02822100", "0.00000000"], ["0.02822400", "12.14400000"], ["0.02823000", "47.03100000"], ["0.02823400", "7.09900000"], ["0.02823500", "3.12100000"]]}, {"e": "depthUpdate", "E": 1604224856325, "s": "ETHBTC", "U": 1737950506, "u": 1737950555, "b": [["0.02820200", "51.93700000"], ["0.02820000", "0.13000000"], ["0.02819900", "4.00000000"], ["0.02819700", "0.00000000"], ["0.02819500", "24.00000000"], ["0.02819300", "10.99900000"], ["0.02818700", "18.59200000"], ["0.02818600", "9.02000000"], ["0.02818400", "2.26400000"], ["0.02817800", "0.01000000"], ["0.02795300", "3.05700000"]], "a": [["0.02820300", "120.85300000"], ["0.02820500", "0.00000000"], ["0.02820600", "0.00000000"], ["0.02820700", "0.11100000"], ["0.02821100", "4.39000000"], ["0.02821200", "24.63200000"], ["0.02822400", "0.00000000"], ["0.02822500", "22.81700000"], ["0.02822800", "6.24800000"], ["0.02823200", "12.14400000"], ["0.02823400", "0.01000000"], ["0.02823600", "50.94000000"], ["0.02823700", "0.00000000"], ["0.02824300", "0.00000000"], ["0.02857800", "0.04300000"], ["0.02998000", "6.18600000"], ["0.03956600", "0.08600000"]]}, {"e": "depthUpdate", "E": 1604224857325, "s": "ETHBTC", "U": 1737950556, "u": 1737950667, "b": [["0.02820200", "0.00000000"], ["0.02820100", "0.00000000"], ["0.02820000", "0.00000000"], ["0.02819900", "0.00000000"], ["0.02819800", "0.00000000"], ["0.02819700", "0.00000000"], ["0.02819600", "0.10700000"], ["0.02819400", "0.00000000"], ["0.02819300", "0.17500000"], ["0.02819100", "11.00000000"], ["0.02819000", "0.00000000"], ["0.02818900", "15.01000000"], ["0.02818700", "9.08900000"], ["0.02818600", "12.43100000"], ["0.02818400", "10.20900000"], ["0.02818100", "0.00000000"], ["0.02817500", "0.00400000"], ["0.02787100", "37.47600000"]], "a": [["0.02819800", "5.82500000"], ["0.02819900", "24.27900000"], ["0.02820000", "7.00000000"], ["0.02820100", "3.96000000"], ["0.02820200", "136.00000000"], ["0.02820300", "35.01500000"], ["0.02820400", "0.26700000"], ["0.02820600", "0.00000000"], ["0.02820700", "0.00000000"], ["0.02821000", "40.57000000"], ["0.02821100", "14.91500000"], ["0.02821200", "5.75700000"], ["0.02821300", "11.66100000"], ["0.02821800", "2.69900000"], ["0.02821900", "35.85700000"], ["0.02822100", "0.00000000"], ["0.02822300", "20.80100000"], ["0.02822500", "28.21900000"], ["0.02822700", "8.26500000"], ["0.02857800", "4.37200000"]]}, {"e": "depthUpdate", "E": 1604224858325, "s": "ETHBTC", "U": 1737950668, "u": 1737950711, "b": [["0.02819700", "61.47200000"], ["0.02819600", "24.00000000"], ["0.02819500", "0.00000000"], ["0.02819400", "0.14600000"], ["0.02819300", "0.00000000"], ["0.02819100", "0.00000000"], ["0.02818800", "14.50700000"], ["0.02818600", "10.66700000"], ["0.02818300", "23.85800000"], ["0.02818100", "1.61100000"], ["0.02818000", "18.02600000"], ["0.02817600", "63.30300000"], ["0.02817500", "0.00000000"]], "a": [["0.02819700", "0.00000000"], ["0.02819800", "8.82500000"], ["0.02819900", "24.00000000"], ["0.02820000", "0.00000000"], ["0.02820100", "0.00000000"], ["0.02820700", "3.96000000"], ["0.02820800", "3.89800000"], ["0.02820900", "22.91500000"], ["0.02821100", "0.00000000"], ["0.02821200", "1.75700000"], ["0.02821700", "4.32900000"], ["0.02822100", "4.03100000"], ["0.02822600", "13.39700000"]]}, {"e": "depthUpdate", "E": 1604224859325, "s": "ETHBTC", "U": 1737950712, "u": 1737950772, "b": [["0.02819900", "61.47200000"], ["0.02819800", "0.00000000"], ["0.02819700", "24.00000000"], ["0.02819600", "0.00000000"], ["0.02819500", "0.00000000"], ["0.02819200", "13.11300000"], ["0.02819100", "0.00000000"], ["0.02818800", "12.94100000"], ["0.02817700", "15.08000000"]], "a": [["0.02819800", "0.00000000"], ["0.02819900", "0.00000000"], ["0.02820000", "97.89400000"], ["0.02820100", "0.00000000"], ["0.02820200", "24.20100000"], ["0.02820300", "0.01500000"], ["0.02820900", "8.00000000"], ["0.02821200", "16.67200000"], ["0.02821300", "11.66100000"], ["0.02821600", "5.17400000"], ["0.02822100", "0.00000000"], ["0.02822400", "4.02800000"]]}, {"e": "depthUpdate", "E": 1604224860326, "s": "ETHBTC", "U": 1737950773, "u": 1737950824, "b": [["0.02819900", "60.92300000"], ["0.02819400", "0.00000000"], ["0.02819200", "12.94400000"], ["0.02819000", "8.32500000"], ["0.02813200", "0.00000000"], ["0.02811700", "0.00400000"], ["0.02806200", "0.00500000"]], "a": [["0.02820000", "4.00000000"], ["0.02820100", "0.00000000"], ["0.02820200", "0.24300000"], ["0.02820700", "0.00000000"], ["0.02820900", "8.00000000"], ["0.02821000", "0.00000000"], ["0.02821200", "20.63200000"], ["0.02822000", "7.62800000"], ["0.02822400", "44.54400000"], ["0.02823000", "6.51500000"], ["0.02998000", "5.05900000"]]}, {"e": "depthUpdate", "E": 1604224861326, "s": "ETHBTC", "U": 1737950825, "u": 1737950902, "b": [["0.02820200", "61.47200000"], ["0.02820100", "0.00000000"], ["0.02820000", "24.00000000"], ["0.02819900", "27.45100000"], ["0.02819800", "5.96500000"], ["0.02819700", "1.14600000"], ["0.02819500", "0.00000000"], ["0.02819300", "10.99900000"], ["0.02819200", "14.51000000"], ["0.02819100", "0.00000000"], ["0.02819000", "0.00000000"], ["0.02818900", "12.27100000"], ["0.02818400", "6.30100000"], ["0.02818200", "2.70900000"], ["0.02818100", "0.00000000"], ["0.02818000", "10.93200000"], ["0.02817500", "0.00000000"]], "a": [["0.02820000", "0.00000000"], ["0.02820100", "0.00000000"], ["0.02820200", "0.00000000"], ["0.02820300", "0.01500000"], ["0.02820400", "1.00000000"], ["0.02820600", "0.29300000"], ["0.02821100", "0.00000000"], ["0.02821200", "5.71700000"], ["0.02821600", "0.01000000"], ["0.02821700", "4.32900000"], ["0.02821800", "17.61400000"], ["0.02822200", "45.75900000"], ["0.02822300", "19.45000000"], ["0.02822400", "0.00000000"], ["0.02822500", "5.40700000"], ["0.02823100", "45.09900000"], ["0.02823600", "46.72000000"], ["0.02998000", "6.18600000"]]}, {"e": "depthUpdate", "E": 1604224862326, "s": "ETHBTC", "U": 1737950903, "u": 1737951027, "b": [["0.02820700", "4.00000000"], ["0.02820600", "0.00000000"], ["0.02820500", "2.94900000"], ["0.02820400", "34.00000000"], ["0.02820300", "0.00000000"], ["0.02820200", "24.00000000"], ["0.02820100", "0.00000000"], ["0.02820000", "0.00000000"], ["0.02819900", "0.00000000"], ["0.02819700", "0.00000000"], ["0.02819400", "3.90800000"], ["0.02819300", "7.26400000"], ["0.02819200", "12.94400000"], ["0.02819100", "3.41100000"], ["0.02819000", "4.51200000"], ["0.02818900", "7.09300000"], ["0.02818800", "49.95100000"], ["0.02818600", "7.25600000"], ["0.02818400", "8.03800000"], ["0.02818300", "21.75800000"], ["0.02818000", "6.42300000"], ["0.02817600", "40.49100000"], ["0.02817200", "7.71500000"], ["0.02804900", "0.09900000"], ["0.02680800", "13.97900000"]], "a": [["0.02820300", "0.00000000"], ["0.02820400", "0.00000000"], ["0.02820500", "0.00000000"], ["0.02820600", "0.00000000"], ["0.02820800", "146.72400000"], ["0.02820900", "0.00000000"], ["0.02821100", "1.12400000"], ["0.02821200", "1.75700000"], ["0.02821300", "15.57100000"], ["0.02821500", "0.00000000"], ["0.02821700", "7.84700000"], ["0.02821800", "4.00000000"], ["0.02821900", "19.60100000"], ["0.02822100", "17.61300000"], ["0.02822200", "50.08900000"], ["0.02822300", "14.28300000"], ["0.02822600", "14.74800000"], ["0.02822700", "28.52000000"], ["0.02822800", "2.70200000"], ["0.02822900", "0.00000000"], ["0.02823100", "40.77000000"], ["0.02823300", "8.52600000"], ["0.02823700", "4.32800000"]]}, {"e": "depthUpdate", "E": 1604224863326, "s": "ETHBTC", "U": 1737951028, "u": 1737951092, "b": [["0.02820700", "0.00000000"], ["0.02820500", "2.81700000"], ["0.02820400", "0.00000000"], ["0.02820300", "0.00000000"], ["0.02820200", "25.00000000"], ["0.02820100", "0.00000000"], ["0.02819800", "10.11400000"], ["0.02819700", "1.90000000"], ["0.02819500", "5.17900000"], ["0.02819400", "10.99900000"], ["0.02819200", "15.20800000"], ["0.02819000", "16.12000000"], ["0.02818900", "13.10200000"], ["0.02818400", "5.77400000"], ["0.02811700", "0.00800000"], ["0.02805100", "0.00800000"], ["0.02804800", "21.03500000"], ["0.02804700", "0.06600000"]], "a": [["0.02820600", "143.63100000"], ["0.02820700", "0.00000000"], ["0.02820800", "26.25400000"], ["0.02820900", "1.00000000"], ["0.02821000", "4.00000000"], ["0.02821100", "0.00000000"], ["0.02821200", "0.00000000"], ["0.02821300", "4.57100000"], ["0.02821500", "1.73500000"], ["0.02821600", "3.97000000"], ["0.02821700", "3.88700000"], ["0.02821800", "4.00000000"], ["0.02821900", "0.00000000"], ["0.02822100", "17.61300000"], ["0.02822400", "5.12200000"], ["0.02822600", "30.34900000"], ["0.02822800", "14.84300000"], ["0.02823200", "0.00000000"], ["0.02857800", "0.04300000"]]}, {"e": "depthUpdate", "E": 1604224864326, "s": "ETHBTC", "U": 1737951093, "u": 1737951163, "b": [["0.02820500", "0.00000000"], ["0.02820200", "0.00000000"], ["0.02820000", "0.00000000"], ["0.02819900", "28.31200000"], ["0.02819800", "9.96500000"], ["0.02819700", "0.11500000"], ["0.02819600", "1.00000000"], ["0.02819400", "3.90800000"], ["0.02819300", "0.00000000"], ["0.02819000", "11.60800000"], ["0.02818300", "17.43000000"], ["0.02817000", "0.00000000"], ["0.02797900", "0.11200000"]], "a": [["0.02820000", "3.00000000"], ["0.02820100", "0.00000000"], ["0.02820200", "0.26800000"], ["0.02820300", "0.00000000"], ["0.02820400", "0.00000000"], ["0.02820500", "18.87500000"], ["0.02820600", "136.00000000"], ["0.02820800", "29.90400000"], ["0.02821400", "20.53000000"], ["0.02821600", "0.01000000"], ["0.02821700", "0.00000000"], ["0.02821900", "0.00000000"], ["0.02822100", "2.69800000"], ["0.02822600", "30.34900000"], ["0.02822800", "2.70200000"], ["0.02823000", "5.15600000"], ["0.02823300", "20.66700000"], ["0.02857300", "0.06600000"]]}, {"e": "depthUpdate", "E": 1604224865325, "s": "ETHBTC", "U": 1737951164, "u": 1737951220, "b": [["0.02820100", "0.00000000"], ["0.02820000", "0.00000000"], ["0.02819900", "24.00000000"], ["0.02819800", "9.96500000"], ["0.02819700", "0.00000000"], ["0.02819600", "0.00000000"], ["0.02819200", "14.60500000"], ["0.02819100", "10.50200000"], ["0.02818500", "9.89600000"], ["0.02818400", "6.30100000"], ["0.02817200", "12.04400000"], ["0.02805600", "0.41700000"], ["0.02798000", "0.31100000"]], "a": [["0.02820000", "0.00000000"], ["0.02820100", "3.00000000"], ["0.02820200", "0.00000000"], ["0.02820300", "0.00000000"], ["0.02820400", "24.00000000"], ["0.02820500", "3.96000000"], ["0.02820700", "0.19700000"], ["0.02820900", "0.00000000"], ["0.02821300", "19.48600000"], ["0.02821900", "0.00000000"], ["0.02822300", "19.67200000"], ["0.02822600", "28.98000000"], ["0.02823000", "7.03100000"], ["0.02857300", "0.00400000"], ["0.02857800", "4.47700000"], ["0.02998000", "5.05900000"]]}, {"e": "depthUpdate", "E": 1604224866325, "s": "ETHBTC", "U": 1737951221, "u": 1737951256, "b": [["0.02820100", "60.27500000"], ["0.02820000", "4.31200000"], ["0.02819900", "24.22200000"], ["0.02819800", "9.96500000"], ["0.02819600", "0.00000000"], ["0.02819200", "12.94400000"], ["0.02819100", "3.41100000"], ["0.02818000", "6.42300000"], ["0.02815500", "0.00000000"], ["0.02815200", "63.94300000"]], "a": [["0.02820000", "0.00000000"], ["0.02820100", "0.00000000"], ["0.02820200", "3.00000000"], ["0.02820300", "8.57500000"], ["0.02820500", "0.00000000"], ["0.02820600", "136.00000000"], ["0.02820700", "0.00000000"], ["0.02820800", "30.05000000"], ["0.02821000", "7.96000000"], ["0.02821100", "0.19500000"], ["0.02822700", "51.33200000"], ["0.02857800", "0.04300000"], ["0.02998000", "6.18600000"]]}, {"e": "depthUpdate", "E": 1604224867326, "s": "ETHBTC", "U": 1737951257, "u": 1737951298, "b": [["0.02820100", "59.65400000"], ["0.02819900", "24.26400000"], ["0.02819800", "5.96500000"], ["0.02819600", "0.00000000"], ["0.02819300", "4.00000000"], ["0.02818900", "13.10200000"], ["0.02818400", "9.22800000"], ["0.02818100", "1.62200000"], ["0.02817500", "0.00400000"], ["0.02815700", "2.26400000"]], "a": [["0.02820200", "3.00000000"], ["0.02820600", "136.00000000"], ["0.02820800", "6.02500000"], ["0.02820900", "0.00000000"], ["0.02821100", "0.00000000"], ["0.02821300", "4.57100000"], ["0.02821600", "14.92500000"], ["0.02821700", "20.26000000"], ["0.02821900", "0.00000000"], ["0.02822100", "2.69800000"], ["0.02822400", "5.12200000"], ["0.02822700", "31.07700000"], ["0.02822900", "40.52000000"], ["0.02823100", "0.25000000"]]}, {"e": "depthUpdate", "E": 1604224868325, "s": "ETHBTC", "U": 1737951299, "u": 1737951321, "b": [["0.02819900", "24.11900000"], ["0.02819800", "5.96500000"], ["0.02818900", "20.19500000"], ["0.02817900", "24.16100000"], ["0.02817500", "0.00000000"], ["0.02790800", "0.90900000"], ["0.02680800", "13.93300000"]], "a": [["0.02820300", "3.00000000"], ["0.02820400", "0.00000000"], ["0.02820900", "11.00000000"], ["0.02821300", "19.48600000"], ["0.02821500", "1.73500000"], ["0.02821600", "0.01000000"], ["0.02857800", "4.39100000"]]}, {"e": "depthUpdate", "E": 1604224869326, "s": "ETHBTC", "U": 1737951322, "u": 1737951352, "b": [["0.02820300", "60.00000000"], ["0.02820200", "0.00000000"], ["0.02820100", "26.83100000"], ["0.02820000", "0.00000000"], ["0.02819900", "24.00000000"], ["0.02818100", "0.00000000"], ["0.02817500", "5.40100000"], ["0.02817300", "0.00000000"], ["0.02808300", "0.00000000"], ["0.02791800", "0.46100000"], ["0.02680800", "13.97900000"]], "a": [["0.02820200", "0.00000000"], ["0.02820300", "0.00000000"], ["0.02820400", "3.34600000"], ["0.02820500", "5.49700000"], ["0.02820800", "5.90400000"], ["0.02821000", "4.12700000"], ["0.02821300", "4.57100000"], ["0.02821700", "3.96000000"], ["0.02821900", "0.00000000"], ["0.02822100", "17.61300000"], ["0.02822400", "25.38100000"]]}, {"e": "depthUpdate", "E": 1604224870326, "s": "ETHBTC", "U": 1737951353, "u": 1737951414, "b": [["0.02820400", "60.23200000"], ["0.02820300", "24.00000000"], ["0.02820200", "0.17300000"], ["0.02820100", "0.00000000"], ["0.02819900", "0.00000000"], ["0.02819800", "5.96500000"], ["0.02819600", "0.00000000"], ["0.02819400", "3.90800000"], ["0.02819000", "15.59600000"], ["0.02818900", "13.10200000"], ["0.02818700", "17.19200000"], ["0.02818300", "12.02800000"], ["0.02818200", "0.00800000"], ["0.02815700", "0.00000000"], ["0.02813900", "4.50000000"], ["0.02809800", "2.44700000"], ["0.02571900", "0.29400000"]], "a": [["0.02820400", "0.00000000"], ["0.02820500", "8.49700000"], ["0.02820600", "112.00000000"], ["0.02820800", "3.89900000"], ["0.02820900", "12.00000000"], ["0.02821000", "4.00000000"], ["0.02821100", "0.00000000"], ["0.02821400", "12.94400000"], ["0.02822300", "14.28300000"], ["0.02822700", "8.26500000"], ["0.02822800", "8.09800000"], ["0.02822900", "0.00000000"], ["0.02823300", "61.18600000"], ["0.02998000", "6.18600000"]]}, {"e": "depthUpdate", "E": 1604224871325, "s": "ETHBTC", "U": 1737951415, "u": 1737951453, "b": [["0.02820200", "1.00000000"], ["0.02819900", "4.00000000"], ["0.02819800", "6.08700000"], ["0.02819700", "3.54600000"], ["0.02819300", "7.09200000"], ["0.02819000", "18.29400000"], ["0.02818700", "26.66000000"], ["0.02818400", "9.22800000"], ["0.02818300", "0.00000000"], ["0.02815500", "0.00000000"], ["0.02380500", "0.03800000"]], "a": [["0.02820500", "119.47000000"], ["0.02820600", "0.00000000"], ["0.02820700", "0.22400000"], ["0.02820900", "1.00000000"], ["0.02821200", "0.00000000"], ["0.02821300", "4.57100000"]]}, {"e": "depthUpdate", "E": 1604224872326, "s": "ETHBTC", "U": 1737951454, "u": 1737951462, "b": [["0.02820400", "61.25800000"], ["0.02820300", "24.00000000"], ["0.02819800", "5.96500000"], ["0.02819600", "0.26800000"], ["0.02311500", "0.12600000"]], "a": [["0.02820500", "115.00000000"], ["0.02820600", "0.27800000"], ["0.02822700", "31.07700000"]]}, {"e": "depthUpdate", "E": 1604224873326, "s": "ETHBTC", "U": 1737951463, "u": 1737951491, "b": [["0.02820400", "3.23200000"], ["0.02820300", "25.02500000"], ["0.02820100", "0.29300000"], ["0.02819900", "0.00000000"], ["0.02819700", "14.54600000"], ["0.02819600", "0.00000000"], ["0.02819500", "6.90600000"], ["0.02819300", "0.00000000"], ["0.02819000", "19.59600000"], ["0.02818700", "14.51900000"], ["0.02817800", "0.01000000"], ["0.01413000", "0.09500000"]], "a": [["0.02820500", "136.00000000"], ["0.02820700", "4.18400000"], ["0.02820800", "14.89900000"], ["0.02821700", "0.00000000"], ["0.02821900", "0.00000000"], ["0.02822100", "17.61300000"]]}, {"e": "depthUpdate", "E": 1604224874326, "s": "ETHBTC", "U": 1737951492, "u": 1737951551, "b": [["0.02820400", "0.00000000"], ["0.02820300", "3.00000000"], ["0.02820200", "0.00000000"], ["0.02820100", "0.00000000"], ["0.02820000", "0.25600000"], ["0.02819900", "12.93500000"], ["0.02819800", "6.96500000"], ["0.02819700", "11.00000000"], ["0.02819600", "0.00000000"], ["0.02819500", "9.17900000"], ["0.02819300", "1.72700000"], ["0.02819000", "13.87200000"], ["0.02818800", "37.01000000"], ["0.02818700", "6.41600000"], ["0.02818600", "9.95400000"], ["0.02818400", "13.98500000"], ["0.02818300", "12.14300000"], ["0.02818200", "2.70900000"], ["0.02818000", "10.45200000"], ["0.02817600", "45.89300000"], ["0.02815500", "150.00000000"], ["0.02815000", "0.00000000"], ["0.00993000", "0.01500000"]], "a": [["0.02820400", "142.90500000"], ["0.02820500", "24.00000000"], ["0.02820600", "0.54100000"], ["0.02820700", "1.00000000"], ["0.02820800", "3.89900000"], ["0.02820900", "0.00000000"], ["0.02821600", "3.97000000"], ["0.02821900", "14.91500000"], ["0.02822100", "2.69800000"], ["0.02822200", "70.34600000"], ["0.02822400", "5.12200000"], ["0.02998000", "5.05900000"]]}, {"e": "depthUpdate", "E": 1604224875326, "s": "ETHBTC", "U": 1737951552, "u": 1737951626, "b": [["0.02820300", "3.00000000"], ["0.02820200", "57.00000000"], ["0.02820100", "1.02600000"], ["0.02820000", "25.00000000"], ["0.02819900", "0.00000000"], ["0.02819800", "5.83200000"], ["0.02819700", "0.00000000"], ["0.02819600", "0.10800000"], ["0.02819500", "4.00000000"], ["0.02819100", "10.50200000"], ["0.02818600", "22.89300000"], ["0.02818400", "6.89200000"], ["0.02818300", "0.00000000"], ["0.02817900", "1.34900000"], ["0.02817800", "12.14200000"], ["0.02804800", "0.00000000"], ["0.02804700", "21.10200000"]], "a": [["0.02820200", "0.00000000"], ["0.02820300", "0.00000000"], ["0.02820400", "3.94700000"], ["0.02820500", "0.27500000"], ["0.02820600", "0.27800000"], ["0.02820800", "3.89900000"], ["0.02821500", "5.69500000"], ["0.02821600", "0.01000000"], ["0.02821700", "0.00000000"], ["0.02821800", "4.00000000"], ["0.02821900", "0.00000000"], ["0.02822400", "14.99600000"], ["0.02822900", "40.51500000"], ["0.02823300", "20.66700000"], ["0.02998000", "6.18600000"]]}, {"e": "depthUpdate", "E": 1604224876326, "s": "ETHBTC", "U": 1737951627, "u": 1737951699, "b": [["0.02820500", "59.21900000"], ["0.02820400", "5.02600000"], ["0.02820300", "24.00000000"], ["0.02820200", "1.00000000"], ["0.02820100", "0.11700000"], ["0.02820000", "24.00000000"], ["0.02819700", "0.00000000"], ["0.02819600", "0.00000000"], ["0.02819500", "5.17900000"], ["0.02819100", "10.50200000"], ["0.02819000", "8.69200000"], ["0.02817900", "5.67700000"], ["0.02817200", "7.71500000"], ["0.01833000", "0.00800000"], ["0.00783000", "0.01900000"]], "a": [["0.02820400", "0.00000000"], ["0.02820500", "0.00000000"], ["0.02820600", "123.65600000"], ["0.02820700", "0.00000000"], ["0.02820800", "5.04200000"], ["0.02820900", "1.72600000"], ["0.02821000", "4.00000000"], ["0.02821200", "0.00000000"], ["0.02821300", "4.07200000"], ["0.02821700", "0.50300000"], ["0.02821800", "4.00000000"], ["0.02821900", "15.60100000"], ["0.02822100", "17.61300000"], ["0.02822400", "5.12200000"], ["0.02822600", "13.37900000"]]}, {"e": "depthUpdate", "E": 1604224877326, "s": "ETHBTC", "U": 1737951700, "u": 1737951714, "b": [["0.02820400", "1.02600000"], ["0.02819600", "4.00000000"], ["0.02819500", "10.35900000"], ["0.02819100", "10.50200000"], ["0.02817500", "4.21900000"], ["0.02817400", "0.00000000"], ["0.02817300", "0.00400000"], ["0.02764500", "0.03700000"]], "a": [["0.02820600", "147.65600000"], ["0.02822600", "18.77900000"], ["0.02823300", "15.26500000"], ["0.02838500", "24.73700000"]]}, {"e": "depthUpdate", "E": 1604224878326, "s": "ETHBTC", "U": 1737951715, "u": 1737951736, "b": [["0.02820500", "32.83100000"], ["0.02820400", "0.00000000"], ["0.02820300", "25.02600000"], ["0.02817900", "7.02800000"], ["0.02817800", "17.54400000"], ["0.02817700", "15.08000000"], ["0.02817500", "0.00000000"], ["0.02817300", "0.00000000"], ["0.02815200", "100.94300000"], ["0.02810300", "0.07300000"], ["0.02806000", "0.41300000"], ["0.02805600", "0.00400000"], ["0.02766200", "0.01900000"]], "a": [["0.02820900", "5.68600000"], ["0.02821000", "15.00000000"], ["0.02821500", "1.73500000"]]}, {"e": "depthUpdate", "E": 1604224879326, "s": "ETHBTC", "U": 1737951737, "u": 1737951779, "b": [["0.02820500", "0.00000000"], ["0.02820300", "24.00000000"], ["0.02820200", "0.00000000"], ["0.02820100", "1.25800000"], ["0.02820000", "24.00000000"], ["0.02819900", "0.00000000"], ["0.02819600", "26.81200000"], ["0.02819500", "12.08600000"], ["0.02819300", "0.00000000"]], "a": [["0.02820400", "123.13700000"], ["0.02820500", "24.00000000"], ["0.02820600", "24.39500000"], ["0.02820800", "4.89900000"], ["0.02821000", "4.00000000"], ["0.02821600", "14.92500000"], ["0.02821700", "20.26000000"], ["0.02821800", "4.00000000"], ["0.02822100", "2.69800000"], ["0.02822200", "50.08900000"], ["0.02822800", "20.23500000"], ["0.02823300", "3.12400000"], ["0.02829700", "27.57100000"], ["0.02998000", "6.18600000"]]}, {"e": "depthUpdate", "E": 1604224880326, "s": "ETHBTC", "U": 1737951780, "u": 1737951803, "b": [["0.02820300", "58.02600000"], ["0.02820100", "0.23200000"], ["0.02818300", "0.00000000"], ["0.02815400", "0.10000000"], ["0.02784000", "16.40800000"]], "a": [["0.02820400", "0.00000000"], ["0.02820500", "4.18800000"], ["0.02820600", "24.27800000"], ["0.02820900", "3.96000000"], ["0.02821000", "4.17500000"], ["0.02821100", "1.72600000"], ["0.02821200", "0.50400000"], ["0.02821700", "0.00000000"], ["0.02822400", "7.82200000"], ["0.02822500", "45.92600000"], ["0.02822800", "17.53300000"], ["0.02822900", "0.00000000"]]}, {"e": "depthUpdate", "E": 1604224881326, "s": "ETHBTC", "U": 1737951804, "u": 1737951818, "b": [["0.02820300", "25.02600000"], ["0.02820100", "0.00000000"], ["0.02820000", "24.13300000"], ["0.02819900", "12.93700000"], ["0.02819500", "10.35900000"], ["0.02818600", "9.95400000"], ["0.02815400", "0.00000000"], ["0.02806000", "0.00000000"]], "a": [["0.02820900", "0.10900000"], ["0.02821000", "4.00000000"], ["0.02821500", "5.69500000"], ["0.02821600", "0.01000000"], ["0.02821800", "18.91500000"], ["0.02822400", "28.08100000"]]}, {"e": "depthUpdate", "E": 1604224882326, "s": "ETHBTC", "U": 1737951819, "u": 1737951832, "b": [["0.02820300", "24.00000000"], ["0.02820000", "0.00000000"], ["0.02819600", "27.05800000"], ["0.02819100", "3.41100000"], ["0.02817300", "0.00000000"], ["0.02807800", "2.08400000"]], "a": [["0.02820500", "8.14800000"], ["0.02820600", "24.50100000"], ["0.02820900", "0.00000000"], ["0.02821500", "1.73500000"], ["0.02823100", "3.79600000"], ["0.02823800", "4.24700000"]]}, {"e": "depthUpdate", "E": 1604224883326, "s": "ETHBTC", "U": 1737951833, "u": 1737951874, "b": [["0.02820300", "0.00000000"], ["0.02820200", "0.00000000"], ["0.02820100", "24.15800000"], ["0.02820000", "0.11600000"], ["0.02819800", "5.83200000"], ["0.02819700", "11.00000000"], ["0.02819600", "26.81200000"], ["0.02819500", "10.35900000"], ["0.02819400", "0.00000000"], ["0.02818500", "13.80400000"], ["0.02782100", "1.06600000"]], "a": [["0.02820200", "0.00000000"], ["0.02820300", "0.00000000"], ["0.02820400", "136.00000000"], ["0.02820500", "24.00000000"], ["0.02820600", "0.27800000"], ["0.02820800", "15.89900000"], ["0.02820900", "1.72600000"], ["0.02821100", "4.10800000"], ["0.02821800", "4.00000000"], ["0.02822600", "13.37900000"], ["0.02823000", "12.43100000"], ["0.02998000", "5.05900000"], ["0.03500500", "0.17000000"]]}, {"e": "depthUpdate", "E": 1604224884326, "s": "ETHBTC", "U": 1737951875, "u": 1737951900, "b": [["0.02820100", "25.02500000"], ["0.02819600", "27.06300000"], ["0.02817300", "0.00000000"], ["0.02791700", "0.86800000"]], "a": [["0.02820300", "5.40800000"], ["0.02820500", "24.23000000"], ["0.02821000", "4.00000000"], ["0.02821100", "3.96000000"], ["0.02821700", "14.91500000"], ["0.02998000", "6.18600000"]]}, {"e": "depthUpdate", "E": 1604224885326, "s": "ETHBTC", "U": 1737951901, "u": 1737951926, "b": [["0.02820200", "0.00000000"], ["0.02819700", "4.00000000"], ["0.02819600", "22.81200000"], ["0.02819500", "10.35900000"], ["0.02819400", "0.21300000"], ["0.02818900", "7.09300000"], ["0.02817300", "7.09600000"], ["0.02791500", "3.12100000"], ["0.02680800", "13.97900000"]], "a": [["0.02820400", "136.15300000"], ["0.02820500", "24.00000000"]]}, {"e": "depthUpdate", "E": 1604224886327, "s": "ETHBTC", "U": 1737951927, "u": 1737952005, "b": [["0.02820200", "70.17500000"], ["0.02820100", "24.00000000"], ["0.02820000", "7.49900000"], ["0.02819600", "1.72600000"], ["0.02819400", "2.14700000"], ["0.02819300", "0.00000000"], ["0.02819200", "0.00000000"], ["0.02819100", "0.00000000"], ["0.02819000", "2.26400000"], ["0.02818900", "0.00000000"], ["0.02818700", "0.00000000"], ["0.02818500", "5.39800000"], ["0.02818100", "0.00000000"], ["0.02817300", "0.00000000"], ["0.02812900", "0.00000000"], ["0.02807800", "1.67100000"], ["0.02805600", "0.41700000"]], "a": [["0.02820300", "0.00400000"], ["0.02820400", "0.00000000"], ["0.02820500", "0.00000000"], ["0.02820600", "0.00000000"], ["0.02820700", "0.00000000"], ["0.02820800", "0.02800000"], ["0.02820900", "0.00000000"], ["0.02821000", "0.00000000"], ["0.02821100", "0.00000000"], ["0.02821200", "0.15600000"], ["0.02821400", "0.00000000"], ["0.02821600", "0.01000000"], ["0.02821700", "0.00000000"], ["0.02821800", "7.96000000"], ["0.02822000", "11.62800000"], ["0.02822200", "4.37800000"], ["0.02822400", "28.07900000"], ["0.02822500", "5.40700000"], ["0.02822600", "26.31300000"], ["0.02822700", "8.26500000"], ["0.02822800", "5.39600000"], ["0.02823000", "58.09900000"], ["0.02823200", "0.00000000"], ["0.02823800", "12.16300000"]]}, {"e": "depthUpdate", "E": 1604224887327, "s": "ETHBTC", "U": 1737952006, "u": 1737952060, "b": [["0.02820200", "72.23300000"], ["0.02820100", "36.93300000"], ["0.02820000", "0.40800000"], ["0.02819900", "19.35000000"], ["0.02819700", "0.00000000"], ["0.02819600", "6.20000000"], ["0.02819400", "0.00000000"], ["0.02818600", "9.95400000"], ["0.02817300", "0.00400000"], ["0.02816600", "0.00000000"], ["0.02792600", "1.28600000"]], "a": [["0.02821000", "0.00000000"], ["0.02821100", "0.00000000"], ["0.02821200", "0.00000000"], ["0.02821700", "14.91500000"], ["0.02821800", "8.09200000"], ["0.02821900", "15.60100000"], ["0.02822000", "15.50800000"], ["0.02822100", "3.19500000"], ["0.02822400", "0.00000000"], ["0.02822500", "0.00500000"], ["0.02822600", "20.93400000"], ["0.02822800", "0.00000000"], ["0.02823000", "14.88800000"], ["0.02823100", "24.04600000"], ["0.02823300", "5.38000000"], ["0.02823500", "4.47100000"], ["0.02823600", "87.22100000"], ["0.02823700", "8.36100000"], ["0.02823900", "5.39800000"], ["0.02824400", "5.40900000"], ["0.02824600", "14.79000000"], ["0.02830200", "13.80100000"], ["0.02857800", "0.04300000"]]}, {"e": "depthUpdate", "E": 1604224888327, "s": "ETHBTC", "U": 1737952061, "u": 1737952088, "b": [["0.02820200", "69.34400000"], ["0.02819600", "20.38200000"], ["0.02819400", "2.14700000"], ["0.02819300", "5.19100000"], ["0.02818900", "22.81200000"], ["0.02817300", "0.00000000"], ["0.02816500", "63.91300000"], ["0.02815200", "37.00000000"], ["0.02813800", "7.20700000"], ["0.02793900", "0.72500000"], ["0.02680800", "13.97900000"]], "a": [["0.02821200", "11.00000000"], ["0.02821500", "1.73500000"], ["0.02821600", "15.61100000"], ["0.02821700", "0.00000000"], ["0.02821800", "23.00700000"], ["0.02821900", "0.00000000"], ["0.02824000", "3.21600000"], ["0.02998000", "5.05900000"]]}, {"e": "depthUpdate", "E": 1604224889327, "s": "ETHBTC", "U": 1737952089, "u": 1737952109, "b": [["0.02819700", "6.43200000"], ["0.02819600", "13.29100000"], ["0.02819000", "4.95300000"], ["0.02818900", "22.81200000"], ["0.02818600", "7.25600000"], ["0.02818400", "12.29000000"], ["0.02817700", "15.08000000"], ["0.02817600", "40.49100000"]], "a": [["0.02821200", "11.00000000"], ["0.02821400", "1.72600000"], ["0.02821700", "0.00000000"], ["0.02821800", "7.96000000"], ["0.02822100", "0.49700000"], ["0.02822500", "14.92000000"], ["0.02822800", "2.68900000"], ["0.02998000", "6.18600000"]]}, {"e": "depthUpdate", "E": 1604224890327, "s": "ETHBTC", "U": 1737952110, "u": 1737952118, "b": [["0.02820100", "36.93300000"], ["0.02818500", "23.53700000"], ["0.02817800", "5.41200000"]], "a": [["0.02821100", "0.14200000"], ["0.02823800", "0.02800000"], ["0.02823900", "17.50100000"], ["0.02825800", "35.88900000"]]}, {"e": "depthUpdate", "E": 1604224891327, "s": "ETHBTC", "U": 1737952119, "u": 1737952132, "b": [["0.02820200", "69.13400000"], ["0.02819900", "19.35000000"], ["0.02805600", "0.00400000"]], "a": [["0.02820900", "0.00000000"], ["0.02821100", "0.27300000"], ["0.02822300", "12.93400000"], ["0.02823200", "1.34500000"], ["0.02825800", "35.88900000"]]}, {"e": "depthUpdate", "E": 1604224892327, "s": "ETHBTC", "U": 1737952133, "u": 1737952151, "b": [["0.02812300", "0.02600000"], ["0.02809800", "2.85900000"], ["0.02793100", "0.00000000"]], "a": [["0.02820700", "0.00000000"], ["0.02821100", "4.00000000"], ["0.02821400", "0.00000000"], ["0.02821700", "0.16000000"], ["0.02822000", "11.50800000"], ["0.02823300", "45.87600000"], ["0.02823600", "46.72000000"], ["0.02824100", "7.88100000"], ["0.02824500", "9.87400000"], ["0.02825800", "35.88900000"], ["0.03498000", "17.85200000"], ["0.05000100", "0.00800000"]]}, {"e": "depthUpdate", "E": 1604224893327, "s": "ETHBTC", "U": 1737952152, "u": 1737952198, "b": [["0.02820500", "1.30900000"], ["0.02820400", "26.24700000"], ["0.02820300", "36.15500000"], ["0.02820200", "68.10900000"], ["0.02820000", "0.11600000"], ["0.02819600", "14.85800000"], ["0.02819500", "0.00000000"], ["0.02819200", "7.68500000"], ["0.02818600", "10.37600000"], ["0.02818500", "17.53000000"], ["0.02818400", "10.58900000"], ["0.02818000", "15.85300000"], ["0.02817800", "0.01000000"], ["0.02817600", "37.37000000"]], "a": [["0.02820300", "0.00000000"], ["0.02821100", "0.00000000"], ["0.02821300", "11.00000000"], ["0.02821600", "15.61100000"], ["0.02821700", "0.24600000"], ["0.02821800", "7.96000000"], ["0.02821900", "4.07000000"], ["0.02822100", "4.49700000"], ["0.02822200", "0.04800000"], ["0.02822900", "4.33000000"], ["0.02823100", "3.79600000"], ["0.02823300", "5.38000000"], ["0.02823700", "28.60800000"], ["0.02823900", "57.99400000"], ["0.02825800", "35.83800000"], ["0.02826000", "0.09600000"], ["0.02998000", "6.18600000"], ["0.05000100", "0.00600000"]]}, {"e": "depthUpdate", "E": 1604224894327, "s": "ETHBTC", "U": 1737952199, "u": 1737952281, "b": [["0.02820700", "69.19600000"], ["0.02820600", "10.34900000"], ["0.02820500", "0.19800000"], ["0.02820400", "26.35400000"], ["0.02820300", "43.24400000"], ["0.02820200", "31.31900000"], ["0.02820100", "12.93300000"], ["0.02819900", "26.44000000"], ["0.02819800", "0.00000000"], ["0.02819600", "6.20000000"], ["0.02819500", "1.65500000"], ["0.02818900", "6.00900000"], ["0.02816500", "0.00000000"], ["0.02816200", "0.25300000"], ["0.02815700", "63.93100000"], ["0.02814500", "0.00000000"], ["0.02807800", "0.04400000"]], "a": [["0.02821500", "0.00000000"], ["0.02821600", "0.01000000"], ["0.02821700", "0.00000000"], ["0.02821800", "0.00000000"], ["0.02821900", "18.98500000"], ["0.02822000", "7.62800000"], ["0.02822100", "4.11800000"], ["0.02822200", "17.41600000"], ["0.02822300", "0.00000000"], ["0.02822500", "7.85000000"], ["0.02822800", "4.00000000"], ["0.02823000", "5.15600000"], ["0.02823200", "0.00000000"], ["0.02823300", "0.00400000"], ["0.02823500", "5.81700000"], ["0.02823600", "54.57200000"], ["0.02823700", "24.57500000"], ["0.02823800", "1.37300000"], ["0.02823900", "70.92200000"], ["0.02824100", "13.27300000"], ["0.02824200", "4.03500000"], ["0.02824400", "0.00800000"], ["0.02824500", "1.35000000"], ["0.02825100", "5.40000000"]]}, {"e": "depthUpdate", "E": 1604224895327, "s": "ETHBTC", "U": 1737952282, "u": 1737952334, "b": [["0.02820700", "71.34300000"], ["0.02820500", "0.00000000"], ["0.02820400", "24.10700000"], ["0.02819900", "19.35000000"], ["0.02819400", "0.00000000"], ["0.02819000", "2.68900000"], ["0.02818700", "0.00000000"], ["0.02818300", "0.00000000"], ["0.02815700", "66.19500000"], ["0.02808500", "1.68200000"], ["0.02680800", "13.97900000"]], "a": [["0.02821800", "3.96000000"], ["0.02821900", "4.07000000"], ["0.02822100", "19.19900000"], ["0.02822300", "0.00000000"], ["0.02822400", "0.49900000"], ["0.02822500", "3.89000000"], ["0.02823100", "0.25000000"], ["0.02823500", "2.69600000"], ["0.02823600", "53.74100000"], ["0.02824000", "2.79500000"], ["0.02824500", "4.46900000"]]}, {"e": "depthUpdate", "E": 1604224896327, "s": "ETHBTC", "U": 1737952335, "u": 1737952380, "b": [["0.02820700", "59.36400000"], ["0.02820600", "5.17500000"], ["0.02820500", "0.12300000"], ["0.02820400", "24.00000000"], ["0.02820000", "4.11600000"], ["0.02819700", "12.26400000"], ["0.02818900", "28.82100000"]], "a": [["0.02821700", "0.00000000"], ["0.02821800", "4.08900000"], ["0.02822100", "4.00000000"], ["0.02822300", "0.00000000"], ["0.02823900", "12.92800000"], ["0.02824000", "2.79500000"], ["0.02824300", "5.39700000"], ["0.02824400", "40.49500000"], ["0.02824600", "14.79200000"], ["0.02824700", "12.10100000"]]}, {"e": "depthUpdate", "E": 1604224897328, "s": "ETHBTC", "U": 1737952381, "u": 1737952450, "b": [["0.02820700", "63.56100000"], ["0.02820500", "0.24600000"], ["0.02820400", "29.83200000"], ["0.02820100", "12.93300000"], ["0.02820000", "2.26300000"], ["0.02819900", "21.14600000"], ["0.02819700", "6.43200000"], ["0.02819600", "14.20000000"], ["0.02818300", "0.00000000"], ["0.02818200", "2.71300000"], ["0.02817700", "1.96900000"], ["0.02809800", "2.44700000"], ["0.02800000", "111.18000000"]], "a": [["0.02821100", "0.00000000"], ["0.02821200", "0.00000000"], ["0.02821600", "0.01000000"], ["0.02821700", "0.00000000"], ["0.02821800", "0.00000000"], ["0.02821900", "5.79500000"], ["0.02822100", "0.00000000"], ["0.02822200", "17.41600000"], ["0.02822300", "3.96000000"], ["0.02822400", "0.00000000"], ["0.02822500", "3.89000000"], ["0.02822600", "21.06800000"], ["0.02822800", "0.00000000"], ["0.02822900", "8.33000000"], ["0.02823000", "9.15600000"], ["0.02823700", "4.32800000"], ["0.02824100", "33.51500000"], ["0.02824600", "0.00000000"], ["0.02825100", "20.19400000"], ["0.02826500", "0.10600000"], ["0.02998000", "5.05900000"], ["0.05000100", "0.00800000"]]}, {"e": "depthUpdate", "E": 1604224898327, "s": "ETHBTC", "U": 1737952451, "u": 1737952489, "b": [["0.02820700", "68.73600000"], ["0.02820600", "6.90000000"], ["0.02820500", "3.54500000"], ["0.02820300", "48.35200000"], ["0.02819900", "19.35000000"], ["0.02819600", "12.47400000"], ["0.02818700", "0.00000000"], ["0.02818200", "2.70900000"], ["0.02800800", "59.78400000"]], "a": [["0.02821700", "11.00000000"], ["0.02821800", "3.96000000"], ["0.02822300", "0.00000000"], ["0.02822400", "0.00000000"], ["0.02822500", "3.89000000"], ["0.02822600", "20.93400000"], ["0.02998000", "6.18600000"], ["0.05000100", "0.01000000"]]}, {"e": "depthUpdate", "E": 1604224899327, "s": "ETHBTC", "U": 1737952490, "u": 1737952512, "b": [["0.02820500", "3.54500000"], ["0.02820300", "43.24400000"], ["0.02820000", "2.26300000"], ["0.02819400", "7.09000000"], ["0.02811800", "0.10000000"], ["0.02811000", "0.47500000"]], "a": [["0.02822200", "17.52700000"], ["0.02822300", "0.00000000"]]}, {"e": "depthUpdate", "E": 1604224900327, "s": "ETHBTC", "U": 1737952513, "u": 1737952587, "b": [["0.02821300", "0.00000000"], ["0.02821100", "0.00000000"], ["0.02821000", "0.00000000"], ["0.02820900", "0.00000000"], ["0.02820800", "3.57000000"], ["0.02820700", "63.71400000"], ["0.02820500", "0.00000000"], ["0.02820400", "24.00000000"], ["0.02820200", "32.60500000"], ["0.02819900", "26.78500000"], ["0.02819500", "11.48700000"], ["0.02819400", "0.00000000"], ["0.02819300", "9.09900000"]], "a": [["0.02820800", "0.00000000"], ["0.02821100", "11.24800000"], ["0.02821200", "115.96000000"], ["0.02821300", "24.00000000"], ["0.02821400", "0.00000000"], ["0.02821500", "0.00000000"], ["0.02821600", "0.01000000"], ["0.02821700", "0.00000000"], ["0.02821800", "0.00000000"], ["0.02821900", "5.72500000"], ["0.02822000", "0.02500000"], ["0.02822200", "17.41600000"], ["0.02822600", "21.19000000"], ["0.02822700", "8.26500000"], ["0.02823000", "5.15600000"], ["0.02823400", "0.01000000"], ["0.02823700", "0.00000000"], ["0.02824100", "56.32700000"], ["0.02824300", "12.48300000"], ["0.02824600", "4.32700000"], ["0.02825800", "31.50500000"], ["0.02827100", "4.33600000"], ["0.02837000", "0.00000000"], ["0.02838800", "17.31800000"]]}, {"e": "depthUpdate", "E": 1604224901327, "s": "ETHBTC", "U": 1737952588, "u": 1737952638, "b": [["0.02820800", "3.37500000"], ["0.02820600", "9.40600000"], ["0.02820400", "29.83200000"], ["0.02819800", "7.09000000"], ["0.02819700", "6.43200000"], ["0.02819500", "1.65500000"], ["0.02815000", "0.00000000"]], "a": [["0.02820900", "0.00000000"], ["0.02821000", "0.00000000"], ["0.02821100", "4.92900000"], ["0.02821200", "112.00000000"], ["0.02821500", "0.00000000"], ["0.02821600", "0.23400000"], ["0.02821700", "0.00000000"], ["0.02821800", "3.96000000"], ["0.02822100", "0.00000000"], ["0.02822200", "1.81500000"], ["0.02822600", "20.93400000"], ["0.02823500", "18.29700000"], ["0.02824000", "43.27700000"], ["0.02824300", "5.39700000"], ["0.02824400", "0.00800000"], ["0.02826500", "0.05500000"]]}, {"e": "depthUpdate", "E": 1604224902327, "s": "ETHBTC", "U": 1737952639, "u": 1737952728, "b": [["0.02821400", "0.00000000"], ["0.02821300", "24.00000000"], ["0.02821200", "0.00000000"], ["0.02821100", "0.00000000"], ["0.02821000", "0.00000000"], ["0.02820900", "2.24700000"], ["0.02820800", "0.00000000"], ["0.02820700", "63.92600000"], ["0.02820600", "9.17500000"], ["0.02820500", "3.90800000"], ["0.02820400", "0.00000000"], ["0.02820200", "11.02600000"], ["0.02820000", "5.67400000"], ["0.02819800", "0.00000000"], ["0.02819300", "5.19100000"], ["0.02819100", "7.08900000"], ["0.02818900", "28.20200000"], ["0.02818800", "41.33700000"], ["0.02818500", "12.13200000"], ["0.02817900", "2.70000000"], ["0.02782900", "0.13300000"]], "a": [["0.02821100", "0.00000000"], ["0.02821200", "0.00000000"], ["0.02821300", "0.00000000"], ["0.02821400", "139.39600000"], ["0.02821500", "0.29100000"], ["0.02821600", "0.01000000"], ["0.02821700", "0.29500000"], ["0.02821800", "3.96000000"], ["0.02822000", "0.02500000"], ["0.02823400", "14.92500000"], ["0.02823500", "38.53700000"], ["0.02824000", "43.27700000"], ["0.02824100", "36.08500000"], ["0.02826500", "0.10600000"], ["0.02998000", "6.18600000"]]}, {"e": "depthUpdate", "E": 1604224903327, "s": "ETHBTC", "U": 1737952729, "u": 1737952796, "b": [["0.02821500", "27.00000000"], ["0.02821400", "5.27200000"], ["0.02821300", "32.50000000"], ["0.02821200", "0.00000000"], ["0.02821100", "0.20900000"], ["0.02821000", "0.00000000"], ["0.02820900", "2.35400000"], ["0.02820700", "31.21400000"], ["0.02820600", "9.17500000"], ["0.02820500", "0.00000000"], ["0.02820000", "2.26300000"], ["0.02819700", "6.43200000"], ["0.02819500", "5.56300000"], ["0.02819300", "9.40900000"], ["0.02819100", "0.00000000"], ["0.02818900", "34.20700000"], ["0.02811800", "0.00000000"]], "a": [["0.02821400", "0.00000000"], ["0.02821500", "0.00000000"], ["0.02821600", "0.01000000"], ["0.02821700", "0.00000000"], ["0.02821800", "14.96000000"], ["0.02821900", "4.00000000"], ["0.02822000", "4.18500000"], ["0.02822100", "0.00000000"], ["0.02822900", "4.33000000"], ["0.02823500", "18.29700000"], ["0.02823900", "33.16700000"], ["0.02989000", "5.00000000"]]}, {"e": "depthUpdate", "E": 1604224904328, "s": "ETHBTC", "U": 1737952797, "u": 1737952953, "b": [["0.02821900", "74.40400000"], ["0.02821800", "5.65800000"], ["0.02821700", "26.38400000"], ["0.02821600", "0.00000000"], ["0.02821500", "24.65200000"], ["0.02821400", "6.01200000"], ["0.02821300", "2.14700000"], ["0.02821100", "0.00000000"], ["0.02821000", "0.00000000"], ["0.02820900", "0.10700000"], ["0.02820800", "6.40800000"], ["0.02820700", "6.43700000"], ["0.02820600", "4.47400000"], ["0.02820500", "7.59600000"], ["0.02820200", "0.00000000"], ["0.02820100", "12.95500000"], ["0.02820000", "42.49600000"], ["0.02819900", "20.37200000"], ["0.02819700", "0.00000000"], ["0.02819600", "8.00000000"], ["0.02819500", "0.00000000"], ["0.02819400", "2.69500000"], ["0.02819300", "9.40900000"], ["0.02819000", "0.00000000"], ["0.02818900", "10.78500000"], ["0.02818800", "39.70800000"], ["0.02818600", "14.41000000"], ["0.02818400", "5.19100000"], ["0.02818200", "0.00800000"], ["0.02818000", "11.82400000"], ["0.02817200", "0.00000000"], ["0.02782300", "0.15100000"]], "a": [["0.02821600", "0.00000000"], ["0.02821800", "0.00000000"], ["0.02821900", "0.00000000"], ["0.02822000", "0.02500000"], ["0.02822200", "0.04800000"], ["0.02822400", "0.00000000"], ["0.02822500", "0.00500000"], ["0.02822600", "0.27800000"], ["0.02822700", "0.93900000"], ["0.02822800", "4.00000000"], ["0.02822900", "4.00000000"], ["0.02823000", "0.06000000"], ["0.02823200", "16.51700000"], ["0.02823300", "3.89400000"], ["0.02823400", "7.34800000"], ["0.02823500", "15.60100000"], ["0.02823600", "48.58800000"], ["0.02823800", "0.02800000"], ["0.02823900", "12.92800000"], ["0.02824000", "4.42900000"], ["0.02824100", "28.11500000"], ["0.02824200", "0.00000000"], ["0.02824300", "43.16300000"], ["0.02824400", "7.85600000"], ["0.02824500", "15.07900000"], ["0.02824600", "19.65700000"], ["0.02824700", "5.39500000"], ["0.02824800", "9.13500000"], ["0.02824900", "1.48300000"], ["0.02825100", "26.92000000"], ["0.02825600", "35.62900000"]]}, {"e": "depthUpdate", "E": 1604224905328, "s": "ETHBTC", "U": 1737952954, "u": 1737953007, "b": [["0.02821900", "30.94400000"], ["0.02821800", "7.51800000"], ["0.02821700", "24.00000000"], ["0.02821000", "10.34400000"], ["0.02820900", "11.10300000"], ["0.02820800", "9.81900000"], ["0.02820200", "4.32500000"], ["0.02820100", "18.18200000"], ["0.02819200", "7.68500000"], ["0.02818500", "0.00000000"], ["0.02810000", "0.05000000"], ["0.02805500", "10.40300000"], ["0.02803200", "0.04300000"], ["0.02473200", "0.00000000"]], "a": [["0.02822000", "119.54700000"], ["0.02822400", "0.16800000"], ["0.02822500", "0.00500000"], ["0.02822600", "0.00000000"], ["0.02823000", "0.06000000"], ["0.02823100", "4.21000000"], ["0.02823200", "1.60200000"], ["0.02824300", "48.28500000"], ["0.02824400", "5.15800000"], ["0.02824500", "11.11900000"], ["0.02824800", "11.83200000"], ["0.02824900", "0.13400000"], ["0.02825000", "0.12400000"], ["0.02825300", "1.35400000"], ["0.02825500", "216.39400000"], ["0.02825800", "35.83000000"], ["0.02826500", "0.05500000"], ["0.02832500", "0.00000000"], ["0.02858400", "0.05100000"], ["0.02983700", "0.11800000"]]}, {"e": "depthUpdate", "E": 1604224906328, "s": "ETHBTC", "U": 1737953008, "u": 1737953049, "b": [["0.02821900", "0.00000000"], ["0.02821800", "0.00000000"], ["0.02821700", "24.23800000"], ["0.02821600", "5.23500000"], ["0.02821400", "0.00000000"], ["0.02821300", "0.00000000"], ["0.02821100", "1.72500000"], ["0.02820900", "3.90800000"], ["0.02820600", "10.17900000"], ["0.02820500", "13.42800000"], ["0.02820400", "2.26400000"], ["0.02819600", "8.00000000"], ["0.02819500", "22.81200000"], ["0.02819100", "12.12600000"], ["0.02817600", "37.37000000"], ["0.02817000", "0.00000000"], ["0.02815700", "63.93100000"], ["0.02811700", "0.00400000"], ["0.02784000", "14.91100000"]], "a": [["0.02822000", "139.47700000"], ["0.02822600", "3.96000000"], ["0.02823100", "0.25000000"], ["0.02823300", "3.89400000"], ["0.02823400", "22.26300000"], ["0.02834700", "1.16900000"], ["0.02998000", "5.05900000"]]}, {"e": "depthUpdate", "E": 1604224907328, "s": "ETHBTC", "U": 1737953050, "u": 1737953103, "b": [["0.02821700", "24.00000000"], ["0.02821600", "5.23500000"], ["0.02821500", "24.65200000"], ["0.02820600", "8.47400000"], ["0.02820400", "3.96500000"], ["0.02820200", "0.00000000"], ["0.02819300", "5.19100000"], ["0.02819200", "12.01200000"], ["0.02819000", "0.00400000"], ["0.02818700", "0.00000000"], ["0.02780000", "30.82600000"]], "a": [["0.02821800", "119.52300000"], ["0.02821900", "0.00000000"], ["0.02822000", "0.02500000"], ["0.02822300", "0.00000000"], ["0.02822400", "0.00000000"], ["0.02823300", "3.89400000"], ["0.02823400", "22.26300000"], ["0.02834700", "0.60200000"], ["0.02841600", "3.10700000"], ["0.02845300", "0.71700000"], ["0.02998000", "6.18600000"], ["0.13691300", "0.00000000"]]}, {"e": "depthUpdate", "E": 1604224908327, "s": "ETHBTC", "U": 1737953104, "u": 1737953160, "b": [["0.02821900", "32.03200000"], ["0.02821800", "0.00000000"], ["0.02821700", "68.52400000"], ["0.02821600", "0.00000000"], ["0.02821500", "24.65200000"], ["0.02820900", "6.11600000"], ["0.02820600", "10.47500000"], ["0.02820500", "7.59600000"], ["0.02819700", "0.00000000"], ["0.02819000", "0.00400000"], ["0.02818600", "15.75900000"], ["0.02818500", "5.39700000"], ["0.02818000", "6.42300000"], ["0.02817900", "1.34900000"], ["0.02798200", "0.00500000"], ["0.02794000", "0.03900000"]], "a": [["0.02821800", "0.00000000"], ["0.02822000", "3.47700000"], ["0.02822300", "0.10700000"], ["0.02822400", "11.00000000"], ["0.02822500", "1.72900000"], ["0.02823200", "2.09400000"], ["0.02824500", "14.66300000"], ["0.02834700", "1.12700000"], ["0.13689300", "0.00600000"]]}, {"e": "depthUpdate", "E": 1604224909329, "s": "ETHBTC", "U": 1737953161, "u": 1737953268, "b": [["0.02822000", "0.00000000"], ["0.02821900", "0.00000000"], ["0.02821800", "0.00000000"], ["0.02821700", "0.00000000"], ["0.02821500", "0.65200000"], ["0.02821400", "0.00000000"], ["0.02821100", "0.00000000"], ["0.02821000", "0.00000000"], ["0.02820900", "2.20800000"], ["0.02820800", "0.00000000"], ["0.02820700", "0.00000000"], ["0.02820600", "6.00100000"], ["0.02820500", "13.42800000"], ["0.02820400", "9.58300000"], ["0.02820300", "36.15500000"], ["0.02820100", "12.95500000"], ["0.02819700", "7.08900000"], ["0.02819500", "0.00000000"], ["0.02819300", "9.19100000"], ["0.02819100", "12.12600000"], ["0.02819000", "0.00000000"], ["0.02818900", "10.78500000"], ["0.02792400", "0.11800000"], ["0.02792200", "0.40200000"]], "a": [["0.02821800", "11.39300000"], ["0.02821900", "7.07000000"], ["0.02822000", "136.00000000"], ["0.02822100", "24.47600000"], ["0.02822300", "0.00000000"], ["0.02822400", "0.00000000"], ["0.02822800", "0.00000000"], ["0.02822900", "0.00000000"], ["0.02823000", "60.76200000"], ["0.02823200", "1.60200000"], ["0.02823300", "0.00400000"], ["0.02823400", "12.52000000"], ["0.02824000", "0.09600000"], ["0.02824100", "7.88100000"], ["0.02824300", "7.81600000"], ["0.02824400", "0.00800000"], ["0.02825800", "31.50500000"]]}, {"e": "depthUpdate", "E": 1604224910329, "s": "ETHBTC", "U": 1737953269, "u": 1737953334, "b": [["0.02821600", "0.00000000"], ["0.02821500", "3.65200000"], ["0.02821400", "0.00000000"], ["0.02821200", "0.00000000"], ["0.02820900", "0.00000000"], ["0.02820700", "4.00000000"], ["0.02820600", "0.00000000"], ["0.02820200", "6.41100000"], ["0.02820000", "47.66700000"], ["0.02819500", "1.69100000"], ["0.02819400", "7.16200000"], ["0.02819300", "5.19100000"], ["0.02819200", "7.68500000"], ["0.02818200", "4.33600000"], ["0.02812400", "2.00000000"], ["0.02805500", "0.03900000"], ["0.02803600", "10.37100000"]], "a": [["0.02821600", "147.42200000"], ["0.02821700", "24.00000000"], ["0.02821800", "8.00000000"], ["0.02821900", "0.00000000"], ["0.02822000", "24.00000000"], ["0.02822100", "0.00000000"], ["0.02822600", "0.00000000"], ["0.02822800", "7.46000000"], ["0.02822900", "0.00000000"], ["0.02823000", "0.06000000"], ["0.02823100", "5.40400000"], ["0.02823400", "7.34800000"], ["0.02824100", "12.20900000"], ["0.02824300", "7.81600000"], ["0.02824500", "15.08500000"], ["0.02834700", "0.60200000"]]}, {"e": "depthUpdate", "E": 1604224911329, "s": "ETHBTC", "U": 1737953335, "u": 1737953420, "b": [["0.02821500", "0.00000000"], ["0.02821300", "0.00000000"], ["0.02821200", "65.50000000"], ["0.02821100", "0.00000000"], ["0.02821000", "0.11700000"], ["0.02820900", "5.18400000"], ["0.02820800", "24.00000000"], ["0.02820500", "5.83200000"], ["0.02820300", "43.24300000"], ["0.02820200", "10.25500000"], ["0.02820100", "19.39000000"], ["0.02820000", "5.28700000"], ["0.02814600", "0.01000000"], ["0.02811000", "0.06300000"], ["0.02807800", "21.05600000"], ["0.02806000", "0.41300000"], ["0.02804700", "0.06600000"], ["0.02794000", "0.10600000"]], "a": [["0.02821300", "7.46200000"], ["0.02821400", "112.00000000"], ["0.02821500", "0.21300000"], ["0.02821600", "24.32800000"], ["0.02821700", "24.00000000"], ["0.02821800", "0.00000000"], ["0.02822000", "0.00000000"], ["0.02822300", "1.75400000"], ["0.02822400", "3.96000000"], ["0.02822500", "8.99300000"], ["0.02822600", "0.00000000"], ["0.02822700", "0.93900000"], ["0.02823000", "8.06000000"], ["0.02823200", "14.91500000"], ["0.02823300", "0.00400000"], ["0.02823800", "20.25500000"], ["0.02824300", "48.27000000"], ["0.02824500", "8.00000000"], ["0.02839900", "0.28000000"], ["0.02841800", "16.05000000"], ["0.02998000", "6.18600000"]]}, {"e": "depthUpdate", "E": 1604224912329, "s": "ETHBTC", "U": 1737953421, "u": 1737953487, "b": [["0.02821200", "27.00000000"], ["0.02821000", "0.11700000"], ["0.02820900", "5.18400000"], ["0.02820700", "0.00000000"], ["0.02820400", "5.17000000"], ["0.02820300", "36.15500000"], ["0.02820200", "8.57500000"], ["0.02820100", "23.39000000"], ["0.02820000", "5.28700000"], ["0.02819700", "10.50000000"], ["0.02819500", "5.59900000"], ["0.02818800", "39.70800000"], ["0.02816900", "49.26300000"], ["0.02816500", "2.26400000"], ["0.02815600", "0.00000000"]], "a": [["0.02821300", "4.06900000"], ["0.02821400", "112.33000000"], ["0.02821500", "0.00000000"], ["0.02821600", "24.00000000"], ["0.02821700", "0.27200000"], ["0.02821800", "0.00000000"], ["0.02822800", "7.46000000"], ["0.02822900", "0.00000000"], ["0.02823100", "5.40400000"], ["0.02823200", "0.00000000"], ["0.02823300", "0.00400000"], ["0.02823400", "22.26300000"], ["0.02824100", "12.20900000"], ["0.02824900", "3.25300000"]]}, {"e": "depthUpdate", "E": 1604224913329, "s": "ETHBTC", "U": 1737953488, "u": 1737953537, "b": [["0.02821200", "0.00000000"], ["0.02821000", "0.00000000"], ["0.02820800", "24.16900000"], ["0.02820600", "4.00000000"], ["0.02820500", "16.83200000"], ["0.02820400", "12.48900000"], ["0.02820100", "19.39000000"], ["0.02820000", "12.37500000"], ["0.02819700", "9.35300000"], ["0.02819500", "1.69100000"], ["0.02818500", "0.00000000"], ["0.02816500", "0.00000000"], ["0.02787100", "37.40400000"], ["0.02680800", "13.97900000"]], "a": [["0.02821300", "139.39300000"], ["0.02821400", "0.33000000"], ["0.02821500", "3.96000000"], ["0.02821600", "24.00000000"], ["0.02821700", "0.00000000"], ["0.02821800", "0.10300000"], ["0.02821900", "0.00000000"], ["0.02822100", "4.00000000"], ["0.02822200", "0.54000000"], ["0.02822400", "0.00000000"], ["0.02822800", "9.50400000"], ["0.02823000", "4.06000000"], ["0.02823300", "14.91900000"], ["0.02823400", "7.34800000"], ["0.02838800", "0.07400000"], ["0.02858400", "4.18500000"]]}, {"e": "depthUpdate", "E": 1604224914328, "s": "ETHBTC", "U": 1737953538, "u": 1737953614, "b": [["0.02821300", "66.58100000"], ["0.02821200", "0.61600000"], ["0.02821100", "28.86900000"], ["0.02821000", "24.00000000"], ["0.02820900", "0.00000000"], ["0.02820800", "0.00000000"], ["0.02820500", "5.83200000"], ["0.02820400", "8.58100000"], ["0.02820200", "2.16400000"], ["0.02820100", "12.95500000"], ["0.02820000", "5.17100000"], ["0.02819800", "13.50100000"], ["0.02819500", "1.69100000"]], "a": [["0.02821100", "0.00000000"], ["0.02821200", "0.00000000"], ["0.02821300", "0.00000000"], ["0.02821400", "112.00000000"], ["0.02821500", "4.06800000"], ["0.02821800", "0.00000000"], ["0.02822000", "0.12600000"], ["0.02822300", "0.00000000"], ["0.02822800", "8.30100000"], ["0.02823100", "5.40400000"], ["0.02823200", "0.00000000"], ["0.02823300", "0.00400000"], ["0.02823400", "22.26300000"], ["0.02823900", "35.73300000"], ["0.02836900", "17.41800000"]]}, {"e": "depthUpdate", "E": 1604224915328, "s": "ETHBTC", "U": 1737953615, "u": 1737953664, "b": [["0.02821300", "63.58100000"], ["0.02821200", "0.61600000"], ["0.02821100", "28.76400000"], ["0.02821000", "24.17500000"], ["0.02820600", "4.00000000"], ["0.02820000", "11.59900000"], ["0.02819800", "12.41000000"], ["0.02819700", "7.08900000"], ["0.02815600", "2.26400000"], ["0.02815200", "37.00000000"], ["0.02814200", "30.00000000"]], "a": [["0.02821400", "139.39300000"], ["0.02821500", "4.39800000"], ["0.02821600", "24.28300000"], ["0.02822000", "0.00000000"], ["0.02822600", "3.11900000"], ["0.02823300", "0.00400000"], ["0.02823400", "12.57900000"], ["0.02858400", "0.05100000"], ["0.02858500", "10.04500000"]]}, {"e": "depthUpdate", "E": 1604224916328, "s": "ETHBTC", "U": 1737953665, "u": 1737953730, "b": [["0.02821300", "27.00000000"], ["0.02821200", "5.26500000"], ["0.02821100", "24.00000000"], ["0.02821000", "0.00000000"], ["0.02820900", "0.00000000"], ["0.02820500", "7.55600000"], ["0.02820200", "6.07200000"], ["0.02820100", "20.04400000"], ["0.02819600", "8.10000000"]], "a": [["0.02821400", "143.46100000"], ["0.02821500", "0.33000000"], ["0.02821600", "24.00000000"], ["0.02822400", "1.67100000"], ["0.02822600", "0.00000000"], ["0.02823100", "5.40400000"], ["0.02823200", "0.00000000"], ["0.02823300", "14.91900000"], ["0.02823400", "32.80700000"], ["0.02823800", "0.02800000"], ["0.02823900", "76.18800000"], ["0.02824200", "7.08600000"], ["0.02824300", "7.81600000"], ["0.02998000", "5.05900000"]]}, {"e": "depthUpdate", "E": 1604224917328, "s": "ETHBTC", "U": 1737953731, "u": 1737953763, "b": [["0.02821200", "5.18400000"], ["0.02820900", "0.00000000"], ["0.02820700", "0.28200000"], ["0.02820400", "5.17000000"], ["0.02820100", "12.95500000"], ["0.02820000", "18.68900000"], ["0.02819600", "8.00000000"], ["0.02819500", "5.10200000"], ["0.02819000", "0.00400000"]], "a": [["0.02821400", "119.46100000"], ["0.02821600", "24.23800000"], ["0.02822000", "3.96000000"], ["0.02822600", "12.91900000"], ["0.02822800", "4.34100000"], ["0.02823900", "53.38300000"], ["0.02824600", "6.73400000"], ["0.02824900", "0.13400000"], ["0.02998000", "6.18600000"]]}, {"e": "depthUpdate", "E": 1604224918328, "s": "ETHBTC", "U": 1737953764, "u": 1737953805, "b": [["0.02821300", "65.50000000"], ["0.02820900", "0.28100000"], ["0.02820700", "0.00000000"], ["0.02820400", "8.58100000"], ["0.02820000", "11.59900000"], ["0.02819500", "1.69100000"], ["0.02819000", "0.00000000"], ["0.02818900", "10.78500000"], ["0.02817200", "0.00000000"], ["0.02798700", "0.26700000"]], "a": [["0.02821400", "0.27700000"], ["0.02821600", "24.47800000"], ["0.02821800", "0.27900000"], ["0.02821900", "11.00000000"], ["0.02824200", "0.00000000"]]}, {"e": "depthUpdate", "E": 1604224919329, "s": "ETHBTC", "U": 1737953806, "u": 1737953919, "b": [["0.02821300", "2.33200000"], ["0.02821200", "0.00000000"], ["0.02821100", "1.08200000"], ["0.02820900", "0.00000000"], ["0.02820800", "0.16400000"], ["0.02820600", "0.00000000"], ["0.02820500", "6.89700000"], ["0.02820400", "0.00000000"], ["0.02820200", "0.00000000"], ["0.02820000", "5.17300000"], ["0.02819900", "7.43500000"], ["0.02819800", "6.41200000"], ["0.02819400", "4.46700000"], ["0.02819300", "4.00000000"], ["0.02819200", "13.08000000"], ["0.02818900", "9.29800000"], ["0.02818600", "12.63900000"], ["0.02818500", "5.39600000"], ["0.02818400", "11.02300000"], ["0.02818300", "3.41100000"], ["0.02817800", "0.01000000"], ["0.02817000", "63.90200000"], ["0.02815700", "0.00000000"], ["0.02788500", "33.92400000"], ["0.02783100", "0.00000000"], ["0.02740400", "0.02600000"]], "a": [["0.02821400", "143.73900000"], ["0.02821500", "0.23600000"], ["0.02821600", "0.27700000"], ["0.02821700", "4.00000000"], ["0.02821800", "2.23300000"], ["0.02821900", "11.00000000"], ["0.02822200", "0.04800000"], ["0.02822500", "7.26900000"], ["0.02822600", "20.91900000"], ["0.02823000", "0.06000000"], ["0.02823100", "20.31900000"], ["0.02823200", "18.29500000"], ["0.02823300", "3.12300000"], ["0.02823500", "0.00000000"], ["0.02823700", "12.12500000"], ["0.02823900", "18.32300000"], ["0.02824300", "50.97600000"], ["0.02824500", "0.00000000"], ["0.02824700", "0.00000000"], ["0.02825100", "14.79400000"], ["0.02825600", "30.23200000"], ["0.02845900", "0.11500000"], ["0.02894000", "0.70600000"]]}, {"e": "depthUpdate", "E": 1604224920329, "s": "ETHBTC", "U": 1737953920, "u": 1737954034, "b": [["0.02821300", "0.00000000"], ["0.02821100", "0.00000000"], ["0.02821000", "0.00000000"], ["0.02820900", "2.72100000"], ["0.02820800", "0.00000000"], ["0.02820700", "0.00000000"], ["0.02820600", "0.00000000"], ["0.02820500", "0.00000000"], ["0.02820400", "1.21400000"], ["0.02820300", "36.31200000"], ["0.02820100", "0.02200000"], ["0.02819800", "0.00000000"], ["0.02819700", "0.00000000"], ["0.02819500", "2.26400000"], ["0.02819400", "5.83200000"], ["0.02819300", "7.41100000"], ["0.02819200", "19.49500000"], ["0.02819000", "13.52000000"], ["0.02818700", "4.47200000"], ["0.02818600", "11.29000000"], ["0.02818500", "0.00000000"], ["0.02818400", "5.19100000"], ["0.02818300", "12.92100000"], ["0.02818200", "5.68500000"], ["0.02818100", "0.00000000"], ["0.02818000", "19.34400000"], ["0.02817700", "5.08900000"], ["0.02817500", "5.39600000"], ["0.02816200", "0.00000000"], ["0.02815600", "0.00000000"], ["0.02814900", "0.48000000"], ["0.02806000", "0.00000000"], ["0.02792000", "0.00500000"], ["0.02785700", "1.28900000"]], "a": [["0.02821000", "150.34600000"], ["0.02821100", "30.00000000"], ["0.02821200", "28.23700000"], ["0.02821300", "0.68800000"], ["0.02821400", "1.00000000"], ["0.02821600", "0.00000000"], ["0.02821700", "4.00000000"], ["0.02821800", "1.72400000"], ["0.02821900", "0.00000000"], ["0.02822000", "0.00000000"], ["0.02822100", "0.00000000"], ["0.02822400", "16.58600000"], ["0.02822500", "7.26900000"], ["0.02823000", "0.06000000"], ["0.02823100", "5.40400000"], ["0.02824600", "6.73400000"]]}, {"e": "depthUpdate", "E": 1604224921328, "s": "ETHBTC", "U": 1737954035, "u": 1737954106, "b": [["0.02820900", "0.00000000"], ["0.02820400", "5.52600000"], ["0.02820300", "37.15500000"], ["0.02820200", "0.22900000"], ["0.02819900", "0.00000000"], ["0.02819700", "1.72400000"], ["0.02819500", "9.35500000"], ["0.02819300", "13.41000000"], ["0.02819100", "1.75100000"], ["0.02805800", "0.41300000"], ["0.02792500", "80.00300000"], ["0.02744300", "2983.50000000"], ["0.02680800", "13.97900000"]], "a": [["0.02820600", "28.06900000"], ["0.02820700", "3.96000000"], ["0.02820800", "24.00000000"], ["0.02820900", "105.00000000"], ["0.02821000", "140.27700000"], ["0.02821100", "1.00000000"], ["0.02821200", "0.40300000"], ["0.02821300", "0.49300000"], ["0.02821400", "0.00000000"], ["0.02821700", "4.00000000"], ["0.02822100", "4.34100000"], ["0.02822200", "20.12400000"], ["0.02822300", "58.68200000"], ["0.02822400", "14.59200000"], ["0.02822800", "0.00000000"], ["0.02823100", "0.25000000"], ["0.02823200", "41.10000000"], ["0.02823400", "12.57900000"], ["0.02823900", "5.39500000"], ["0.02824300", "50.97600000"], ["0.02824800", "6.73100000"], ["0.02849800", "111.30000000"], ["0.02858400", "4.52100000"], ["0.02897900", "1282.28100000"], ["0.02998000", "5.05900000"]]}, {"e": "depthUpdate", "E": 1604224922328, "s": "ETHBTC", "U": 1737954107, "u": 1737954209, "b": [["0.02820400", "0.00000000"], ["0.02820300", "33.26200000"], ["0.02820200", "1.00000000"], ["0.02820000", "0.00000000"], ["0.02819900", "0.00000000"], ["0.02819800", "0.15500000"], ["0.02819700", "0.00000000"], ["0.02819600", "0.00000000"], ["0.02819500", "0.00000000"], ["0.02819400", "0.00000000"], ["0.02819300", "0.00000000"], ["0.02819200", "7.68500000"], ["0.02819100", "4.01500000"], ["0.02818900", "3.90800000"], ["0.02818800", "4.00000000"], ["0.02818700", "7.09300000"], ["0.02818600", "7.25600000"], ["0.02818500", "5.83200000"], ["0.02818400", "8.60200000"], ["0.02818200", "8.38300000"], ["0.02817800", "4.04700000"], ["0.02817600", "42.76600000"], ["0.02817200", "8.00000000"], ["0.02798100", "0.10900000"], ["0.02798000", "0.23200000"], ["0.02792900", "0.75400000"], ["0.02680800", "1.98100000"]], "a": [["0.02820400", "140.06900000"], ["0.02820500", "24.00000000"], ["0.02820600", "24.27700000"], ["0.02820800", "0.00000000"], ["0.02820900", "1.12000000"], ["0.02821000", "4.00000000"], ["0.02821100", "0.00000000"], ["0.02821200", "0.00000000"], ["0.02821300", "12.92300000"], ["0.02821700", "0.00000000"], ["0.02821900", "7.50200000"], ["0.02822000", "14.91500000"], ["0.02822100", "19.94200000"], ["0.02822200", "5.20900000"], ["0.02822400", "12.92100000"], ["0.02822600", "13.13100000"], ["0.02823000", "9.93400000"], ["0.02823100", "7.33900000"], ["0.02823200", "25.49900000"], ["0.02823600", "48.58800000"], ["0.02835300", "28.33400000"], ["0.02998000", "6.18600000"]]}, {"e": "depthUpdate", "E": 1604224923328, "s": "ETHBTC", "U": 1737954210, "u": 1737954253, "b": [["0.02820300", "32.98500000"], ["0.02820200", "1.00000000"], ["0.02820100", "0.02200000"], ["0.02820000", "0.00000000"], ["0.02819900", "0.16600000"], ["0.02819800", "0.00000000"], ["0.02819700", "11.00000000"], ["0.02819500", "4.00000000"], ["0.02819400", "5.83200000"], ["0.02819300", "3.41100000"], ["0.02819100", "9.18800000"], ["0.02819000", "18.69300000"], ["0.02818800", "0.00000000"], ["0.02818500", "6.41700000"], ["0.02818400", "5.19100000"], ["0.02818100", "4.46800000"], ["0.02807800", "0.04400000"], ["0.02804700", "21.10200000"], ["0.02680800", "13.97900000"]], "a": [["0.02820400", "144.06900000"], ["0.02820600", "24.23500000"], ["0.02820700", "4.96000000"], ["0.02820800", "11.00000000"], ["0.02820900", "0.00000000"], ["0.02821100", "0.00000000"], ["0.02821300", "17.26500000"], ["0.02821400", "1.66100000"], ["0.02822000", "0.00000000"], ["0.02822100", "15.60100000"], ["0.02822200", "20.12400000"], ["0.02822600", "8.00000000"], ["0.02823100", "0.25000000"], ["0.02839900", "16.28000000"], ["0.02841800", "0.05000000"], ["0.02857800", "4.02100000"]]}, {"e": "depthUpdate", "E": 1604224924328, "s": "ETHBTC", "U": 1737954254, "u": 1737954288, "b": [["0.02820000", "0.17600000"], ["0.02819900", "0.00000000"], ["0.02819300", "10.50300000"], ["0.02818900", "3.90800000"], ["0.02818700", "0.00000000"], ["0.02818600", "13.25600000"], ["0.02818200", "5.68500000"], ["0.02817900", "4.04700000"], ["0.02817500", "0.00000000"], ["0.02817200", "13.39700000"], ["0.02812200", "0.00000000"]], "a": [["0.02820400", "134.68100000"], ["0.02820700", "0.00000000"], ["0.02820900", "0.49400000"], ["0.02821000", "5.00000000"], ["0.02821200", "0.00000000"], ["0.02821700", "7.96000000"], ["0.02821800", "16.63900000"], ["0.02822000", "3.12000000"], ["0.02822200", "5.20900000"], ["0.02822300", "38.45000000"], ["0.02822600", "28.23500000"], ["0.02823100", "40.71900000"], ["0.02823300", "0.00400000"], ["0.02823600", "46.72000000"], ["0.02824300", "10.51800000"]]}, {"e": "depthUpdate", "E": 1604224925329, "s": "ETHBTC", "U": 1737954289, "u": 1737954358, "b": [["0.02820300", "22.17600000"], ["0.02820200", "0.00000000"], ["0.02820000", "0.00000000"], ["0.02819900", "0.00000000"], ["0.02819800", "0.00000000"], ["0.02819700", "11.00000000"], ["0.02819600", "0.00000000"], ["0.02819500", "0.00000000"], ["0.02819400", "1.00000000"], ["0.02819300", "0.23900000"], ["0.02819100", "2.26400000"], ["0.02819000", "12.26500000"], ["0.02818900", "7.90800000"], ["0.02818600", "7.25600000"], ["0.02818500", "12.24900000"], ["0.02818400", "3.41100000"], ["0.02818300", "12.92100000"], ["0.02818200", "17.85500000"], ["0.02817900", "1.34900000"], ["0.02817800", "6.01300000"], ["0.02817700", "6.43800000"], ["0.02817600", "37.37000000"], ["0.02817500", "5.38300000"], ["0.02817400", "14.81000000"], ["0.02817300", "4.03600000"], ["0.02817100", "5.39600000"], ["0.02816400", "47.96200000"], ["0.02816200", "5.23000000"]], "a": [["0.02820400", "148.64100000"], ["0.02820500", "25.00000000"], ["0.02820800", "11.00000000"], ["0.02821000", "4.00000000"], ["0.02821600", "0.00000000"], ["0.02821700", "0.00000000"], ["0.02821800", "6.94200000"], ["0.02822200", "20.12400000"], ["0.02823200", "2.69400000"], ["0.02823600", "48.07000000"]]}, {"e": "depthUpdate", "E": 1604224926328, "s": "ETHBTC", "U": 1737954359, "u": 1737954393, "b": [["0.02820300", "7.25200000"], ["0.02819600", "0.00000000"], ["0.02819400", "0.00000000"], ["0.02819300", "0.00000000"], ["0.02819000", "8.09200000"], ["0.02818600", "9.06900000"], ["0.02818200", "13.52700000"], ["0.02818100", "7.16400000"], ["0.02817900", "6.57600000"], ["0.02817800", "0.01000000"], ["0.02817700", "1.96900000"], ["0.02817300", "9.71500000"], ["0.02817000", "0.00000000"], ["0.02816600", "5.20700000"], ["0.02815300", "65.95000000"], ["0.02805800", "0.00000000"], ["0.02763500", "0.16900000"], ["0.02758900", "0.00000000"], ["0.01410200", "3.00000000"]], "a": [["0.02820400", "148.64100000"], ["0.02821300", "17.47300000"], ["0.02998000", "6.18600000"]]}, {"e": "depthUpdate", "E": 1604224927329, "s": "ETHBTC", "U": 1737954394, "u": 1737954475, "b": [["0.02820300", "0.00000000"], ["0.02820100", "76.78800000"], ["0.02820000", "0.00000000"], ["0.02819900", "0.13800000"], ["0.02819700", "0.00000000"], ["0.02819600", "5.83200000"], ["0.02819500", "0.00000000"], ["0.02819400", "0.00000000"], ["0.02819300", "7.41100000"], ["0.02819200", "20.61200000"], ["0.02819000", "0.00000000"], ["0.02818900", "3.90800000"], ["0.02818700", "5.17600000"], ["0.02818600", "8.90600000"], ["0.02818500", "6.41700000"], ["0.02818400", "0.00000000"], ["0.02818200", "0.00800000"], ["0.02818000", "6.42300000"], ["0.02817400", "14.81000000"], ["0.02816700", "7.09400000"], ["0.02816300", "0.00400000"], ["0.02815200", "0.00000000"], ["0.02805600", "0.41700000"], ["0.01410200", "0.00000000"]], "a": [["0.02820200", "6.00000000"], ["0.02820300", "0.00000000"], ["0.02820400", "0.00000000"], ["0.02820500", "24.00000000"], ["0.02820600", "0.00000000"], ["0.02820800", "0.00000000"], ["0.02820900", "0.00000000"], ["0.02821000", "4.00000000"], ["0.02821100", "0.24100000"], ["0.02821300", "13.13100000"], ["0.02821600", "4.00000000"], ["0.02821700", "0.00000000"], ["0.02822000", "14.91500000"], ["0.02822100", "19.56100000"], ["0.02822200", "5.20900000"], ["0.02822600", "32.56400000"], ["0.02822800", "22.80500000"], ["0.02823000", "0.06000000"], ["0.02824100", "7.88100000"]]}, {"e": "depthUpdate", "E": 1604224928329, "s": "ETHBTC", "U": 1737954476, "u": 1737954522, "b": [["0.02820100", "0.00000000"], ["0.02820000", "0.17700000"], ["0.02819900", "0.29000000"], ["0.02819800", "0.00000000"], ["0.02819100", "0.00000000"], ["0.02819000", "0.00000000"], ["0.02818800", "6.42000000"], ["0.02818500", "0.00000000"], ["0.02818400", "7.09300000"], ["0.02818100", "9.42800000"], ["0.02816700", "0.00000000"], ["0.02816300", "0.00000000"], ["0.01760200", "0.05000000"]], "a": [["0.02820100", "118.00000000"], ["0.02820200", "27.96000000"], ["0.02820400", "0.00000000"], ["0.02820800", "0.25900000"], ["0.02820900", "12.72500000"], ["0.02821100", "0.00000000"], ["0.02821800", "5.21800000"], ["0.02822100", "15.60100000"], ["0.02823100", "47.80800000"], ["0.02836900", "0.17400000"], ["0.02838800", "17.31800000"]]}, {"e": "depthUpdate", "E": 1604224929329, "s": "ETHBTC", "U": 1737954523, "u": 1737954573, "b": [["0.02819900", "0.00000000"], ["0.02819800", "0.19400000"], ["0.02819600", "0.00000000"], ["0.02819400", "3.54600000"], ["0.02819300", "4.00000000"], ["0.02818800", "0.00000000"], ["0.02818500", "12.25000000"], ["0.02818300", "20.01400000"], ["0.02818200", "8.59500000"], ["0.02817500", "28.18800000"], ["0.02812800", "0.10000000"], ["0.02735000", "5.14400000"], ["0.02734900", "0.12100000"], ["0.01493700", "0.04500000"]], "a": [["0.02820100", "150.00000000"], ["0.02821000", "0.00000000"], ["0.02821100", "0.00000000"], ["0.02821200", "0.00000000"], ["0.02821300", "17.46800000"], ["0.02821500", "20.48100000"], ["0.02821600", "0.00000000"], ["0.02821800", "5.21800000"], ["0.02822000", "0.00000000"], ["0.02822200", "20.12400000"], ["0.02822600", "12.32900000"], ["0.02822900", "40.48400000"], ["0.02823100", "7.33900000"], ["0.02823200", "5.81400000"]]}, {"e": "depthUpdate", "E": 1604224930329, "s": "ETHBTC", "U": 1737954574, "u": 1737954637, "b": [["0.02820000", "0.00000000"], ["0.02819800", "0.00000000"], ["0.02819700", "47.50000000"], ["0.02819600", "29.21400000"], ["0.02819500", "0.17500000"], ["0.02819400", "3.74700000"], ["0.02819200", "12.92700000"], ["0.02818700", "7.44000000"], ["0.02818400", "6.41900000"], ["0.02818300", "26.01800000"], ["0.02818100", "7.16400000"], ["0.02817100", "13.02400000"], ["0.02816700", "0.00000000"], ["0.02815400", "7.10100000"], ["0.02792600", "1.28200000"], ["0.02775900", "1.19400000"], ["0.02775700", "0.30400000"]], "a": [["0.02819700", "0.00000000"], ["0.02819800", "3.00400000"], ["0.02819900", "24.00000000"], ["0.02820000", "0.00000000"], ["0.02820100", "140.00000000"], ["0.02820200", "25.00000000"], ["0.02820500", "0.00000000"], ["0.02820600", "0.20700000"], ["0.02820700", "4.00000000"], ["0.02820800", "3.96000000"], ["0.02821200", "0.00000000"], ["0.02821300", "24.72200000"], ["0.02821500", "0.23600000"], ["0.02822700", "21.18600000"], ["0.02823100", "0.25000000"], ["0.02824100", "0.00000000"], ["0.02998000", "5.05900000"]]}, {"e": "depthUpdate", "E": 1604224931329, "s": "ETHBTC", "U": 1737954638, "u": 1737954756, "b": [["0.02819900", "0.00000000"], ["0.02819800", "0.00000000"], ["0.02819700", "0.00000000"], ["0.02819600", "0.00000000"], ["0.02819500", "23.89600000"], ["0.02819400", "3.54600000"], ["0.02819300", "1.17400000"], ["0.02819200", "0.00000000"], ["0.02819100", "0.00000000"], ["0.02819000", "0.00000000"], ["0.02818800", "4.00000000"], ["0.02818700", "5.17600000"], ["0.02818500", "12.25000000"], ["0.02818000", "6.42300000"], ["0.02817800", "2.27400000"], ["0.02817700", "2.17100000"], ["0.02817400", "12.93000000"], ["0.02817100", "22.46800000"], ["0.02816900", "0.00000000"], ["0.02816800", "5.39900000"], ["0.02815400", "0.00000000"], ["0.02814500", "0.00000000"], ["0.02708800", "0.07500000"], ["0.01760200", "0.01200000"]], "a": [["0.02819800", "0.14600000"], ["0.02819900", "23.00000000"], ["0.02820000", "1.00000000"], ["0.02820100", "136.00000000"], ["0.02820200", "24.00000000"], ["0.02820500", "0.00000000"], ["0.02820600", "0.00000000"], ["0.02820700", "0.00000000"], ["0.02821000", "0.00000000"], ["0.02821100", "4.00000000"], ["0.02821200", "18.91500000"], ["0.02821400", "1.66100000"], ["0.02821600", "5.10100000"], ["0.02821700", "0.00000000"], ["0.02822200", "0.04800000"], ["0.02824300", "5.39600000"], ["0.02825100", "16.80400000"], ["0.02826900", "0.00400000"], ["0.02998000", "6.18600000"]]}, {"e": "depthUpdate", "E": 1604224932329, "s": "ETHBTC", "U": 1737954757, "u": 1737954807, "b": [["0.02819700", "0.00000000"], ["0.02819600", "0.00000000"], ["0.02819500", "0.00000000"], ["0.02819400", "24.00000000"], ["0.02819300", "0.00000000"], ["0.02819000", "1.00000000"], ["0.02818900", "0.00000000"], ["0.02818600", "7.25600000"], ["0.02818000", "10.33100000"], ["0.02817900", "8.31500000"], ["0.02817800", "2.27400000"], ["0.02817700", "1.96900000"], ["0.02817300", "9.95300000"], ["0.02816900", "0.00000000"], ["0.02815400", "58.75400000"], ["0.02813800", "0.00000000"], ["0.02625000", "27.59700000"], ["0.01493700", "0.00000000"]], "a": [["0.02819600", "0.00000000"], ["0.02819700", "0.20200000"], ["0.02819800", "0.00000000"], ["0.02820000", "9.00000000"], ["0.02821100", "0.00000000"], ["0.02821200", "0.00000000"], ["0.02822800", "32.67900000"]]}, {"e": "depthUpdate", "E": 1604224933329, "s": "ETHBTC", "U": 1737954808, "u": 1737954895, "b": [["0.02819500", "0.00000000"], ["0.02819400", "23.64600000"], ["0.02819000", "0.00000000"], ["0.02818900", "11.00000000"], ["0.02818100", "3.90800000"], ["0.02818000", "6.42300000"], ["0.02817900", "1.73900000"], ["0.02817700", "1.96900000"], ["0.02817500", "4.48000000"], ["0.02817400", "13.16000000"], ["0.02817300", "8.37500000"], ["0.02817200", "8.00000000"], ["0.02817100", "11.67800000"], ["0.02816700", "5.39800000"], ["0.02816600", "21.39200000"], ["0.02816400", "38.56100000"], ["0.02816300", "4.22000000"], ["0.02816000", "14.81400000"], ["0.02815300", "2.01000000"], ["0.02813500", "63.96300000"], ["0.02812000", "7.21400000"], ["0.02792100", "0.00400000"], ["0.02708300", "0.00400000"]], "a": [["0.02819500", "5.12800000"], ["0.02819600", "136.00000000"], ["0.02819700", "0.14600000"], ["0.02819800", "1.72600000"], ["0.02820000", "12.00000000"], ["0.02820100", "24.00000000"], ["0.02820200", "0.00000000"], ["0.02820700", "0.00000000"], ["0.02820800", "3.96000000"], ["0.02820900", "0.00000000"], ["0.02821000", "4.00000000"], ["0.02821100", "4.00000000"], ["0.02821200", "0.00000000"], ["0.02821600", "5.10100000"], ["0.02822300", "41.57100000"], ["0.02822500", "14.35900000"], ["0.02822800", "9.87400000"], ["0.02823200", "2.69400000"], ["0.02823300", "66.34400000"], ["0.02825500", "150.05400000"]]}, {"e": "depthUpdate", "E": 1604224934329, "s": "ETHBTC", "U": 1737954896, "u": 1737954958, "b": [["0.02819400", "0.00000000"], ["0.02819300", "50.91100000"], ["0.02819200", "3.90800000"], ["0.02819100", "0.00000000"], ["0.02819000", "24.00000000"], ["0.02818900", "0.17400000"], ["0.02818700", "0.00000000"], ["0.02818600", "1.72600000"], ["0.02818300", "31.19600000"], ["0.02818200", "5.18400000"], ["0.02818100", "2.07400000"], ["0.02817800", "15.05100000"], ["0.02817700", "2.21800000"], ["0.02817600", "37.37000000"], ["0.02817400", "12.93000000"], ["0.02817300", "4.04600000"], ["0.02816300", "8.55000000"], ["0.02812800", "0.00000000"], ["0.02810300", "43.07300000"], ["0.02624500", "0.00400000"]], "a": [["0.02819300", "0.00000000"], ["0.02819400", "0.14400000"], ["0.02819500", "5.08400000"], ["0.02819600", "24.00000000"], ["0.02819700", "0.00000000"], ["0.02820000", "0.00000000"], ["0.02820100", "0.00000000"], ["0.02820700", "7.66300000"], ["0.02821200", "14.91500000"], ["0.02821400", "4.36000000"], ["0.02821900", "12.90300000"], ["0.02822100", "60.14500000"], ["0.02822200", "12.19300000"], ["0.02822500", "7.26900000"], ["0.02822600", "17.73100000"], ["0.02822900", "0.00000000"], ["0.02823200", "0.00000000"], ["0.02823400", "5.24100000"], ["0.02823700", "0.00000000"], ["0.02823900", "0.00000000"], ["0.02824300", "0.00000000"], ["0.02824800", "2.69700000"]]}, {"e": "depthUpdate", "E": 1604224935329, "s": "ETHBTC", "U": 1737954959, "u": 1737955070, "b": [["0.02819900", "77.59300000"], ["0.02819800", "5.17400000"], ["0.02819700", "24.00000000"], ["0.02819600", "0.00000000"], ["0.02819500", "33.63600000"], ["0.02819400", "0.00000000"], ["0.02819300", "3.41100000"], ["0.02819000", "0.00000000"], ["0.02818800", "0.00000000"], ["0.02818700", "4.48600000"], ["0.02818500", "6.41800000"], ["0.02818400", "7.27300000"], ["0.02818300", "20.22900000"], ["0.02818200", "0.00800000"], ["0.02818100", "2.07400000"], ["0.02818000", "10.75100000"], ["0.02817800", "15.05100000"], ["0.02817700", "1.96900000"], ["0.02817500", "0.00000000"], ["0.02817200", "8.00000000"], ["0.02816300", "4.22000000"], ["0.02804700", "0.06600000"], ["0.02803800", "21.04200000"]], "a": [["0.02819400", "0.00000000"], ["0.02819500", "0.00000000"], ["0.02819600", "0.00000000"], ["0.02819800", "0.00000000"], ["0.02819900", "0.00000000"], ["0.02820000", "0.00000000"], ["0.02820200", "0.27700000"], ["0.02820700", "0.00000000"], ["0.02820900", "0.00000000"], ["0.02821000", "4.00000000"], ["0.02821200", "14.91500000"], ["0.02821300", "20.38500000"], ["0.02821500", "0.23600000"], ["0.02821600", "2.70000000"], ["0.02821700", "0.00000000"], ["0.02821800", "25.46900000"], ["0.02821900", "7.50200000"], ["0.02822100", "20.69900000"], ["0.02822300", "38.45000000"], ["0.02822400", "22.36200000"], ["0.02822500", "49.12000000"], ["0.02822600", "13.40200000"], ["0.02822700", "0.93900000"], ["0.02823200", "3.12100000"], ["0.02823700", "4.32800000"], ["0.02824800", "0.00000000"], ["0.02825300", "0.00500000"], ["0.02838400", "16.51800000"], ["0.02839900", "0.28000000"], ["0.02998000", "5.05900000"]]}, {"e": "depthUpdate", "E": 1604224936329, "s": "ETHBTC", "U": 1737955071, "u": 1737955149, "b": [["0.02820000", "0.00000000"], ["0.02819900", "24.00000000"], ["0.02819800", "0.09300000"], ["0.02819500", "0.00000000"], ["0.02819300", "0.00000000"], ["0.02818800", "3.84400000"], ["0.02818700", "10.90900000"], ["0.02818600", "7.55800000"], ["0.02818400", "9.53700000"], ["0.02818200", "3.41900000"], ["0.02817800", "12.78700000"], ["0.02815600", "0.00000000"], ["0.02805600", "0.00400000"], ["0.02792300", "0.51500000"]], "a": [["0.02820000", "112.17800000"], ["0.02820100", "24.00700000"], ["0.02820200", "24.25100000"], ["0.02820300", "0.00000000"], ["0.02821100", "19.60100000"], ["0.02821200", "14.91500000"], ["0.02821400", "1.66100000"], ["0.02821600", "0.00000000"], ["0.02821700", "2.69800000"], ["0.02821800", "24.58400000"], ["0.02822000", "2.70000000"], ["0.02822100", "5.09800000"], ["0.02822200", "0.04800000"], ["0.02822700", "13.08300000"], ["0.02823100", "3.37100000"], ["0.02842300", "1.23700000"], ["0.02845300", "0.00800000"], ["0.02856400", "0.25500000"], ["0.02998000", "6.18600000"]]}, {"e": "depthUpdate", "E": 1604224937329, "s": "ETHBTC", "U": 1737955150, "u": 1737955201, "b": [["0.02819900", "0.00000000"], ["0.02819800", "0.00000000"], ["0.02819700", "0.00000000"], ["0.02819400", "5.03700000"], ["0.02819300", "24.00000000"], ["0.02818700", "6.42300000"], ["0.02818300", "26.02000000"], ["0.02818100", "2.07400000"], ["0.02818000", "10.90800000"], ["0.02817700", "2.21400000"], ["0.02817500", "0.00400000"], ["0.02817100", "11.67800000"], ["0.02816400", "42.89100000"], ["0.02815500", "150.00000000"], ["0.02807800", "0.45700000"], ["0.02792500", "80.53900000"]], "a": [["0.02819600", "0.00000000"], ["0.02819700", "5.32900000"], ["0.02819800", "28.00000000"], ["0.02819900", "0.00000000"], ["0.02820000", "136.00000000"], ["0.02820200", "0.00000000"], ["0.02820800", "0.00000000"], ["0.02821100", "4.00000000"], ["0.02821200", "14.91500000"], ["0.02822000", "7.93500000"], ["0.02822200", "15.64900000"], ["0.02822500", "71.92500000"]]}, {"e": "depthUpdate", "E": 1604224938329, "s": "ETHBTC", "U": 1737955202, "u": 1737955220, "b": [["0.02819000", "11.00000000"], ["0.02818800", "9.02200000"], ["0.02818300", "31.39300000"], ["0.02817800", "7.68700000"], ["0.02817700", "1.96900000"], ["0.02816800", "5.39900000"], ["0.02815600", "7.10100000"]], "a": [["0.02820100", "35.00700000"], ["0.02820900", "4.33300000"], ["0.02821000", "18.91500000"], ["0.02821100", "4.00000000"], ["0.02821200", "5.10200000"], ["0.02821800", "20.25100000"], ["0.02822100", "0.00000000"], ["0.02857800", "0.04300000"]]}, {"e": "depthUpdate", "E": 1604224939330, "s": "ETHBTC", "U": 1737955221, "u": 1737955335, "b": [["0.02820000", "30.00000000"], ["0.02819900", "29.08700000"], ["0.02819800", "9.38200000"], ["0.02819700", "0.00000000"], ["0.02819600", "24.00000000"], ["0.02819500", "0.00000000"], ["0.02819400", "0.00000000"], ["0.02819300", "0.00000000"], ["0.02819200", "0.00000000"], ["0.02819000", "0.00000000"], ["0.02818900", "4.08200000"], ["0.02818800", "45.91800000"], ["0.02818700", "13.51400000"], ["0.02818600", "1.72600000"], ["0.02818300", "26.02000000"], ["0.02818200", "0.00800000"], ["0.02818100", "5.91800000"], ["0.02817900", "1.73900000"], ["0.02817700", "11.47100000"], ["0.02817500", "0.00000000"], ["0.02817200", "30.80500000"], ["0.02816400", "38.56100000"], ["0.02816300", "0.00000000"], ["0.02815600", "0.00000000"], ["0.02785700", "1.20000000"]], "a": [["0.02819700", "0.00000000"], ["0.02819800", "0.00000000"], ["0.02820000", "0.00000000"], ["0.02820100", "35.00700000"], ["0.02820200", "0.00000000"], ["0.02820300", "0.00000000"], ["0.02820400", "0.12000000"], ["0.02820800", "0.00000000"], ["0.02820900", "0.00000000"], ["0.02821000", "4.00000000"], ["0.02821100", "4.00000000"], ["0.02821200", "0.00000000"], ["0.02821600", "8.33800000"], ["0.02821700", "17.61300000"], ["0.02822000", "5.23500000"], ["0.02822400", "25.06200000"], ["0.02822800", "0.00000000"], ["0.02823400", "8.78700000"], ["0.02824000", "4.31600000"], ["0.02856400", "3.92500000"]]}, {"e": "depthUpdate", "E": 1604224940329, "s": "ETHBTC", "U": 1737955336, "u": 1737955429, "b": [["0.02820300", "6.00000000"], ["0.02820200", "0.00000000"], ["0.02820100", "0.00000000"], ["0.02820000", "72.00000000"], ["0.02819900", "24.15100000"], ["0.02819800", "0.00000000"], ["0.02819200", "7.79000000"], ["0.02819000", "3.84400000"], ["0.02818900", "9.91400000"], ["0.02818800", "47.83200000"], ["0.02818700", "6.42300000"], ["0.02818600", "5.13700000"], ["0.02818100", "2.07400000"], ["0.02817900", "1.83900000"], ["0.02817300", "4.04600000"], ["0.02785000", "12.61100000"], ["0.02680800", "12.32600000"]], "a": [["0.02820100", "0.00000000"], ["0.02820300", "0.00000000"], ["0.02820400", "0.00000000"], ["0.02820700", "24.00000000"], ["0.02820800", "0.14100000"], ["0.02820900", "0.00000000"], ["0.02821000", "4.00000000"], ["0.02821200", "14.91500000"], ["0.02821300", "13.13100000"], ["0.02821400", "1.66100000"], ["0.02821500", "4.23600000"], ["0.02821600", "4.33800000"], ["0.02821700", "0.00000000"], ["0.02821800", "0.00000000"], ["0.02822100", "0.00000000"], ["0.02822400", "19.66100000"], ["0.02822500", "92.16700000"], ["0.02822800", "5.39900000"], ["0.02856400", "3.79600000"], ["0.02998000", "6.18600000"]]}, {"e": "depthUpdate", "E": 1604224941329, "s": "ETHBTC", "U": 1737955430, "u": 1737955504, "b": [["0.02820600", "0.00000000"], ["0.02820500", "0.00000000"], ["0.02820400", "9.77300000"], ["0.02820300", "0.00000000"], ["0.02820200", "4.99800000"], ["0.02820100", "13.15100000"], ["0.02820000", "72.00000000"], ["0.02819900", "24.16700000"], ["0.02819600", "0.00000000"], ["0.02819300", "7.09100000"], ["0.02819100", "7.09200000"], ["0.02819000", "0.00000000"], ["0.02818900", "2.43800000"], ["0.02818800", "40.74000000"], ["0.02818600", "1.72600000"], ["0.02818400", "7.27300000"], ["0.02818300", "12.92100000"], ["0.02818100", "0.00000000"], ["0.02817900", "1.73900000"], ["0.02817700", "6.29700000"], ["0.02817200", "8.00000000"], ["0.02680800", "13.97900000"]], "a": [["0.02820500", "139.21300000"], ["0.02820600", "0.00000000"], ["0.02820700", "24.00000000"], ["0.02820800", "0.00000000"], ["0.02820900", "0.00000000"], ["0.02821000", "0.00000000"], ["0.02821100", "4.00000000"], ["0.02821200", "0.00000000"], ["0.02821900", "11.50200000"], ["0.02822000", "0.00000000"], ["0.02822100", "14.91500000"], ["0.02822300", "43.54600000"], ["0.02822400", "15.62100000"], ["0.02822500", "70.71000000"], ["0.02822600", "8.00000000"], ["0.02823100", "8.76100000"], ["0.02823400", "14.18600000"]]}, {"e": "depthUpdate", "E": 1604224942329, "s": "ETHBTC", "U": 1737955505, "u": 1737955613, "b": [["0.02821000", "0.49800000"], ["0.02820900", "5.75100000"], ["0.02820800", "0.00000000"], ["0.02820700", "5.05900000"], ["0.02820600", "72.27300000"], ["0.02820500", "0.64200000"], ["0.02820400", "27.84400000"], ["0.02820200", "5.83200000"], ["0.02820100", "7.31900000"], ["0.02820000", "29.17300000"], ["0.02819900", "0.00000000"], ["0.02819400", "6.41400000"], ["0.02819100", "0.00000000"], ["0.02819000", "0.00000000"], ["0.02818900", "8.67300000"], ["0.02818700", "6.00100000"], ["0.02818500", "0.00000000"], ["0.02818000", "6.42300000"], ["0.02817900", "0.00000000"], ["0.02817600", "42.55900000"]], "a": [["0.02820500", "0.00000000"], ["0.02820700", "0.00000000"], ["0.02820900", "0.00000000"], ["0.02821100", "0.00000000"], ["0.02821300", "0.35800000"], ["0.02821400", "0.00000000"], ["0.02821600", "0.00000000"], ["0.02821800", "14.91500000"], ["0.02822000", "4.00000000"], ["0.02822100", "0.00000000"], ["0.02822200", "15.64900000"], ["0.02822300", "5.09600000"], ["0.02822400", "12.92100000"], ["0.02822500", "9.96700000"], ["0.02822700", "0.93900000"], ["0.02822800", "0.00000000"], ["0.02822900", "20.23800000"], ["0.02823000", "0.06000000"], ["0.02823100", "4.29900000"], ["0.02823200", "15.26200000"], ["0.02823300", "84.66500000"], ["0.02823400", "12.82600000"], ["0.02823900", "40.47600000"]]}, {"e": "depthUpdate", "E": 1604224943330, "s": "ETHBTC", "U": 1737955614, "u": 1737955656, "b": [["0.02820800", "0.00000000"], ["0.02820700", "5.23200000"], ["0.02820600", "72.00000000"], ["0.02820500", "0.74900000"], ["0.02819500", "13.51600000"], ["0.02819400", "27.33600000"], ["0.02817900", "0.00000000"], ["0.02817400", "0.00000000"], ["0.02817200", "0.00000000"], ["0.02816200", "0.00000000"]], "a": [["0.02821100", "136.21200000"], ["0.02821200", "24.00000000"], ["0.02821400", "11.00000000"], ["0.02821700", "0.00000000"], ["0.02821800", "0.00000000"], ["0.02821900", "4.00000000"], ["0.02822200", "0.04800000"], ["0.02822300", "1.62400000"], ["0.02822400", "17.25900000"], ["0.02822500", "7.26900000"], ["0.02822800", "20.69400000"], ["0.02823000", "2.75800000"], ["0.02823700", "27.13300000"], ["0.02823800", "5.42500000"], ["0.02824100", "7.85000000"], ["0.02856400", "0.12600000"]]}, {"e": "depthUpdate", "E": 1604224944329, "s": "ETHBTC", "U": 1737955657, "u": 1737955680, "b": [["0.02820800", "0.00000000"], ["0.02820700", "5.06800000"], ["0.02820600", "72.17800000"], ["0.02820500", "0.10700000"], ["0.02819600", "2.26400000"], ["0.02819500", "6.42500000"], ["0.02818900", "6.40900000"], ["0.02818400", "12.41000000"], ["0.02815600", "63.92200000"], ["0.02813500", "0.00000000"]], "a": [["0.02821100", "139.21200000"], ["0.02821500", "0.23600000"], ["0.02822000", "8.00000000"], ["0.02822100", "0.00800000"], ["0.02823100", "2.94900000"], ["0.02823300", "18.32500000"], ["0.02823700", "28.48200000"], ["0.02825400", "66.34000000"], ["0.02998000", "5.05900000"]]}, {"e": "depthUpdate", "E": 1604224945329, "s": "ETHBTC", "U": 1737955681, "u": 1737955737, "b": [["0.02821000", "0.00000000"], ["0.02820900", "5.75100000"], ["0.02820800", "0.00000000"], ["0.02820700", "0.00000000"], ["0.02820600", "0.27000000"], ["0.02820500", "0.10700000"], ["0.02820400", "0.00000000"], ["0.02820200", "0.00000000"], ["0.02820100", "0.00000000"], ["0.02819800", "7.09000000"], ["0.02819700", "3.84400000"], ["0.02819200", "17.53000000"], ["0.02819000", "3.41100000"], ["0.02818800", "45.91400000"], ["0.02818200", "22.81300000"], ["0.02818100", "0.00000000"], ["0.02817900", "3.12000000"], ["0.02815100", "31.65800000"], ["0.02810300", "0.07300000"]], "a": [["0.02821000", "139.21100000"], ["0.02821100", "25.72500000"], ["0.02821200", "24.27000000"], ["0.02821300", "0.20800000"], ["0.02821400", "0.00000000"], ["0.02821900", "4.00000000"], ["0.02822100", "0.01200000"], ["0.02822300", "16.53900000"], ["0.02998000", "6.18600000"]]}, {"e": "depthUpdate", "E": 1604224946329, "s": "ETHBTC", "U": 1737955738, "u": 1737955812, "b": [["0.02820900", "0.00000000"], ["0.02820600", "0.00000000"], ["0.02820500", "0.00000000"], ["0.02820400", "0.00000000"], ["0.02820300", "53.75100000"], ["0.02820200", "0.00000000"], ["0.02820100", "5.02100000"], ["0.02820000", "29.45300000"], ["0.02819800", "0.00000000"], ["0.02819700", "0.00000000"], ["0.02819600", "6.10800000"], ["0.02819500", "0.00000000"], ["0.02819400", "33.33800000"], ["0.02819200", "7.79000000"], ["0.02819000", "13.15100000"], ["0.02818800", "40.74000000"], ["0.02818700", "0.00000000"], ["0.02818400", "12.41000000"], ["0.02817400", "5.39600000"], ["0.02816800", "0.00000000"], ["0.02815300", "2.01000000"]], "a": [["0.02820400", "0.28300000"], ["0.02820600", "24.00000000"], ["0.02820700", "0.00000000"], ["0.02820800", "8.00000000"], ["0.02820900", "14.91500000"], ["0.02821000", "136.00000000"], ["0.02821200", "0.00000000"], ["0.02821700", "7.59100000"], ["0.02821800", "4.00000000"], ["0.02821900", "0.00000000"], ["0.02822000", "0.00000000"], ["0.02822100", "0.02000000"], ["0.02822300", "1.62400000"], ["0.02823200", "3.12100000"], ["0.02823600", "60.21000000"]]}, {"e": "depthUpdate", "E": 1604224947329, "s": "ETHBTC", "U": 1737955813, "u": 1737955889, "b": [["0.02820600", "0.00000000"], ["0.02820500", "5.02100000"], ["0.02820400", "0.00000000"], ["0.02820300", "24.00000000"], ["0.02820200", "0.00000000"], ["0.02820100", "0.12500000"], ["0.02820000", "5.17300000"], ["0.02819600", "3.84400000"], ["0.02819500", "6.42400000"], ["0.02819000", "15.41500000"], ["0.02818600", "1.73000000"], ["0.02816500", "0.00000000"], ["0.02805100", "21.04100000"], ["0.02803800", "0.00000000"]], "a": [["0.02820400", "0.00000000"], ["0.02820600", "3.00000000"], ["0.02820700", "136.00000000"], ["0.02820800", "0.00000000"], ["0.02820900", "0.14700000"], ["0.02821000", "24.00000000"], ["0.02822100", "4.02000000"], ["0.02822200", "4.04800000"], ["0.02822300", "16.53900000"], ["0.02823200", "0.00000000"], ["0.02823600", "100.68500000"], ["0.02823900", "0.00000000"], ["0.02824000", "0.09600000"], ["0.02838400", "0.51800000"]]}, {"e": "depthUpdate", "E": 1604224948329, "s": "ETHBTC", "U": 1737955890, "u": 1737955992, "b": [["0.02820500", "0.00000000"], ["0.02820400", "0.00000000"], ["0.02820300", "0.00000000"], ["0.02820100", "0.00000000"], ["0.02820000", "58.49500000"], ["0.02819900", "0.00000000"], ["0.02819800", "0.00000000"], ["0.02819600", "0.00000000"], ["0.02819500", "5.17400000"], ["0.02819400", "27.33600000"], ["0.02819300", "0.00000000"], ["0.02819200", "0.12300000"], ["0.02819100", "3.84400000"], ["0.02819000", "15.41500000"], ["0.02818900", "4.65600000"], ["0.02818700", "0.00000000"], ["0.02818400", "8.90800000"], ["0.02818200", "0.00800000"], ["0.02817700", "8.99500000"], ["0.02817300", "1.34700000"], ["0.02817100", "23.82100000"], ["0.02816800", "5.39800000"], ["0.02816600", "9.24700000"], ["0.02816400", "33.16000000"], ["0.02815500", "150.00000000"], ["0.02807800", "0.04400000"], ["0.02680800", "13.97900000"]], "a": [["0.02820100", "27.00000000"], ["0.02820200", "4.00000000"], ["0.02820300", "0.18900000"], ["0.02820400", "0.00000000"], ["0.02820500", "136.00000000"], ["0.02820600", "0.00000000"], ["0.02820700", "24.00000000"], ["0.02820900", "11.00000000"], ["0.02821000", "0.00000000"], ["0.02821100", "1.72500000"], ["0.02821200", "1.67300000"], ["0.02821600", "4.00000000"], ["0.02821800", "0.00000000"], ["0.02822200", "14.96300000"], ["0.02822300", "48.82000000"], ["0.02822400", "37.49800000"], ["0.02822900", "0.00000000"], ["0.02823700", "8.79700000"], ["0.02839900", "16.28000000"]]}, {"e": "depthUpdate", "E": 1604224949329, "s": "ETHBTC", "U": 1737955993, "u": 1737956103, "b": [["0.02820400", "9.74000000"], ["0.02820300", "9.41100000"], ["0.02820200", "24.00000000"], ["0.02820100", "72.00000000"], ["0.02820000", "24.00000000"], ["0.02819600", "5.17400000"], ["0.02819500", "5.38300000"], ["0.02819400", "34.58600000"], ["0.02819300", "0.00000000"], ["0.02819200", "0.00000000"], ["0.02819100", "9.84600000"], ["0.02819000", "6.42100000"], ["0.02818900", "4.65600000"], ["0.02818600", "1.72600000"], ["0.02818500", "2.26400000"], ["0.02818100", "0.00000000"], ["0.02815100", "8.65800000"], ["0.02810200", "30.18300000"], ["0.02806000", "0.41300000"], ["0.02763600", "0.01300000"]], "a": [["0.02820100", "0.00000000"], ["0.02820200", "0.00000000"], ["0.02820300", "0.00000000"], ["0.02820400", "0.00000000"], ["0.02820500", "0.00000000"], ["0.02820700", "0.00000000"], ["0.02820900", "0.00000000"], ["0.02821000", "24.00000000"], ["0.02821200", "0.00000000"], ["0.02821600", "4.00000000"], ["0.02821800", "14.91500000"], ["0.02821900", "9.09800000"], ["0.02822000", "0.00000000"], ["0.02822100", "19.62100000"], ["0.02822200", "0.04800000"], ["0.02822800", "0.00000000"], ["0.02824000", "0.09600000"], ["0.02857800", "4.43800000"], ["0.02858500", "5.76000000"], ["0.02998000", "6.18600000"]]}, {"e": "depthUpdate", "E": 1604224950329, "s": "ETHBTC", "U": 1737956104, "u": 1737956163, "b": [["0.02820600", "0.00000000"], ["0.02820500", "48.00000000"], ["0.02820400", "0.00000000"], ["0.02820300", "0.00000000"], ["0.02820100", "0.00000000"], ["0.02820000", "0.00000000"], ["0.02819900", "0.16300000"], ["0.02819700", "3.84400000"], ["0.02819500", "17.17800000"], ["0.02819200", "7.09200000"], ["0.02819100", "9.41300000"], ["0.02818500", "0.00000000"], ["0.02818100", "7.09100000"], ["0.02764000", "1.10500000"]], "a": [["0.02820600", "0.00000000"], ["0.02820700", "136.00000000"], ["0.02820800", "0.19800000"], ["0.02820900", "0.00000000"], ["0.02821500", "4.00000000"], ["0.02821600", "5.68700000"], ["0.02821800", "0.00000000"], ["0.02821900", "5.09800000"], ["0.02822200", "14.96300000"], ["0.02822800", "22.80500000"], ["0.03000000", "349.15300000"]]}, {"e": "depthUpdate", "E": 1604224951329, "s": "ETHBTC", "U": 1737956164, "u": 1737956174, "b": [["0.02820600", "0.00000000"], ["0.02820500", "0.00000000"], ["0.02819500", "14.91400000"], ["0.02819000", "8.68500000"]], "a": [["0.02820800", "0.00000000"], ["0.02820900", "0.28600000"]]}, {"e": "depthUpdate", "E": 1604224952329, "s": "ETHBTC", "U": 1737956175, "u": 1737956188, "b": [["0.02820300", "5.20300000"], ["0.02818000", "29.22800000"], ["0.02817500", "1.35000000"], ["0.02817200", "5.39900000"], ["0.02817100", "22.47100000"], ["0.02816800", "0.00000000"], ["0.02816700", "5.39800000"]], "a": [["0.02820800", "0.22700000"], ["0.02820900", "0.00000000"], ["0.02822600", "13.23100000"], ["0.02822700", "41.42200000"], ["0.02823300", "28.19900000"], ["0.02823600", "60.21000000"]]}, {"e": "depthUpdate", "E": 1604224953329, "s": "ETHBTC", "U": 1737956189, "u": 1737956228, "b": [["0.02820300", "0.00000000"], ["0.02820200", "0.00000000"], ["0.02820000", "5.20300000"], ["0.02819900", "11.00000000"], ["0.02819600", "0.00000000"], ["0.02819500", "14.91400000"], ["0.02819400", "27.33600000"], ["0.02819200", "0.28300000"], ["0.02818900", "0.17400000"], ["0.02818500", "7.09300000"], ["0.02818100", "9.66800000"], ["0.02818000", "6.42300000"], ["0.02816100", "0.00000000"], ["0.02791700", "0.33200000"]], "a": [["0.02820300", "24.13200000"], ["0.02820400", "4.00000000"], ["0.02820500", "4.00000000"], ["0.02820600", "19.21200000"], ["0.02820800", "0.00000000"], ["0.02821100", "12.72500000"], ["0.02821500", "0.00000000"], ["0.02821600", "1.68700000"], ["0.02822100", "15.62100000"], ["0.02822200", "0.04800000"], ["0.02822400", "33.16000000"], ["0.02822700", "0.93900000"], ["0.02823200", "40.48500000"]]}, {"e": "depthUpdate", "E": 1604224954329, "s": "ETHBTC", "U": 1737956229, "u": 1737956254, "b": [["0.02819400", "20.92200000"], ["0.02819300", "0.15300000"], ["0.02819200", "0.00000000"], ["0.02818700", "6.41600000"], ["0.02817400", "5.39600000"], ["0.02808500", "0.05600000"]], "a": [["0.02820300", "24.00000000"], ["0.02820500", "4.12100000"], ["0.02821500", "4.33600000"], ["0.02823600", "58.86000000"], ["0.02998000", "6.18600000"], ["0.03261300", "6.51100000"]]}, {"e": "depthUpdate", "E": 1604224955330, "s": "ETHBTC", "U": 1737956255, "u": 1737956285, "b": [["0.02819900", "11.00000000"], ["0.02819700", "0.00000000"], ["0.02819500", "0.18900000"], ["0.02819300", "0.00000000"], ["0.02819200", "3.84400000"], ["0.02819100", "16.50500000"], ["0.02818600", "11.46600000"], ["0.02817600", "65.36400000"], ["0.02815700", "0.00000000"], ["0.02807500", "1.68700000"], ["0.02806000", "0.00000000"], ["0.02792500", "81.07500000"]], "a": [["0.02820300", "24.23400000"], ["0.02820400", "4.00000000"], ["0.02820500", "5.72500000"], ["0.02821100", "11.00000000"], ["0.02823000", "4.10100000"]]}, {"e": "depthUpdate", "E": 1604224956329, "s": "ETHBTC", "U": 1737956286, "u": 1737956299, "b": [["0.02820000", "4.56600000"], ["0.02819100", "21.68000000"], ["0.02817900", "3.22000000"], ["0.02817400", "0.00000000"], ["0.02817100", "27.86900000"], ["0.02805600", "0.41700000"], ["0.02800800", "59.78000000"]], "a": [["0.02820200", "0.63700000"], ["0.02820600", "4.29700000"], ["0.02821500", "17.26400000"], ["0.02822100", "35.86300000"], ["0.02822400", "12.92100000"], ["0.02822800", "0.00000000"], ["0.02823300", "15.27600000"]]}, {"e": "depthUpdate", "E": 1604224957329, "s": "ETHBTC", "U": 1737956300, "u": 1737956311, "b": [["0.02820100", "0.00000000"], ["0.02819000", "6.42100000"], ["0.02818900", "2.43800000"], ["0.02818600", "9.74000000"], ["0.02817000", "0.00400000"], ["0.02801500", "0.56800000"]], "a": [["0.02820200", "2.00800000"], ["0.02820500", "4.00000000"], ["0.02822500", "12.66700000"], ["0.02823300", "9.87800000"]]}, {"e": "depthUpdate", "E": 1604224958330, "s": "ETHBTC", "U": 1737956312, "u": 1737956348, "b": [["0.02820000", "0.00000000"], ["0.02819900", "0.00000000"], ["0.02819700", "30.00000000"], ["0.02819600", "0.00000000"], ["0.02819500", "0.00000000"], ["0.02819400", "11.00000000"], ["0.02819100", "15.84300000"], ["0.02819000", "0.00000000"], ["0.02818800", "0.00000000"], ["0.02818400", "14.91000000"], ["0.02817700", "21.92300000"], ["0.02817300", "9.34700000"], ["0.02815600", "0.00000000"], ["0.02814300", "65.05900000"], ["0.02680800", "13.97900000"]], "a": [["0.02819800", "0.18600000"], ["0.02820100", "0.00000000"], ["0.02820200", "0.00000000"], ["0.02820300", "20.97400000"], ["0.02820500", "15.00000000"], ["0.02822200", "2.74700000"], ["0.02822700", "23.74400000"], ["0.02822800", "40.48800000"], ["0.02823000", "1.40300000"], ["0.02823200", "0.00000000"], ["0.02823800", "0.02800000"], ["0.02998000", "5.05900000"]]}, {"e": "depthUpdate", "E": 1604224959330, "s": "ETHBTC", "U": 1737956349, "u": 1737956393, "b": [["0.02819900", "0.00000000"], ["0.02819800", "0.00000000"], ["0.02819700", "48.00000000"], ["0.02819500", "0.00000000"], ["0.02819400", "0.12500000"], ["0.02819300", "0.00000000"], ["0.02819100", "8.58600000"], ["0.02818900", "0.17400000"], ["0.02818500", "20.60600000"], ["0.02818100", "13.21400000"], ["0.02817900", "0.10000000"], ["0.02817800", "9.95100000"], ["0.02817600", "37.37000000"], ["0.02817500", "0.00000000"], ["0.02817200", "0.00000000"], ["0.02817000", "1.35000000"], ["0.02816500", "5.39900000"], ["0.02812200", "0.10000000"], ["0.02805100", "0.00800000"], ["0.02804000", "21.04100000"]], "a": [["0.02819800", "0.00000000"], ["0.02820000", "0.00000000"], ["0.02820400", "4.22900000"], ["0.02822700", "0.93900000"], ["0.02822800", "47.57700000"], ["0.02822900", "5.39900000"], ["0.02998000", "6.18600000"]]}, {"e": "depthUpdate", "E": 1604224960330, "s": "ETHBTC", "U": 1737956394, "u": 1737956404, "b": [["0.02819800", "4.79600000"], ["0.02818700", "8.68000000"], ["0.02817800", "7.68700000"], ["0.02817100", "15.72600000"], ["0.02816900", "12.14400000"]], "a": [["0.02820200", "2.12000000"], ["0.02822800", "40.48800000"], ["0.02839400", "16.12800000"], ["0.02839900", "0.28000000"]]}, {"e": "depthUpdate", "E": 1604224961330, "s": "ETHBTC", "U": 1737956405, "u": 1737956445, "b": [["0.02819800", "2.14100000"], ["0.02819400", "0.00000000"], ["0.02819300", "0.26500000"], ["0.02819100", "0.00000000"], ["0.02818800", "1.72500000"], ["0.02818700", "13.95600000"], ["0.02818500", "13.51200000"], ["0.02818400", "13.27500000"], ["0.02818200", "3.41900000"], ["0.02817900", "0.00000000"], ["0.02817300", "12.04600000"], ["0.02817100", "7.62800000"], ["0.02816800", "7.09700000"], ["0.02816600", "14.64600000"]], "a": [["0.02820000", "26.65500000"], ["0.02820100", "104.00000000"], ["0.02820200", "1.72500000"], ["0.02820300", "21.14000000"], ["0.02820400", "0.00000000"], ["0.02820500", "11.00000000"], ["0.02820700", "24.00000000"], ["0.02820900", "0.00000000"], ["0.02821000", "0.00000000"], ["0.02821100", "0.00000000"], ["0.02821400", "22.91500000"], ["0.02822000", "20.24400000"], ["0.02822100", "15.62100000"], ["0.02822400", "25.06500000"], ["0.02822800", "63.29300000"], ["0.02823600", "46.72000000"], ["0.03272400", "0.06800000"]]}, {"e": "depthUpdate", "E": 1604224962330, "s": "ETHBTC", "U": 1737956446, "u": 1737956481, "b": [["0.02819900", "24.00000000"], ["0.02819800", "0.00000000"], ["0.02819700", "0.00000000"], ["0.02819600", "0.18200000"], ["0.02819300", "1.72500000"], ["0.02818800", "0.00000000"], ["0.02817700", "27.06100000"], ["0.02817400", "0.00000000"], ["0.02817200", "4.22000000"], ["0.02817000", "1.35000000"], ["0.02816800", "0.00000000"]], "a": [["0.02820000", "26.65500000"], ["0.02820200", "0.26100000"], ["0.02820300", "20.97400000"], ["0.02821400", "22.91500000"], ["0.02823200", "3.12100000"]]}, {"e": "depthUpdate", "E": 1604224963330, "s": "ETHBTC", "U": 1737956482, "u": 1737956533, "b": [["0.02819900", "0.00000000"], ["0.02819600", "0.00000000"], ["0.02819500", "0.16200000"], ["0.02819400", "24.00000000"], ["0.02819300", "0.00000000"], ["0.02819200", "14.84400000"], ["0.02818200", "5.13500000"], ["0.02817700", "17.59500000"], ["0.02816900", "16.18500000"], ["0.02816700", "12.49600000"], ["0.02816600", "14.93600000"], ["0.02814900", "0.01000000"], ["0.02814000", "0.39400000"], ["0.02720900", "0.00900000"], ["0.01410500", "0.00000000"]], "a": [["0.02819800", "4.00000000"], ["0.02819900", "0.39600000"], ["0.02820000", "136.00000000"], ["0.02820100", "0.00000000"], ["0.02820200", "0.00000000"], ["0.02820300", "21.22300000"], ["0.02820500", "0.00000000"], ["0.02820600", "6.02300000"], ["0.02821000", "7.64900000"], ["0.02821400", "0.00000000"], ["0.02821600", "0.00000000"], ["0.02822400", "65.55700000"], ["0.02822500", "16.99600000"], ["0.02822800", "7.09000000"], ["0.02823700", "4.46900000"], ["0.02998000", "6.18600000"]]}, {"e": "depthUpdate", "E": 1604224964330, "s": "ETHBTC", "U": 1737956534, "u": 1737956567, "b": [["0.02819500", "5.14900000"], ["0.02819400", "24.11400000"], ["0.02819200", "14.95500000"], ["0.02818900", "0.00000000"], ["0.02818700", "13.41800000"], ["0.02818400", "15.53900000"], ["0.02816700", "5.39800000"], ["0.02815600", "7.09800000"], ["0.02815200", "0.00000000"], ["0.02814300", "1.36100000"], ["0.02813500", "63.71800000"], ["0.02812200", "0.00000000"]], "a": [["0.02819700", "24.00000000"], ["0.02819800", "0.00000000"], ["0.02819900", "0.39600000"], ["0.02820200", "0.16800000"], ["0.02820300", "20.97400000"], ["0.02820600", "10.02300000"], ["0.02820700", "0.00000000"], ["0.02820900", "4.00000000"], ["0.02821400", "14.91500000"], ["0.02822000", "25.64200000"], ["0.02822800", "0.00000000"], ["0.02824600", "1.34500000"]]}, {"e": "depthUpdate", "E": 1604224965330, "s": "ETHBTC", "U": 1737956568, "u": 1737956596, "b": [["0.02819500", "5.14900000"], ["0.02819400", "24.28900000"], ["0.02819300", "0.00000000"], ["0.02819200", "14.84400000"], ["0.02818200", "3.41900000"], ["0.02817900", "1.60500000"], ["0.02817000", "1.35000000"], ["0.02815600", "0.00000000"], ["0.02815500", "157.10100000"], ["0.02811100", "0.10900000"]], "a": [["0.02819700", "0.00000000"], ["0.02820200", "0.00000000"], ["0.02820300", "21.25200000"], ["0.02820400", "0.00000000"], ["0.02821400", "0.00000000"], ["0.02821900", "20.01300000"], ["0.02822400", "88.36200000"]]}, {"e": "depthUpdate", "E": 1604224966330, "s": "ETHBTC", "U": 1737956597, "u": 1737956613, "b": [["0.02819600", "0.22600000"], ["0.02819400", "24.11400000"], ["0.02818700", "13.31800000"], ["0.02817200", "4.32000000"], ["0.02817000", "1.35000000"], ["0.02815600", "0.00000000"], ["0.02815500", "150.00000000"], ["0.02815300", "2.11000000"], ["0.02680800", "13.97900000"]], "a": [["0.02820300", "20.97400000"], ["0.02820500", "0.10100000"], ["0.02822400", "47.87000000"], ["0.02822700", "41.43200000"], ["0.02822900", "12.48800000"]]}, {"e": "depthUpdate", "E": 1604224967331, "s": "ETHBTC", "U": 1737956614, "u": 1737956658, "b": [["0.02819600", "0.00000000"], ["0.02819300", "0.00000000"], ["0.02819200", "15.04700000"], ["0.02819000", "11.00000000"], ["0.02818700", "11.59200000"], ["0.02818600", "11.46600000"], ["0.02818100", "13.21400000"], ["0.02817000", "1.35400000"], ["0.02816900", "38.99000000"], ["0.02794200", "2.05800000"], ["0.02777400", "0.00000000"]], "a": [["0.02819700", "24.39600000"], ["0.02819800", "8.00000000"], ["0.02819900", "1.72600000"], ["0.02820100", "11.00000000"], ["0.02820200", "0.13500000"], ["0.02820300", "20.97400000"], ["0.02820500", "0.00000000"], ["0.02820600", "6.02300000"], ["0.02820900", "0.00000000"], ["0.02821400", "14.91500000"], ["0.02821700", "27.83800000"], ["0.02821900", "5.09800000"], ["0.02822000", "5.39800000"], ["0.02822800", "3.12100000"], ["0.02822900", "5.39900000"], ["0.02823600", "50.94000000"], ["0.02823700", "1.34900000"], ["0.02836600", "17.27300000"], ["0.02838800", "0.07400000"], ["0.02998000", "5.05900000"]]}, {"e": "depthUpdate", "E": 1604224968331, "s": "ETHBTC", "U": 1737956659, "u": 1737956809, "b": [["0.02820400", "0.00000000"], ["0.02820300", "0.00000000"], ["0.02820200", "0.00000000"], ["0.02820100", "0.00000000"], ["0.02820000", "0.00000000"], ["0.02819900", "0.00000000"], ["0.02819800", "77.03200000"], ["0.02819700", "0.00000000"], ["0.02819600", "5.17400000"], ["0.02819500", "0.00000000"], ["0.02819400", "0.11400000"], ["0.02819300", "6.42100000"], ["0.02819200", "16.77100000"], ["0.02819100", "7.48000000"], ["0.02819000", "0.00000000"], ["0.02818800", "7.31900000"], ["0.02818700", "6.41600000"], ["0.02818600", "1.72600000"], ["0.02818500", "0.00000000"], ["0.02818200", "0.00800000"], ["0.02818100", "12.36500000"], ["0.02817900", "0.00000000"], ["0.02817800", "10.38500000"], ["0.02817700", "1.96900000"], ["0.02817600", "37.37000000"], ["0.02816900", "16.18500000"], ["0.02816600", "10.60600000"], ["0.02814900", "0.22100000"], ["0.02814200", "30.10000000"], ["0.02814000", "0.09900000"], ["0.02784000", "16.40800000"], ["0.02760700", "0.06000000"]], "a": [["0.02819700", "0.00000000"], ["0.02819800", "0.00000000"], ["0.02819900", "0.00000000"], ["0.02820000", "0.00000000"], ["0.02820100", "0.00000000"], ["0.02820200", "0.00000000"], ["0.02820300", "3.05000000"], ["0.02820400", "136.00000000"], ["0.02820500", "24.00000000"], ["0.02820600", "0.29700000"], ["0.02820800", "0.00000000"], ["0.02820900", "4.00000000"], ["0.02821000", "0.00000000"], ["0.02821100", "0.00000000"], ["0.02821200", "0.00000000"], ["0.02821300", "0.20800000"], ["0.02821400", "5.66400000"], ["0.02821500", "21.26400000"], ["0.02821700", "7.59100000"], ["0.02822000", "5.39800000"], ["0.02822100", "35.86000000"], ["0.02822400", "25.06500000"], ["0.02822500", "7.26900000"], ["0.02822800", "0.00000000"], ["0.02823000", "6.80200000"], ["0.02823500", "3.12000000"], ["0.02823600", "55.26800000"], ["0.02839900", "0.12400000"], ["0.02856900", "0.25900000"], ["0.02874100", "0.13200000"], ["0.02998000", "6.18600000"]]}, {"e": "depthUpdate", "E": 1604224969331, "s": "ETHBTC", "U": 1737956810, "u": 1737956832, "b": [["0.02820000", "3.61200000"], ["0.02819900", "7.75200000"], ["0.02819200", "12.92700000"], ["0.02818800", "7.09200000"], ["0.02818700", "8.15600000"], ["0.02818300", "13.02100000"], ["0.02818200", "7.10000000"], ["0.02818100", "12.36500000"], ["0.02817800", "15.61700000"], ["0.02817000", "1.35000000"], ["0.02794600", "0.18800000"], ["0.02777800", "0.77400000"], ["0.02761100", "26.20000000"]], "a": [["0.02821000", "0.24400000"], ["0.02822000", "20.31300000"], ["0.02822100", "35.85200000"], ["0.02842500", "0.15600000"]]}, {"e": "depthUpdate", "E": 1604224970331, "s": "ETHBTC", "U": 1737956833, "u": 1737956855, "b": [["0.02820000", "0.20100000"], ["0.02819900", "2.14200000"], ["0.02819800", "71.20000000"], ["0.02819300", "10.26500000"], ["0.02818900", "5.83200000"], ["0.02818800", "17.59600000"], ["0.02818700", "10.32400000"], ["0.02818200", "0.00800000"], ["0.02817200", "7.44000000"], ["0.02815600", "63.68900000"], ["0.02813500", "0.00000000"], ["0.02811100", "0.00900000"]], "a": [["0.02820400", "136.12800000"], ["0.02821000", "0.00000000"], ["0.02822100", "35.84400000"], ["0.02822800", "22.80500000"], ["0.02859500", "0.16800000"], ["0.02876700", "0.37300000"]]}, {"e": "depthUpdate", "E": 1604224971331, "s": "ETHBTC", "U": 1737956856, "u": 1737956885, "b": [["0.02820200", "77.00000000"], ["0.02820100", "0.00000000"], ["0.02820000", "3.84400000"], ["0.02819900", "5.83200000"], ["0.02819800", "24.00000000"], ["0.02819300", "6.42100000"], ["0.02818900", "5.17500000"], ["0.02818800", "47.62300000"], ["0.02818500", "1.62700000"], ["0.02817200", "14.43100000"], ["0.02815300", "2.01000000"], ["0.02804900", "0.06800000"], ["0.02804000", "0.00000000"]], "a": [["0.02820300", "115.05000000"], ["0.02820400", "24.00000000"], ["0.02821900", "20.01300000"], ["0.02822000", "5.39800000"]]}, {"e": "depthUpdate", "E": 1604224972331, "s": "ETHBTC", "U": 1737956886, "u": 1737956922, "b": [["0.02820200", "6.00000000"], ["0.02820000", "3.96800000"], ["0.02819900", "7.97400000"], ["0.02819600", "16.17400000"], ["0.02819200", "20.01900000"], ["0.02818800", "53.62500000"], ["0.02818400", "9.53700000"], ["0.02818000", "6.92300000"], ["0.02817800", "38.42200000"], ["0.02817200", "7.34000000"], ["0.02811000", "0.16300000"], ["0.02807600", "0.03900000"], ["0.02804200", "21.03900000"]], "a": [["0.02820300", "139.05000000"], ["0.02820500", "0.00000000"], ["0.02820600", "0.50400000"], ["0.02820700", "11.00000000"], ["0.02821700", "7.59100000"], ["0.02821800", "14.91500000"], ["0.02821900", "5.09800000"], ["0.02822100", "15.60100000"], ["0.02822400", "12.92100000"], ["0.02822600", "15.93000000"], ["0.02822800", "20.23900000"], ["0.02823000", "18.94300000"], ["0.02823100", "0.25000000"], ["0.02823400", "8.78700000"], ["0.02839400", "0.12800000"], ["0.02839600", "16.00000000"], ["0.02998000", "5.05900000"]]}, {"e": "depthUpdate", "E": 1604224973330, "s": "ETHBTC", "U": 1737956923, "u": 1737956959, "b": [["0.02820400", "6.00000000"], ["0.02820300", "2.14100000"], ["0.02820200", "24.00000000"], ["0.02820100", "3.41100000"], ["0.02820000", "7.87600000"], ["0.02819900", "5.83200000"], ["0.02819400", "1.83900000"], ["0.02819200", "12.92700000"], ["0.02818800", "50.21400000"], ["0.02818700", "6.41600000"], ["0.02818600", "0.00000000"], ["0.02814200", "30.00000000"], ["0.02680800", "13.97900000"]], "a": [["0.02820300", "0.00000000"], ["0.02820400", "0.00000000"], ["0.02820500", "27.08200000"], ["0.02820600", "0.29700000"], ["0.02820700", "11.24300000"], ["0.02821500", "16.92800000"], ["0.02821800", "14.91500000"], ["0.02821900", "5.09800000"], ["0.02822100", "19.93800000"], ["0.02822600", "19.97000000"], ["0.02998000", "6.18600000"]]}, {"e": "depthUpdate", "E": 1604224974331, "s": "ETHBTC", "U": 1737956960, "u": 1737957026, "b": [["0.02820400", "0.00000000"], ["0.02820300", "52.82000000"], ["0.02820200", "0.00000000"], ["0.02820100", "0.16600000"], ["0.02820000", "3.84400000"], ["0.02819900", "7.97300000"], ["0.02819700", "7.09000000"], ["0.02819600", "5.17400000"], ["0.02819200", "16.33800000"], ["0.02819100", "11.38800000"], ["0.02818400", "14.64300000"], ["0.02818300", "12.92100000"], ["0.02817800", "15.61700000"], ["0.02816500", "0.00000000"]], "a": [["0.02820400", "120.06700000"], ["0.02820500", "24.00000000"], ["0.02820600", "0.46500000"], ["0.02820700", "0.00000000"], ["0.02820900", "0.00000000"], ["0.02821200", "1.72500000"], ["0.02821800", "0.00000000"], ["0.02821900", "9.09800000"], ["0.02822000", "0.00000000"], ["0.02822600", "15.93000000"], ["0.02822700", "46.82800000"], ["0.02822900", "0.00000000"], ["0.02823000", "22.98300000"], ["0.02823200", "4.47100000"], ["0.02823600", "56.44700000"], ["0.02823700", "0.00000000"]]}, {"e": "depthUpdate", "E": 1604224975331, "s": "ETHBTC", "U": 1737957027, "u": 1737957074, "b": [["0.02820300", "0.00000000"], ["0.02820200", "0.00000000"], ["0.02820100", "70.79600000"], ["0.02820000", "0.00000000"], ["0.02819900", "8.19100000"], ["0.02819700", "0.00000000"], ["0.02819500", "3.84400000"], ["0.02818900", "7.43900000"], ["0.02818400", "12.37900000"], ["0.02818300", "13.02100000"], ["0.02817500", "12.14000000"], ["0.02817000", "6.74900000"], ["0.02816900", "4.04100000"], ["0.02807800", "0.45700000"], ["0.02805600", "0.00400000"]], "a": [["0.02820200", "111.06600000"], ["0.02820300", "24.00000000"], ["0.02820400", "0.00000000"], ["0.02820500", "0.00000000"], ["0.02822000", "14.91500000"]]}, {"e": "depthUpdate", "E": 1604224976331, "s": "ETHBTC", "U": 1737957075, "u": 1737957123, "b": [["0.02820200", "2.14100000"], ["0.02820100", "70.79600000"], ["0.02820000", "0.18300000"], ["0.02819900", "0.00000000"], ["0.02819700", "12.26400000"], ["0.02819600", "11.58700000"], ["0.02819300", "19.34700000"], ["0.02819200", "12.92700000"], ["0.02819100", "7.48000000"], ["0.02819000", "17.64300000"], ["0.02818900", "2.26400000"], ["0.02818700", "0.00000000"], ["0.02818300", "0.10000000"], ["0.02818100", "7.87400000"], ["0.02817900", "22.80500000"], ["0.02816900", "9.43900000"], ["0.02816600", "5.20700000"], ["0.02812300", "0.12600000"]], "a": [["0.02820200", "0.00000000"], ["0.02820300", "6.00000000"], ["0.02820400", "3.11200000"], ["0.02820500", "24.00000000"], ["0.02821300", "0.20800000"], ["0.02821400", "5.66400000"], ["0.02821800", "0.00000000"], ["0.02821900", "4.00000000"], ["0.02822000", "0.00000000"], ["0.02822200", "0.04800000"], ["0.02822500", "12.36400000"]]}, {"e": "depthUpdate", "E": 1604224977331, "s": "ETHBTC", "U": 1737957124, "u": 1737957186, "b": [["0.02820300", "71.18200000"], ["0.02820200", "9.74000000"], ["0.02820100", "23.79600000"], ["0.02820000", "0.00000000"], ["0.02819900", "16.33700000"], ["0.02819800", "24.00000000"], ["0.02819700", "5.17400000"], ["0.02819200", "0.00000000"], ["0.02819000", "4.49200000"], ["0.02817400", "0.00000000"], ["0.02817000", "6.75300000"], ["0.02811000", "0.06300000"]], "a": [["0.02820200", "0.00000000"], ["0.02820300", "0.00000000"], ["0.02820400", "0.00000000"], ["0.02820500", "0.00000000"], ["0.02820600", "0.00000000"], ["0.02820700", "0.10700000"], ["0.02821100", "0.29500000"], ["0.02821200", "12.72500000"], ["0.02821400", "1.66400000"], ["0.02821600", "4.00000000"], ["0.02822500", "15.06200000"], ["0.02823300", "0.00400000"], ["0.02823700", "9.87400000"], ["0.02829700", "27.57100000"], ["0.02998000", "5.05900000"]]}, {"e": "depthUpdate", "E": 1604224978331, "s": "ETHBTC", "U": 1737957187, "u": 1737957221, "b": [["0.02820400", "0.00000000"], ["0.02820300", "71.00000000"], ["0.02820200", "0.00000000"], ["0.02820100", "23.79600000"], ["0.02819900", "20.43400000"], ["0.02819500", "0.00000000"], ["0.02819200", "9.74000000"], ["0.02816500", "7.09900000"]], "a": [["0.02820600", "0.22900000"], ["0.02820700", "0.00000000"], ["0.02820900", "0.00000000"], ["0.02821000", "24.00000000"], ["0.02821100", "4.30300000"], ["0.02821600", "0.00000000"], ["0.02822000", "14.91500000"], ["0.02823100", "23.05500000"], ["0.02829700", "27.57100000"], ["0.02998000", "6.18600000"]]}, {"e": "depthUpdate", "E": 1604224979331, "s": "ETHBTC", "U": 1737957222, "u": 1737957275, "b": [["0.02820600", "71.00000000"], ["0.02820500", "3.84400000"], ["0.02820400", "5.95000000"], ["0.02820300", "24.00000000"], ["0.02820200", "0.00000000"], ["0.02820100", "23.79600000"], ["0.02820000", "3.90800000"], ["0.02819900", "16.33700000"], ["0.02819800", "7.09000000"], ["0.02819600", "13.61300000"], ["0.02819200", "8.00000000"], ["0.02818800", "43.12200000"], ["0.02818500", "0.00000000"], ["0.02817900", "22.80500000"], ["0.02817300", "4.04600000"], ["0.02817200", "0.00000000"], ["0.02817000", "6.74900000"], ["0.02816500", "0.00000000"]], "a": [["0.02820600", "0.00000000"], ["0.02820700", "0.00000000"], ["0.02820800", "0.00000000"], ["0.02820900", "5.07900000"], ["0.02821000", "24.12900000"], ["0.02821100", "0.01200000"], ["0.02821200", "11.00000000"], ["0.02821600", "4.00000000"], ["0.02821900", "4.00000000"], ["0.02822500", "35.30300000"], ["0.02822600", "13.23100000"], ["0.02822800", "0.00000000"], ["0.02823000", "25.68200000"]]}, {"e": "depthUpdate", "E": 1604224980331, "s": "ETHBTC", "U": 1737957276, "u": 1737957352, "b": [["0.02820800", "0.00000000"], ["0.02820700", "5.07900000"], ["0.02820600", "71.00000000"], ["0.02820500", "16.76700000"], ["0.02820400", "5.83200000"], ["0.02820200", "1.00000000"], ["0.02820100", "7.08900000"], ["0.02819700", "0.00000000"], ["0.02819600", "11.58700000"], ["0.02819500", "1.66600000"], ["0.02819300", "6.42100000"], ["0.02818300", "0.00000000"], ["0.02817900", "0.00000000"], ["0.02817100", "9.63800000"], ["0.02815300", "0.00000000"], ["0.02814900", "20.22100000"], ["0.02812800", "6.60000000"], ["0.02808600", "0.00000000"], ["0.02666900", "0.16000000"]], "a": [["0.02820800", "0.00000000"], ["0.02820900", "0.00000000"], ["0.02821000", "25.00000000"], ["0.02821100", "0.01600000"], ["0.02821200", "11.29500000"], ["0.02821500", "4.00000000"], ["0.02821700", "0.00000000"], ["0.02821800", "0.00000000"], ["0.02821900", "4.00000000"], ["0.02822000", "0.00000000"], ["0.02822100", "15.60100000"], ["0.02822300", "14.91500000"], ["0.02822500", "12.36400000"], ["0.02822600", "0.00000000"], ["0.02822700", "45.76800000"], ["0.02822800", "33.16100000"], ["0.02823000", "24.33900000"], ["0.02823100", "5.64500000"], ["0.02823400", "12.82700000"], ["0.02823500", "5.13000000"], ["0.02823700", "0.00000000"], ["0.02824000", "8.09600000"], ["0.02824500", "7.08600000"], ["0.02825100", "14.79400000"], ["0.02825900", "23.92500000"], ["0.02827700", "6.60000000"], ["0.02831100", "0.00000000"]]}, {"e": "depthUpdate", "E": 1604224981331, "s": "ETHBTC", "U": 1737957353, "u": 1737957395, "b": [["0.02820900", "29.07800000"], ["0.02820800", "3.41100000"], ["0.02820700", "0.00000000"], ["0.02820600", "76.17300000"], ["0.02820500", "22.12600000"], ["0.02820400", "6.83200000"], ["0.02820200", "0.00000000"], ["0.02820100", "0.00000000"], ["0.02819900", "12.92600000"], ["0.02819600", "6.41300000"], ["0.02812300", "0.02600000"], ["0.02810200", "0.18300000"]], "a": [["0.02821000", "0.00000000"], ["0.02821100", "0.02000000"], ["0.02821200", "12.00000000"], ["0.02821400", "0.00000000"], ["0.02821500", "0.13100000"], ["0.02822400", "16.92100000"], ["0.02822700", "5.27500000"], ["0.02823000", "18.94000000"], ["0.02823500", "10.52700000"], ["0.02824100", "48.31900000"], ["0.02824500", "0.00000000"], ["0.02857800", "0.04300000"]]}, {"e": "depthUpdate", "E": 1604224982331, "s": "ETHBTC", "U": 1737957396, "u": 1737957440, "b": [["0.02820900", "0.00000000"], ["0.02820800", "0.00000000"], ["0.02820700", "5.33400000"], ["0.02820600", "71.00000000"], ["0.02820500", "18.09600000"], ["0.02820400", "1.00000000"], ["0.02820000", "7.75200000"], ["0.02819800", "10.50100000"], ["0.02819500", "14.58900000"]], "a": [["0.02820900", "0.00000000"], ["0.02821000", "143.00000000"], ["0.02821100", "24.02000000"], ["0.02821200", "11.00000000"], ["0.02821300", "11.20800000"], ["0.02821400", "0.24600000"], ["0.02821500", "0.00000000"], ["0.02821600", "0.00000000"], ["0.02822100", "1.66400000"], ["0.02822200", "19.64900000"], ["0.02822300", "14.91500000"], ["0.02822700", "5.27500000"], ["0.02823000", "16.24100000"], ["0.02823300", "22.80900000"], ["0.02823400", "15.52500000"], ["0.02823500", "5.13000000"], ["0.02823900", "5.39700000"], ["0.02998000", "5.05900000"]]}, {"e": "depthUpdate", "E": 1604224983332, "s": "ETHBTC", "U": 1737957441, "u": 1737957509, "b": [["0.02820800", "0.00000000"], ["0.02820700", "5.07800000"], ["0.02820600", "24.00000000"], ["0.02820500", "12.92300000"], ["0.02820400", "0.00000000"], ["0.02820300", "25.00000000"], ["0.02820200", "0.00000000"], ["0.02820100", "0.15300000"], ["0.02820000", "3.84400000"], ["0.02818300", "2.69700000"], ["0.02817800", "12.91900000"], ["0.02807500", "0.06000000"]], "a": [["0.02820800", "130.00000000"], ["0.02820900", "24.00000000"], ["0.02821000", "24.00000000"], ["0.02821100", "0.30300000"], ["0.02821200", "0.00000000"], ["0.02821300", "0.20800000"], ["0.02821400", "0.00000000"], ["0.02822100", "1.66400000"], ["0.02822200", "15.64900000"], ["0.02822300", "14.91500000"], ["0.02823000", "2.75700000"], ["0.02823200", "16.60800000"], ["0.02998000", "6.18600000"]]}, {"e": "depthUpdate", "E": 1604224984331, "s": "ETHBTC", "U": 1737957510, "u": 1737957548, "b": [["0.02820700", "0.00000000"], ["0.02820600", "0.00000000"], ["0.02820500", "0.00000000"], ["0.02820400", "5.07800000"], ["0.02820300", "24.00000000"], ["0.02820000", "4.84400000"], ["0.02819900", "18.09900000"], ["0.02819700", "1.72600000"], ["0.02819500", "14.68900000"], ["0.02819400", "5.28800000"], ["0.02819100", "24.31200000"], ["0.02818700", "0.10000000"], ["0.02818400", "35.18400000"], ["0.02809800", "2.85900000"], ["0.02808500", "1.68200000"], ["0.02807800", "0.04400000"], ["0.02805200", "21.15200000"], ["0.02804200", "0.00000000"]], "a": [["0.02820700", "5.13000000"], ["0.02820800", "129.00000000"], ["0.02820900", "25.00000000"], ["0.02821000", "0.00000000"], ["0.02821700", "12.92400000"], ["0.02822100", "1.66400000"], ["0.02822300", "14.91500000"], ["0.02822400", "16.92100000"], ["0.02822800", "20.23800000"], ["0.02823700", "1.86600000"], ["0.02839600", "0.00000000"], ["0.02840700", "16.85500000"]]}, {"e": "depthUpdate", "E": 1604224985331, "s": "ETHBTC", "U": 1737957549, "u": 1737957584, "b": [["0.02820400", "8.07800000"], ["0.02820300", "0.00000000"], ["0.02820100", "0.00000000"], ["0.02820000", "1.00000000"], ["0.02819800", "0.20800000"], ["0.02819600", "13.50400000"], ["0.02819500", "7.59800000"], ["0.02819400", "9.28800000"], ["0.02819100", "31.40300000"], ["0.02818900", "5.67500000"], ["0.02818400", "12.37900000"]], "a": [["0.02820500", "25.55200000"], ["0.02820600", "0.00000000"], ["0.02820700", "5.40700000"], ["0.02820800", "123.00000000"], ["0.02821000", "0.00000000"], ["0.02821100", "0.02000000"], ["0.02822100", "1.66400000"], ["0.02822300", "14.91500000"], ["0.02822400", "52.42100000"], ["0.02822800", "0.00000000"], ["0.02822900", "20.23700000"], ["0.02823200", "13.48700000"], ["0.02823400", "11.97900000"]]}, {"e": "depthUpdate", "E": 1604224986332, "s": "ETHBTC", "U": 1737957585, "u": 1737957705, "b": [["0.02820400", "0.00000000"], ["0.02820300", "87.12900000"], ["0.02820200", "3.00000000"], ["0.02820100", "0.20700000"], ["0.02820000", "24.00000000"], ["0.02819900", "12.92600000"], ["0.02819800", "1.00000000"], ["0.02819700", "0.00000000"], ["0.02819600", "0.00000000"], ["0.02819500", "7.65800000"], ["0.02819400", "4.11400000"], ["0.02819300", "0.00000000"], ["0.02819200", "8.00000000"], ["0.02819100", "16.83200000"], ["0.02819000", "15.17700000"], ["0.02818800", "6.00200000"], ["0.02818500", "6.41700000"], ["0.02818400", "16.86800000"]], "a": [["0.02820100", "0.00000000"], ["0.02820200", "0.00000000"], ["0.02820300", "0.00000000"], ["0.02820400", "0.00000000"], ["0.02820500", "0.00000000"], ["0.02820600", "1.13100000"], ["0.02820700", "0.29500000"], ["0.02820800", "99.00000000"], ["0.02820900", "0.00000000"], ["0.02821300", "1.90100000"], ["0.02821400", "4.00000000"], ["0.02821500", "7.47400000"], ["0.02821600", "4.00000000"], ["0.02821900", "0.00000000"], ["0.02822000", "0.00000000"], ["0.02822100", "14.91500000"], ["0.02822300", "0.00000000"], ["0.02822400", "48.42100000"], ["0.02822700", "0.93900000"], ["0.02823200", "53.96800000"], ["0.02823600", "59.56700000"], ["0.02823800", "3.57400000"], ["0.02824100", "7.85000000"], ["0.02857800", "4.44200000"]]}, {"e": "depthUpdate", "E": 1604224987333, "s": "ETHBTC", "U": 1737957706, "u": 1737957825, "b": [["0.02820800", "89.74600000"], ["0.02820700", "0.00000000"], ["0.02820600", "8.49000000"], ["0.02820500", "37.74000000"], ["0.02820400", "25.00000000"], ["0.02820300", "0.00000000"], ["0.02820200", "1.00000000"], ["0.02820100", "0.00000000"], ["0.02820000", "0.00000000"], ["0.02819900", "12.92600000"], ["0.02819800", "0.00000000"], ["0.02819600", "0.00000000"], ["0.02819500", "1.82600000"], ["0.02819400", "6.52800000"], ["0.02819300", "7.09200000"], ["0.02819100", "20.40900000"], ["0.02819000", "0.00000000"], ["0.02818900", "2.26400000"], ["0.02818800", "52.40200000"], ["0.02818500", "1.74300000"], ["0.02817900", "22.80500000"], ["0.02817600", "41.58900000"], ["0.02817000", "6.75300000"], ["0.02813300", "0.10000000"]], "a": [["0.02820500", "0.00000000"], ["0.02820600", "0.00000000"], ["0.02820700", "0.00000000"], ["0.02820800", "0.00000000"], ["0.02820900", "0.00000000"], ["0.02821100", "1.02000000"], ["0.02821200", "0.29500000"], ["0.02821300", "0.20800000"], ["0.02821400", "0.00000000"], ["0.02821500", "11.00000000"], ["0.02822000", "4.33500000"], ["0.02822100", "0.00000000"], ["0.02822300", "18.91500000"], ["0.02822400", "12.92100000"], ["0.02822600", "5.23600000"], ["0.02823800", "18.38700000"], ["0.02823900", "15.27100000"], ["0.02825100", "0.00000000"], ["0.02825800", "31.55600000"], ["0.02998000", "6.18600000"]]}, {"e": "depthUpdate", "E": 1604224988332, "s": "ETHBTC", "U": 1737957826, "u": 1737957895, "b": [["0.02821000", "24.00000000"], ["0.02820900", "5.07900000"], ["0.02820800", "24.00000000"], ["0.02820700", "1.00000000"], ["0.02820600", "0.00000000"], ["0.02820500", "24.00000000"], ["0.02820400", "0.00000000"], ["0.02820200", "0.00000000"], ["0.02820000", "3.90800000"], ["0.02819800", "7.31800000"], ["0.02819600", "4.00000000"], ["0.02819500", "7.65800000"], ["0.02819400", "9.93900000"], ["0.02819300", "9.35600000"], ["0.02818900", "0.00000000"], ["0.02818800", "46.40000000"], ["0.02818600", "7.09300000"], ["0.02818400", "12.37900000"], ["0.02817100", "2.01000000"], ["0.02700900", "0.05400000"]], "a": [["0.02821100", "123.15200000"], ["0.02821200", "1.29500000"], ["0.02821300", "0.42700000"], ["0.02821400", "0.00000000"], ["0.02821600", "0.00000000"], ["0.02822000", "0.00000000"], ["0.02822100", "1.77200000"], ["0.02822300", "4.00000000"], ["0.02822400", "17.25400000"], ["0.02822500", "16.36400000"], ["0.02822600", "0.00000000"], ["0.02825800", "31.50500000"], ["0.02857800", "0.04300000"], ["0.03637400", "0.00300000"]]}, {"e": "depthUpdate", "E": 1604224989332, "s": "ETHBTC", "U": 1737957896, "u": 1737957997, "b": [["0.02821000", "0.00000000"], ["0.02820900", "0.00000000"], ["0.02820800", "0.00000000"], ["0.02820700", "0.00000000"], ["0.02820600", "0.00000000"], ["0.02820500", "0.00000000"], ["0.02820300", "3.00000000"], ["0.02820200", "24.00000000"], ["0.02820100", "0.00000000"], ["0.02820000", "0.00000000"], ["0.02819800", "0.00000000"], ["0.02819500", "11.00800000"], ["0.02819400", "9.93900000"], ["0.02819200", "14.42000000"], ["0.02819000", "3.90800000"], ["0.02818900", "9.66800000"], ["0.02818700", "0.00000000"], ["0.02818600", "0.00000000"], ["0.02818500", "0.00000000"], ["0.02817400", "1.35000000"], ["0.02817000", "5.39900000"], ["0.02816100", "0.00000000"]], "a": [["0.02820500", "11.13200000"], ["0.02820600", "118.00000000"], ["0.02820700", "24.00000000"], ["0.02820800", "0.00000000"], ["0.02820900", "0.00000000"], ["0.02821000", "4.00000000"], ["0.02821100", "24.02000000"], ["0.02821200", "0.29500000"], ["0.02821300", "0.20800000"], ["0.02821500", "0.00000000"], ["0.02821800", "7.76300000"], ["0.02822100", "1.77200000"], ["0.02822200", "0.04800000"], ["0.02822300", "4.00000000"], ["0.02822500", "12.36400000"], ["0.02823100", "21.24600000"], ["0.02823200", "41.83100000"], ["0.02823700", "14.00300000"], ["0.02823800", "3.57400000"], ["0.02824300", "14.81500000"]]}, {"e": "depthUpdate", "E": 1604224990332, "s": "ETHBTC", "U": 1737957998, "u": 1737958076, "b": [["0.02820900", "65.79100000"], ["0.02820800", "0.00000000"], ["0.02820700", "37.24300000"], ["0.02820600", "0.00000000"], ["0.02820500", "27.90800000"], ["0.02820400", "25.00000000"], ["0.02820300", "0.00000000"], ["0.02820200", "0.00000000"], ["0.02819800", "0.00000000"], ["0.02819600", "6.00200000"], ["0.02819500", "5.17600000"], ["0.02819400", "6.52800000"], ["0.02819000", "1.69100000"], ["0.02818900", "4.49200000"], ["0.02818400", "7.27300000"], ["0.02817900", "0.00000000"], ["0.02817500", "0.00000000"], ["0.02817300", "9.44500000"], ["0.02817000", "0.00000000"], ["0.02816800", "0.10000000"], ["0.02770800", "0.06100000"]], "a": [["0.02820500", "0.00000000"], ["0.02820600", "0.00000000"], ["0.02820700", "0.00000000"], ["0.02820800", "0.00000000"], ["0.02821000", "91.13200000"], ["0.02821100", "0.02000000"], ["0.02821200", "0.00000000"], ["0.02821300", "1.20800000"], ["0.02821800", "0.00000000"], ["0.02822200", "4.04800000"], ["0.02823200", "1.35000000"], ["0.02823600", "100.05400000"]]}, {"e": "depthUpdate", "E": 1604224991332, "s": "ETHBTC", "U": 1737958077, "u": 1737958131, "b": [["0.02820900", "0.00000000"], ["0.02820800", "0.00000000"], ["0.02820700", "0.00000000"], ["0.02820600", "6.23000000"], ["0.02820500", "24.00000000"], ["0.02820400", "0.00000000"], ["0.02820200", "0.00000000"], ["0.02820100", "0.00000000"], ["0.02820000", "4.16300000"], ["0.02819900", "12.92600000"], ["0.02819700", "9.24300000"], ["0.02819600", "9.91000000"], ["0.02818400", "12.50000000"], ["0.02817900", "7.09500000"], ["0.02817800", "25.05000000"], ["0.02817700", "4.66800000"], ["0.02817300", "12.14400000"], ["0.02816900", "4.04100000"], ["0.02816800", "0.20000000"], ["0.02815900", "0.10000000"]], "a": [["0.02820900", "6.00000000"], ["0.02821000", "115.14400000"], ["0.02821100", "0.31500000"], ["0.02821200", "0.00000000"], ["0.02821400", "0.00000000"], ["0.02822300", "18.91500000"], ["0.02822600", "20.24000000"], ["0.02822900", "0.00000000"]]}, {"e": "depthUpdate", "E": 1604224992332, "s": "ETHBTC", "U": 1737958132, "u": 1737958211, "b": [["0.02820600", "0.00000000"], ["0.02820500", "0.00000000"], ["0.02820400", "0.00000000"], ["0.02820300", "91.92700000"], ["0.02820200", "3.00000000"], ["0.02820100", "4.00000000"], ["0.02820000", "0.00000000"], ["0.02819800", "0.00000000"], ["0.02819600", "10.06100000"], ["0.02819500", "9.17600000"], ["0.02818500", "0.00000000"], ["0.02817900", "0.00000000"], ["0.02816800", "0.10000000"], ["0.02815900", "0.00000000"], ["0.02813300", "0.00000000"], ["0.02809800", "2.44700000"]], "a": [["0.02820400", "5.86700000"], ["0.02820500", "112.00000000"], ["0.02820600", "24.20100000"], ["0.02820700", "0.00000000"], ["0.02820800", "1.00000000"], ["0.02820900", "0.00000000"], ["0.02821000", "9.50000000"], ["0.02821300", "0.20800000"], ["0.02821700", "20.31900000"], ["0.02822200", "4.04800000"], ["0.02822300", "4.00000000"], ["0.02822500", "27.27900000"], ["0.02998000", "5.05900000"]]}, {"e": "depthUpdate", "E": 1604224993332, "s": "ETHBTC", "U": 1737958212, "u": 1737958237, "b": [["0.02820300", "93.26700000"], ["0.02820200", "0.00000000"], ["0.02820100", "1.00000000"], ["0.02819600", "4.05900000"], ["0.02819300", "7.09200000"], ["0.02819200", "19.59400000"], ["0.02818500", "0.00000000"], ["0.02818200", "22.81300000"], ["0.02817700", "11.76400000"], ["0.02817500", "5.39400000"], ["0.02817400", "5.39100000"], ["0.02816900", "0.00000000"], ["0.02816700", "0.00000000"], ["0.02816500", "2.26400000"], ["0.02806000", "0.41300000"]], "a": [["0.02820400", "0.00000000"], ["0.02820500", "136.13200000"], ["0.02822300", "18.91500000"], ["0.02822400", "17.25400000"], ["0.02822500", "12.36400000"], ["0.02998000", "6.18600000"]]}, {"e": "depthUpdate", "E": 1604224994332, "s": "ETHBTC", "U": 1737958238, "u": 1737958334, "b": [["0.02820800", "5.15700000"], ["0.02820700", "27.00000000"], ["0.02820600", "3.00000000"], ["0.02820500", "0.00000000"], ["0.02820400", "1.00000000"], ["0.02820300", "87.00000000"], ["0.02820100", "0.00000000"], ["0.02820000", "0.24700000"], ["0.02819800", "0.00000000"], ["0.02819700", "3.90800000"], ["0.02819600", "0.00000000"], ["0.02819400", "6.52800000"], ["0.02819200", "14.42000000"], ["0.02817700", "4.66800000"]], "a": [["0.02820400", "0.00000000"], ["0.02820500", "0.00000000"], ["0.02820600", "0.00000000"], ["0.02820700", "0.00000000"], ["0.02820800", "0.00000000"], ["0.02820900", "112.00000000"], ["0.02821000", "0.00000000"], ["0.02821100", "0.49000000"], ["0.02821200", "1.00000000"], ["0.02821600", "0.00000000"], ["0.02821700", "12.92400000"], ["0.02822200", "4.04800000"], ["0.02822300", "20.26200000"], ["0.02822400", "17.25400000"], ["0.02822600", "0.00000000"], ["0.02823100", "41.48800000"], ["0.02823500", "10.52800000"], ["0.02823600", "94.65500000"], ["0.02824200", "4.21900000"], ["0.02824600", "0.00000000"]]}, {"e": "depthUpdate", "E": 1604224995332, "s": "ETHBTC", "U": 1737958335, "u": 1737958375, "b": [["0.02820800", "1.45100000"], ["0.02820700", "29.18300000"], ["0.02820600", "0.25400000"], ["0.02820400", "5.00000000"], ["0.02820000", "0.00000000"], ["0.02819800", "5.83200000"], ["0.02819700", "7.31900000"], ["0.02819500", "5.17600000"], ["0.02819400", "8.67800000"], ["0.02817900", "0.00000000"], ["0.02816800", "0.00000000"], ["0.02816500", "0.00000000"], ["0.02680800", "13.97900000"]], "a": [["0.02820900", "142.00000000"], ["0.02821100", "0.02000000"], ["0.02821500", "0.00000000"], ["0.02821600", "0.24000000"], ["0.02821700", "12.92400000"], ["0.02822700", "3.63600000"], ["0.02823000", "0.06000000"], ["0.02823300", "0.00400000"], ["0.02823600", "94.64900000"], ["0.02823700", "21.09000000"]]}, {"e": "depthUpdate", "E": 1604224996332, "s": "ETHBTC", "U": 1737958376, "u": 1737958419, "b": [["0.02820800", "1.34000000"], ["0.02820700", "0.00000000"], ["0.02820600", "0.00000000"], ["0.02820400", "1.00000000"], ["0.02820300", "87.29300000"], ["0.02820200", "0.00000000"], ["0.02819800", "9.83200000"], ["0.02819500", "10.35100000"], ["0.02819400", "21.77100000"], ["0.02818100", "7.87400000"], ["0.02817700", "7.78800000"], ["0.02817600", "41.58900000"], ["0.02805200", "0.12000000"], ["0.02804700", "21.10200000"]], "a": [["0.02820900", "144.02600000"], ["0.02821200", "1.00000000"], ["0.02821400", "0.29500000"], ["0.02821500", "0.00000000"], ["0.02821600", "0.00000000"], ["0.02822000", "0.73000000"], ["0.02822200", "18.96300000"], ["0.02822300", "5.34700000"], ["0.02839900", "16.12400000"], ["0.02840700", "0.85500000"]]}, {"e": "depthUpdate", "E": 1604224997332, "s": "ETHBTC", "U": 1737958420, "u": 1737958456, "b": [["0.02820800", "0.00000000"], ["0.02820700", "0.00000000"], ["0.02820600", "0.00000000"], ["0.02820500", "1.34000000"], ["0.02820400", "5.13900000"], ["0.02820300", "87.40400000"], ["0.02819400", "14.68000000"], ["0.02817200", "0.00400000"], ["0.02680800", "13.97900000"]], "a": [["0.02820700", "24.00000000"], ["0.02820800", "6.18600000"], ["0.02820900", "138.02600000"], ["0.02821400", "0.00000000"], ["0.02822200", "18.96300000"], ["0.02822300", "5.34700000"], ["0.02823100", "46.88600000"], ["0.02823200", "24.15500000"], ["0.02823900", "9.87400000"], ["0.02998000", "6.18600000"]]}, {"e": "depthUpdate", "E": 1604224998332, "s": "ETHBTC", "U": 1737958457, "u": 1737958504, "b": [["0.02820500", "0.00000000"], ["0.02820400", "5.13900000"], ["0.02820300", "63.00000000"], ["0.02820200", "0.17000000"], ["0.02819800", "0.00000000"], ["0.02819700", "0.00000000"], ["0.02819400", "8.67800000"], ["0.02819300", "4.00000000"], ["0.02819000", "8.78300000"], ["0.02818900", "5.83200000"], ["0.02818500", "7.31900000"], ["0.02818400", "14.36400000"], ["0.02818300", "7.17800000"], ["0.02818200", "0.00800000"], ["0.02817600", "41.58900000"]], "a": [["0.02820500", "92.00000000"], ["0.02820600", "24.00000000"], ["0.02820700", "0.14500000"], ["0.02820800", "0.00000000"], ["0.02820900", "26.02600000"], ["0.02821100", "0.74800000"], ["0.02821200", "0.00000000"], ["0.02821900", "7.39600000"], ["0.02822000", "0.00000000"], ["0.02822200", "4.04800000"], ["0.02822300", "20.26200000"]]}, {"e": "depthUpdate", "E": 1604224999332, "s": "ETHBTC", "U": 1737958505, "u": 1737958555, "b": [["0.02820400", "0.00000000"], ["0.02820300", "63.00000000"], ["0.02820200", "0.00000000"], ["0.02820000", "5.30300000"], ["0.02819800", "0.00000000"], ["0.02819500", "5.17600000"], ["0.02819400", "6.41400000"], ["0.02819200", "20.26700000"], ["0.02819000", "15.20400000"], ["0.02818900", "8.09600000"], ["0.02818400", "7.27300000"], ["0.02817800", "19.81800000"], ["0.02817200", "0.00000000"]], "a": [["0.02820400", "142.00000000"], ["0.02820500", "24.00000000"], ["0.02820600", "0.00000000"], ["0.02820700", "0.00000000"], ["0.02820800", "4.00000000"], ["0.02820900", "2.02600000"], ["0.02821100", "13.67600000"], ["0.02821400", "4.00000000"], ["0.02821500", "4.33700000"], ["0.02821600", "5.09900000"], ["0.02822200", "0.04800000"], ["0.02822300", "1.34700000"], ["0.02822400", "20.24300000"], ["0.02822500", "7.26900000"], ["0.02822600", "5.23200000"], ["0.02823000", "14.97500000"], ["0.02823100", "26.64400000"], ["0.02823200", "1.35000000"], ["0.02823700", "14.00300000"]]}, {"e": "depthUpdate", "E": 1604225000332, "s": "ETHBTC", "U": 1737958556, "u": 1737958578, "b": [["0.02819400", "9.82500000"], ["0.02819100", "26.51100000"], ["0.02818500", "3.90800000"], ["0.02818100", "12.98000000"], ["0.02817800", "7.68700000"], ["0.02815500", "150.10000000"], ["0.02791400", "0.07600000"], ["0.02680800", "13.97900000"]], "a": [["0.02820900", "2.27200000"], ["0.02822300", "16.26200000"], ["0.02822600", "45.71900000"], ["0.02823000", "0.06000000"], ["0.02823600", "54.16800000"]]}, {"e": "depthUpdate", "E": 1604225001332, "s": "ETHBTC", "U": 1737958579, "u": 1737958602, "b": [["0.02820300", "0.00000000"], ["0.02820000", "5.41100000"], ["0.02819400", "3.41100000"], ["0.02817600", "53.72700000"], ["0.02815500", "150.00000000"], ["0.02791600", "1.23400000"]], "a": [["0.02820300", "6.00000000"], ["0.02820400", "136.00000000"], ["0.02820600", "0.20700000"], ["0.02820900", "2.02600000"], ["0.02822400", "59.41300000"], ["0.02822700", "26.44100000"], ["0.02823400", "11.97900000"], ["0.02998000", "5.05900000"]]}, {"e": "depthUpdate", "E": 1604225002332, "s": "ETHBTC", "U": 1737958603, "u": 1737958667, "b": [["0.02820100", "3.00000000"], ["0.02820000", "87.50000000"], ["0.02819800", "0.10300000"], ["0.02819600", "3.90800000"], ["0.02819300", "5.72600000"], ["0.02819200", "13.17500000"], ["0.02819100", "26.41100000"], ["0.02818600", "6.41600000"], ["0.02818500", "0.00000000"], ["0.02817600", "53.72700000"], ["0.02817200", "7.09700000"], ["0.02815900", "20.24400000"], ["0.02815500", "190.48800000"], ["0.02806000", "0.00000000"]], "a": [["0.02820100", "0.00000000"], ["0.02820200", "6.00000000"], ["0.02820300", "0.18200000"], ["0.02820400", "24.26800000"], ["0.02820500", "0.00000000"], ["0.02820600", "0.00000000"], ["0.02820700", "1.72600000"], ["0.02820900", "0.30000000"], ["0.02822100", "16.68700000"], ["0.02822200", "15.64900000"], ["0.02822300", "1.34700000"], ["0.02823100", "11.04300000"], ["0.02857800", "4.71000000"], ["0.02998000", "6.18600000"]]}, {"e": "depthUpdate", "E": 1604225003332, "s": "ETHBTC", "U": 1737958668, "u": 1737958709, "b": [["0.02820200", "36.83200000"], ["0.02820100", "87.50000000"], ["0.02820000", "24.00000000"], ["0.02819800", "0.00000000"], ["0.02819300", "1.72600000"], ["0.02818900", "0.00000000"], ["0.02817800", "37.58300000"], ["0.02817200", "0.00000000"], ["0.02816700", "2.26400000"], ["0.02805800", "0.41300000"], ["0.02735100", "1.05500000"], ["0.02734900", "2.01900000"], ["0.02669200", "0.00000000"]], "a": [["0.02820200", "0.00000000"], ["0.02820300", "6.00000000"], ["0.02820400", "0.00000000"], ["0.02820500", "0.00000000"], ["0.02820700", "0.00000000"], ["0.02820800", "15.00000000"], ["0.02821600", "0.00000000"], ["0.02822100", "21.78400000"], ["0.02829700", "31.83400000"]]}, {"e": "depthUpdate", "E": 1604225004332, "s": "ETHBTC", "U": 1737958710, "u": 1737958755, "b": [["0.02820300", "0.00000000"], ["0.02820200", "93.33200000"], ["0.02820100", "24.25400000"], ["0.02820000", "0.00000000"], ["0.02819800", "0.00000000"], ["0.02819700", "4.00000000"], ["0.02819200", "20.26600000"], ["0.02817800", "30.49200000"]], "a": [["0.02820300", "0.00000000"], ["0.02820400", "0.00000000"], ["0.02820500", "0.21400000"], ["0.02820600", "0.00000000"], ["0.02820700", "0.18200000"], ["0.02821000", "1.72600000"], ["0.02822700", "38.58000000"], ["0.02823200", "0.00000000"], ["0.02823500", "17.61600000"], ["0.02823700", "1.86600000"], ["0.02829700", "27.57100000"], ["0.02857400", "3.53600000"]]}, {"e": "depthUpdate", "E": 1604225005332, "s": "ETHBTC", "U": 1737958756, "u": 1737958776, "b": [["0.02820700", "0.00000000"], ["0.02820300", "5.04100000"], ["0.02817500", "10.79300000"], ["0.02817300", "6.74500000"]], "a": [["0.02820500", "0.00000000"], ["0.02820600", "0.18600000"], ["0.02820700", "6.00000000"], ["0.02820800", "15.00000000"], ["0.02820900", "2.02600000"], ["0.02821000", "0.00000000"], ["0.02822700", "39.93000000"], ["0.02823500", "10.52800000"], ["0.02829700", "31.83400000"], ["0.02858400", "0.05100000"]]}, {"e": "depthUpdate", "E": 1604225006332, "s": "ETHBTC", "U": 1737958777, "u": 1737958815, "b": [["0.02820400", "24.00000000"], ["0.02820300", "5.02100000"], ["0.02820200", "24.00000000"], ["0.02819700", "0.00000000"], ["0.02819600", "0.00000000"], ["0.02819400", "4.00000000"], ["0.02818900", "5.83200000"], ["0.02818600", "10.32400000"], ["0.02818500", "3.41100000"], ["0.02817400", "10.79000000"], ["0.02817300", "1.34700000"], ["0.02815000", "0.00000000"]], "a": [["0.02820500", "142.00000000"], ["0.02820600", "24.00000000"], ["0.02820700", "0.29100000"], ["0.02820800", "4.00000000"], ["0.02821800", "14.91500000"], ["0.02821900", "7.39600000"], ["0.02822000", "0.00000000"], ["0.02822100", "6.86900000"], ["0.02998000", "5.05900000"]]}, {"e": "depthUpdate", "E": 1604225007332, "s": "ETHBTC", "U": 1737958816, "u": 1737958861, "b": [["0.02820400", "0.00000000"], ["0.02820300", "0.00000000"], ["0.02820200", "29.02100000"], ["0.02820100", "24.10800000"], ["0.02819200", "13.17500000"], ["0.02818900", "8.09600000"], ["0.02817900", "0.00400000"], ["0.02816800", "20.24400000"], ["0.02816700", "0.00000000"], ["0.02816400", "73.64800000"], ["0.02815900", "0.00000000"], ["0.02815500", "150.00000000"]], "a": [["0.02820300", "142.00000000"], ["0.02820400", "24.00000000"], ["0.02820500", "0.00000000"], ["0.02820600", "0.00000000"], ["0.02820700", "0.00000000"], ["0.02821700", "12.92400000"], ["0.02821800", "0.00000000"], ["0.02821900", "22.31100000"], ["0.02822000", "20.24400000"], ["0.02822100", "6.86900000"], ["0.02822400", "39.17000000"], ["0.02822700", "17.12500000"], ["0.02823300", "0.00400000"], ["0.02829700", "27.57100000"], ["0.02998000", "6.18600000"]]}, {"e": "depthUpdate", "E": 1604225008332, "s": "ETHBTC", "U": 1737958862, "u": 1737958952, "b": [["0.02820200", "0.00000000"], ["0.02820100", "0.00000000"], ["0.02820000", "0.00000000"], ["0.02819900", "0.00000000"], ["0.02819800", "0.00000000"], ["0.02819700", "5.02100000"], ["0.02819600", "24.00000000"], ["0.02819500", "0.36300000"], ["0.02819400", "0.63700000"], ["0.02819300", "3.84400000"], ["0.02819200", "14.90100000"], ["0.02819100", "12.92400000"], ["0.02819000", "18.68900000"], ["0.02818700", "12.92900000"], ["0.02818600", "16.32700000"], ["0.02818300", "8.81800000"], ["0.02818100", "3.54600000"], ["0.02817800", "7.68700000"], ["0.02817600", "41.58900000"], ["0.02817500", "5.39400000"], ["0.02817300", "13.48700000"], ["0.02817100", "6.33900000"], ["0.02816800", "25.64400000"], ["0.02816700", "0.00000000"], ["0.02809800", "2.85900000"], ["0.02805800", "0.00000000"], ["0.02805100", "21.04100000"], ["0.02804700", "0.06600000"]], "a": [["0.02819800", "6.00000000"], ["0.02819900", "0.00000000"], ["0.02820000", "0.00000000"], ["0.02820100", "0.00000000"], ["0.02820200", "136.00000000"], ["0.02820300", "24.00000000"], ["0.02820400", "0.00000000"], ["0.02820500", "6.50000000"], ["0.02820700", "1.60400000"], ["0.02820800", "4.21900000"], ["0.02821100", "21.31500000"], ["0.02821300", "0.00000000"], ["0.02821600", "14.91500000"], ["0.02821800", "0.00000000"], ["0.02821900", "7.39600000"], ["0.02822100", "13.09700000"], ["0.02822600", "49.71900000"], ["0.02824000", "0.09600000"], ["0.02839900", "0.12400000"], ["0.02840500", "16.26400000"]]}, {"e": "depthUpdate", "E": 1604225009332, "s": "ETHBTC", "U": 1737958953, "u": 1737958987, "b": [["0.02819800", "5.26300000"], ["0.02819700", "77.00000000"], ["0.02819600", "24.17700000"], ["0.02819500", "0.10800000"], ["0.02819400", "0.00000000"], ["0.02818900", "5.83200000"], ["0.02818100", "5.81000000"], ["0.02817900", "0.00000000"], ["0.02817600", "46.83600000"], ["0.02817500", "5.39400000"], ["0.02816900", "7.09700000"], ["0.02784000", "14.91100000"]], "a": [["0.02819800", "0.00000000"], ["0.02819900", "6.00000000"], ["0.02820000", "0.00000000"], ["0.02820100", "4.00000000"], ["0.02822600", "45.71900000"], ["0.02822800", "5.40000000"], ["0.02823500", "5.13000000"]]}, {"e": "depthUpdate", "E": 1604225010332, "s": "ETHBTC", "U": 1737958988, "u": 1737959011, "b": [["0.02819800", "82.26300000"], ["0.02819700", "24.00000000"], ["0.02818300", "6.12100000"], ["0.02818100", "3.54600000"], ["0.02817700", "7.78700000"], ["0.02817400", "5.39100000"], ["0.02817200", "2.69900000"], ["0.02817000", "5.39900000"], ["0.02816900", "0.00000000"], ["0.02815600", "65.95300000"]], "a": [["0.02820100", "0.10300000"], ["0.02820600", "4.00000000"], ["0.02820700", "1.60400000"], ["0.02820800", "4.00000000"], ["0.02822500", "11.31800000"], ["0.02822600", "68.52400000"], ["0.02822700", "14.42800000"], ["0.02823400", "7.93900000"]]}, {"e": "depthUpdate", "E": 1604225011333, "s": "ETHBTC", "U": 1737959012, "u": 1737959044, "b": [["0.02819900", "0.00000000"], ["0.02819800", "77.00000000"], ["0.02819600", "0.00000000"], ["0.02816500", "0.00000000"]], "a": [["0.02819900", "0.00000000"], ["0.02820000", "24.00000000"], ["0.02820100", "6.00000000"], ["0.02820200", "136.00000000"], ["0.02820300", "24.14000000"], ["0.02820400", "0.00000000"], ["0.02821600", "0.00000000"], ["0.02821900", "25.00900000"], ["0.02998000", "6.18600000"]]}, {"e": "depthUpdate", "E": 1604225012333, "s": "ETHBTC", "U": 1737959045, "u": 1737959073, "b": [["0.02819800", "82.26300000"], ["0.02819700", "24.16700000"], ["0.02818800", "46.40000000"], ["0.02818400", "7.27300000"], ["0.02817100", "49.38700000"], ["0.02816800", "5.40000000"], ["0.02816700", "40.48600000"], ["0.02816400", "33.16000000"], ["0.02736200", "0.00800000"]], "a": [["0.02820100", "10.00000000"], ["0.02820300", "24.00000000"], ["0.02820600", "0.00000000"], ["0.02820800", "4.21600000"], ["0.02821900", "25.00900000"], ["0.02822200", "18.34800000"], ["0.02822500", "16.71700000"], ["0.02823100", "5.64500000"], ["0.02823400", "5.24100000"], ["0.02856400", "0.32400000"]]}, {"e": "depthUpdate", "E": 1604225013333, "s": "ETHBTC", "U": 1737959074, "u": 1737959117, "b": [["0.02819900", "5.07800000"], ["0.02819800", "77.00000000"], ["0.02819700", "24.19200000"], ["0.02817200", "2.69900000"], ["0.02816900", "7.09300000"], ["0.02815600", "2.26400000"], ["0.02814300", "65.05900000"]], "a": [["0.02819900", "0.00000000"], ["0.02820000", "135.50000000"], ["0.02820100", "0.00000000"], ["0.02820200", "24.00000000"], ["0.02820300", "0.00000000"], ["0.02820400", "11.00000000"], ["0.02820500", "0.00000000"], ["0.02820600", "1.72600000"], ["0.02820800", "4.16700000"], ["0.02820900", "4.30000000"], ["0.02821000", "0.00000000"], ["0.02821500", "4.33700000"], ["0.02821600", "0.00000000"], ["0.02821800", "14.91500000"], ["0.02821900", "10.09400000"]]}, {"e": "depthUpdate", "E": 1604225014333, "s": "ETHBTC", "U": 1737959118, "u": 1737959148, "b": [["0.02820100", "0.15600000"], ["0.02820000", "5.26300000"], ["0.02819900", "77.00000000"], ["0.02819800", "24.00000000"], ["0.02819700", "0.00000000"], ["0.02818500", "10.50400000"], ["0.02816900", "0.00000000"], ["0.02809800", "2.44700000"], ["0.02807800", "0.45700000"]], "a": [["0.02820000", "0.00000000"], ["0.02820200", "0.00000000"], ["0.02820800", "4.00000000"], ["0.02821100", "21.60400000"], ["0.02821500", "4.33700000"], ["0.02821600", "0.00000000"], ["0.02821800", "14.91500000"], ["0.02823700", "0.00000000"]]}, {"e": "depthUpdate", "E": 1604225015334, "s": "ETHBTC", "U": 1737959149, "u": 1737959216, "b": [["0.02820300", "29.26300000"], ["0.02820200", "3.84400000"], ["0.02820100", "13.30700000"], ["0.02820000", "0.00000000"], ["0.02819700", "12.92500000"], ["0.02819300", "0.00000000"], ["0.02819200", "9.72600000"], ["0.02819100", "25.85400000"], ["0.02819000", "20.95300000"], ["0.02818900", "0.00000000"], ["0.02818700", "0.00000000"], ["0.02818600", "12.41900000"], ["0.02818500", "0.00000000"], ["0.02818400", "7.27300000"], ["0.02817800", "14.77900000"], ["0.02817700", "4.66700000"], ["0.02817100", "26.58200000"], ["0.02815600", "0.00000000"]], "a": [["0.02820400", "112.00000000"], ["0.02820600", "0.00000000"], ["0.02820700", "0.18100000"], ["0.02820800", "0.00000000"], ["0.02820900", "0.30000000"], ["0.02821100", "13.67600000"], ["0.02821300", "1.62100000"], ["0.02821400", "8.00000000"], ["0.02821500", "19.25200000"], ["0.02821600", "15.60100000"], ["0.02821700", "16.92400000"], ["0.02821800", "0.00000000"], ["0.02822000", "0.00000000"], ["0.02822200", "0.04800000"], ["0.02822400", "59.41100000"], ["0.02822700", "17.12700000"], ["0.02822800", "7.27600000"], ["0.02823300", "7.09200000"], ["0.02998000", "5.05900000"]]}, {"e": "depthUpdate", "E": 1604225016334, "s": "ETHBTC", "U": 1737959217, "u": 1737959264, "b": [["0.02820300", "0.00000000"], ["0.02820200", "29.07800000"], ["0.02820100", "5.98800000"], ["0.02820000", "7.31900000"], ["0.02819300", "3.84400000"], ["0.02819200", "9.72600000"], ["0.02819000", "18.68900000"], ["0.02818900", "0.00000000"], ["0.02818700", "7.09100000"], ["0.02817800", "7.68700000"], ["0.02817300", "13.48700000"], ["0.02815600", "2.26400000"]], "a": [["0.02820400", "136.00000000"], ["0.02820500", "0.12900000"], ["0.02820600", "0.00000000"], ["0.02820700", "0.00000000"], ["0.02820900", "0.30000000"], ["0.02821500", "4.33700000"], ["0.02821600", "0.00000000"], ["0.02821800", "0.00000000"], ["0.02822300", "16.94800000"], ["0.02823300", "0.00400000"], ["0.02998000", "6.18600000"]]}, {"e": "depthUpdate", "E": 1604225017333, "s": "ETHBTC", "U": 1737959265, "u": 1737959290, "b": [["0.02820300", "29.26300000"], ["0.02820200", "0.00000000"], ["0.02819800", "0.00000000"], ["0.02819300", "3.84400000"], ["0.02818300", "6.12500000"], ["0.02817600", "67.07200000"], ["0.02817100", "6.33900000"], ["0.02817000", "45.87200000"], ["0.02816700", "0.00000000"], ["0.02802200", "0.01400000"], ["0.02801500", "0.56400000"]], "a": [["0.02820400", "118.00000000"], ["0.02820500", "0.00000000"], ["0.02820600", "0.00000000"], ["0.02820700", "0.00000000"], ["0.02821300", "1.82700000"]]}, {"e": "depthUpdate", "E": 1604225018333, "s": "ETHBTC", "U": 1737959291, "u": 1737959319, "b": [["0.02820500", "0.00000000"], ["0.02820400", "5.07800000"], ["0.02820300", "77.29100000"], ["0.02820100", "9.67600000"], ["0.02819900", "24.00000000"], ["0.02819300", "0.00000000"], ["0.02818400", "12.46600000"], ["0.02817100", "9.45900000"]], "a": [["0.02820400", "0.00000000"], ["0.02820600", "142.00000000"], ["0.02820700", "0.00000000"], ["0.02820800", "24.00000000"], ["0.02820900", "11.30000000"], ["0.02821100", "12.94800000"], ["0.02821200", "1.72500000"], ["0.02821300", "1.62100000"], ["0.02821400", "8.20500000"], ["0.02821500", "4.33700000"], ["0.02821600", "0.73100000"]]}, {"e": "depthUpdate", "E": 1604225019333, "s": "ETHBTC", "U": 1737959320, "u": 1737959349, "b": [["0.02820400", "0.00000000"], ["0.02820300", "29.26200000"], ["0.02820200", "0.12300000"], ["0.02820100", "5.83200000"], ["0.02819300", "3.84400000"], ["0.02819200", "11.99000000"], ["0.02818300", "6.12100000"], ["0.02816900", "0.00000000"], ["0.02815600", "63.68900000"], ["0.02814300", "1.36100000"]], "a": [["0.02820500", "136.43000000"], ["0.02820600", "24.00000000"], ["0.02820800", "0.00000000"], ["0.02820900", "0.30000000"], ["0.02821200", "1.95000000"], ["0.02821400", "8.00000000"], ["0.02822500", "11.31800000"], ["0.02822600", "28.03700000"], ["0.02823200", "40.47100000"], ["0.02823300", "5.40100000"]]}, {"e": "depthUpdate", "E": 1604225020334, "s": "ETHBTC", "U": 1737959350, "u": 1737959393, "b": [["0.02820300", "0.00000000"], ["0.02820200", "0.00000000"], ["0.02820100", "5.83200000"], ["0.02820000", "5.18800000"], ["0.02819800", "0.00000000"], ["0.02819600", "1.72500000"], ["0.02819200", "10.26400000"], ["0.02819000", "22.10000000"], ["0.02818900", "3.90800000"], ["0.02818700", "0.00000000"], ["0.02818500", "7.09200000"], ["0.02818400", "7.27300000"], ["0.02805100", "0.00800000"], ["0.02804800", "21.03500000"]], "a": [["0.02820400", "127.12700000"], ["0.02820500", "24.00000000"], ["0.02820600", "0.00000000"], ["0.02821100", "12.94800000"], ["0.02821200", "1.72500000"], ["0.02839900", "16.12400000"], ["0.02840500", "0.26400000"], ["0.02998000", "6.18600000"], ["0.03333400", "0.03000000"], ["0.03531400", "0.00000000"]]}, {"e": "depthUpdate", "E": 1604225021334, "s": "ETHBTC", "U": 1737959394, "u": 1737959411, "b": [["0.02820200", "29.26200000"], ["0.02820000", "0.11000000"], ["0.02819600", "0.00000000"], ["0.02819400", "1.72500000"], ["0.02818500", "0.00000000"], ["0.02817900", "0.00000000"], ["0.02814200", "30.00000000"]], "a": [["0.02820400", "127.00000000"], ["0.02820500", "24.13000000"]]}, {"e": "depthUpdate", "E": 1604225022333, "s": "ETHBTC", "U": 1737959412, "u": 1737959442, "b": [["0.02820000", "0.17200000"], ["0.02819900", "24.00000000"], ["0.02819500", "7.19900000"], ["0.02817800", "27.92400000"], ["0.02817600", "46.83600000"], ["0.02817500", "5.39400000"], ["0.02817300", "53.96100000"], ["0.02817000", "5.39900000"]], "a": [["0.02820500", "24.28700000"], ["0.02822000", "14.91500000"], ["0.03333400", "0.02700000"]]}, {"e": "depthUpdate", "E": 1604225023333, "s": "ETHBTC", "U": 1737959443, "u": 1737959472, "b": [["0.02820300", "29.07800000"], ["0.02820200", "24.00000000"], ["0.02819600", "3.84400000"], ["0.02819300", "0.00000000"], ["0.02817500", "6.74300000"], ["0.02817400", "40.33700000"], ["0.02817300", "40.47400000"], ["0.02817000", "10.79600000"], ["0.02816800", "0.00000000"], ["0.02816400", "48.00100000"], ["0.02816000", "0.00000000"], ["0.02807800", "0.04400000"], ["0.02806000", "0.41300000"]], "a": [["0.02820400", "96.69600000"], ["0.02820500", "24.00000000"], ["0.02820600", "0.25700000"], ["0.02820800", "11.00000000"], ["0.02822000", "0.00000000"], ["0.03511300", "0.04000000"]]}, {"e": "depthUpdate", "E": 1604225024333, "s": "ETHBTC", "U": 1737959473, "u": 1737959488, "b": [["0.02820100", "5.97000000"], ["0.02820000", "0.00000000"], ["0.02819500", "0.10800000"], ["0.02819200", "15.09200000"], ["0.02818900", "6.17200000"], ["0.02818400", "7.27300000"], ["0.02680800", "13.97900000"]], "a": [["0.02820400", "126.69600000"], ["0.02822000", "14.91500000"], ["0.02823000", "40.53200000"], ["0.02823200", "0.00000000"], ["0.02998000", "5.05900000"]]}, {"e": "depthUpdate", "E": 1604225025333, "s": "ETHBTC", "U": 1737959489, "u": 1737959496, "b": [["0.02818400", "12.51100000"], ["0.02818200", "0.00800000"], ["0.02817000", "5.39700000"]], "a": [["0.02820400", "136.19600000"], ["0.02998000", "6.18600000"], ["0.03333400", "0.03000000"]]}, {"e": "depthUpdate", "E": 1604225026333, "s": "ETHBTC", "U": 1737959497, "u": 1737959504, "b": [["0.02817800", "30.62200000"], ["0.02817700", "1.96900000"], ["0.02817300", "45.87100000"], ["0.02812700", "0.00000000"]], "a": [["0.02820400", "142.19600000"], ["0.02821600", "15.64600000"], ["0.02822000", "0.00000000"]]}, {"e": "depthUpdate", "E": 1604225027333, "s": "ETHBTC", "U": 1737959505, "u": 1737959558, "b": [["0.02820300", "0.00000000"], ["0.02820200", "29.26200000"], ["0.02820100", "5.83200000"], ["0.02820000", "0.00000000"], ["0.02819900", "24.25100000"], ["0.02819800", "0.00000000"], ["0.02819400", "0.00000000"], ["0.02819300", "1.72500000"], ["0.02819200", "8.00000000"], ["0.02817500", "6.74300000"], ["0.02817400", "80.80800000"], ["0.02817300", "5.39700000"], ["0.02816900", "0.00400000"], ["0.02814900", "0.22100000"], ["0.02810400", "47.00000000"], ["0.02806000", "0.00000000"]], "a": [["0.02820300", "0.00000000"], ["0.02820400", "24.30300000"], ["0.02820500", "24.00000000"], ["0.02820600", "0.00000000"], ["0.02820800", "0.00000000"], ["0.02820900", "0.00000000"], ["0.02821300", "16.53600000"], ["0.02821400", "8.00000000"], ["0.02821500", "4.33700000"], ["0.02821600", "0.73100000"], ["0.03333400", "0.03300000"]]}, {"e": "depthUpdate", "E": 1604225028333, "s": "ETHBTC", "U": 1737959559, "u": 1737959627, "b": [["0.02820500", "3.84400000"], ["0.02820400", "5.44400000"], ["0.02820300", "93.67200000"], ["0.02820200", "24.00000000"], ["0.02820000", "14.40800000"], ["0.02819900", "24.00000000"], ["0.02819800", "5.17200000"], ["0.02819600", "0.00000000"], ["0.02819200", "8.00000000"], ["0.02819100", "20.68100000"], ["0.02819000", "13.51300000"], ["0.02818900", "2.26400000"], ["0.02818500", "4.32800000"], ["0.02817900", "20.23500000"], ["0.02817800", "10.38500000"], ["0.02817500", "12.13900000"], ["0.02817400", "52.61200000"], ["0.02817100", "5.13000000"], ["0.02812400", "2.10000000"], ["0.02805800", "0.41300000"], ["0.02783000", "9.89400000"], ["0.02735400", "0.00000000"]], "a": [["0.02820400", "0.00000000"], ["0.02820500", "0.00000000"], ["0.02820600", "0.00000000"], ["0.02820700", "0.00000000"], ["0.02820800", "0.12000000"], ["0.02821000", "0.30300000"], ["0.02821300", "12.62100000"], ["0.02821500", "0.00000000"], ["0.02821900", "7.39600000"], ["0.02822000", "14.91500000"], ["0.02822200", "4.38800000"], ["0.02822300", "15.60100000"], ["0.02822400", "62.10900000"], ["0.02822500", "7.26900000"], ["0.02822600", "5.23200000"], ["0.02822700", "3.63800000"], ["0.02822800", "3.22500000"], ["0.02823100", "23.18000000"], ["0.02823400", "10.63800000"]]}, {"e": "depthUpdate", "E": 1604225029333, "s": "ETHBTC", "U": 1737959628, "u": 1737959647, "b": [["0.02820700", "5.07800000"], ["0.02820600", "24.00000000"], ["0.02820400", "0.18200000"], ["0.02819900", "0.00000000"], ["0.02817600", "46.83600000"], ["0.02816900", "0.00000000"]], "a": [["0.02820800", "0.00000000"], ["0.02820900", "24.00000000"], ["0.02821000", "0.45000000"], ["0.02821100", "0.02000000"], ["0.02822000", "0.00000000"], ["0.02822200", "19.30300000"], ["0.02822500", "20.19000000"], ["0.02822700", "44.10300000"], ["0.02823000", "0.06000000"], ["0.02856400", "0.12600000"], ["0.02998000", "5.05900000"]]}, {"e": "depthUpdate", "E": 1604225030334, "s": "ETHBTC", "U": 1737959648, "u": 1737959653, "b": [["0.02735100", "1.16100000"], ["0.02680800", "13.97900000"]], "a": [["0.02821300", "11.00000000"], ["0.02823200", "22.80500000"], ["0.02998000", "6.18600000"]]}, {"e": "depthUpdate", "E": 1604225031334, "s": "ETHBTC", "U": 1737959654, "u": 1737959658, "b": [], "a": [["0.02821800", "1.60900000"], ["0.02822400", "41.86800000"], ["0.02822700", "3.63800000"], ["0.02822900", "20.23200000"], ["0.02823200", "63.26900000"]]}, {"e": "depthUpdate", "E": 1604225032334, "s": "ETHBTC", "U": 1737959659, "u": 1737959689, "b": [["0.02820700", "0.00000000"], ["0.02820600", "29.26100000"], ["0.02820500", "0.00000000"], ["0.02820400", "0.00000000"], ["0.02820300", "88.50000000"], ["0.02820000", "7.31900000"], ["0.02819900", "3.84400000"], ["0.02819400", "18.67700000"], ["0.02819200", "8.00000000"], ["0.02818600", "6.00300000"], ["0.02818000", "29.72800000"], ["0.02817500", "52.60100000"], ["0.02817400", "12.14100000"], ["0.02804800", "0.00000000"], ["0.02804700", "21.10200000"], ["0.02792800", "0.09200000"], ["0.02680800", "1.98100000"]], "a": [["0.02820800", "136.00000000"], ["0.02821000", "0.30300000"], ["0.02822000", "14.91500000"], ["0.02822200", "4.38800000"]]}, {"e": "depthUpdate", "E": 1604225033334, "s": "ETHBTC", "U": 1737959690, "u": 1737959722, "b": [["0.02820600", "29.26100000"], ["0.02820500", "0.22200000"], ["0.02820400", "3.84400000"], ["0.02819900", "0.00000000"], ["0.02818100", "23.77700000"], ["0.02817900", "0.00000000"], ["0.02812400", "2.00000000"], ["0.02805800", "0.00000000"], ["0.02680800", "13.97900000"]], "a